Workbook

Sheet 1. População

Sheet Q1.1
A1: Quadro 1.1- População por área de residencia e município, segundo o sexo, RGPH - 2024
A2: Área de residência,município e comuna | B2: Total | C2: Homens | D2: Mulheres
A3: Cunene | B3: 1806416.5 | C3: 867639.37 | D3: 938777.16
A5: Área de residência
A6: Urbana | B6: 460652.76 | C6: 216545.6 | D6: 244107.16
A7: Rural | B7: 1345763.8 | C7: 651093.77 | D7: 694670.01
A8: Municípios / Comunas
A9: Ombadja | B9: 247337.52 | C9: 117195.4 | D9: 130142.12
A10: Xangongo | B10: 155253.8 | C10: 73739.431 | D10: 81514.367
A11: Ombala yo Mungu | B11: 92083.725 | C11: 43455.972 | D11: 48627.753
A12: CuanhamCuanhama | B12: 500288.17 | C12: 238406.12 | D12: 261882.05
A13: Ondjiva | B13: 401981.03 | C13: 190714.08 | D13: 211266.95
A14: Môngua | B14: 98307.147 | C14: 47692.045 | D14: 50615.102
A15: Curoca | B15: 35716.784 | C15: 17314.789 | D15: 18401.995
A16: Curoca | B16: 35716.784 | C16: 17314.789 | D16: 18401.995
A17: Chitado | B17: 35425.089 | C17: 17601.94 | D17: 17823.149
A18: Chitado | B18: 35425.089 | C18: 17601.94 | D18: 17823.149
A19: Cahama | B19: 140924.93 | C19: 67445.311 | D19: 73479.623
A20: Cahama | B20: 81990.081 | C20: 39045.001 | D20: 42945.08
... A41: Naulila | B41: 83503.559 | C41: 39624.95 | D41: 43878.609

Sheet Q1.2
A1: Quadro 1.2 - População por idade simples segundo o sexo, RGPH - 2024
A2: Idades Simples | B2: Total | C2: Homens | D2: Mulheres
A3: Cunene | B3: 1806416.5 | C3: 867639.37 | D3: 938777.16
A5: Idade
A6: 0 ano | B6: 55928.18 | C6: 27878.851 | D6: 28049.329
A7: 1 ano | B7: 61811.568 | C7: 31006.177 | D7: 30805.391
A8: 2 anos | B8: 61883.548 | C8: 31085.733 | D8: 30797.815
A9: 3 anos | B9: 66607.685 | C9: 33226.18 | D9: 33381.505
A10: 4 anos | B10: 66988.42 | C10: 33328.467 | D10: 33659.952
A11: 5 anos | B11: 67113.703 | C11: 33855.685 | D11: 33258.019
A12: 6 anos | B12: 63232.681 | C12: 32041.749 | D12: 31190.932
A13: 7 anos | B13: 57393.066 | C13: 28954.443 | D13: 28438.623
A14: 8 anos | B14: 54220.106 | C14: 27532.607 | D14: 26687.5
A15: 9 anos | B15: 54433.287 | C15: 26929.231 | D15: 27504.056
A16: 10 anos | B16: 54450.417 | C16: 27150.025 | D16: 27300.393
A17: 11 anos | B17: 48420.462 | C17: 24017.037 | D17: 24403.426
... A101: 95 ou mais | B101: 994 | C101: 291 | D101: 702

Sheet Q1.3
A1: Quadro 1.3 - População por grupos etários quinquenais, 2024
A2: Área de residência e grupos quinquenais | B2: Total | C2: Homens | D2: Mulheres
A3: Cunene | B3: 1806416.5 | C3: 867639.37 | D3: 938777.16
A5: Área de residência
A6: Urbana | B6: 460652.76 | C6: 216545.6 | D6: 244107.16
A7: Rural | B7: 1345763.8 | C7: 651093.77 | D7: 694670.01
A8: Grupos etários
A9: 0-4 anos | B9: 313219.4 | C9: 156525.41 | D9: 156693.99
A10: 5-9 anos | B10: 296392.84 | C10: 149313.71 | D10: 147079.13
A11: 10-14 anos | B11: 247955.25 | C11: 124099.44 | D11: 123855.81
A12: 15-19 anos | B12: 222947.75 | C12: 108515.24 | D12: 114432.51
A13: 20-24 anos | B13: 178638.56 | C13: 82625.305 | D13: 96013.254
A14: 25-29 anos | B14: 143424.46 | C14: 65544.364 | D14: 77880.094
A15: 30-34 anos | B15: 108989.34 | C15: 50129.437 | D15: 58859.903
A16: 35-39 anos | B16: 85608.959 | C16: 39083.653 | D16: 46525.306
A17: 40-44 anos | B17: 64954.912 | C17: 29529.091 | D17: 35425.821
A18: 45-49 anos | B18: 37086.555 | C18: 16301.395 | D18: 20785.16
A19: 50-54 anos | B19: 29832.023 | C19: 12959.139 | D19: 16872.884
A20: 55-59 anos | B20: 22217.555 | C20: 9824.0291 | D20: 12393.526
... A28: 95 ou mais anos | B28: 993.6733 | C28: 291.36154 | D28: 702.31176

Sheet Q1.4
A1: Quadro 1.4 - População por município, comuna e área de residência, 2024
A2: Área de residência,município e comuna | B2: Total | C2: 0 - 14 anos | D2: 15-64 anos | E2: 65 ou mais anos
A4: Cunene | B4: 1806416.5 | C4: 857567.49 | D4: 914223.77 | E4: 34625.275
A6: Área de residência
A7: Urbana | B7: 460652.76 | C7: 195887.59 | D7: 260058.81 | E7: 4706.3585
A8: Rural | B8: 1345763.8 | C8: 661679.91 | D8: 654164.96 | E8: 29918.916
A9: Sexo
A10: Homens | B10: 867639.37 | C10: 429938.57 | D10: 423505.63 | E10: 14195.178
A11: Mulheres | B11: 938777.16 | C11: 427628.93 | D11: 490718.14 | E11: 20430.097
A12: Municípios / Comunas
A13: Ombadja | B13: 247337.52 | C13: 119423.56 | D13: 122092.17 | E13: 5821.7949
A14: Xangongo | B14: 155253.8 | C14: 77360.285 | D14: 75157.106 | E14: 2736.4067
A15: Ombala yo Mungu | B15: 92083.725 | C15: 42063.272 | D15: 46935.064 | E15: 3085.3882
A16: Cuanhama | B16: 500288.17 | C16: 219401.63 | D16: 272447.93 | E16: 8438.6129
A17: Ondjiva | B17: 401981.03 | C17: 172574.02 | D17: 223184.04 | E17: 6222.9606
A18: Môngua | B18: 98307.147 | C18: 46827.608 | D18: 49263.886 | E18: 2215.6523
A19: Curoca | B19: 35716.784 | C19: 18145.104 | D19: 17134.637 | E19: 437.0423
A20: Curoca | B20: 35716.784 | C20: 18145.104 | D20: 17134.637 | E20: 437.0423
A21: Chitado | B21: 35425.089 | C21: 17242.868 | D21: 17691.907 | E21: 490.31363
A22: Chitado | B22: 35425.089 | C22: 17242.868 | D22: 17691.907 | E22: 490.31363
A23: Cahama | B23: 140924.93 | C23: 75427.466 | D23: 63240.504 | E23: 2256.9647
A24: Cahama | B24: 81990.081 | C24: 42379.851 | D24: 38287.143 | E24: 1323.0858
... A45: Naulila | B45: 83503.559 | C45: 40114.526 | D45: 41466.917 | E45: 1922.1164

Sheet Q1.5
A1: Quadro 1.5 - População por município e comuna, segundo outros grupos etários, 2024
A2: Área de residência,município e comuna | B2: Total | C2: 0-19 anos | D2: 20-29 anos | E2: 30-54 anos | F2: 55-64 anos | G2: 65-74 anos | H2: 75 ou mais anos
A3: Cunene | B3: 1806416.5 | C3: 1080515.2 | D3: 322063.02 | E3: 326471.79 | F3: 42741.211 | G3: 18511.242 | H3: 16114.032
A4: Área de residência
A5: Urbana | B5: 460652.76 | C5: 261238.97 | D5: 93761.097 | E5: 92285.851 | F5: 8660.4833 | G5: 2780.9806 | H5: 1925.3779
A6: Rural | B6: 1345763.8 | C6: 819276.28 | D6: 228301.92 | E6: 234185.94 | F6: 34080.728 | G6: 15730.261 | H6: 14188.655
A7: Municipios / Comunas
A8: Ombadja | B8: 247337.52 | C8: 149485.86 | D8: 40825.178 | E8: 44339.474 | F8: 6865.2143 | G8: 3127.7878 | H8: 2694.007
A9: Xangongo | B9: 155253.8 | C9: 96712.069 | D9: 25455.512 | E9: 26566.817 | F9: 3782.9931 | G9: 1574.222 | H9: 1162.1846
A10: Ombala yo Mungu | B10: 92083.725 | C10: 52773.792 | D10: 15369.666 | E10: 17772.657 | F10: 3082.2212 | G10: 1553.5658 | H10: 1531.8224
A11: Cuanhama | B11: 500288.17 | C11: 286207.74 | D11: 95233.749 | E11: 99247.136 | F11: 11160.932 | G11: 4582.4212 | H11: 3856.1917
A12: Ondjiva | B12: 401981.03 | C12: 227051.75 | D12: 78402.795 | E12: 81509.344 | F12: 8794.1735 | G12: 3372.4011 | H12: 2850.5595
A13: Môngua | B13: 98307.147 | C13: 59155.991 | D13: 16830.954 | E13: 17737.791 | F13: 2366.758 | G13: 1210.0201 | H13: 1005.6322
A14: Curoca | B14: 35716.784 | C14: 22133.896 | D14: 6883.7376 | E14: 5623.0391 | F14: 639.06874 | G14: 252.22342 | H14: 184.81889
A15: Curoca | B15: 35716.784 | C15: 22133.896 | D15: 6883.7376 | E15: 5623.0391 | F15: 639.06874 | G15: 252.22342 | H15: 184.81889
A16: Chitado | B16: 35425.089 | C16: 21345.625 | D16: 7142.8152 | E16: 5785.2293 | F16: 661.10559 | G16: 280.48984 | H16: 209.82379
A17: Chitado | B17: 35425.089 | C17: 21345.625 | D17: 7142.8152 | E17: 5785.2293 | F17: 661.10559 | G17: 280.48984 | H17: 209.82379
A18: Cahama | B18: 140924.93 | C18: 93152.449 | D18: 21551.167 | E18: 21071.65 | F18: 2892.7043 | G18: 1187.1895 | H18: 1069.7752
A19: Cahama | B19: 81990.081 | C19: 53269.141 | D19: 12483.45 | E19: 13035.395 | F19: 1879.009 | G19: 727.31667 | H19: 595.76911
... A40: Naulila | B40: 83503.559 | C40: 49814.999 | D40: 14049.279 | E40: 15434.147 | F40: 2283.018 | G40: 1024.1141 | H40: 898.00235

Sheet Q1.6
A1: Quadro 1.6 - População por município, comuna e área de residência, 2024
A2: Área de residência,município e comuna | B2: Grupos etários
B3: 0 - 14 anos | F3: 15 - 64 anos | J3: 65 ou mais anos
B4: Total | C4: Homens | D4: Mulheres | F4: Total | G4: Homens | H4: Mulheres | J4: Total | K4: Homens | L4: Mulheres
A5: Cunene | B5: 857567.49 | C5: 429938.57 | D5: 427628.93 | F5: 914223.77 | G5: 423505.63 | H5: 490718.14 | J5: 34625.275 | K5: 14195.178 | L5: 20430.097
A7: Área de residência
A8: Urbana | B8: 195887.59 | C8: 94101.732 | D8: 101785.86 | F8: 260058.81 | G8: 120315.19 | H8: 139743.62 | J8: 4706.3585 | K8: 2128.6787 | L8: 2577.6799
A9: Rural | B9: 661679.91 | C9: 335836.83 | D9: 325843.07 | F9: 654164.96 | G9: 303190.44 | H9: 350974.52 | J9: 29918.916 | K9: 12066.499 | L9: 17852.417
A10: Municipios / Comunas
A11: Ombadja | B11: 119423.56 | C11: 60197.379 | D11: 59226.178 | F11: 122092.17 | G11: 54834.555 | H11: 67257.614 | J11: 5821.7949 | K11: 2163.4681 | L11: 3658.3268
A12: Xangongo | B12: 77360.285 | C12: 38555.636 | D12: 38804.649 | F12: 75157.106 | G12: 33998.78 | H12: 41158.326 | J12: 2736.4067 | K12: 1185.0152 | L12: 1551.3915
A13: Ombala yo Mungu | B13: 42063.272 | C13: 21641.743 | D13: 20421.529 | F13: 46935.064 | G13: 20835.776 | H13: 26099.288 | J13: 3085.3882 | K13: 978.45292 | L13: 2106.9353
A14: Cuanhama | B14: 219401.63 | C14: 108007.3 | D14: 111394.33 | F14: 272447.93 | G14: 126934.01 | H14: 145513.92 | J14: 8438.6129 | K14: 3464.8105 | L14: 4973.8023
A15: Ondjiva | B15: 172574.02 | C15: 84247.873 | D15: 88326.15 | F15: 223184.04 | G15: 103888.52 | H15: 119295.52 | J15: 6222.9606 | K15: 2577.6799 | L15: 3645.2807
A16: Môngua | B16: 46827.608 | C16: 23759.431 | D16: 23068.177 | F16: 49263.886 | G16: 23045.483 | H16: 26218.403 | J16: 2215.6523 | K16: 887.13065 | L16: 1328.5216
A17: Curoca | B17: 18145.104 | C17: 9195.4683 | D17: 8949.6362 | F17: 17134.637 | G17: 7883.4047 | H17: 9251.2322 | J17: 437.0423 | K17: 235.91587 | L17: 201.12643
A18: Curoca | B18: 18145.104 | C18: 9195.4683 | D18: 8949.6362 | F18: 17134.637 | G18: 7883.4047 | H18: 9251.2322 | J18: 437.0423 | K18: 235.91587 | L18: 201.12643
A19: Chitado | B19: 17242.868 | C19: 8591.6324 | D19: 8651.2355 | F19: 17691.907 | G19: 8751.561 | H19: 8940.3461 | J19: 490.31363 | K19: 258.74644 | L19: 231.56719
A20: Chitado | B20: 17242.868 | C20: 8591.6324 | D20: 8651.2355 | F20: 17691.907 | G20: 8751.561 | H20: 8940.3461 | J20: 490.31363 | K20: 258.74644 | L20: 231.56719
A21: Cahama | B21: 75427.466 | C21: 37730.951 | D21: 37696.515 | F21: 63240.504 | G21: 28686.985 | H21: 34553.519 | J21: 2256.9647 | K21: 1027.3756 | L21: 1229.5892
A22: Cahama | B22: 42379.851 | C22: 21051.782 | D22: 21328.069 | F22: 38287.143 | G22: 17401.798 | H22: 20885.346 | J22: 1323.0858 | K22: 591.42043 | L22: 731.66535
... A43: Naulila | B43: 40114.526 | C43: 20224.679 | D43: 19889.847 | F43: 41466.917 | G43: 18594.678 | H43: 22872.239 | J43: 1922.1164 | K43: 805.5929 | L43: 1116.5235

Sheet Q1.7
A1: Quadro 1.7 - Idade média e mediana da população por área de residência e sexo, 2024
A2: Área de residência,município e comuna | B2: Média | C2: Mediana
A3: Cunene | B3: 19.385348 | C3: 15
A5: Área de residência
A6: Urbana | B6: 19.790324 | C6: 17
A7: Rural | B7: 19.246725 | C7: 15
A8: Sexo
A9: Homens | B9: 18.614175 | C9: 15
A10: Mulheres | B10: 20.098084 | C10: 16
A11: Município/comuna
A12: Ombadja | B12: 19.679862 | C12: 15
A13: Xangongo | B13: 18.805222 | C13: 15
A14: Ombala yo Mungu | B14: 21.154512 | C14: 16
A15: Cuanhama | B15: 20.06606 | C15: 17
A16: Ondjiva | B16: 20.191198 | C16: 17
A17: Môngua | B17: 19.554368 | C17: 15
A18: Curoca | B18: 18.00397 | C18: 14
A19: Curoca | B19: 18.00397 | C19: 14
A20: Chitado | B20: 18.323519 | C20: 15
A21: Chitado | B21: 18.323519 | C21: 15
A22: Cahama | B22: 17.516782 | C22: 13
A23: Cahama | B23: 18.045898 | C23: 14
... A44: Naulila | B44: 19.845102 | C44: 15

Sheet 2. Estado Civil

Sheet Q2.1
A1: Quadro 2.2 - População com 12 ou mais por estado civil segundo o sexo, 2024
A2: Área de residência,município e comuna | B2: População com 12 ou mais anos | C2: Estado Civil
C3: Solteiro(a) | D3: Casado(a) ou em União de facto | E3: Separado(a) | F3: Divorciado(a) | G3: Viúvo(a) | H3: Não declarado
A4: Cunene | B4: 1093933.4 | C4: 761938.45 | D4: 296339.69 | E4: 12057.934 | F4: 1162.4945 | G4: 10566.768 | H4: 11868.076
A6: Área de residência
A7: Urbana | B7: 302576.11 | C7: 205158.84 | D7: 89744.426 | E7: 2849.3301 | F7: 282.43299 | G7: 2443.5526 | H7: 2097.5283
A8: Rural | B8: 791357.31 | C8: 556779.61 | D8: 206595.26 | E8: 9208.6039 | F8: 880.0615 | G8: 8123.2157 | H8: 9770.5473
A9: Municípios / Comunas
A10: Ombadja | B10: 148246.03 | C10: 110833.26 | D10: 32580.473 | E10: 1811.9681 | F10: 194.66259 | G10: 1722.6444 | H10: 1103.0175
A11: Xangongo | B11: 91571.308 | C11: 64375.808 | D11: 24600.176 | E11: 1159.1408 | F11: 109.5742 | G11: 869.07256 | H11: 457.53648
A12: Ombala yo Mungu | B12: 56674.721 | C12: 46457.456 | D12: 7980.2967 | E12: 652.82724 | F12: 85.08839 | G12: 853.57183 | H12: 645.48105
A13: Cuanhama | B13: 320530.45 | C13: 228766.07 | D13: 83013.329 | E13: 2602.785 | F13: 255.93139 | G13: 3278.8479 | H13: 2613.4896
A14: Ondjiva | B14: 260860.6 | C14: 183054.11 | D14: 70938.653 | E14: 2111.9527 | F14: 212.16681 | G14: 2692.5384 | H14: 1851.1849
A15: Môngua | B15: 59669.847 | C15: 45711.959 | D15: 12074.677 | E15: 490.83228 | F15: 43.764575 | G15: 586.30953 | H15: 762.30474
A16: Curoca | B16: 20672.31 | C16: 12279.441 | D16: 7079.7655 | E16: 548.10058 | F16: 22.691714 | G16: 146.61785 | H16: 595.69313
A17: Curoca | B17: 20672.31 | C17: 12279.441 | D17: 7079.7655 | E17: 548.10058 | F17: 22.691714 | G17: 146.61785 | H17: 595.69313
A18: Chitado | B18: 21008.762 | C18: 14143.652 | D18: 6417.6145 | E18: 186.11894 | F18: 24.60653 | G18: 134.541 | H18: 102.2293
A19: Chitado | B19: 21008.762 | C19: 14143.652 | D19: 6417.6145 | E19: 186.11894 | F19: 24.60653 | G19: 134.541 | H19: 102.2293
A20: Cahama | B20: 77939.961 | C20: 50457.559 | D20: 25081.391 | E20: 1056.7267 | F20: 71.284038 | G20: 764.09123 | H20: 508.9097
A21: Cahama | B21: 46957.333 | C21: 30606.045 | D21: 14907.925 | E21: 590.95561 | F21: 37.739508 | G21: 506.58238 | H21: 308.08566
... A42: Naulila | B42: 49978.586 | C42: 36411.648 | D42: 11863.84 | E42: 498.21389 | F42: 81.363892 | G42: 618.39952 | H42: 505.1207

Sheet 3. Registo Civil

Sheet Q3.1
A1: Quadro 3.1 - População residente com registo de nascimento por município e área de residência, segundo sexo, RGPH 2024
A2: Área de residência,município e comuna | B2: Total da população | C2: População com registo de nascimento
C3: Total | D3: Homens | E3: Mulheres
A4: Cunene | B4: 1806416.5 | C4: 824448.41 | D4: 387607.84 | E4: 436840.56
A6: Área de residência
A7: Urbana | B7: 460652.76 | C7: 352345.76 | D7: 165100.63 | E7: 187245.13
A8: Rural | B8: 1345763.8 | C8: 472102.64 | D8: 222507.21 | E8: 249595.43
A9: Municipios / Comunas
A10: Ombadja | B10: 247337.52 | C10: 106911.23 | D10: 49208.273 | E10: 57702.959
A11: Xangongo | B11: 155253.8 | C11: 76564.505 | D11: 35792.396 | E11: 40772.109
A12: Ombala yo Mungu | B12: 92083.725 | C12: 30346.726 | D12: 13415.876 | E12: 16930.85
A13: Cuanhama | B13: 500288.17 | C13: 329951.95 | D13: 154709.86 | E13: 175242.09
A14: Ondjiva | B14: 401981.03 | C14: 285598.09 | D14: 133690.18 | E14: 151907.92
A15: Môngua | B15: 98307.147 | C15: 44353.854 | D15: 21019.683 | E15: 23334.171
A16: Curoca | B16: 35716.784 | C16: 13406.429 | D16: 6517.9306 | E16: 6888.4979
A17: Curoca | B17: 35716.784 | C17: 13406.429 | D17: 6517.9306 | E17: 6888.4979
A18: Chitado | B18: 35425.089 | C18: 8073.5062 | D18: 4044.6623 | E18: 4028.844
A19: Chitado | B19: 35425.089 | C19: 8073.5062 | D19: 4044.6623 | E19: 4028.844
A20: Cahama | B20: 140924.93 | C20: 55520.112 | D20: 25997.315 | E20: 29522.798
A21: Cahama | B21: 81990.081 | C21: 37041.355 | D21: 17293.524 | E21: 19747.831
... A42: Naulila | B42: 83503.559 | C42: 25391.967 | D42: 11711.26 | E42: 13680.706

Sheet Q3.2
A1: Quadro 3.2 - População residente com registo de nascimento por grupos etários segundo sexo, RGPH - 2024
A2: Área de residência e grupo etário | B2: Total da população | C2: População com registo de nascimento
C3: Total | D3: Homens | E3: Mulheres
A4: Cunene | B4: 1806416.5 | C4: 824448.41 | D4: 387607.84 | E4: 436840.56
A6: Área de residencia
A7: Urbana | B7: 460652.76 | C7: 352345.76 | D7: 165100.63 | E7: 187245.13
A8: Rural | B8: 1345763.8 | C8: 472102.64 | D8: 222507.21 | E8: 249595.43
A9: Grupo Etário
A10: 0-4 anos | B10: 313219.4 | C10: 81280.166 | D10: 40352.165 | E10: 40928.002
A11: 5-9 anos | B11: 296392.84 | C11: 108291.75 | D11: 53807.07 | E11: 54484.678
A12: 10-14 anos | B12: 247955.25 | C12: 101995.32 | D12: 49497.784 | E12: 52497.534
A13: 15-19 anos | B13: 222947.75 | C13: 107520.84 | D13: 50100.116 | E13: 57420.721
A14: 20-24 anos | B14: 178638.56 | C14: 92079.365 | D14: 41559.231 | E14: 50520.135
A15: 25-29 anos | B15: 143424.46 | C15: 80482.233 | D15: 36364.043 | E15: 44118.19
A16: 30-34 anos | B16: 108989.34 | C16: 64919.8 | D16: 30196.217 | E16: 34723.584
A17: 35-39 anos | B17: 85608.959 | C17: 54074.36 | D17: 25241.311 | E17: 28833.05
A18: 40-44 anos | B18: 64954.912 | C18: 41262.655 | D18: 19264.03 | E18: 21998.625
A19: 45-49 anos | B19: 37086.555 | C19: 23926.146 | D19: 10729.009 | E19: 13197.137
A20: 50-54 anos | B20: 29832.023 | C20: 19283.716 | D20: 8572.3359 | E20: 10711.38
A21: 55-59 anos | B21: 22217.555 | C21: 14794.074 | D21: 6687.4504 | E21: 8106.6237
... A23: 65 ou mais anos | B23: 34625.275 | C23: 21199.813 | D23: 9138.7503 | E23: 12061.063

Sheet Q3.3
A1: Quadro 3.3 - População residente com Bilhete de identidade por área de residência, segundo os grupos etários e sexo, RGPH 2024
A2: Área de residência e grupo etário | B2: População com 5 ou mais anos | C2: População com Bilhete de Identidade
C3: Total | D3: Homens | E3: Mulheres
A4: Cunene | B4: 1493197.1 | C4: 551841.65 | D4: 256269.08 | E4: 295572.57
A6: Área de residência
A7: Urbana | B7: 395494.13 | C7: 271370.69 | D7: 126565.37 | E7: 144805.32
A8: Rural | B8: 1097703 | C8: 280470.95 | D8: 129703.7 | E8: 150767.25
A9: Grupo Etário
A10: 5-9 anos | B10: 296392.84 | C10: 38724.569 | D10: 19336.589 | E10: 19387.98
A11: 10-14 anos | B11: 247955.25 | C11: 56321.454 | D11: 26575.199 | E11: 29746.255
A12: 15-19 anos | B12: 222947.75 | C12: 81858.494 | D12: 37436.54 | E12: 44421.953
A13: 20-24 anos | B13: 178638.56 | C13: 77632.38 | D13: 34830.031 | E13: 42802.349
A14: 25-29 anos | B14: 143424.46 | C14: 70655.465 | D14: 32014.266 | E14: 38641.199
A15: 30-34 anos | B15: 108989.34 | C15: 57633.053 | D15: 27193.118 | E15: 30439.934
A16: 35-39 anos | B16: 85608.959 | C16: 48724.962 | D16: 23213.083 | E16: 25511.879
A17: 40-44 anos | B17: 64954.912 | C17: 37036.837 | D17: 17574.529 | E17: 19462.308
A18: 45-49 anos | B18: 37086.555 | C18: 21518.253 | D18: 9812.2761 | E18: 11705.976
A19: 50-54 anos | B19: 29832.023 | C19: 17398.83 | D19: 7908.292 | E19: 9490.5381
A20: 55-59 anos | B20: 22217.555 | C20: 13548.257 | D20: 6256.9972 | E20: 7291.2601
A21: 60-64 anos | B21: 20523.656 | C21: 12115.862 | D21: 5700.1993 | E21: 6415.6625
A22: 65 ou mais anos | B22: 34625.275 | C22: 18673.23 | D22: 8417.9566 | E22: 10255.274

Sheet Q3.4
A1: Quadro 3.4 - População com 5 anos ou mais, residente com Bilhete de identidade por município, área de residencia segundo sexo, RGPH 2024
A2: Área de residência,município e comuna | B2: População com 5 ou mais anos | C2: População com bilhete de identidade
C3: Total | D3: Homens | E3: Mulheres
A4: Cunene | B4: 1493197.1 | C4: 551841.65 | D4: 256269.08 | E4: 295572.57
A6: Área de residência
A7: Urbana | B7: 395494.13 | C7: 271370.69 | D7: 126565.37 | E7: 144805.32
A8: Rural | B8: 1097703 | C8: 280470.95 | D8: 129703.7 | E8: 150767.25
A9: Municipios / Comuna
A10: Ombadja | B10: 204356.21 | C10: 70931.486 | D10: 32115.472 | E10: 38816.015
A11: Xangongo | B11: 128320.15 | C11: 53841.693 | D11: 24787.33 | E11: 29054.363
A12: Ombala yo Mungu | B12: 76036.053 | C12: 17089.793 | D12: 7328.1422 | E12: 9761.6511
A13: Cuanhama | B13: 423262.38 | C13: 238216.37 | D13: 110404.67 | E13: 127811.7
A14: Ondjiva | B14: 341758.69 | C14: 214751.45 | D14: 99599.03 | E14: 115152.42
A15: Môngua | B15: 81503.689 | C15: 23464.921 | D15: 10805.637 | E15: 12659.284
A16: Curoca | B16: 29450.767 | C16: 10597.885 | D16: 5145.6883 | E16: 5452.1966
A17: Curoca | B17: 29450.767 | C17: 10597.885 | D17: 5145.6883 | E17: 5452.1966
A18: Chitado | B18: 28761.289 | C18: 6138.672 | D18: 3117.2603 | E18: 3021.4118
A19: Chitado | B19: 28761.289 | C19: 6138.672 | D19: 3117.2603 | E19: 3021.4118
A20: Cahama | B20: 113811.34 | C20: 34748.851 | D20: 15978.142 | E20: 18770.709
A21: Cahama | B21: 66853.52 | C21: 26169.68 | D21: 12065.865 | E21: 14103.814
... A42: Naulila | B42: 69092.478 | C42: 15519.106 | D42: 7166.4872 | E42: 8352.6192

Sheet 4. Deficiência e Albinismo

Sheet Q4.1
A1: Quadro 4.1- Resumo síntese dos indicadores da dificiência
A3: Domínio Funcional | B3: Grau de dificuldade | C3: 2024
C4: N | D4: %
A5: Dificulade em ver, mesmo quando usa os seus óculos/lentes de contacto | B5: Não tem dificuldade | C5: 1456814.7 | D5: 97.563452
B6: Tem alguma dificuldade | C6: 32338.523 | D6: 2.1657236
B7: Tem muita dificuldade | C7: 3412.9065 | D7: 0.22856369
B8: Não consegue ver de modo algum | C8: 631.02827 | D8: 0.042260212
B9: Total dos 5 ou mais anos | C9: 1493197.1 | D9: 100
A11: Dificuldade em ouvir, mesmo quando usa aparelho(S) auditivo | B11: Não tem dificuldade | C11: 1478597.9 | D11: 99.022287
B12: Tem alguma dificuldade | C12: 12332.73 | D12: 0.82592776
B13: Tem muita dificuldade | C13: 1739.2453 | D13: 0.11647794
B14: Não consegue ouvir de modo algum | C14: 527.2117 | D14: 0.035307575
B15: Total | C15: 1493197.1 | D15: 100
A17: Dificuldade em andar ou subir escadas | B17: Não tem dificuldade | C17: 1474432 | D17: 98.74329
B18: Tem alguma dificuldade | C18: 14589.119 | D18: 0.97703907
B19: Tem muita dificuldade | C19: 3379.6636 | D19: 0.2263374
B20: Não consegue andar de modo algum | C20: 796.37497 | D20: 0.053333546
B21: Total | C21: 1493197.1 | D21: 100
A23: Dificuldade de se comunicar (por exemplo, compreender, interpretar ou ser compreendido pelos outros) | B23: Não tem dificuldade | C23: 1487144.4 | D23: 99.594647
B24: Tem alguma dificuldade | C24: 4235.584 | D24: 0.28365872
B25: Tem muita dificuldade | C25: 1278.2376 | D25: 0.085604078
B26: Não consegue entender os outros ou fazer-se entender de modo algum | C26: 538.89237 | D26: 0.036089834
B27: Total | C27: 1493197.1 | D27: 100
A29: Dificuldade em lembrar das coisas ou concentrar-se | B29: Não tem dificuldade | C29: 1480403.2 | D29: 99.143188
B30: Tem alguma dificuldade | C30: 10562.793 | D30: 0.7073944
B31: Tem muita dificuldade | C31: 1750.0221 | D31: 0.11719967
B32: Não consegue se concentrar ou lembrar de modo algum | C32: 481.08386 | D32: 0.032218375
B33: Total | C33: 1493197.1 | D33: 100
A35: Dificuldades em usar as mãos e os dedos(por exemplo, apanhar pequenos objectos, como um botão, lápis, abrir ou fechar recipientes) | B35: Não tem dificuldade | C35: 1486017.1 | D35: 99.519151
B36: Tem alguma dificuldade | C36: 5597.82 | D36: 0.37488821
B37: Tem muita dificuldade | C37: 1268.0056 | D37: 0.084918833
B38: Não consegue usar os dedos de modo algum | C38: 314.19878 | D38: 0.021042016
B39: Total | C39: 1493197.1 | D39: 100
A41: Dificuldades em cuidar de si próprio (por exemplo tomar banho da cabeça aos pés ou vestir-se sozinho) | B41: Não tem dificuldade | C41: 1486996.1 | D41: 99.584715
B42: Tem alguma dificuldade | C42: 4390.6041 | D42: 0.29404049
B43: Tem muita dificuldade | C43: 1474.5851 | D43: 0.098753545
B44: Não consegue cuidar da si de modo algum | C44: 335.83948 | D44: 0.022491302
B45: Total | C45: 1493197.1 | D45: 100
A46: Nota-A : O denominador usado para o cálculo das percentagens é o total da população com 5 ou mais anos,
A47: Nota-B: Inseriu-se a linha do total respodente,visto que para o nosso caso a população será a mesma uma vez que os missings foram recodificados em todas as variáveis para a opção de resposta não tem dificuldade

Sheet Q4.2
A1: Quadro 8.1 - Pessoas que têm albinismo por área de residência e município segundo o sexo
A2: Área de residência, município e comuna | B2: Total da população | C2: Total | D2: Homens | E2: Mulheres
A3: Cunene | B3: 1806416.5 | C3: 22786.528 | D3: 11049.912 | E3: 11736.616
A5: Áreas de residência
A6: Urbana | B6: 460652.76 | C6: =D6+E6 -> 4701.9963 | D6: 2243.2477 | E6: 2458.7486
A7: Rural | B7: 1345763.8 | C7: =D7+E7 -> 18084.531 | D7: 8806.6642 | E7: 9277.8671
A8: Municipios / Comunas
A9: Ombadja | B9: 247337.52 | C9: 3268.5766 | D9: 1458.1177 | E9: 1810.4589
A10: Xangongo | B10: 155253.8 | C10: 1303.9156 | D10: 607.63655 | E10: 696.27902
A11: Ombala yo Mungu | B11: 92083.725 | C11: 1964.661 | D11: 850.48116 | E11: 1114.1798
A12: Cuanhama | B12: 500288.17 | C12: 6059.4328 | D12: 2937.1801 | E12: 3122.2527
A13: Ondjiva | B13: 401981.03 | C13: 4496.1292 | D13: 2193.4522 | E13: 2302.6769
A14: Môngua | B14: 98307.147 | C14: 1563.3037 | D14: 743.7279 | E14: 819.57576
A15: Curoca | B15: 35716.784 | C15: 197.81192 | D15: 94.411468 | E15: 103.40046
A16: Curoca | B16: 35716.784 | C16: 197.81192 | D16: 94.411468 | E16: 103.40046
A17: Chitado | B17: 35425.089 | C17: 226.7144 | D17: 134.55924 | E17: 92.155164
A18: Chitado | B18: 35425.089 | C18: 226.7144 | D18: 134.55924 | E18: 92.155164
A19: Cahama | B19: 140924.93 | C19: 981.37351 | D19: 489.12064 | E19: 492.25287
A20: Cahama | B20: 81990.081 | C20: 762.59098 | D20: 352.54562 | E20: 410.04537
... A39: Naulila | B39: 83503.559 | C39: 1395.1018 | D39: 653.81915 | E39: 741.28265

Sheet Q4.3
A1: Quadro 4.2 - População com albinismo por área de residência, municipio e comuna, segundo grupo etário
A2: Área de residência, município e comuna | B2: Total da população | C2: Total da população com albinismo | D2: Grupos etários
D3: 0-4 anos | E3: 5-14 anos | F3: 15-64 anos | G3: 65 ou mais
A4: Cunene | B4: 1806416.5 | C4: 22786.528 | D4: 4195.6553 | E4: 6231.7148 | F4: 11859.059 | G4: 500.09816
A6: Area de residência
A7: Urbana | B7: 460652.76 | C7: 4701.9963 | D7: 734.95 | E7: 1309.5357 | F7: 2605.3264 | G7: 52.184156
A8: Rural | B8: 1345763.8 | C8: 18084.531 | D8: 3460.7053 | E8: 4922.1792 | F8: 9253.7329 | G8: 447.914
A9: Municípios / Comunas
A10: Ombadja | B10: 247337.52 | C10: 3268.5766 | D10: 609.93273 | E10: 833.68696 | F10: 1699.9324 | G10: 125.02454
A11: Xangongo | B11: 155253.8 | C11: 1303.9156 | D11: 323.90838 | E11: 378.77558 | F11: 570.79086 | G11: 30.440758
A12: Ombala yo Mungu | B12: 92083.725 | C12: 1964.661 | D12: 286.02436 | E12: 454.91138 | F12: 1129.1415 | G12: 94.583782
A13: Cuanhama | B13: 500288.17 | C13: 6059.4328 | D13: 1074.012 | E13: 1684.5045 | F13: 3159.5843 | G13: 141.33209
A14: Ondjiva | B14: 401981.03 | C14: 4496.1292 | D14: 803.14124 | E14: 1286.6949 | F14: 2312.7964 | G14: 93.496612
A15: Môngua | B15: 98307.147 | C15: 1563.3037 | D15: 270.87075 | E15: 397.80953 | F15: 846.78791 | G15: 47.835476
A16: Curoca | B16: 35716.784 | C16: 197.81192 | D16: 35.98982 | E16: 57.101846 | F16: 102.54592 | G16: 2.1743398
A17: Curoca | B17: 35716.784 | C17: 197.81192 | D17: 35.98982 | E17: 57.101846 | F17: 102.54592 | G17: 2.1743398
A18: Chitado | B18: 35425.089 | C18: 226.7144 | D18: 60.614433 | E18: 32.357713 | F18: 128.30641 | G18: 5.4358496
A19: Chitado | B19: 35425.089 | C19: 226.7144 | D19: 60.614433 | E19: 32.357713 | F19: 128.30641 | G19: 5.4358496
A20: Cahama | B20: 140924.93 | C20: 981.37351 | D20: 196.99691 | E20: 289.31602 | F20: 484.18888 | G20: 10.871699
A21: Cahama | B21: 81990.081 | C21: 762.59098 | D21: 134.48827 | E21: 218.89041 | F21: 398.3406 | G21: 10.871699
... A42: Naulila | B42: 83503.559 | C42: 1395.1018 | D42: 225.40992 | E42: 350.22466 | F42: 789.02646 | G42: 30.440758

Sheet 5. Orfandade

Sheet Q5.1
A1: Quadro 5.1 - Crianças com 0-17 anos que não vivem com os pais por município, comuna e área de residência, 2024
A2: ='Q4.3'!$A$2 -> Área de residência, município e comuna | B2: População com 0 -17 anos | C2: Popualação com 0 - 17 anos que não vivem com pelo menos um dos pais | D2: Mãe vive noutro agregado | H2: Pai vive noutro agregado | L2: Ambos vivem noutro agregado
D4: Total | E4: Masculino | F4: Feminino | H4: Total | I4: Masculino | J4: Feminino | L4: Total | M4: Masculino | N4: Feminino
A5: Cunene | B5: 998746.13 | C5: 773163.04 | D5: 138292.39 | E5: 67530.791 | F5: 70761.602 | H5: 527031.77 | I5: 257164.37 | J5: 269867.4 | L5: 107838.88 | M5: 51764.111 | N5: 56074.769
A7: Área de residência
A8: Urbana | B8: 236781.08 | C8: 144826.67 | D8: 24035.189 | E8: 10833.386 | F8: 13201.803 | H8: 104966.5 | I8: 47366.448 | J8: 57600.047 | L8: 15824.985 | M8: 6778.2645 | N8: 9046.7201
A9: Rural | B9: 761965.05 | C9: 628336.37 | D9: 114257.2 | E9: 56697.405 | F9: 57559.799 | H9: 422065.27 | I9: 209797.92 | J9: 212267.36 | L9: 92013.896 | M9: 44985.847 | N9: 47028.049
A10: Municípios / Comunas
A11: Ombadja | B11: 138480.37 | C11: 126622.71 | D11: 23161.939 | E11: 11465.475 | F11: 11696.464 | H11: 84491.01 | I11: 41976.729 | J11: 42514.282 | L11: 18969.765 | M11: 9321.3829 | N11: 9648.3819
A12: Xangongo | B12: 89820.51 | C12: 75508.141 | D12: 14639.738 | E12: 7108.9438 | F12: 7530.7942 | H12: 49241.56 | I12: 23809.292 | J12: 25432.268 | L12: 11626.842 | M12: 5582.2165 | N12: 6044.6258
A13: Ombala yo Mungu | B13: 48659.862 | C13: 51114.574 | D13: 8522.2012 | E13: 4356.5309 | F13: 4165.6703 | H13: 35249.45 | I13: 18167.437 | J13: 17082.013 | L13: 7342.9224 | M13: 3739.1663 | N13: 3603.7561
A14: Cuanhama | B14: 261582.26 | C14: 185267.03 | D14: 31869.598 | E14: 15060.541 | F14: 16809.057 | H14: 129791.51 | I14: 61473.324 | J14: 68318.19 | L14: 23605.917 | M14: 10982.314 | N14: 12623.603
A15: Ondjiva | B15: 206741.32 | C15: 136008.27 | D15: 22584.92 | E15: 10444.056 | F15: 12140.864 | H15: 97506.803 | I15: 45502.074 | J15: 52004.73 | L15: 15916.545 | M15: 7191.4494 | N15: 8725.0959
A16: Môngua | B16: 54840.945 | C16: 49258.76 | D16: 9284.6776 | E16: 4616.4848 | F16: 4668.1928 | H16: 32284.71 | I16: 15971.25 | J16: 16313.46 | L16: 7689.3719 | M16: 3790.8647 | N16: 3898.5071
A17: Curoca | B17: 20616.591 | C17: 14364.497 | D17: 2184.6387 | E17: 1104.0002 | F17: 1080.6385 | H17: 10607.427 | I17: 5092.8202 | J17: 5514.607 | L17: 1572.4309 | M17: 737.53858 | N17: 834.89231
A18: Curoca | B18: 20616.591 | C18: 14364.497 | D18: 2184.6387 | E18: 1104.0002 | F18: 1080.6385 | H18: 10607.427 | I18: 5092.8202 | J18: 5514.607 | L18: 1572.4309 | M18: 737.53858 | N18: 834.89231
A19: Chitado | B19: 19678.601 | C19: 12939.2 | D19: 2544.6394 | E19: 1257.8176 | F19: 1286.8218 | H19: 8693.3165 | I19: 4097.8202 | J19: 4595.4963 | L19: 1701.2443 | M19: 831.81698 | N19: 869.42733
A20: Chitado | B20: 19678.601 | C20: 12939.2 | D20: 2544.6394 | E20: 1257.8176 | F20: 1286.8218 | H20: 8693.3165 | I20: 4097.8202 | J20: 4595.4963 | L20: 1701.2443 | M20: 831.81698 | N20: 869.42733
A21: Cahama | B21: 87206.133 | C21: 63973.669 | D21: 10965.217 | E21: 5409.6152 | F21: 5555.6015 | H21: 44570.015 | I21: 21717.752 | J21: 22852.263 | L21: 8438.4376 | M21: 4037.0674 | N21: 4401.3702
A22: Cahama | B22: 49637.888 | C22: 36389.241 | D22: 6356.7083 | E22: 3126.997 | F22: 3229.7113 | H22: 25177.701 | I22: 12176.61 | J22: 13001.09 | L22: 4854.8321 | M22: 2316.7156 | N22: 2538.1165
... A43: Naulila | B43: 46255.254 | C43: 40048.368 | D43: 6935.3436 | E43: 3410.7344 | F43: 3524.6092 | H43: 27309.797 | I43: 13573.572 | J43: 13736.224 | L43: 5803.2274 | M43: 2814.4877 | N43: 2988.7397

Sheet Q5.2
A1: Quadro 5.2 - Crianças com 0-17 anos por área de residência, segundo a situação de viver junto com os pais biológicos e taxa de orfandade, RGPH 2024
A2: Área de residência e grupo etário | B2: População com 0 - 17 anos | C2: Total de crianças orfãos | D2: Crianças orfãos de mãe | H2: Crianças orfãos de pai | L2: Crianças orfãos de ambos | O2: Taxa de orfandade
D4: Total | E4: Masculino | F4: Feminino | H4: Total | I4: Masculino | J4: Feminino | L4: Total | M4: Masculino | N4: Feminino
A5: Cunene | B5: 998746.13 | C5: =+D5+H5+L5 -> 75121.085 | D5: =E5+F5 -> 14591.404 | E5: 7201.4245 | F5: 7389.9798 | H5: =I5+J5 -> 53252.947 | I5: 26266.044 | J5: 26986.903 | L5: =M5+N5 -> 7276.7333 | M5: 3620.0102 | N5: 3656.7231 | O5: 7.5215395
D6: =E6+F6 -> 0 | H6: =I6+J6 -> 0 | L6: =M6+N6 -> 0
A7: Área de residência | D7: =E7+F7 -> 0 | H7: =I7+J7 -> 0 | L7: =M7+N7 -> 0
A8: Urbana | B8: 236781.08 | C8: =SUM(L8,H8,D8) -> 16188.637 | D8: =E8+F8 -> 2692.1402 | E8: 1206.7521 | F8: 1485.3881 | H8: =I8+J8 -> 12654.845 | I8: 5743.0972 | J8: 6911.7479 | L8: =M8+N8 -> 841.65214 | M8: 355.11012 | N8: 486.54203 | O8: 6.8369641
A9: Rural | B9: 761965.05 | C9: =SUM(L9,H9,D9) -> 58932.448 | D9: =E9+F9 -> 11899.264 | E9: 5994.6724 | F9: 5904.5917 | H9: =I9+J9 -> 40598.102 | I9: 20522.947 | J9: 20075.155 | L9: =M9+N9 -> 6435.0812 | M9: 3264.9001 | N9: 3170.1811 | O9: 7.7342717
A10: Grupo etário | D10: =E10+F10 -> 0 | H10: =I10+J10 -> 0 | L10: =M10+N10 -> 0
A11: 0-4 anos | B11: 313219.4 | C11: =+D11+H11+L11 -> 15409.325 | D11: =E11+F11 -> 1657.4259 | E11: 839.13106 | F11: 818.29485 | H11: =I11+J11 -> 12929.816 | I11: 6432.7067 | J11: 6497.1096 | L11: =M11+N11 -> 822.08325 | M11: 424.30103 | N11: 397.78222 | O11: 4.9196587
A12: 5-9 anos | B12: 296392.84 | C12: =+D12+H12+L12 -> 22159.323 | D12: =E12+F12 -> 5437.9992 | E12: 2721.8547 | F12: 2716.1445 | H12: =I12+J12 -> 13917.623 | I12: 6875.0623 | J12: 7042.561 | L12: =M12+N12 -> 2803.7007 | M12: 1414.2224 | N12: 1389.4783 | O12: 7.4763354
A13: 10-14 anos | B13: 247955.25 | C13: =+D13+H13+L13 -> 21279.955 | D13: =E13+F13 -> 3782.0456 | E13: 1886.2643 | F13: 1895.7813 | H13: =I13+J13 -> 15607.838 | I13: 7744.9138 | J13: 7862.9242 | L13: =M13+N13 -> 1890.0711 | M13: 934.56688 | N13: 955.50423 | O13: 8.5821755
A14: 15-17 anos | B14: 141178.64 | C14: =+D14+H14+L14 -> 16272.482 | D14: =E14+F14 -> 3713.9336 | E14: 1754.1744 | F14: 1959.7592 | H14: =I14+J14 -> 10797.67 | I14: 5213.3617 | J14: 5584.3081 | L14: =M14+N14 -> 1760.8783 | M14: 846.91988 | N14: 913.9584 | O14: 11.526164

Sheet 6. Língua Materna

Sheet Q 6.1
A1: Quadro 6.1 - População de 2 ou mais anos por residência, município e comuna, segundo grupos étinicos tribos, 2024
A2: ='Q5.1'!$A$2 -> Área de residência, município e comuna | B2: População com 2 ou mais anos | C2: Grupo_Étnico da população com 2 ou mais anos
C3: Quicongo (Kikongu ou Congolês conguês | D3: Quimbundo (Kimbundu ou Tymbundu) | E3: Lunda-Quioco (Lunda-kioko ou Lunda-Tchokwe Tshokwe) | F3: Umbundo (ou Ovimbundo) | G3: Nhaneca-Humbe (Nyaneka-Lumkumbi) | H3: Ambó (Vahambo tanbé designado Xikwanyama) | I3: Helelo, Herero (Tchielelo, Tjiherero) | J3: Cuangar | K3: Khoisan | L3: Vátua | M3: Kwoi | N3: Xindonga (Oshindonga) | O3: Não sabe | P3: Outra Etnia
A4: Cunene | B4: 1688676.8 | C4: 9484.7302 | D4: 58790.722 | E4: 25788.43 | F4: 111295.62 | G4: 420264.09 | H4: 856870.91 | I4: 87586.351 | J4: 4315.3081 | K4: 3709.4596 | L4: 1765.6241 | M4: 143.42902 | N4: 997.68229 | O4: 47816.908 | P4: 59847.528
A6: Área de residência
A7: Urbana | B7: 434543.09 | C7: 8044.7608 | D7: 22719.588 | E7: 11624.426 | F7: 99763.641 | G7: 97519.641 | H7: 147762.13 | I7: 3933.8705 | J7: 1134.2685 | K7: 253.47192 | L7: 380.85104 | M7: 109.15426 | N7: 226.95216 | O7: 21834.187 | P7: 19236.145
A8: Rural | B8: 1254133.7 | C8: 1439.9693 | D8: 36071.135 | E8: 14164.003 | F8: 11531.979 | G8: 322744.44 | H8: 709108.78 | I8: 83652.48 | J8: 3181.0396 | K8: 3455.9877 | L8: 1384.773 | M8: 34.274762 | N8: 770.73014 | O8: 25982.721 | P8: 40611.384
A9: Municipios / Comunas
A10: Ombadja | B10: =SUM(B11:B12) -> 231702.79 | C10: =SUM(C11:C12) -> 1187.5119 | D10: =SUM(D11:D12) -> 5708.4004 | E10: =SUM(E11:E12) -> 1478.0724 | F10: =SUM(F11:F12) -> 13742.763 | G10: =SUM(G11:G12) -> 61831.214 | H10: =SUM(H11:H12) -> 129796.47 | I10: =SUM(I11:I12) -> 775.78651 | ... P10: =SUM(P11:P12) -> 9930.9813
A11: Xangongo | B11: 145167.18 | C11: 1104.9286 | D11: 3867.9301 | E11: 1443.7708 | F11: 13667.413 | G11: 60465.932 | H11: 54401.22 | I11: 716.7327 | J11: 46.538367 | K11: 1087.061 | L11: 113.72305 | M11: 64.243518 | N11: 35.487703 | O11: 4496.7314 | P11: 3655.4644
A12: Ombala yo Mungu | B12: 86535.61 | C12: 82.583354 | D12: 1840.4704 | E12: 34.301588 | F12: 75.350105 | G12: 1365.2818 | H12: 75395.25 | I12: 59.053812 | J12: 0 | K12: 6.8178319 | L12: 1.4691235 | M12: 1.0871699 | N12: 23.561809 | O12: 1374.8664 | P12: 6275.5168
A13: Cuanhama | B13: =SUM(B14:B15) -> 470833.35 | C13: =SUM(C14:C15) -> 4969.4278 | D13: =SUM(D14:D15) -> 19477.477 | E13: =SUM(E14:E15) -> 6369.8409 | F13: =SUM(F14:F15) -> 62982.473 | G13: =SUM(G14:G15) -> 41638.725 | H13: =SUM(H14:H15) -> 301081.02 | I13: =SUM(I14:I15) -> 1021.0359 | ... P13: =SUM(P14:P15) -> 14012.416
A14: Ondjiva | B14: 378684.25 | C14: 4937.5883 | D14: 17082.239 | E14: 6347.527 | F14: 62736.398 | G14: 41154.145 | H14: 214812.89 | I14: 1017.6761 | J14: 843.73438 | K14: 1084.7319 | L14: 256.06344 | M14: 36.225263 | N14: 123.63405 | O14: 14310.297 | P14: 13941.096
A15: Môngua | B15: 92149.099 | C15: 31.839553 | D15: 2395.238 | E15: 22.31383 | F15: 246.07508 | G15: 484.57965 | H15: 86268.126 | I15: 3.3597806 | J15: 0 | K15: 4.3000218 | L15: 0 | M15: 0 | N15: 2.0654047 | O15: 2619.8823 | P15: 71.319673
A16: Curoca | B16: =SUM(B17) -> 33663.47 | C16: =SUM(C17) -> 582.61486 | D16: =SUM(D17) -> 2293.7353 | E16: =SUM(E17) -> 133.56146 | F16: =SUM(F17) -> 2039.4677 | G16: =SUM(G17) -> 7101.7751 | H16: =SUM(H17) -> 393.36186 | I16: =SUM(I17) -> 7442.3076 | ... P16: =SUM(P17) -> 9478.585
A17: Curoca | B17: 33663.47 | C17: 582.61486 | D17: 2293.7353 | E17: 133.56146 | F17: 2039.4677 | G17: 7101.7751 | H17: 393.36186 | I17: 7442.3076 | J17: 0 | K17: 3.7975959 | L17: 1234.6868 | M17: 0 | N17: 13.528338 | O17: 2946.0483 | P17: 9478.585
A18: Chitado | B18: =SUM(B19) -> 32985.358 | C18: =SUM(C19) -> 30.868424 | D18: =SUM(D19) -> 590.62671 | E18: =SUM(E19) -> 49.272172 | F18: =SUM(F19) -> 589.89028 | G18: =SUM(G19) -> 7770.1582 | H18: =SUM(H19) -> 211.44509 | I18: =SUM(I19) -> 16950.58 | ... P18: =SUM(P19) -> 4129.6769
A19: Chitado | B19: 32985.358 | C19: 30.868424 | D19: 590.62671 | E19: 49.272172 | F19: 589.89028 | G19: 7770.1582 | H19: 211.44509 | I19: 16950.58 | J19: 3.8067898 | K19: 20.834831 | L19: 2.2726106 | M19: 0 | N19: 4.1308094 | O19: 2631.7954 | P19: 4129.6769
A20: Cahama | B20: 76089.644 | C20: 321.09244 | D20: 1771.6435 | E20: 454.09516 | F20: 4895.4853 | G20: 28838.804 | H20: 2476.0344 | I20: 30391.791 | J20: 10.921042 | K20: 2.0654047 | L20: 5.6451291 | M20: 5.1728642 | N20: 2.0654047 | O20: 3971.6274 | P20: 2943.2018
A21: Otchinjau | B21: 54436.127 | C21: 9.4335311 | D21: 964.12903 | E21: 7.7572016 | F21: 407.85791 | G21: 23645.004 | H21: 268.28078 | I21: 28295.03 | J21: 0 | K21: 11.573185 | L21: 32.085024 | M21: 0 | N21: 0 | O21: 198.21124 | P21: 596.76521
A22: Cuvelai | B22: =SUM(B23) -> 70728.53 | C22: =SUM(C23) -> 266.64566 | D22: =SUM(D23) -> 2143.4753 | E22: =SUM(E23) -> 11981.878 | F22: =SUM(F23) -> 3786.477 | G22: =SUM(G23) -> 35596.204 | H22: =SUM(H23) -> 11593.913 | I22: =SUM(I23) -> 268.10942 | ... P22: =SUM(P23) -> 2852.5979
A23: Cuvelai | B23: 70728.53 | C23: 266.64566 | D23: 2143.4753 | E23: 11981.878 | F23: 3786.477 | G23: 35596.204 | H23: 11593.913 | I23: 268.10942 | J23: 139.58209 | K23: 199.56572 | L23: 4.3000218 | M23: 2.2346171 | N23: 34.832127 | O23: 1858.7152 | P23: 2852.5979
A24: Namacunde | B24: =SUM(B25) -> 130243.73 | C24: =SUM(C25) -> 1325.7387 | D24: =SUM(D25) -> 6517.104 | E24: =SUM(E25) -> 2611.7529 | F24: =SUM(F25) -> 15358.993 | G24: =SUM(G25) -> 16135.34 | H24: =SUM(H25) -> 80487.115 | I24: =SUM(I25) -> 60.267198 | ... P24: =SUM(P25) -> 3530.7907
A25: Namacunde | B25: 130243.73 | C25: 1325.7387 | D25: 6517.104 | E25: 2611.7529 | F25: 15358.993 | G25: 16135.34 | H25: 80487.115 | I25: 60.267198 | J25: 254.03358 | K25: 14.539031 | L25: 73.33078 | M25: 30.931061 | N25: 73.974162 | O25: 3769.8224 | P25: 3530.7907
A26: Nehone | B26: =SUM(B27:B28) -> 169044.38 | C26: =SUM(C27:C28) -> 78.234857 | D26: =SUM(D27:D28) -> 6167.7295 | E26: =SUM(E27:E28) -> 9.1416638 | F26: =SUM(F27:F28) -> 142.95673 | G26: =SUM(G27:G28) -> 292.92635 | H26: =SUM(H27:H28) -> 160386.65 | I26: =SUM(I27:I28) -> 29.535817 | ... P26: =SUM(P27:P28) -> 195.67402
A27: Nehone | B27: 88467.719 | C27: 28.451665 | D27: 3751.599 | E27: 4.841642 | F27: 61.032916 | G27: 128.1251 | H27: 83287.869 | I27: 20.186947 | J27: 0 | K27: 402.05127 | L27: 0 | M27: 0 | N27: 12.701448 | O27: 600.91019 | P27: 169.94952
A28: Evale | B28: 80576.666 | C28: 49.783192 | D28: 2416.1305 | E28: 4.3000218 | F28: 81.923817 | G28: 164.80125 | H28: 77098.778 | I28: 9.3488697 | J28: 0 | K28: 118.16408 | L28: 0 | M28: 0 | N28: 541.50507 | O28: 66.205862 | P28: 25.724503
A29: Cafima | B29: =SUM(B30) -> 17787.905 | C29: =SUM(C30) -> 8.2688214 | D29: =SUM(D30) -> 291.77508 | E29: =SUM(E30) -> 15.935826 | F29: =SUM(F30) -> 30.162548 | G29: =SUM(G30) -> 57.298103 | H29: =SUM(H30) -> 15656.178 | I29: =SUM(I30) -> 1.9033949 | ... P29: =SUM(P30) -> 1548.2565
A30: Cafima | B30: 17787.905 | C30: 8.2688214 | D30: 291.77508 | E30: 15.935826 | F30: 30.162548 | G30: 57.298103 | H30: 15656.178 | I30: 1.9033949 | J30: 9.5540034 | K30: 115.80527 | L30: 0 | M30: 0 | N30: 1.894201 | O30: 50.873564 | P30: 1548.2565
A31: Chissuata | B31: =SUM(B32) -> 7406.5458 | C31: =SUM(C32) -> 1.9033949 | D31: =SUM(D32) -> 134.88965 | E31: =SUM(E32) -> 772.83542 | F31: =SUM(F32) -> 252.83624 | G31: =SUM(G32) -> 1702.2493 | H31: =SUM(H32) -> 507.17244 | I31: =SUM(I32) -> 0 | ... P31: =SUM(P32) -> 898.82527
A32: Chissuata | B32: 7406.5458 | C32: 1.9033949 | D32: 134.88965 | E32: 772.83542 | F32: 252.83624 | G32: 1702.2493 | H32: 507.17244 | I32: 0 | J32: 2967.2709 | K32: 0 | L32: 0 | M32: 0 | N32: 0 | O32: 168.56325 | P32: 898.82527
A33: Mupa | B33: =SUM(B34) -> 37495.011 | C33: =SUM(C34) -> 32.531242 | D33: =SUM(D34) -> 721.51588 | E33: =SUM(E34) -> 795.82009 | F33: =SUM(F34) -> 98.032759 | G33: =SUM(G34) -> 75.017596 | H33: =SUM(H34) -> 35309.679 | I33: =SUM(I34) -> 18.287968 | ... P33: =SUM(P34) -> 127.30468
A34: Mupa | B34: 37495.011 | C34: 32.531242 | D34: 721.51588 | E34: 795.82009 | F34: 98.032759 | G34: 75.017596 | H34: 35309.679 | I34: 18.287968 | J34: 0 | K34: 63.976879 | L34: 0 | M34: 0 | N34: 0 | O34: 252.84491 | P34: 127.30468
A35: Chiéde | B35: =SUM(B36) -> 93839.841 | C35: =SUM(C36) -> 33.607897 | D35: =SUM(D36) -> 4137.2255 | E35: =SUM(E36) -> 155.42134 | F35: =SUM(F36) -> 90.768905 | G35: =SUM(G36) -> 170.76421 | H35: =SUM(H36) -> 88597.476 | I35: =SUM(I36) -> 21.062133 | ... P35: =SUM(P36) -> 34.409611
A36: Chiéde | B36: 93839.841 | C36: 33.607897 | D36: 4137.2255 | E36: 155.42134 | F36: 90.768905 | G36: 170.76421 | H36: 88597.476 | I36: 21.062133 | J36: 6.4394223 | K36: 549.18248 | L36: 0 | M36: 0 | N36: 37.403501 | O36: 6.0794004 | P36: 34.409611
A37: Humbe | B37: =SUM(B38:B40) -> 262420.11 | C37: =SUM(C38:C40) -> 636.85056 | D37: =SUM(D38:D40) -> 7870.9957 | E37: =SUM(E38:E40) -> 953.0453 | F37: =SUM(F38:F40) -> 6877.4552 | G37: =SUM(G38:G40) -> 195408.61 | H37: =SUM(H38:H40) -> 30106.12 | I37: =SUM(I38:I40) -> 2310.6546 | ... P37: =SUM(P38:P40) -> 9568.0433
A38: Mucope | B38: 112763.08 | C38: 305.8092 | D38: 2513.5052 | E38: 83.16404 | F38: 1884.9301 | G38: 106056.29 | H38: 1266.7369 | I38: 86.368915 | J38: 6.4486162 | K38: 21.186341 | L38: 0 | M38: 1.4691235 | N38: 0 | O38: 97.081587 | P38: 440.09016
A39: Humbe | B39: 71296.219 | C39: 47.399505 | D39: 2895.8159 | E39: 34.649276 | F39: 138.00619 | G39: 60901.662 | H39: 671.89294 | I39: 1445.1868 | J39: 0 | K39: 3.8067898 | L39: 20.884061 | M39: 0 | N39: 4.3000218 | O39: 1951.558 | P39: 3181.0574
A40: Naulila | B40: 78360.803 | C40: 283.64186 | D40: 2461.6746 | E40: 835.23198 | F40: 4854.5189 | G40: 28450.651 | H40: 28167.49 | I40: 779.09896 | J40: 26.978964 | K40: 0 | L40: 21.164062 | M40: 2.0654047 | N40: 86.598244 | O40: 6444.794 | P40: 5946.8957

Sheet Q 6.2
A1: Quadro 6.2 - População por município, comuna e área de residência, segundo a língua materna, 2024
A2: ='Q5.1'!$A$2 -> Área de residência, município e comuna | B2: Número de pessoas com 2 ou mais anos | C2: Língua materna agrupada
C3: Português | D3: Kimbundu | E3: Umbundu | F3: Cokue (Chokwe/Kioko) | G3: Kikongo | H3: Olunyaneka (Nhaneka) | I3: Nganguela | J3: Oxikwanhama (Kwanhama) | K3: Ifyoti (Fiote) | L3: Muhumbi | M3: Luvale | N3: Khoisan | O3: Línguas estrangeiras | P3: Outras línguas | Q3: Não sabe
A4: Cunene | B4: 1688676.8 | C4: 151042.93 | D4: 9734.6246 | E4: 92524.918 | F4: 22472.269 | G4: 5229.6724 | H4: 254861.92 | I4: 26960.074 | J4: 958838.5 | K4: 770.19899 | L4: 115675.01 | M4: 117.21704 | N4: 1932.4361 | O4: 938.30052 | P4: 39440.971 | Q4: 8137.751
A6: Área de residência
A7: Urbana | B7: 434543.09 | C7: 76302.197 | D7: 8318.4364 | E7: 83708.808 | F7: 9299.8733 | G7: 4146.3502 | H7: 58466.667 | I7: 17636.837 | J7: 137122.52 | K7: 604.89434 | L7: 27332.035 | M7: 85.9642 | N7: 99.973218 | O7: 641.02132 | P7: 8412.403 | Q7: 2365.1073
A8: Rural | B8: 1254133.7 | C8: 74740.734 | D8: 1416.1882 | E8: 8816.1104 | F8: 13172.395 | G8: 1083.3222 | H8: 196395.25 | I8: 9323.2371 | J8: 821715.97 | K8: 165.30464 | L8: 88342.973 | M8: 31.252835 | N8: 1832.4628 | O8: 297.2792 | P8: 31028.568 | Q8: 5772.6437
A9: Municipios / Comunas
A10: Ombadja | B10: =SUM(B11:B12) -> 231702.79 | C10: =SUM(C11:C12) -> 22923.115 | D10: =SUM(D11:D12) -> 1044.7567 | E10: =SUM(E11:E12) -> 11266.702 | F10: =SUM(F11:F12) -> 1137.3753 | G10: =SUM(G11:G12) -> 617.97009 | H10: =SUM(H11:H12) -> 34502.125 | I10: =SUM(I11:I12) -> 3185.2337 | ... N10: =SUM(N11:N12) -> 218.32276 | O10: 119.48563 | P10: =SUM(P11:P12) -> 9971.8087 | Q10: =SUM(Q11:Q12) -> 566.63588
A11: Xangongo | B11: 145167.18 | C11: 19168.098 | D11: 1019.7195 | E11: 11210.038 | F11: 1111.0565 | G11: 565.22617 | H11: 34179.278 | I11: 3171.0746 | J11: 48891.024 | K11: 53.566567 | L11: 22745.468 | M11: 2.2346171 | N11: 196.49107 | O11: 107.7611 | P11: 2389.941 | Q11: 356.19961
A12: Ombala yo Mungu | B12: 86535.61 | C12: 3755.0167 | D12: 25.037224 | E12: 56.663297 | F12: 26.318793 | G12: 52.743919 | H12: 322.84671 | I12: 14.15915 | J12: 74348.02 | K12: 2.2346171 | L12: 106.70875 | M12: 0 | N12: 21.83169 | O12: 11.724529 | P12: 7581.8677 | Q12: 210.43626
A13: Cuanhama | B13: =SUM(B14:B15) -> 470833.35 | C13: =SUM(C14:C15) -> 56944.783 | D13: =SUM(D14:D15) -> 5774.6678 | E13: =SUM(E14:E15) -> 52662.032 | F13: =SUM(F14:F15) -> 4719.7516 | G13: =SUM(G14:G15) -> 2955.1436 | H13: =SUM(H14:H15) -> 22570.056 | I13: =SUM(I14:I15) -> 10197.146 | ... N13: =SUM(N14:N15) -> 152.91907 | O13: 421.90789 | P13: =SUM(P14:P15) -> 4603.5305 | Q13: =SUM(Q14:Q15) -> 1494.4075
A14: Ondjiva | B14: 378684.25 | C14: 53594.619 | D14: 5741.4678 | E14: 52479.421 | F14: 4716.2171 | G14: 2858.4529 | H14: 22260.579 | I14: 10144.218 | J14: 207557.62 | K14: 463.47147 | L14: 12207.114 | M14: 47.745011 | N14: 128.36204 | O14: 415.46846 | P14: 4587.0044 | Q14: 1482.4835
A15: Môngua | B15: 92149.099 | C15: 3350.1637 | D15: 33.199978 | E15: 182.61183 | F15: 3.5345282 | G15: 96.69067 | H15: 309.4773 | I15: 52.927432 | J15: 87950.605 | K15: 3.8067898 | L15: 106.63514 | M15: 0 | N15: 24.557029 | O15: 6.4394223 | P15: 16.526106 | Q15: 11.924013
A16: Curoca | B16: =SUM(B17) -> 33663.47 | C16: =SUM(C17) -> 3128.4573 | D16: =SUM(D17) -> 451.12556 | E16: =SUM(E17) -> 1718.5298 | F16: =SUM(F17) -> 102.51101 | G16: =SUM(G17) -> 142.92418 | H16: =SUM(H17) -> 6414.2056 | I16: =SUM(I17) -> 104.07683 | ... N16: =SUM(N17) -> 11.245062 | O16: 4.138012 | P16: =SUM(P17) -> 5268.5855 | Q16: =SUM(Q17) -> 2640.0971
A17: Curoca | B17: 33663.47 | C17: 3128.4573 | D17: 451.12556 | E17: 1718.5298 | F17: 102.51101 | G17: 142.92418 | H17: 6414.2056 | I17: 104.07683 | J17: 13438.327 | K17: 5.2759133 | L17: 233.97055 | M17: 0 | N17: 11.245062 | O17: 4.138012 | P17: 5268.5855 | Q17: 2640.0971
A18: Chitado | B18: =SUM(B19) -> 32985.358 | C18: =SUM(C19) -> 1295.4835 | D18: =SUM(D19) -> 24.708904 | E18: =SUM(E19) -> 588.03101 | F18: =SUM(F19) -> 12.437624 | G18: =SUM(G19) -> 3.7417342 | H18: =SUM(H19) -> 4692.633 | I18: =SUM(I19) -> 79.330206 | ... N18: =SUM(N19) -> 2.2726106 | O18: 3.5345282 | P18: =SUM(P19) -> 2084.3347 | Q18: =SUM(Q19) -> 1285.6451
A19: Chitado | B19: 32985.358 | C19: 1295.4835 | D19: 24.708904 | E19: 588.03101 | F19: 12.437624 | G19: 3.7417342 | H19: 4692.633 | I19: 79.330206 | J19: 22237.028 | K19: 8.352011 | L19: 665.75958 | M19: 2.0654047 | N19: 2.2726106 | O19: 3.5345282 | P19: 2084.3347 | Q19: 1285.6451
A20: Cahama | B20: =SUM(B21:B22) -> 130525.77 | C20: =SUM(C21:C22) -> 7666.7597 | D20: =SUM(D21:D22) -> 515.15717 | E20: =SUM(E21:E22) -> 4544.538 | F20: =SUM(F21:F22) -> 289.95048 | G20: =SUM(G21:G22) -> 61.587107 | H20: =SUM(H21:H22) -> 32055.556 | I20: =SUM(I21:I22) -> 767.03536 | ... N20: =SUM(N21:N22) -> 24.359629 | O20: 23.224256 | P20: =SUM(P21:P22) -> 2483.7177 | Q20: =SUM(Q21:Q22) -> 832.39942
A21: Cahama | B21: 76089.644 | C21: 6536.6256 | D21: 510.7498 | E21: 4121.1556 | F21: 289.95048 | G21: 61.587107 | H21: 12427.814 | I21: 724.39696 | J21: 45549.39 | K21: 33.095838 | L21: 3551.1436 | M21: 0 | N21: 16.58404 | O21: 23.224256 | P21: 1506.1779 | Q21: 737.74878
A22: Otchinjau | B22: 54436.127 | C22: 1130.1341 | D22: 4.4073706 | E22: 423.38238 | F22: 0 | G22: 0 | H22: 19627.741 | I22: 42.638403 | J22: 32099.334 | K22: 2.2346171 | L22: 26.288279 | M22: 0 | N22: 7.7755893 | O22: 0 | P22: 977.5398 | Q22: 94.650637
A23: Cuvelai | B23: =SUM(B24) -> 70728.53 | C23: =SUM(C24) -> 4294.6451 | D23: =SUM(D24) -> 363.50754 | E23: =SUM(E24) -> 3030.6838 | F23: =SUM(F24) -> 11617.129 | G23: =SUM(G24) -> 51.526649 | H23: =SUM(H24) -> 30337.884 | I23: =SUM(I24) -> 2982.6205 | ... N23: =SUM(N24) -> 182.56015 | O23: 84.258697 | P23: =SUM(P24) -> 756.33881 | Q23: =SUM(Q24) -> 141.12959
A24: Cuvelai | B24: 70728.53 | C24: 4294.6451 | D24: 363.50754 | E24: 3030.6838 | F24: 11617.129 | G24: 51.526649 | H24: 30337.884 | I24: 2982.6205 | J24: 10411.245 | K24: 43.888991 | L24: 6405.4084 | M24: 25.703016 | N24: 182.56015 | O24: 84.258697 | P24: 756.33881 | Q24: 141.12959
A25: Namacunde | B25: =SUM(B26) -> 130243.73 | C25: =SUM(C26) -> 16657.201 | D25: =SUM(D26) -> 1000.884 | E25: =SUM(E26) -> 12397.594 | F25: =SUM(F26) -> 2310.8554 | G25: =SUM(G26) -> 769.64844 | H25: =SUM(H26) -> 6357.7405 | I25: =SUM(I26) -> 2829.4078 | ... N25: =SUM(N26) -> 25.164409 | O25: 164.98107 | P25: =SUM(P26) -> 1044.4015 | Q25: =SUM(Q26) -> 197.33559
A26: Namacunde | B26: 130243.73 | C26: 16657.201 | D26: 1000.884 | E26: 12397.594 | F26: 2310.8554 | G26: 769.64844 | H26: 6357.7405 | I26: 2829.4078 | J26: 78769.538 | K26: 86.772258 | L26: 7619.8645 | M26: 12.34497 | N26: 25.164409 | O26: 164.98107 | P26: 1044.4015 | Q26: 197.33559
A27: Nehone | B27: =SUM(B28:B29) -> 169044.38 | C27: =SUM(C28:C29) -> 8710.0547 | D27: =SUM(D28:D29) -> 66.305356 | E27: =SUM(E28:E29) -> 77.472658 | F27: =SUM(F28:F29) -> 5.4379231 | G27: =SUM(G28:G29) -> 262.5191 | H27: =SUM(H28:H29) -> 75.47519 | I27: =SUM(I28:I29) -> 35.679477 | ... N27: =SUM(N28:N29) -> 530.76597 | O27: 17.106862 | P27: =SUM(P28:P29) -> 20.656915 | Q27: =SUM(Q28:Q29) -> 47.778706
A28: Nehone | B28: 88467.719 | C28: 5135.0686 | D28: 15.812451 | E28: 30.839514 | F28: 3.3725184 | G28: 175.24136 | H28: 41.248285 | I28: 33.614073 | J28: 82560.317 | K28: 0 | L28: 3.5345282 | M28: 0 | N28: 412.60189 | O28: 10.741435 | P28: 19.187791 | Q28: 26.139706
A29: Evale | B29: 80576.666 | C29: 3574.9861 | D29: 50.492905 | E29: 46.633144 | F29: 2.0654047 | G29: 87.277732 | H29: 34.226905 | I29: 2.0654047 | J29: 76614.563 | K29: 4.3380153 | L29: 10.314367 | M29: 2.0654047 | N29: 118.16408 | O29: 6.3654265 | P29: 1.4691235 | Q29: 21.639
A30: Cafima | B30: =SUM(B31:B32) -> 25194.451 | C30: =SUM(C31:C32) -> 1139.4079 | D30: =SUM(D31:D32) -> 12.342979 | E30: =SUM(E31:E32) -> 268.45027 | F30: =SUM(F31:F32) -> 755.95179 | G30: =SUM(G31:G32) -> 8.3140175 | H30: =SUM(H31:H32) -> 1813.0791 | I30: =SUM(I31:I32) -> 5738.934 | ... N30: =SUM(N31:N32) -> 113.54186 | O30: 2.0654047 | P30: =SUM(P31:P32) -> 114.50506 | Q30: =SUM(Q31:Q32) -> 16.015357
A31: Cafima | B31: 17787.905 | C31: 864.31241 | D31: 8.6392379 | E31: 35.982136 | F31: 5.2179793 | G31: 3.8067898 | H31: 27.366567 | I31: 1923.1251 | J31: 14779.017 | K31: 0 | L31: 6.6871028 | M31: 0 | N31: 113.54186 | O31: 2.0654047 | P31: 18.143381 | Q31: 0
A32: Chissuata | B32: 7406.5458 | C32: 275.09547 | D32: 3.7037406 | E32: 232.46814 | F32: 750.73381 | G32: 4.5072277 | H32: 1785.7125 | I32: 3815.8089 | J32: 391.34243 | K32: 1.4691235 | L32: 33.327434 | M32: 0 | N32: 0 | O32: 0 | P32: 96.361681 | Q32: 16.015357
A33: Mupa | B33: =SUM(B34) -> 37495.011 | C33: =SUM(C34) -> 1856.2621 | D33: =SUM(D34) -> 20.984208 | E33: =SUM(E34) -> 59.336889 | F33: =SUM(F34) -> 829.35585 | G33: =SUM(G34) -> 51.697102 | H33: =SUM(H34) -> 45.528447 | I33: =SUM(I34) -> 8.0797495 | ... N33: =SUM(N34) -> 73.304422 | O33: 5.8071389 | P33: =SUM(P34) -> 5.7691453 | Q33: =SUM(Q34) -> 16.944852
A34: Mupa | B34: 37495.011 | C34: 1856.2621 | D34: 20.984208 | E34: 59.336889 | F34: 829.35585 | G34: 51.697102 | H34: 45.528447 | I34: 8.0797495 | J34: 34502.991 | K34: 7.1285768 | L34: 11.821484 | M34: 0 | N34: 73.304422 | O34: 5.8071389 | P34: 5.7691453 | Q34: 16.944852
A35: Chiéde | B35: =SUM(B36) -> 93839.841 | C35: =SUM(C36) -> 4861.4702 | D35: =SUM(D36) -> 58.82572 | E35: =SUM(E36) -> 42.415227 | F35: =SUM(F36) -> 143.98244 | G35: =SUM(G36) -> 139.29862 | H35: =SUM(H36) -> 53.75972 | I35: =SUM(I36) -> 8.9632575 | ... N35: =SUM(N36) -> 567.98652 | O35: 20.848596 | P35: =SUM(P36) -> 227.48229 | Q35: =SUM(Q36) -> 7.7663955
A36: Chiéde | B36: 93839.841 | C36: 4861.4702 | D36: 58.82572 | E36: 42.415227 | F36: 143.98244 | G36: 139.29862 | H36: 53.75972 | I36: 8.9632575 | J36: 87679.259 | K36: 10.069167 | L36: 17.713538 | M36: 0 | N36: 567.98652 | O36: 20.848596 | P36: 227.48229 | Q36: 7.7663955
A37: Humbe | B37: =SUM(B38:B39) -> 184059.3 | C37: =SUM(C38:C39) -> 15564.347 | D37: =SUM(D38:D39) -> 108.36124 | E37: =SUM(E38:E39) -> 1181.8613 | F37: =SUM(F38:F39) -> 28.411328 | G37: =SUM(G38:G39) -> 21.736963 | H37: =SUM(H38:H39) -> 98522.331 | I37: =SUM(I38:I39) -> 384.87082 | ... N37: =SUM(N38:N39) -> 21.186341 | O37: 27.239359 | P37: =SUM(P38:P39) -> 2032.0976 | Q37: =SUM(Q38:Q39) -> 208.7763
A38: Mucope | B38: 112763.08 | C38: 10460.179 | D38: 80.063419 | E38: 1025.5795 | F38: 9.8999547 | G38: 18.798716 | H38: 58550.108 | I38: 363.90768 | J38: 1392.4818 | K38: 1.4691235 | L38: 40381.007 | M38: 0 | N38: 21.186341 | O38: 23.497625 | P38: 264.38103 | Q38: 170.52517
A39: Humbe | B39: 71296.219 | C39: 5104.1685 | D39: 28.297822 | E39: 156.28188 | F39: 18.511374 | G39: 2.9382471 | H39: 39972.223 | I39: 20.963147 | J39: 10437.885 | K39: 12.509629 | L39: 13732.73 | M39: 0 | N39: 0 | O39: 3.7417342 | P39: 1767.7166 | Q39: 38.251128
A40: Naulila | B40: =SUM(B41) -> 78360.803 | C40: =SUM(C41) -> 6000.9458 | D40: =SUM(D41) -> 292.99743 | E40: =SUM(E41) -> 4687.2714 | F40: =SUM(F41) -> 519.11865 | G40: =SUM(G41) -> 143.56481 | H40: =SUM(H41) -> 17421.546 | I40: =SUM(I41) -> 638.69683 | ... N40: =SUM(N41) -> 8.8072495 | O40: 43.703082 | P40: =SUM(P41) -> 10827.743 | Q40: =SUM(Q41) -> 682.81924
A41: Naulila | B41: 78360.803 | C41: 6000.9458 | D41: 292.99743 | E41: 4687.2714 | F41: 519.11865 | G41: 143.56481 | H41: 17421.546 | I41: 638.69683 | J41: 29228.504 | K41: 30.516279 | L41: 7809.511 | M41: 25.058613 | N41: 8.8072495 | O41: 43.703082 | P41: 10827.743 | Q41: 682.81924

Sheet 7. Religião

Sheet Q 7.1
A1: Quadro 7.1 - População com 2 ou mais anos por município, comuna e área de residência, segundo a religião ou espiritualidade, 2024
A2: Área de residência e município | B2: População com 2 ou mais anos | C2: Católica | D2: Bom Deus | E2: Islâmica/ Muçulmana | F2: Animista | G2: Judaica | H2: Protestante | I2: Universal do reino de Deus | J2: Nova apostólica | K2: Tocoísta | L2: Kimbanguista | M2: Josafat | N2: Assembleia de Deus Pentecostal | O2: Testemunha de Jeová | P2: Metodista | Q2: Evangélica | R2: Adventista | S2: Baptista | T2: Mensagem dos últimos Tempos | U2: Sem religião | V2: Outra religião | W2: Não sabe/ Não respondeu
A3: Cunene | B3: 1688676.8 | C3: 1192862 | D3: 10526.441 | E3: 1223.6073 | F3: 526.40375 | G3: 453.55204 | H3: 35003.856 | I3: 3857.0698 | J3: 6777.6398 | K3: 3583.059 | L3: 653.98724 | M3: 2212.4272 | N3: 45778.731 | O3: 11009.027 | P3: 3328.4395 | Q3: 172374.69 | R3: 36443.413 | S3: 3638.6939 | T3: 186.79369 | U3: 100676.27 | V3: 26197.404 | W3: 31363.266
A5: Área de residência
A6: Urbana | B6: 434543.09 | C6: 235080.23 | D6: 9017.4938 | E6: 428.99458 | F6: 47.595658 | G6: 108.15364 | H6: 14284.966 | I6: 2777.5937 | J6: 4694.3859 | K6: 2639.351 | L6: 478.4584 | M6: 1526.2613 | N6: 36476.772 | O6: 7711.9244 | P6: 2319.5948 | Q6: 48867.547 | R6: 29948.653 | S6: 1732.9886 | T6: 22719.588 | U6: 14073.566 | V6: 14495.623 | W6: 7664.3408
A7: Rural | B7: 1254133.7 | C7: 957781.78 | D7: 1508.9472 | E7: 794.61273 | F7: 478.80809 | G7: 345.3984 | H7: 20718.89 | I7: 1079.4761 | J7: 2083.2539 | K7: 943.70798 | L7: 175.52883 | M7: 686.16595 | N7: 9301.9592 | O7: 3297.1025 | P7: 1008.8447 | Q7: 123507.14 | R7: 6494.761 | S7: 1905.7054 | T7: 36071.135 | U7: 86602.707 | V7: 11701.781 | W7: 23698.926
A8: Municipios
A9: Ombadja | B9: 231702.79 | C9: 147879.63 | D9: 1298.9897 | E9: 143.61808 | F9: 44.491419 | G9: 37.871766 | H9: 5411.1581 | I9: 536.13546 | J9: 1317.1008 | K9: 546.7809 | L9: 134.20719 | M9: 242.0307 | N9: 3855.7159 | O9: 911.40716 | P9: 616.25389 | Q9: 49639.699 | R9: 3594.095 | S9: 549.8875 | T9: 23.091535 | U9: 7995.8097 | V9: 3752.2542 | W9: 3172.5557
A10: Cuanhama | B10: 470833.35 | C10: 338431.43 | D10: 5185.2615 | E10: 359.86568 | F10: 30.754963 | G10: 54.890614 | H10: 8452.7375 | I10: 2000.8961 | J10: 2793.0341 | K10: 1774.8657 | L10: 383.27338 | M10: 1309.8843 | N10: 26080.869 | O10: 4985.1746 | P10: 1349.0092 | Q10: 32635.625 | R10: 19622.17 | S10: 849.34251 | T10: 108.45468 | U10: 11221.921 | V10: 8300.4732 | W10: 4903.4108
A11: Curoca | B11: 33663.47 | C11: 10047.365 | D11: 225.34616 | E11: 2.2726106 | F11: 0 | G11: 6.0702066 | H11: 108.40602 | I11: 68.806024 | J11: 7.9085459 | K11: 58.526921 | L11: 29.463675 | M11: 23.972562 | N11: 321.99212 | O11: 86.816727 | P11: 366.14812 | Q11: 1274.0215 | R11: 665.65978 | S11: 6.2322164 | T11: 0 | U11: 16358.283 | V11: 199.87494 | W11: 3806.3032
A12: Chitado | B12: 32985.358 | C12: 16403.611 | D12: 9.384791 | E12: 18.722239 | F12: 10.208219 | G12: 10.199025 | H12: 231.77773 | I12: 78.357397 | J12: 73.50884 | K12: 4.5452213 | L12: 6.032213 | M12: 12.635636 | N12: 481.79151 | O12: 330.10661 | P12: 19.337144 | Q12: 5809.0989 | R12: 688.56144 | S12: 0 | T12: 2.0654047 | U12: 5875.9173 | V12: 1700.4836 | W12: 1219.0135
A13: Cahama | B13: 130525.77 | C13: 81075.28 | D13: 768.27523 | E13: 46.737851 | F13: 8.3048237 | G13: 5.8630006 | H13: 1478.413 | I13: 99.480235 | J13: 75.979854 | K13: 11.78349 | L13: 7.9375991 | M13: 136.35616 | N13: 2798.8529 | O13: 2790.2005 | P13: 154.9931 | Q13: 4937.9734 | R13: 3175.7423 | S13: 310.52578 | T13: 4.3000218 | U13: 24626.606 | V13: 1180.7646 | W13: 6831.401
A14: Cuvelai | B14: 70728.53 | C14: 45486.021 | D14: 674.57928 | E14: 51.169091 | F14: 9.6011908 | G14: 60.355432 | H14: 5562.0576 | I14: 155.30966 | J14: 301.00335 | K14: 122.33108 | L14: 6.0143448 | M14: 77.811581 | N14: 2368.9266 | O14: 252.6582 | P14: 25.58409 | Q14: 6727.096 | R14: 1426.9368 | S14: 505.97061 | T14: 0 | U14: 3172.8261 | V14: 2166.9369 | W14: 1575.3405
A15: Namacunde | B15: 130243.73 | C15: 77341.924 | D15: 1492.1772 | E15: 195.81306 | F15: 247.36628 | G15: 118.19291 | H15: 4397.6105 | I15: 428.89424 | J15: 904.62511 | K15: 518.42933 | L15: 24.474717 | M15: 188.75489 | N15: 5814.0281 | O15: 1029.1666 | P15: 133.49255 | Q15: 22646.107 | R15: 4289.9663 | S15: 130.00338 | T15: 48.882041 | U15: 4401.7245 | V15: 3942.0612 | W15: 1950.0395
