Workbook

Sheet Início
B2: Índices Compósitos do PDN 2023–2027
B3: Angola · Execução do Plano de Desenvolvimento Nacional · dados do Relatório Anual 2025 (MINPLAN)
B6: Este livro apresenta dois indicadores compósitos construídos segundo as boas práticas internacionais (OCDE/JRC, Handbook on Constructing Composite Indicators, 2008), a partir dos 51 indicadores de execução do painel oficial do MINPLAN, organizados em 7 domínios. Todos os cálculos estão em fórmulas vivas: ao alterar um valor na folha «Dados», índices, painel e gráficos recalculam automaticamente.
B9: Os dois índices
B10: 1 · ICD — Índice Compósito de Desenvolvimento | I10: =ICD!E13 -> 131.60202
B11: Mede o progresso observado do desenvolvimento: cada indicador é normalizado com base 2022 = 100 («menor é melhor» invertidos) e agregado por média geométrica dentro do domínio e entre os 7 domínios.
I12: em 2025 (2022 = 100)
B13: → ver folha «ICD»
B15: 2 · ICE — Índice Compósito de Execução do PDN | I15: =ICE!D13 -> 0.8673533
B16: Mede a execução face ao previsto (executado ÷ previsto): grau de atingimento da meta anual interpolada, com tecto de 100% por indicador (excedentes não compensam défices) e média aritmética por domínio e entre domínios.
I17: da meta anual em 2025
B18: → ver folha «ICE»
B20: Como utilizar
B21: 1. | C21: Abra a folha «Painel» — síntese, gráficos, mapa de calor e explorador de domínio (com menu pendente ▼).
B22: 2. | C22: Consulte «ICD» e «ICE» para os resultados por domínio e o detalhe dos 51 indicadores, com fórmulas auditáveis.
B23: 3. | C23: Os valores de entrada estão na folha «Dados», a azul. Corrija ou actualize aí — tudo recalcula automaticamente.
B24: 4. | C24: A folha «Metodologia» documenta opções de cálculo, alinhamento com a OCDE/JRC, robustez e limitações.
B25: 5. | C25: Nada está protegido: pode ordenar, filtrar e copiar. Evite apagar colunas ocultas (auxiliares técnicas).
B27: Navegação
B28: → Painel | D28: Visualizações e dashboards — síntese 2025, evoluções, domínios, radar, distribuição, explorador e extremos
B29: → ICD | D29: Índice Compósito de Desenvolvimento — resultados e detalhe normalizado (2022 = 100)
B30: → ICE | D30: Índice Compósito de Execução — % da meta anual por domínio e indicador (executado/previsto)
B31: → Dados | D31: Base de dados editável: 51 indicadores, observações 2022–2025 e metas anuais 2022–2027
B32: → Metodologia | D32: Especificação completa dos índices, alinhamento OCDE/JRC, robustez, limitações e fontes
B34: Convenções
B35: Texto azul | D35: valores de entrada editáveis (folha «Dados»)
B36: Texto preto | D36: fórmulas — não escrever por cima
B37: ● ● ● | D37: semáforos ICE: verde ≥90% · amarelo 75–90% · vermelho <75% da meta anual
B38: Mapa de calor | D38: avermelhado = abaixo de 2022/da meta · azulado/violeta = acima
B40: Ficha técnica
B41: Execução (observações e metas MINPLAN 2025) | F41: https://www.minplan.gov.ao/en/publicacoes/relatorios-balanco-pdn
B42: Plano (PDN 2023–2027, metas 2027) | F42: https://www.nepad.org/sites/default/files/2024-07/20231030%283%29_layout_Final_Angola_PDN%202023-2027-1.pdf
B43: Extracção dos dados: 2026-07-17 · Ano-base: 2022 · Metodologia: OCDE/JRC (2008), Handbook on Constructing Composite Indicators. As metas anuais 2026–2027 sem valor publicado no PDN são derivadas (ver «Metodologia» — limitações); os índices não substituem os relatórios oficiais de balanço do PDN.

Sheet Painel
A1: PDN Angola 2023–2027 · Índices Compósitos — Painel de Interpretação | U1: ÁREA TÉCNICA DOS GRÁFICOS — não editar
A2: ICD — Desenvolvimento (progresso observado, 2022 = 100) · ICE — Execução (executado ÷ previsto, % da meta anual) · Dados: painel MINPLAN, Relatório Anual 2025
U3: 2022 | V3: =ICD!B13 -> 100 | W3: =ICD!G13 -> 100
A4: Síntese 2025 | U4: 2023 | V4: =ICD!C13 -> 104.00863 | W4: =ICD!H13 -> 116.92774
U5: 2024 | V5: =ICD!D13 -> 123.35547 | W5: =ICD!I13 -> 130.72015
A6: ICD · DESENVOLVIMENTO 2025 | E6: HIATO FACE À TRAJECTÓRIA DE METAS | I6: ICE · EXECUÇÃO DA META ANUAL 2025 | M6: INDICADORES NA META (≥100%) | U6: 2025 | V6: =ICD!E13 -> 131.60202 | W6: =ICD!J13 -> 142.94737
A7: =ICD!E13 -> 131.60202 | E7: =ICD!N13 -> -11.345346 | I7: =ICE!D13 -> 0.8673533 | M7: =COUNTIF(ICE!$I$21:$I$71,"≥100%") -> 17 | U7: 2026 | W7: =ICD!K13 -> 154.54809
U8: 2027 | W8: =ICD!L13 -> 165.56544
A9: =ICD!E13-ICD!D13 -> 8.2465512 | E9: ="obs. "&ROUND(ICD!E13,1)&" vs meta "&ROUND(ICD!J13,1) -> obs. 131,6 vs meta 142,9 | I9: =ICE!D13-ICE!C13 -> -0.006278338
A10: Índice global, base 2022 = 100 | E10: Pontos de índice: observado 2025 vs meta interpolada 2025 | I10: Média dos 7 domínios, tecto de 100% por indicador | M10: ="em "&COUNTIF(ICE!$G$21:$G$71,">0")&" indicadores avaliados em 2025" -> em 43 indicadores avaliados em 2025
U11: 2023 | V11: =ICE!B13 -> 0.8706822 | W11: 1
A12: Evolução global | U12: 2024 | V12: =ICE!C13 -> 0.87363164 | W12: 1
A13: ICD — desenvolvimento observado vs trajectória de metas (2022 = 100) | J13: ICE — execução global da meta anual | U13: 2025 | V13: =ICE!D13 -> 0.8673533 | W13: 1
A14: A linha tracejada indica onde o índice deveria estar se todas as metas anuais interpoladas fossem cumpridas, até 2027. | J14: Média dos 7 domínios; cada indicador com tecto de 100%.
U16: =INDEX(ICE!$A$6:$A$12,MATCH(LARGE($X$16:$X$22,1),$X$16:$X$22,0)) -> Comunicação | V16: =INDEX(ICE!$D$6:$D$12,MATCH(LARGE($X$16:$X$22,1),$X$16:$X$22,0)) -> 0.99367089 | W16: 1 | X16: =ICE!D6+ROW()/10^7 -> 0.92974381
U17: =INDEX(ICE!$A$6:$A$12,MATCH(LARGE($X$16:$X$22,2),$X$16:$X$22,0)) -> Económico | V17: =INDEX(ICE!$D$6:$D$12,MATCH(LARGE($X$16:$X$22,2),$X$16:$X$22,0)) -> 0.94067534 | W17: 1 | X17: =ICE!D7+ROW()/10^7 -> 0.71452611
U18: =INDEX(ICE!$A$6:$A$12,MATCH(LARGE($X$16:$X$22,3),$X$16:$X$22,0)) -> Saúde | V18: =INDEX(ICE!$D$6:$D$12,MATCH(LARGE($X$16:$X$22,3),$X$16:$X$22,0)) -> 0.92974221 | W18: 1 | X18: =ICE!D8+ROW()/10^7 -> 0.99367269
U19: =INDEX(ICE!$A$6:$A$12,MATCH(LARGE($X$16:$X$22,4),$X$16:$X$22,0)) -> Educação e FP | V19: =INDEX(ICE!$D$6:$D$12,MATCH(LARGE($X$16:$X$22,4),$X$16:$X$22,0)) -> 0.89157843 | W19: 1 | X19: =ICE!D9+ROW()/10^7 -> 0.89158033
U20: =INDEX(ICE!$A$6:$A$12,MATCH(LARGE($X$16:$X$22,5),$X$16:$X$22,0)) -> Infraestruturas | V20: =INDEX(ICE!$D$6:$D$12,MATCH(LARGE($X$16:$X$22,5),$X$16:$X$22,0)) -> 0.80944156 | W20: 1 | X20: =ICE!D10+ROW()/10^7 -> 0.80944356
U21: =INDEX(ICE!$A$6:$A$12,MATCH(LARGE($X$16:$X$22,6),$X$16:$X$22,0)) -> Fomento à Produção | V21: =INDEX(ICE!$D$6:$D$12,MATCH(LARGE($X$16:$X$22,6),$X$16:$X$22,0)) -> 0.79184027 | W21: 1 | X21: =ICE!D11+ROW()/10^7 -> 0.79184237
U22: =INDEX(ICE!$A$6:$A$12,MATCH(LARGE($X$16:$X$22,7),$X$16:$X$22,0)) -> Protecção Social | V22: =INDEX(ICE!$D$6:$D$12,MATCH(LARGE($X$16:$X$22,7),$X$16:$X$22,0)) -> 0.71452441 | W22: 1 | X22: =ICE!D12+ROW()/10^7 -> 0.94067754
U25: =INDEX(ICD!$A$6:$A$12,MATCH(LARGE($X$25:$X$31,1),$X$25:$X$31,0)) -> Protecção Social | V25: =INDEX(ICD!$E$6:$E$12,MATCH(LARGE($X$25:$X$31,1),$X$25:$X$31,0)) -> 219.44308 | W25: 100 | X25: =ICD!E6+ROW()/10^7 -> 124.03483
U26: =INDEX(ICD!$A$6:$A$12,MATCH(LARGE($X$25:$X$31,2),$X$25:$X$31,0)) -> Fomento à Produção | V26: =INDEX(ICD!$E$6:$E$12,MATCH(LARGE($X$25:$X$31,2),$X$25:$X$31,0)) -> 139.70089 | W26: 100 | X26: =ICD!E7+ROW()/10^7 -> 219.44308
U27: =INDEX(ICD!$A$6:$A$12,MATCH(LARGE($X$25:$X$31,3),$X$25:$X$31,0)) -> Comunicação | V27: =INDEX(ICD!$E$6:$E$12,MATCH(LARGE($X$25:$X$31,3),$X$25:$X$31,0)) -> 134.37096 | W27: 100 | X27: =ICD!E8+ROW()/10^7 -> 134.37097
U28: =INDEX(ICD!$A$6:$A$12,MATCH(LARGE($X$25:$X$31,4),$X$25:$X$31,0)) -> Educação e FP | V28: =INDEX(ICD!$E$6:$E$12,MATCH(LARGE($X$25:$X$31,4),$X$25:$X$31,0)) -> 126.39887 | W28: 100 | X28: =ICD!E9+ROW()/10^7 -> 126.39887
U29: =INDEX(ICD!$A$6:$A$12,MATCH(LARGE($X$25:$X$31,5),$X$25:$X$31,0)) -> Saúde | V29: =INDEX(ICD!$E$6:$E$12,MATCH(LARGE($X$25:$X$31,5),$X$25:$X$31,0)) -> 124.03483 | W29: 100 | X29: =ICD!E10+ROW()/10^7 -> 101.79064
U30: =INDEX(ICD!$A$6:$A$12,MATCH(LARGE($X$25:$X$31,6),$X$25:$X$31,0)) -> Económico | V30: =INDEX(ICD!$E$6:$E$12,MATCH(LARGE($X$25:$X$31,6),$X$25:$X$31,0)) -> 103.99606 | W30: 100 | X30: =ICD!E11+ROW()/10^7 -> 139.70089
A31: Domínios em 2025 | U31: =INDEX(ICD!$A$6:$A$12,MATCH(LARGE($X$25:$X$31,7),$X$25:$X$31,0)) -> Infraestruturas | V31: =INDEX(ICD!$E$6:$E$12,MATCH(LARGE($X$25:$X$31,7),$X$25:$X$31,0)) -> 101.79063 | W31: 100 | X31: =ICD!E12+ROW()/10^7 -> 103.99606
A32: ICE por domínio — % da meta anual em 2025 (ordenado) | J32: ICD por domínio — nível do índice em 2025 (2022 = 100)
A33: Distância de cada domínio à meta anual interpolada; a linha tracejada marca os 100%. | J33: Acima da linha = domínio melhor do que em 2022; Protecção Social mais do que duplicou.
U34: =ICE!A6 -> Saúde | V34: =ICE!B6 -> 0.97317948 | W34: =ICE!D6 -> 0.92974221
U35: =ICE!A7 -> Protecção Social | V35: =ICE!B7 -> 0.76454173 | W35: =ICE!D7 -> 0.71452441
U36: =ICE!A8 -> Comunicação | V36: =ICE!B8 -> 0.98529412 | W36: =ICE!D8 -> 0.99367089
U37: =ICE!A9 -> Educação e FP | V37: =ICE!B9 -> 0.95696565 | W37: =ICE!D9 -> 0.89157843
U38: =ICE!A10 -> Infraestruturas | V38: =ICE!B10 -> 0.87727498 | W38: =ICE!D10 -> 0.80944156
U39: =ICE!A11 -> Fomento à Produção | V39: =ICE!B11 -> 0.93441698 | W39: =ICE!D11 -> 0.79184027
U40: =ICE!A12 -> Económico | V40: =ICE!B12 -> 0.60310245 | W40: =ICE!D12 -> 0.94067534
U43: ≥100% | V43: =SUMPRODUCT(--(ICE!$I$21:$I$71="≥100%")) -> 17
U44: 75–100% | V44: =SUMPRODUCT(--(ICE!$I$21:$I$71="75–100%")) -> 17
U45: 50–75% | V45: =SUMPRODUCT(--(ICE!$I$21:$I$71="50–75%")) -> 5
...

Sheet ICD
A1: ICD — Índice Compósito de Desenvolvimento (Execução do PDN, 2022 = 100)
A2: Progresso observado dos 51 indicadores face ao ano-base 2022, com inversão dos indicadores «menor é melhor». Agregação: média geométrica dentro de cada domínio e entre os 7 domínios (pesos iguais). Valores >100 = melhoria face a 2022.
A4: A. Resultados — domínios e índice global
A5: Domínio | B5: 2022 | C5: 2023 | D5: 2024 | E5: 2025 | G5: Trajectória de metas: 2022 | H5: 2023 | I5: 2024 | J5: 2025 | K5: 2026 | L5: 2027 | N5: Hiato 2025 (obs. − meta)
A6: Saúde | B6: =EXP(SUMIFS($O$21:$O$71,$B$21:$B$71,$A6,$E$21:$E$71,">0")/COUNTIFS($B$21:$B$71,$A6,$E$21:$E$71,">0")) -> 100 | C6: =EXP(SUMIFS($P$21:$P$71,$B$21:$B$71,$A6,$F$21:$F$71,">0")/COUNTIFS($B$21:$B$71,$A6,$F$21:$F$71,">0")) -> 117.09798 | D6: =EXP(SUMIFS($Q$21:$Q$71,$B$21:$B$71,$A6,$G$21:$G$71,">0")/COUNTIFS($B$21:$B$71,$A6,$G$21:$G$71,">0")) -> 118.73722 | E6: =EXP(SUMIFS($R$21:$R$71,$B$21:$B$71,$A6,$H$21:$H$71,">0")/COUNTIFS($B$21:$B$71,$A6,$H$21:$H$71,">0")) -> 124.03483 | G6: =EXP(SUMIFS($S$21:$S$71,$B$21:$B$71,$A6,$I$21:$I$71,">0")/COUNTIFS($B$21:$B$71,$A6,$I$21:$I$71,">0")) -> 100 | H6: =EXP(SUMIFS($T$21:$T$71,$B$21:$B$71,$A6,$J$21:$J$71,">0")/COUNTIFS($B$21:$B$71,$A6,$J$21:$J$71,">0")) -> 107.99741 | I6: =EXP(SUMIFS($U$21:$U$71,$B$21:$B$71,$A6,$K$21:$K$71,">0")/COUNTIFS($B$21:$B$71,$A6,$K$21:$K$71,">0")) -> 115.82334 | J6: =EXP(SUMIFS($V$21:$V$71,$B$21:$B$71,$A6,$L$21:$L$71,">0")/COUNTIFS($B$21:$B$71,$A6,$L$21:$L$71,">0")) -> 123.57953 | K6: =EXP(SUMIFS($W$21:$W$71,$B$21:$B$71,$A6,$M$21:$M$71,">0")/COUNTIFS($B$21:$B$71,$A6,$M$21:$M$71,">0")) -> 131.34195 | L6: =EXP(SUMIFS($X$21:$X$71,$B$21:$B$71,$A6,$N$21:$N$71,">0")/COUNTIFS($B$21:$B$71,$A6,$N$21:$N$71,">0")) -> 139.1745 | N6: =E6-J6 -> 0.45530177
A7: Protecção Social | B7: =EXP(SUMIFS($O$21:$O$71,$B$21:$B$71,$A7,$E$21:$E$71,">0")/COUNTIFS($B$21:$B$71,$A7,$E$21:$E$71,">0")) -> 100 | C7: =EXP(SUMIFS($P$21:$P$71,$B$21:$B$71,$A7,$F$21:$F$71,">0")/COUNTIFS($B$21:$B$71,$A7,$F$21:$F$71,">0")) -> 127.20929 | D7: =EXP(SUMIFS($Q$21:$Q$71,$B$21:$B$71,$A7,$G$21:$G$71,">0")/COUNTIFS($B$21:$B$71,$A7,$G$21:$G$71,">0")) -> 192.24445 | E7: =EXP(SUMIFS($R$21:$R$71,$B$21:$B$71,$A7,$H$21:$H$71,">0")/COUNTIFS($B$21:$B$71,$A7,$H$21:$H$71,">0")) -> 219.44308 | G7: =EXP(SUMIFS($S$21:$S$71,$B$21:$B$71,$A7,$I$21:$I$71,">0")/COUNTIFS($B$21:$B$71,$A7,$I$21:$I$71,">0")) -> 100 | H7: =EXP(SUMIFS($T$21:$T$71,$B$21:$B$71,$A7,$J$21:$J$71,">0")/COUNTIFS($B$21:$B$71,$A7,$J$21:$J$71,">0")) -> 168.63177 | I7: =EXP(SUMIFS($U$21:$U$71,$B$21:$B$71,$A7,$K$21:$K$71,">0")/COUNTIFS($B$21:$B$71,$A7,$K$21:$K$71,">0")) -> 236.86879 | J7: =EXP(SUMIFS($V$21:$V$71,$B$21:$B$71,$A7,$L$21:$L$71,">0")/COUNTIFS($B$21:$B$71,$A7,$L$21:$L$71,">0")) -> 304.98014 | K7: =EXP(SUMIFS($W$21:$W$71,$B$21:$B$71,$A7,$M$21:$M$71,">0")/COUNTIFS($B$21:$B$71,$A7,$M$21:$M$71,">0")) -> 373.03543 | L7: =EXP(SUMIFS($X$21:$X$71,$B$21:$B$71,$A7,$N$21:$N$71,">0")/COUNTIFS($B$21:$B$71,$A7,$N$21:$N$71,">0")) -> 441.06084 | N7: =E7-J7 -> -85.537063
A8: Comunicação | B8: =EXP(SUMIFS($O$21:$O$71,$B$21:$B$71,$A8,$E$21:$E$71,">0")/COUNTIFS($B$21:$B$71,$A8,$E$21:$E$71,">0")) -> 100 | C8: =EXP(SUMIFS($P$21:$P$71,$B$21:$B$71,$A8,$F$21:$F$71,">0")/COUNTIFS($B$21:$B$71,$A8,$F$21:$F$71,">0")) -> 107.0436 | D8: =EXP(SUMIFS($Q$21:$Q$71,$B$21:$B$71,$A8,$G$21:$G$71,">0")/COUNTIFS($B$21:$B$71,$A8,$G$21:$G$71,">0")) -> 111.8034 | E8: =EXP(SUMIFS($R$21:$R$71,$B$21:$B$71,$A8,$H$21:$H$71,">0")/COUNTIFS($B$21:$B$71,$A8,$H$21:$H$71,">0")) -> 134.37096 | G8: =EXP(SUMIFS($S$21:$S$71,$B$21:$B$71,$A8,$I$21:$I$71,">0")/COUNTIFS($B$21:$B$71,$A8,$I$21:$I$71,">0")) -> 100 | H8: =EXP(SUMIFS($T$21:$T$71,$B$21:$B$71,$A8,$J$21:$J$71,">0")/COUNTIFS($B$21:$B$71,$A8,$J$21:$J$71,">0")) -> 108.16939 | I8: =EXP(SUMIFS($U$21:$U$71,$B$21:$B$71,$A8,$K$21:$K$71,">0")/COUNTIFS($B$21:$B$71,$A8,$K$21:$K$71,">0")) -> 116.13636 | J8: =EXP(SUMIFS($V$21:$V$71,$B$21:$B$71,$A8,$L$21:$L$71,">0")/COUNTIFS($B$21:$B$71,$A8,$L$21:$L$71,">0")) -> 123.93995 | K8: =EXP(SUMIFS($W$21:$W$71,$B$21:$B$71,$A8,$M$21:$M$71,">0")/COUNTIFS($B$21:$B$71,$A8,$M$21:$M$71,">0")) -> 131.60922 | L8: =EXP(SUMIFS($X$21:$X$71,$B$21:$B$71,$A8,$N$21:$N$71,">0")/COUNTIFS($B$21:$B$71,$A8,$N$21:$N$71,">0")) -> 139.16639 | N8: =E8-J8 -> 10.431013
A9: Educação e FP | B9: =EXP(SUMIFS($O$21:$O$71,$B$21:$B$71,$A9,$E$21:$E$71,">0")/COUNTIFS($B$21:$B$71,$A9,$E$21:$E$71,">0")) -> 100 | C9: =EXP(SUMIFS($P$21:$P$71,$B$21:$B$71,$A9,$F$21:$F$71,">0")/COUNTIFS($B$21:$B$71,$A9,$F$21:$F$71,">0")) -> 106.97092 | D9: =EXP(SUMIFS($Q$21:$Q$71,$B$21:$B$71,$A9,$G$21:$G$71,">0")/COUNTIFS($B$21:$B$71,$A9,$G$21:$G$71,">0")) -> 116.01022 | E9: =EXP(SUMIFS($R$21:$R$71,$B$21:$B$71,$A9,$H$21:$H$71,">0")/COUNTIFS($B$21:$B$71,$A9,$H$21:$H$71,">0")) -> 126.39887 | G9: =EXP(SUMIFS($S$21:$S$71,$B$21:$B$71,$A9,$I$21:$I$71,">0")/COUNTIFS($B$21:$B$71,$A9,$I$21:$I$71,">0")) -> 100 | H9: =EXP(SUMIFS($T$21:$T$71,$B$21:$B$71,$A9,$J$21:$J$71,">0")/COUNTIFS($B$21:$B$71,$A9,$J$21:$J$71,">0")) -> 105.21599 | I9: =EXP(SUMIFS($U$21:$U$71,$B$21:$B$71,$A9,$K$21:$K$71,">0")/COUNTIFS($B$21:$B$71,$A9,$K$21:$K$71,">0")) -> 108.05398 | J9: =EXP(SUMIFS($V$21:$V$71,$B$21:$B$71,$A9,$L$21:$L$71,">0")/COUNTIFS($B$21:$B$71,$A9,$L$21:$L$71,">0")) -> 109.29576 | K9: =EXP(SUMIFS($W$21:$W$71,$B$21:$B$71,$A9,$M$21:$M$71,">0")/COUNTIFS($B$21:$B$71,$A9,$M$21:$M$71,">0")) -> 113.71785 | L9: =EXP(SUMIFS($X$21:$X$71,$B$21:$B$71,$A9,$N$21:$N$71,">0")/COUNTIFS($B$21:$B$71,$A9,$N$21:$N$71,">0")) -> 117.79886 | N9: =E9-J9 -> 17.103108
A10: Infraestruturas | B10: =EXP(SUMIFS($O$21:$O$71,$B$21:$B$71,$A10,$E$21:$E$71,">0")/COUNTIFS($B$21:$B$71,$A10,$E$21:$E$71,">0")) -> 100 | C10: =EXP(SUMIFS($P$21:$P$71,$B$21:$B$71,$A10,$F$21:$F$71,">0")/COUNTIFS($B$21:$B$71,$A10,$F$21:$F$71,">0")) -> 102.07015 | D10: =EXP(SUMIFS($Q$21:$Q$71,$B$21:$B$71,$A10,$G$21:$G$71,">0")/COUNTIFS($B$21:$B$71,$A10,$G$21:$G$71,">0")) -> 107.2446 | E10: =EXP(SUMIFS($R$21:$R$71,$B$21:$B$71,$A10,$H$21:$H$71,">0")/COUNTIFS($B$21:$B$71,$A10,$H$21:$H$71,">0")) -> 101.79063 | G10: =EXP(SUMIFS($S$21:$S$71,$B$21:$B$71,$A10,$I$21:$I$71,">0")/COUNTIFS($B$21:$B$71,$A10,$I$21:$I$71,">0")) -> 100 | H10: =EXP(SUMIFS($T$21:$T$71,$B$21:$B$71,$A10,$J$21:$J$71,">0")/COUNTIFS($B$21:$B$71,$A10,$J$21:$J$71,">0")) -> 119.99703 | I10: =EXP(SUMIFS($U$21:$U$71,$B$21:$B$71,$A10,$K$21:$K$71,">0")/COUNTIFS($B$21:$B$71,$A10,$K$21:$K$71,">0")) -> 134.97381 | J10: =EXP(SUMIFS($V$21:$V$71,$B$21:$B$71,$A10,$L$21:$L$71,">0")/COUNTIFS($B$21:$B$71,$A10,$L$21:$L$71,">0")) -> 147.84704 | K10: =EXP(SUMIFS($W$21:$W$71,$B$21:$B$71,$A10,$M$21:$M$71,">0")/COUNTIFS($B$21:$B$71,$A10,$M$21:$M$71,">0")) -> 159.75875 | L10: =EXP(SUMIFS($X$21:$X$71,$B$21:$B$71,$A10,$N$21:$N$71,">0")/COUNTIFS($B$21:$B$71,$A10,$N$21:$N$71,">0")) -> 170.87824 | N10: =E10-J10 -> -46.056409
A11: Fomento à Produção | B11: =EXP(SUMIFS($O$21:$O$71,$B$21:$B$71,$A11,$E$21:$E$71,">0")/COUNTIFS($B$21:$B$71,$A11,$E$21:$E$71,">0")) -> 100 | C11: =EXP(SUMIFS($P$21:$P$71,$B$21:$B$71,$A11,$F$21:$F$71,">0")/COUNTIFS($B$21:$B$71,$A11,$F$21:$F$71,">0")) -> 113.04715 | D11: =EXP(SUMIFS($Q$21:$Q$71,$B$21:$B$71,$A11,$G$21:$G$71,">0")/COUNTIFS($B$21:$B$71,$A11,$G$21:$G$71,">0")) -> 134.20486 | E11: =EXP(SUMIFS($R$21:$R$71,$B$21:$B$71,$A11,$H$21:$H$71,">0")/COUNTIFS($B$21:$B$71,$A11,$H$21:$H$71,">0")) -> 139.70089 | G11: =EXP(SUMIFS($S$21:$S$71,$B$21:$B$71,$A11,$I$21:$I$71,">0")/COUNTIFS($B$21:$B$71,$A11,$I$21:$I$71,">0")) -> 100 | H11: =EXP(SUMIFS($T$21:$T$71,$B$21:$B$71,$A11,$J$21:$J$71,">0")/COUNTIFS($B$21:$B$71,$A11,$J$21:$J$71,">0")) -> 119.1503 | I11: =EXP(SUMIFS($U$21:$U$71,$B$21:$B$71,$A11,$K$21:$K$71,">0")/COUNTIFS($B$21:$B$71,$A11,$K$21:$K$71,">0")) -> 138.65581 | J11: =EXP(SUMIFS($V$21:$V$71,$B$21:$B$71,$A11,$L$21:$L$71,">0")/COUNTIFS($B$21:$B$71,$A11,$L$21:$L$71,">0")) -> 159.62118 | K11: =EXP(SUMIFS($W$21:$W$71,$B$21:$B$71,$A11,$M$21:$M$71,">0")/COUNTIFS($B$21:$B$71,$A11,$M$21:$M$71,">0")) -> 183.18247 | L11: =EXP(SUMIFS($X$21:$X$71,$B$21:$B$71,$A11,$N$21:$N$71,">0")/COUNTIFS($B$21:$B$71,$A11,$N$21:$N$71,">0")) -> 209.37193 | N11: =E11-J11 -> -19.920293
A12: Económico | B12: =EXP(SUMIFS($O$21:$O$71,$B$21:$B$71,$A12,$E$21:$E$71,">0")/COUNTIFS($B$21:$B$71,$A12,$E$21:$E$71,">0")) -> 100 | C12: =EXP(SUMIFS($P$21:$P$71,$B$21:$B$71,$A12,$F$21:$F$71,">0")/COUNTIFS($B$21:$B$71,$A12,$F$21:$F$71,">0")) -> 66.900969 | D12: =EXP(SUMIFS($Q$21:$Q$71,$B$21:$B$71,$A12,$G$21:$G$71,">0")/COUNTIFS($B$21:$B$71,$A12,$G$21:$G$71,">0")) -> 101.9937 | E12: =EXP(SUMIFS($R$21:$R$71,$B$21:$B$71,$A12,$H$21:$H$71,">0")/COUNTIFS($B$21:$B$71,$A12,$H$21:$H$71,">0")) -> 103.99606 | G12: =EXP(SUMIFS($S$21:$S$71,$B$21:$B$71,$A12,$I$21:$I$71,">0")/COUNTIFS($B$21:$B$71,$A12,$I$21:$I$71,">0")) -> 100 | H12: =EXP(SUMIFS($T$21:$T$71,$B$21:$B$71,$A12,$J$21:$J$71,">0")/COUNTIFS($B$21:$B$71,$A12,$J$21:$J$71,">0")) -> 100.83663 | I12: =EXP(SUMIFS($U$21:$U$71,$B$21:$B$71,$A12,$K$21:$K$71,">0")/COUNTIFS($B$21:$B$71,$A12,$K$21:$K$71,">0")) -> 101.22722 | J12: =EXP(SUMIFS($V$21:$V$71,$B$21:$B$71,$A12,$L$21:$L$71,">0")/COUNTIFS($B$21:$B$71,$A12,$L$21:$L$71,">0")) -> 101.22722 | K12: =EXP(SUMIFS($W$21:$W$71,$B$21:$B$71,$A12,$M$21:$M$71,">0")/COUNTIFS($B$21:$B$71,$A12,$M$21:$M$71,">0")) -> 98.136029 | L12: =EXP(SUMIFS($X$21:$X$71,$B$21:$B$71,$A12,$N$21:$N$71,">0")/COUNTIFS($B$21:$B$71,$A12,$N$21:$N$71,">0")) -> 94.721588 | N12: =E12-J12 -> 2.7688322
A13: ÍNDICE GLOBAL (ICD) | B13: =GEOMEAN(B6:B12) -> 100 | C13: =GEOMEAN(C6:C12) -> 104.00863 | D13: =GEOMEAN(D6:D12) -> 123.35547 | E13: =GEOMEAN(E6:E12) -> 131.60202 | G13: =GEOMEAN(G6:G12) -> 100 | H13: =GEOMEAN(H6:H12) -> 116.92774 | I13: =GEOMEAN(I6:I12) -> 130.72015 | J13: =GEOMEAN(J6:J12) -> 142.94737 | K13: =GEOMEAN(K6:K12) -> 154.54809 | L13: =GEOMEAN(L6:L12) -> 165.56544 | N13: =E13-J13 -> -11.345346
A14: Robustez: painel equilibrado (48 indicadores) | B14: =GEOMEAN(B6:B8,B10:B12,B16) -> 100 | C14: =GEOMEAN(C6:C8,C10:C12,C16) -> 103.96447 | D14: =GEOMEAN(D6:D8,D10:D12,D16) -> 123.35547 | E14: =GEOMEAN(E6:E8,E10:E12,E16) -> 131.60202
A15: Leitura: 100 = nível de 2022. O hiato compara o observado em 2025 com a trajectória de metas no mesmo ano (pontos de índice).
A16: Educação e FP (painel 48 — auxiliar) | B16: =EXP(SUMIFS($O$21:$O$71,$B$21:$B$71,$A$9,$E$21:$E$71,">0",$Y$21:$Y$71,1)/COUNTIFS($B$21:$B$71,$A$9,$E$21:$E$71,">0",$Y$21:$Y$71,1)) -> 100 | C16: =EXP(SUMIFS($P$21:$P$71,$B$21:$B$71,$A$9,$F$21:$F$71,">0",$Y$21:$Y$71,1)/COUNTIFS($B$21:$B$71,$A$9,$F$21:$F$71,">0",$Y$21:$Y$71,1)) -> 106.65343 | D16: =EXP(SUMIFS($Q$21:$Q$71,$B$21:$B$71,$A$9,$G$21:$G$71,">0",$Y$21:$Y$71,1)/COUNTIFS($B$21:$B$71,$A$9,$G$21:$G$71,">0",$Y$21:$Y$71,1)) -> 116.01022 | E16: =EXP(SUMIFS($R$21:$R$71,$B$21:$B$71,$A$9,$H$21:$H$71,">0",$Y$21:$Y$71,1)/COUNTIFS($B$21:$B$71,$A$9,$H$21:$H$71,">0",$Y$21:$Y$71,1)) -> 126.39887
A19: B. Detalhe por indicador — valores normalizados (2022 = 100)
A20: ID | B20: Domínio | C20: Indicador | D20: Direcção | E20: Obs. 2022 | F20: Obs. 2023 | G20: Obs. 2024 | H20: Obs. 2025 | I20: Meta 2022 | J20: Meta 2023 | K20: Meta 2024 | L20: Meta 2025 | M20: Meta 2026 | N20: Meta 2027 | O20: ln obs 2022 | P20: ln obs 2023 | Q20: ln obs 2024 | R20: ln obs 2025 | S20: ln meta 2022 | T20: ln meta 2023 | U20: ln meta 2024 | V20: ln meta 2025 | W20: ln meta 2026 | X20: ln meta 2027 | Y20: Painel 48
A21: IMP-saude-novas_camas_em_hospitais_cumulativo | B21: =Dados!C5 -> Saúde | C21: =Dados!D5 -> Novas Camas em Hospitais (Cumulativo) | D21: =Dados!F5 -> Maior é melhor | E21: =IF(OR(Dados!H5="",Dados!$H5=""),"",IF(Dados!$F5="Menor é melhor",100*Dados!$H5/Dados!H5,100*Dados!H5/Dados!$H5)) -> 100 | F21: =IF(OR(Dados!I5="",Dados!$H5=""),"",IF(Dados!$F5="Menor é melhor",100*Dados!$H5/Dados!I5,100*Dados!I5/Dados!$H5)) -> 109.77143 | G21: =IF(OR(Dados!J5="",Dados!$H5=""),"",IF(Dados!$F5="Menor é melhor",100*Dados!$H5/Dados!J5,100*Dados!J5/Dados!$H5)) -> 133.69524 | H21: =IF(OR(Dados!K5="",Dados!$H5=""),"",IF(Dados!$F5="Menor é melhor",100*Dados!$H5/Dados!K5,100*Dados!K5/Dados!$H5)) -> 139.12381 | I21: =IF(OR(Dados!M5="",Dados!$H5=""),"",IF(Dados!$F5="Menor é melhor",100*Dados!$H5/Dados!M5,100*Dados!M5/Dados!$H5)) | J21: =IF(OR(Dados!N5="",Dados!$H5=""),"",IF(Dados!$F5="Menor é melhor",100*Dados!$H5/Dados!N5,100*Dados!N5/Dados!$H5)) | K21: =IF(OR(Dados!O5="",Dados!$H5=""),"",IF(Dados!$F5="Menor é melhor",100*Dados!$H5/Dados!O5,100*Dados!O5/Dados!$H5)) | L21: =IF(OR(Dados!P5="",Dados!$H5=""),"",IF(Dados!$F5="Menor é melhor",100*Dados!$H5/Dados!P5,100*Dados!P5/Dados!$H5)) | M21: =IF(OR(Dados!Q5="",Dados!$H5=""),"",IF(Dados!$F5="Menor é melhor",100*Dados!$H5/Dados!Q5,100*Dados!Q5/Dados!$H5)) | N21: =IF(OR(Dados!R5="",Dados!$H5=""),"",IF(Dados!$F5="Menor é melhor",100*Dados!$H5/Dados!R5,100*Dados!R5/Dados!$H5)) | O21: =IF(ISNUMBER(E21),LN(E21),"") -> 4.6051702 | P21: =IF(ISNUMBER(F21),LN(F21),"") -> 4.6984003 | Q21: =IF(ISNUMBER(G21),LN(G21),"") -> 4.8955629 | R21: =IF(ISNUMBER(H21),LN(H21),"") -> 4.9353643 | S21: =IF(ISNUMBER(I21),LN(I21),"") | T21: =IF(ISNUMBER(J21),LN(J21),"") | U21: =IF(ISNUMBER(K21),LN(K21),"") | V21: =IF(ISNUMBER(L21),LN(L21),"") | ... X21: =IF(ISNUMBER(N21),LN(N21),"") | Y21: =Dados!U5 -> 1
A22: IMP-saude-taxa_de_cobertura_da_4_a_consulta_pre_natal | B22: =Dados!C6 -> Saúde | C22: =Dados!D6 -> Taxa de cobertura da 4.ª consulta pré-natal | D22: =Dados!F6 -> Maior é melhor | E22: =IF(OR(Dados!H6="",Dados!$H6=""),"",IF(Dados!$F6="Menor é melhor",100*Dados!$H6/Dados!H6,100*Dados!H6/Dados!$H6)) -> 100 | F22: =IF(OR(Dados!I6="",Dados!$H6=""),"",IF(Dados!$F6="Menor é melhor",100*Dados!$H6/Dados!I6,100*Dados!I6/Dados!$H6)) -> 159.09091 | G22: =IF(OR(Dados!J6="",Dados!$H6=""),"",IF(Dados!$F6="Menor é melhor",100*Dados!$H6/Dados!J6,100*Dados!J6/Dados!$H6)) -> 170.45455 | H22: =IF(OR(Dados!K6="",Dados!$H6=""),"",IF(Dados!$F6="Menor é melhor",100*Dados!$H6/Dados!K6,100*Dados!K6/Dados!$H6)) -> 136.36364 | I22: =IF(OR(Dados!M6="",Dados!$H6=""),"",IF(Dados!$F6="Menor é melhor",100*Dados!$H6/Dados!M6,100*Dados!M6/Dados!$H6)) -> 100 | J22: =IF(OR(Dados!N6="",Dados!$H6=""),"",IF(Dados!$F6="Menor é melhor",100*Dados!$H6/Dados!N6,100*Dados!N6/Dados!$H6)) -> 109.09091 | K22: =IF(OR(Dados!O6="",Dados!$H6=""),"",IF(Dados!$F6="Menor é melhor",100*Dados!$H6/Dados!O6,100*Dados!O6/Dados!$H6)) -> 118.18182 | L22: =IF(OR(Dados!P6="",Dados!$H6=""),"",IF(Dados!$F6="Menor é melhor",100*Dados!$H6/Dados!P6,100*Dados!P6/Dados!$H6)) -> 127.27273 | M22: =IF(OR(Dados!Q6="",Dados!$H6=""),"",IF(Dados!$F6="Menor é melhor",100*Dados!$H6/Dados!Q6,100*Dados!Q6/Dados!$H6)) -> 136.36364 | N22: =IF(OR(Dados!R6="",Dados!$H6=""),"",IF(Dados!$F6="Menor é melhor",100*Dados!$H6/Dados!R6,100*Dados!R6/Dados!$H6)) -> 145.45455 | O22: =IF(ISNUMBER(E22),LN(E22),"") -> 4.6051702 | P22: =IF(ISNUMBER(F22),LN(F22),"") -> 5.0694758 | Q22: =IF(ISNUMBER(G22),LN(G22),"") -> 5.1384687 | R22: =IF(ISNUMBER(H22),LN(H22),"") -> 4.9153251 | S22: =IF(ISNUMBER(I22),LN(I22),"") -> 4.6051702 | T22: =IF(ISNUMBER(J22),LN(J22),"") -> 4.6921816 | U22: =IF(ISNUMBER(K22),LN(K22),"") -> 4.7722243 | V22: =IF(ISNUMBER(L22),LN(L22),"") -> 4.8463322 | ... X22: =IF(ISNUMBER(N22),LN(N22),"") -> 4.9798636 | Y22: =Dados!U6 -> 1
A23: IMP-saude-taxa_de_imunizacao_bcg | B23: =Dados!C7 -> Saúde | C23: =Dados!D7 -> Taxa de imunização BCG | D23: =Dados!F7 -> Maior é melhor | E23: =IF(OR(Dados!H7="",Dados!$H7=""),"",IF(Dados!$F7="Menor é melhor",100*Dados!$H7/Dados!H7,100*Dados!H7/Dados!$H7)) -> 100 | F23: =IF(OR(Dados!I7="",Dados!$H7=""),"",IF(Dados!$F7="Menor é melhor",100*Dados!$H7/Dados!I7,100*Dados!I7/Dados!$H7)) -> 121.51899 | G23: =IF(OR(Dados!J7="",Dados!$H7=""),"",IF(Dados!$F7="Menor é melhor",100*Dados!$H7/Dados!J7,100*Dados!J7/Dados!$H7)) -> 107.59494 | H23: =IF(OR(Dados!K7="",Dados!$H7=""),"",IF(Dados!$F7="Menor é melhor",100*Dados!$H7/Dados!K7,100*Dados!K7/Dados!$H7)) -> 98.734177 | I23: =IF(OR(Dados!M7="",Dados!$H7=""),"",IF(Dados!$F7="Menor é melhor",100*Dados!$H7/Dados!M7,100*Dados!M7/Dados!$H7)) -> 100 | J23: =IF(OR(Dados!N7="",Dados!$H7=""),"",IF(Dados!$F7="Menor é melhor",100*Dados!$H7/Dados!N7,100*Dados!N7/Dados!$H7)) -> 102.95359 | K23: =IF(OR(Dados!O7="",Dados!$H7=""),"",IF(Dados!$F7="Menor é melhor",100*Dados!$H7/Dados!O7,100*Dados!O7/Dados!$H7)) -> 105.90717 | L23: =IF(OR(Dados!P7="",Dados!$H7=""),"",IF(Dados!$F7="Menor é melhor",100*Dados!$H7/Dados!P7,100*Dados!P7/Dados!$H7)) -> 108.86076 | M23: =IF(OR(Dados!Q7="",Dados!$H7=""),"",IF(Dados!$F7="Menor é melhor",100*Dados!$H7/Dados!Q7,100*Dados!Q7/Dados!$H7)) -> 111.81435 | N23: =IF(OR(Dados!R7="",Dados!$H7=""),"",IF(Dados!$F7="Menor é melhor",100*Dados!$H7/Dados!R7,100*Dados!R7/Dados!$H7)) -> 114.76793 | O23: =IF(ISNUMBER(E23),LN(E23),"") -> 4.6051702 | P23: =IF(ISNUMBER(F23),LN(F23),"") -> 4.8000705 | Q23: =IF(ISNUMBER(G23),LN(G23),"") -> 4.6783736 | R23: =IF(ISNUMBER(H23),LN(H23),"") -> 4.5924312 | S23: =IF(ISNUMBER(I23),LN(I23),"") -> 4.6051702 | T23: =IF(ISNUMBER(J23),LN(J23),"") -> 4.6342783 | U23: =IF(ISNUMBER(K23),LN(K23),"") -> 4.662563 | V23: =IF(ISNUMBER(L23),LN(L23),"") -> 4.6900696 | ... X23: =IF(ISNUMBER(N23),LN(N23),"") -> 4.7429121 | Y23: =Dados!U7 -> 1
A24: IMP-saude-taxa_de_vacinacao_contra_o_sarampo | B24: =Dados!C8 -> Saúde | C24: =Dados!D8 -> Taxa de vacinação contra o sarampo | D24: =Dados!F8 -> Maior é melhor | E24: =IF(OR(Dados!H8="",Dados!$H8=""),"",IF(Dados!$F8="Menor é melhor",100*Dados!$H8/Dados!H8,100*Dados!H8/Dados!$H8)) -> 100 | F24: =IF(OR(Dados!I8="",Dados!$H8=""),"",IF(Dados!$F8="Menor é melhor",100*Dados!$H8/Dados!I8,100*Dados!I8/Dados!$H8)) -> 107.57576 | G24: =IF(OR(Dados!J8="",Dados!$H8=""),"",IF(Dados!$F8="Menor é melhor",100*Dados!$H8/Dados!J8,100*Dados!J8/Dados!$H8)) -> 103.0303 | H24: =IF(OR(Dados!K8="",Dados!$H8=""),"",IF(Dados!$F8="Menor é melhor",100*Dados!$H8/Dados!K8,100*Dados!K8/Dados!$H8)) -> 115.15152 | I24: =IF(OR(Dados!M8="",Dados!$H8=""),"",IF(Dados!$F8="Menor é melhor",100*Dados!$H8/Dados!M8,100*Dados!M8/Dados!$H8)) -> 100 | J24: =IF(OR(Dados!N8="",Dados!$H8=""),"",IF(Dados!$F8="Menor é melhor",100*Dados!$H8/Dados!N8,100*Dados!N8/Dados!$H8)) -> 107.07071 | K24: =IF(OR(Dados!O8="",Dados!$H8=""),"",IF(Dados!$F8="Menor é melhor",100*Dados!$H8/Dados!O8,100*Dados!O8/Dados!$H8)) -> 114.14141 | L24: =IF(OR(Dados!P8="",Dados!$H8=""),"",IF(Dados!$F8="Menor é melhor",100*Dados!$H8/Dados!P8,100*Dados!P8/Dados!$H8)) -> 121.21212 | M24: =IF(OR(Dados!Q8="",Dados!$H8=""),"",IF(Dados!$F8="Menor é melhor",100*Dados!$H8/Dados!Q8,100*Dados!Q8/Dados!$H8)) -> 128.28283 | N24: =IF(OR(Dados!R8="",Dados!$H8=""),"",IF(Dados!$F8="Menor é melhor",100*Dados!$H8/Dados!R8,100*Dados!R8/Dados!$H8)) -> 135.35354 | O24: =IF(ISNUMBER(E24),LN(E24),"") -> 4.6051702 | P24: =IF(ISNUMBER(F24),LN(F24),"") -> 4.6781953 | Q24: =IF(ISNUMBER(G24),LN(G24),"") -> 4.6350231 | R24: =IF(ISNUMBER(H24),LN(H24),"") -> 4.7462488 | S24: =IF(ISNUMBER(I24),LN(I24),"") -> 4.6051702 | T24: =IF(ISNUMBER(J24),LN(J24),"") -> 4.6734894 | U24: =IF(ISNUMBER(K24),LN(K24),"") -> 4.7374382 | V24: =IF(ISNUMBER(L24),LN(L24),"") -> 4.7975421 | ... X24: =IF(ISNUMBER(N24),LN(N24),"") -> 4.9078901 | Y24: =Dados!U8 -> 1
A25: IMP-saude-taxa_de_incidencia_da_malaria | B25: =Dados!C9 -> Saúde | C25: =Dados!D9 -> Taxa de incidência da malária | D25: =Dados!F9 -> Menor é melhor | E25: =IF(OR(Dados!H9="",Dados!$H9=""),"",IF(Dados!$F9="Menor é melhor",100*Dados!$H9/Dados!H9,100*Dados!H9/Dados!$H9)) -> 100 | F25: =IF(OR(Dados!I9="",Dados!$H9=""),"",IF(Dados!$F9="Menor é melhor",100*Dados!$H9/Dados!I9,100*Dados!I9/Dados!$H9)) -> 95.864662 | G25: =IF(OR(Dados!J9="",Dados!$H9=""),"",IF(Dados!$F9="Menor é melhor",100*Dados!$H9/Dados!J9,100*Dados!J9/Dados!$H9)) -> 83.061889 | H25: =IF(OR(Dados!K9="",Dados!$H9=""),"",IF(Dados!$F9="Menor é melhor",100*Dados!$H9/Dados!K9,100*Dados!K9/Dados!$H9)) -> 85.57047 | I25: =IF(OR(Dados!M9="",Dados!$H9=""),"",IF(Dados!$F9="Menor é melhor",100*Dados!$H9/Dados!M9,100*Dados!M9/Dados!$H9)) -> 100 | J25: =IF(OR(Dados!N9="",Dados!$H9=""),"",IF(Dados!$F9="Menor é melhor",100*Dados!$H9/Dados!N9,100*Dados!N9/Dados!$H9)) -> 105.51724 | K25: =IF(OR(Dados!O9="",Dados!$H9=""),"",IF(Dados!$F9="Menor é melhor",100*Dados!$H9/Dados!O9,100*Dados!O9/Dados!$H9)) -> 111.67883 | L25: =IF(OR(Dados!P9="",Dados!$H9=""),"",IF(Dados!$F9="Menor é melhor",100*Dados!$H9/Dados!P9,100*Dados!P9/Dados!$H9)) -> 118.60465 | M25: =IF(OR(Dados!Q9="",Dados!$H9=""),"",IF(Dados!$F9="Menor é melhor",100*Dados!$H9/Dados!Q9,100*Dados!Q9/Dados!$H9)) -> 126.44628 | N25: =IF(OR(Dados!R9="",Dados!$H9=""),"",IF(Dados!$F9="Menor é melhor",100*Dados!$H9/Dados!R9,100*Dados!R9/Dados!$H9)) -> 135.39823 | O25: =IF(ISNUMBER(E25),LN(E25),"") -> 4.6051702 | P25: =IF(ISNUMBER(F25),LN(F25),"") -> 4.5629374 | Q25: =IF(ISNUMBER(G25),LN(G25),"") -> 4.419586 | R25: =IF(ISNUMBER(H25),LN(H25),"") -> 4.4493402 | S25: =IF(ISNUMBER(I25),LN(I25),"") -> 4.6051702 | T25: =IF(ISNUMBER(J25),LN(J25),"") -> 4.6588744 | U25: =IF(ISNUMBER(K25),LN(K25),"") -> 4.7156272 | V25: =IF(ISNUMBER(L25),LN(L25),"") -> 4.7757957 | ... X25: =IF(ISNUMBER(N25),LN(N25),"") -> 4.9082203 | Y25: =Dados!U9 -> 1
A26: IMP-saude-taxa_de_sucesso_do_tratamento_para_a_tuberculose | B26: =Dados!C10 -> Saúde | C26: =Dados!D10 -> Taxa de sucesso do tratamento para a tuberculose | D26: =Dados!F10 -> Maior é melhor | E26: =IF(OR(Dados!H10="",Dados!$H10=""),"",IF(Dados!$F10="Menor é melhor",100*Dados!$H10/Dados!H10,100*Dados!H10/Dados!$H10)) -> 100 | F26: =IF(OR(Dados!I10="",Dados!$H10=""),"",IF(Dados!$F10="Menor é melhor",100*Dados!$H10/Dados!I10,100*Dados!I10/Dados!$H10)) -> 95.714286 | G26: =IF(OR(Dados!J10="",Dados!$H10=""),"",IF(Dados!$F10="Menor é melhor",100*Dados!$H10/Dados!J10,100*Dados!J10/Dados!$H10)) -> 105.71429 | H26: =IF(OR(Dados!K10="",Dados!$H10=""),"",IF(Dados!$F10="Menor é melhor",100*Dados!$H10/Dados!K10,100*Dados!K10/Dados!$H10)) -> 130 | I26: =IF(OR(Dados!M10="",Dados!$H10=""),"",IF(Dados!$F10="Menor é melhor",100*Dados!$H10/Dados!M10,100*Dados!M10/Dados!$H10)) -> 100 | J26: =IF(OR(Dados!N10="",Dados!$H10=""),"",IF(Dados!$F10="Menor é melhor",100*Dados!$H10/Dados!N10,100*Dados!N10/Dados!$H10)) -> 102.85714 | K26: =IF(OR(Dados!O10="",Dados!$H10=""),"",IF(Dados!$F10="Menor é melhor",100*Dados!$H10/Dados!O10,100*Dados!O10/Dados!$H10)) -> 105.71429 | L26: =IF(OR(Dados!P10="",Dados!$H10=""),"",IF(Dados!$F10="Menor é melhor",100*Dados!$H10/Dados!P10,100*Dados!P10/Dados!$H10)) -> 108.57143 | M26: =IF(OR(Dados!Q10="",Dados!$H10=""),"",IF(Dados!$F10="Menor é melhor",100*Dados!$H10/Dados!Q10,100*Dados!Q10/Dados!$H10)) -> 111.42857 | N26: =IF(OR(Dados!R10="",Dados!$H10=""),"",IF(Dados!$F10="Menor é melhor",100*Dados!$H10/Dados!R10,100*Dados!R10/Dados!$H10)) -> 114.28571 | O26: =IF(ISNUMBER(E26),LN(E26),"") -> 4.6051702 | P26: =IF(ISNUMBER(F26),LN(F26),"") -> 4.5613676 | Q26: =IF(ISNUMBER(G26),LN(G26),"") -> 4.66074 | R26: =IF(ISNUMBER(H26),LN(H26),"") -> 4.8675345 | S26: =IF(ISNUMBER(I26),LN(I26),"") -> 4.6051702 | T26: =IF(ISNUMBER(J26),LN(J26),"") -> 4.6333411 | U26: =IF(ISNUMBER(K26),LN(K26),"") -> 4.66074 | V26: =IF(ISNUMBER(L26),LN(L26),"") -> 4.6874083 | ... X26: =IF(ISNUMBER(N26),LN(N26),"") -> 4.7387016 | Y26: =Dados!U10 -> 1
A27: IMP-saude-partos_institucionais_realizados_por_profissionais_qualificados | B27: =Dados!C11 -> Saúde | C27: =Dados!D11 -> Partos institucionais realizados por profissionais qualificados | D27: =Dados!F11 -> Maior é melhor | E27: =IF(OR(Dados!H11="",Dados!$H11=""),"",IF(Dados!$F11="Menor é melhor",100*Dados!$H11/Dados!H11,100*Dados!H11/Dados!$H11)) -> 100 | F27: =IF(OR(Dados!I11="",Dados!$H11=""),"",IF(Dados!$F11="Menor é melhor",100*Dados!$H11/Dados!I11,100*Dados!I11/Dados!$H11)) -> 144.11765 | G27: =IF(OR(Dados!J11="",Dados!$H11=""),"",IF(Dados!$F11="Menor é melhor",100*Dados!$H11/Dados!J11,100*Dados!J11/Dados!$H11)) -> 150 | H27: =IF(OR(Dados!K11="",Dados!$H11=""),"",IF(Dados!$F11="Menor é melhor",100*Dados!$H11/Dados!K11,100*Dados!K11/Dados!$H11)) -> 188.23529 | I27: =IF(OR(Dados!M11="",Dados!$H11=""),"",IF(Dados!$F11="Menor é melhor",100*Dados!$H11/Dados!M11,100*Dados!M11/Dados!$H11)) -> 100 | J27: =IF(OR(Dados!N11="",Dados!$H11=""),"",IF(Dados!$F11="Menor é melhor",100*Dados!$H11/Dados!N11,100*Dados!N11/Dados!$H11)) -> 121.56863 | K27: =IF(OR(Dados!O11="",Dados!$H11=""),"",IF(Dados!$F11="Menor é melhor",100*Dados!$H11/Dados!O11,100*Dados!O11/Dados!$H11)) -> 143.13725 | L27: =IF(OR(Dados!P11="",Dados!$H11=""),"",IF(Dados!$F11="Menor é melhor",100*Dados!$H11/Dados!P11,100*Dados!P11/Dados!$H11)) -> 164.70588 | M27: =IF(OR(Dados!Q11="",Dados!$H11=""),"",IF(Dados!$F11="Menor é melhor",100*Dados!$H11/Dados!Q11,100*Dados!Q11/Dados!$H11)) -> 186.27451 | N27: =IF(OR(Dados!R11="",Dados!$H11=""),"",IF(Dados!$F11="Menor é melhor",100*Dados!$H11/Dados!R11,100*Dados!R11/Dados!$H11)) -> 207.84314 | O27: =IF(ISNUMBER(E27),LN(E27),"") -> 4.6051702 | P27: =IF(ISNUMBER(F27),LN(F27),"") -> 4.97063 | Q27: =IF(ISNUMBER(G27),LN(G27),"") -> 5.0106353 | R27: =IF(ISNUMBER(H27),LN(H27),"") -> 5.2376927 | S27: =IF(ISNUMBER(I27),LN(I27),"") -> 4.6051702 | T27: =IF(ISNUMBER(J27),LN(J27),"") -> 4.8004789 | U27: =IF(ISNUMBER(K27),LN(K27),"") -> 4.963804 | V27: =IF(ISNUMBER(L27),LN(L27),"") -> 5.1041614 | ... X27: =IF(ISNUMBER(N27),LN(N27),"") -> 5.3367836 | Y27: =Dados!U11 -> 1
A28: IMP-proteccao_social-pessoas_integradas_em_actividades_geradoras_de_renda_cumulativo | B28: =Dados!C12 -> Protecção Social | C28: =Dados!D12 -> Pessoas integradas em actividades geradoras de renda (cumulativo) | D28: =Dados!F12 -> Maior é melhor | E28: =IF(OR(Dados!H12="",Dados!$H12=""),"",IF(Dados!$F12="Menor é melhor",100*Dados!$H12/Dados!H12,100*Dados!H12/Dados!$H12)) -> 100 | F28: =IF(OR(Dados!I12="",Dados!$H12=""),"",IF(Dados!$F12="Menor é melhor",100*Dados!$H12/Dados!I12,100*Dados!I12/Dados!$H12)) -> 101.47297 | G28: =IF(OR(Dados!J12="",Dados!$H12=""),"",IF(Dados!$F12="Menor é melhor",100*Dados!$H12/Dados!J12,100*Dados!J12/Dados!$H12)) -> 103.48378 | H28: =IF(OR(Dados!K12="",Dados!$H12=""),"",IF(Dados!$F12="Menor é melhor",100*Dados!$H12/Dados!K12,100*Dados!K12/Dados!$H12)) -> 105.18108 | I28: =IF(OR(Dados!M12="",Dados!$H12=""),"",IF(Dados!$F12="Menor é melhor",100*Dados!$H12/Dados!M12,100*Dados!M12/Dados!$H12)) -> 100 | J28: =IF(OR(Dados!N12="",Dados!$H12=""),"",IF(Dados!$F12="Menor é melhor",100*Dados!$H12/Dados!N12,100*Dados!N12/Dados!$H12)) -> 155.85586 | K28: =IF(OR(Dados!O12="",Dados!$H12=""),"",IF(Dados!$F12="Menor é melhor",100*Dados!$H12/Dados!O12,100*Dados!O12/Dados!$H12)) -> 211.71171 | L28: =IF(OR(Dados!P12="",Dados!$H12=""),"",IF(Dados!$F12="Menor é melhor",100*Dados!$H12/Dados!P12,100*Dados!P12/Dados!$H12)) -> 267.56757 | M28: =IF(OR(Dados!Q12="",Dados!$H12=""),"",IF(Dados!$F12="Menor é melhor",100*Dados!$H12/Dados!Q12,100*Dados!Q12/Dados!$H12)) -> 323.42342 | N28: =IF(OR(Dados!R12="",Dados!$H12=""),"",IF(Dados!$F12="Menor é melhor",100*Dados!$H12/Dados!R12,100*Dados!R12/Dados!$H12)) -> 379.27928 | O28: =IF(ISNUMBER(E28),LN(E28),"") -> 4.6051702 | P28: =IF(ISNUMBER(F28),LN(F28),"") -> 4.6197925 | Q28: =IF(ISNUMBER(G28),LN(G28),"") -> 4.6394149 | R28: =IF(ISNUMBER(H28),LN(H28),"") -> 4.6556834 | S28: =IF(ISNUMBER(I28),LN(I28),"") -> 4.6051702 | T28: =IF(ISNUMBER(J28),LN(J28),"") -> 5.0489316 | U28: =IF(ISNUMBER(K28),LN(K28),"") -> 5.3552255 | V28: =IF(ISNUMBER(L28),LN(L28),"") -> 5.5893721 | ... X28: =IF(ISNUMBER(N28),LN(N28),"") -> 5.9382728 | Y28: =Dados!U12 -> 1
A29: IMP-proteccao_social-beneficiarios_de_transferencias_sociais_monetarias_cumulativo | B29: =Dados!C13 -> Protecção Social | C29: =Dados!D13 -> Beneficiários de transferências sociais monetárias (cumulativo) | D29: =Dados!F13 -> Maior é melhor | E29: =IF(OR(Dados!H13="",Dados!$H13=""),"",IF(Dados!$F13="Menor é melhor",100*Dados!$H13/Dados!H13,100*Dados!H13/Dados!$H13)) -> 100 | F29: =IF(OR(Dados!I13="",Dados!$H13=""),"",IF(Dados!$F13="Menor é melhor",100*Dados!$H13/Dados!I13,100*Dados!I13/Dados!$H13)) -> 155.72252 | G29: =IF(OR(Dados!J13="",Dados!$H13=""),"",IF(Dados!$F13="Menor é melhor",100*Dados!$H13/Dados!J13,100*Dados!J13/Dados!$H13)) -> 175.17697 | H29: =IF(OR(Dados!K13="",Dados!$H13=""),"",IF(Dados!$F13="Menor é melhor",100*Dados!$H13/Dados!K13,100*Dados!K13/Dados!$H13)) -> 221.14919 | I29: =IF(OR(Dados!M13="",Dados!$H13=""),"",IF(Dados!$F13="Menor é melhor",100*Dados!$H13/Dados!M13,100*Dados!M13/Dados!$H13)) -> 100 | J29: =IF(OR(Dados!N13="",Dados!$H13=""),"",IF(Dados!$F13="Menor é melhor",100*Dados!$H13/Dados!N13,100*Dados!N13/Dados!$H13)) -> 164.89335 | K29: =IF(OR(Dados!O13="",Dados!$H13=""),"",IF(Dados!$F13="Menor é melhor",100*Dados!$H13/Dados!O13,100*Dados!O13/Dados!$H13)) -> 229.7867 | L29: =IF(OR(Dados!P13="",Dados!$H13=""),"",IF(Dados!$F13="Menor é melhor",100*Dados!$H13/Dados!P13,100*Dados!P13/Dados!$H13)) -> 294.68004 | M29: =IF(OR(Dados!Q13="",Dados!$H13=""),"",IF(Dados!$F13="Menor é melhor",100*Dados!$H13/Dados!Q13,100*Dados!Q13/Dados!$H13)) -> 359.57339 | N29: =IF(OR(Dados!R13="",Dados!$H13=""),"",IF(Dados!$F13="Menor é melhor",100*Dados!$H13/Dados!R13,100*Dados!R13/Dados!$H13)) -> 424.46674 | O29: =IF(ISNUMBER(E29),LN(E29),"") -> 4.6051702 | P29: =IF(ISNUMBER(F29),LN(F29),"") -> 5.0480757 | Q29: =IF(ISNUMBER(G29),LN(G29),"") -> 5.1657967 | R29: =IF(ISNUMBER(H29),LN(H29),"") -> 5.3988375 | S29: =IF(ISNUMBER(I29),LN(I29),"") -> 4.6051702 | T29: =IF(ISNUMBER(J29),LN(J29),"") -> 5.1052989 | U29: =IF(ISNUMBER(K29),LN(K29),"") -> 5.4371515 | V29: =IF(ISNUMBER(L29),LN(L29),"") -> 5.6858902 | ... X29: =IF(ISNUMBER(N29),LN(N29),"") -> 6.0508336 | Y29: =Dados!U13 -> 1
A30: IMP-proteccao_social-familias_assistidas_com_cesta_basica_de_alimentos_cumulativo | B30: =Dados!C14 -> Protecção Social | C30: =Dados!D14 -> Famílias assistidas com cesta básica de alimentos (cumulativo) | D30: =Dados!F14 -> Maior é melhor | E30: =IF(OR(Dados!H14="",Dados!$H14=""),"",IF(Dados!$F14="Menor é melhor",100*Dados!$H14/Dados!H14,100*Dados!H14/Dados!$H14)) -> 100 | F30: =IF(OR(Dados!I14="",Dados!$H14=""),"",IF(Dados!$F14="Menor é melhor",100*Dados!$H14/Dados!I14,100*Dados!I14/Dados!$H14)) -> 130.27308 | G30: =IF(OR(Dados!J14="",Dados!$H14=""),"",IF(Dados!$F14="Menor é melhor",100*Dados!$H14/Dados!J14,100*Dados!J14/Dados!$H14)) -> 391.93325 | H30: =IF(OR(Dados!K14="",Dados!$H14=""),"",IF(Dados!$F14="Menor é melhor",100*Dados!$H14/Dados!K14,100*Dados!K14/Dados!$H14)) -> 454.29996 | I30: =IF(OR(Dados!M14="",Dados!$H14=""),"",IF(Dados!$F14="Menor é melhor",100*Dados!$H14/Dados!M14,100*Dados!M14/Dados!$H14)) -> 100 | J30: =IF(OR(Dados!N14="",Dados!$H14=""),"",IF(Dados!$F14="Menor é melhor",100*Dados!$H14/Dados!N14,100*Dados!N14/Dados!$H14)) -> 186.59153 | K30: =IF(OR(Dados!O14="",Dados!$H14=""),"",IF(Dados!$F14="Menor é melhor",100*Dados!$H14/Dados!O14,100*Dados!O14/Dados!$H14)) -> 273.18307 | L30: =IF(OR(Dados!P14="",Dados!$H14=""),"",IF(Dados!$F14="Menor é melhor",100*Dados!$H14/Dados!P14,100*Dados!P14/Dados!$H14)) -> 359.7746 | M30: =IF(OR(Dados!Q14="",Dados!$H14=""),"",IF(Dados!$F14="Menor é melhor",100*Dados!$H14/Dados!Q14,100*Dados!Q14/Dados!$H14)) -> 446.36613 | N30: =IF(OR(Dados!R14="",Dados!$H14=""),"",IF(Dados!$F14="Menor é melhor",100*Dados!$H14/Dados!R14,100*Dados!R14/Dados!$H14)) -> 532.95767 | O30: =IF(ISNUMBER(E30),LN(E30),"") -> 4.6051702 | P30: =IF(ISNUMBER(F30),LN(F30),"") -> 4.8696329 | Q30: =IF(ISNUMBER(G30),LN(G30),"") -> 5.9710915 | R30: =IF(ISNUMBER(H30),LN(H30),"") -> 6.1187577 | S30: =IF(ISNUMBER(I30),LN(I30),"") -> 4.6051702 | T30: =IF(ISNUMBER(J30),LN(J30),"") -> 5.2289219 | U30: =IF(ISNUMBER(K30),LN(K30),"") -> 5.6101421 | V30: =IF(ISNUMBER(L30),LN(L30),"") -> 5.8854777 | ... X30: =IF(ISNUMBER(N30),LN(N30),"") -> 6.278442 | Y30: =Dados!U14 -> 1
A31: IMP-comunicacao-numero_de_assinantes_de_internet | B31: =Dados!C15 -> Comunicação | C31: =Dados!D15 -> Número de assinantes de Internet | D31: =Dados!F15 -> Maior é melhor | E31: =IF(OR(Dados!H15="",Dados!$H15=""),"",IF(Dados!$F15="Menor é melhor",100*Dados!$H15/Dados!H15,100*Dados!H15/Dados!$H15)) -> 100 | F31: =IF(OR(Dados!I15="",Dados!$H15=""),"",IF(Dados!$F15="Menor é melhor",100*Dados!$H15/Dados!I15,100*Dados!I15/Dados!$H15)) -> 110 | G31: =IF(OR(Dados!J15="",Dados!$H15=""),"",IF(Dados!$F15="Menor é melhor",100*Dados!$H15/Dados!J15,100*Dados!J15/Dados!$H15)) -> 120 | H31: =IF(OR(Dados!K15="",Dados!$H15=""),"",IF(Dados!$F15="Menor é melhor",100*Dados!$H15/Dados!K15,100*Dados!K15/Dados!$H15)) -> 166.66667 | I31: =IF(OR(Dados!M15="",Dados!$H15=""),"",IF(Dados!$F15="Menor é melhor",100*Dados!$H15/Dados!M15,100*Dados!M15/Dados!$H15)) -> 100 | J31: =IF(OR(Dados!N15="",Dados!$H15=""),"",IF(Dados!$F15="Menor é melhor",100*Dados!$H15/Dados!N15,100*Dados!N15/Dados!$H15)) -> 113.33333 | K31: =IF(OR(Dados!O15="",Dados!$H15=""),"",IF(Dados!$F15="Menor é melhor",100*Dados!$H15/Dados!O15,100*Dados!O15/Dados!$H15)) -> 126.66667 | L31: =IF(OR(Dados!P15="",Dados!$H15=""),"",IF(Dados!$F15="Menor é melhor",100*Dados!$H15/Dados!P15,100*Dados!P15/Dados!$H15)) -> 140 | M31: =IF(OR(Dados!Q15="",Dados!$H15=""),"",IF(Dados!$F15="Menor é melhor",100*Dados!$H15/Dados!Q15,100*Dados!Q15/Dados!$H15)) -> 153.33333 | N31: =IF(OR(Dados!R15="",Dados!$H15=""),"",IF(Dados!$F15="Menor é melhor",100*Dados!$H15/Dados!R15,100*Dados!R15/Dados!$H15)) -> 166.66667 | O31: =IF(ISNUMBER(E31),LN(E31),"") -> 4.6051702 | P31: =IF(ISNUMBER(F31),LN(F31),"") -> 4.7004804 | Q31: =IF(ISNUMBER(G31),LN(G31),"") -> 4.7874917 | R31: =IF(ISNUMBER(H31),LN(H31),"") -> 5.1159958 | S31: =IF(ISNUMBER(I31),LN(I31),"") -> 4.6051702 | T31: =IF(ISNUMBER(J31),LN(J31),"") -> 4.7303333 | U31: =IF(ISNUMBER(K31),LN(K31),"") -> 4.841559 | V31: =IF(ISNUMBER(L31),LN(L31),"") -> 4.9416424 | ... X31: =IF(ISNUMBER(N31),LN(N31),"") -> 5.1159958 | Y31: =Dados!U15 -> 1
A32: IMP-comunicacao-numero_de_assinantes_de_servicos_moveis | B32: =Dados!C16 -> Comunicação | C32: =Dados!D16 -> Número de assinantes de serviços móveis | D32: =Dados!F16 -> Maior é melhor | E32: =IF(OR(Dados!H16="",Dados!$H16=""),"",IF(Dados!$F16="Menor é melhor",100*Dados!$H16/Dados!H16,100*Dados!H16/Dados!$H16)) -> 100 | F32: =IF(OR(Dados!I16="",Dados!$H16=""),"",IF(Dados!$F16="Menor é melhor",100*Dados!$H16/Dados!I16,100*Dados!I16/Dados!$H16)) -> 104.16667 | G32: =IF(OR(Dados!J16="",Dados!$H16=""),"",IF(Dados!$F16="Menor é melhor",100*Dados!$H16/Dados!J16,100*Dados!J16/Dados!$H16)) -> 104.16667 | H32: =IF(OR(Dados!K16="",Dados!$H16=""),"",IF(Dados!$F16="Menor é melhor",100*Dados!$H16/Dados!K16,100*Dados!K16/Dados!$H16)) -> 108.33333 | I32: =IF(OR(Dados!M16="",Dados!$H16=""),"",IF(Dados!$F16="Menor é melhor",100*Dados!$H16/Dados!M16,100*Dados!M16/Dados!$H16)) -> 100 | J32: =IF(OR(Dados!N16="",Dados!$H16=""),"",IF(Dados!$F16="Menor é melhor",100*Dados!$H16/Dados!N16,100*Dados!N16/Dados!$H16)) -> 103.24074 | K32: =IF(OR(Dados!O16="",Dados!$H16=""),"",IF(Dados!$F16="Menor é melhor",100*Dados!$H16/Dados!O16,100*Dados!O16/Dados!$H16)) -> 106.48148 | L32: =IF(OR(Dados!P16="",Dados!$H16=""),"",IF(Dados!$F16="Menor é melhor",100*Dados!$H16/Dados!P16,100*Dados!P16/Dados!$H16)) -> 109.72222 | M32: =IF(OR(Dados!Q16="",Dados!$H16=""),"",IF(Dados!$F16="Menor é melhor",100*Dados!$H16/Dados!Q16,100*Dados!Q16/Dados!$H16)) -> 112.96296 | N32: =IF(OR(Dados!R16="",Dados!$H16=""),"",IF(Dados!$F16="Menor é melhor",100*Dados!$H16/Dados!R16,100*Dados!R16/Dados!$H16)) -> 116.2037 | O32: =IF(ISNUMBER(E32),LN(E32),"") -> 4.6051702 | P32: =IF(ISNUMBER(F32),LN(F32),"") -> 4.6459922 | Q32: =IF(ISNUMBER(G32),LN(G32),"") -> 4.6459922 | R32: =IF(ISNUMBER(H32),LN(H32),"") -> 4.6852129 | S32: =IF(ISNUMBER(I32),LN(I32),"") -> 4.6051702 | T32: =IF(ISNUMBER(J32),LN(J32),"") -> 4.6370635 | U32: =IF(ISNUMBER(K32),LN(K32),"") -> 4.6679711 | V32: =IF(ISNUMBER(L32),LN(L32),"") -> 4.6979519 | ... X32: =IF(ISNUMBER(N32),LN(N32),"") -> 4.7553447 | Y32: =Dados!U16 -> 1
... A71: IMP-economico-taxa_de_desemprego | B71: =Dados!C55 -> Económico | C71: =Dados!D55 -> Taxa de Desemprego | D71: =Dados!F55 -> Menor é melhor | E71: =IF(OR(Dados!H55="",Dados!$H55=""),"",IF(Dados!$F55="Menor é melhor",100*Dados!$H55/Dados!H55,100*Dados!H55/Dados!$H55)) -> 100 | F71: =IF(OR(Dados!I55="",Dados!$H55=""),"",IF(Dados!$F55="Menor é melhor",100*Dados!$H55/Dados!I55,100*Dados!I55/Dados!$H55)) -> 100 | G71: =IF(OR(Dados!J55="",Dados!$H55=""),"",IF(Dados!$F55="Menor é melhor",100*Dados!$H55/Dados!J55,100*Dados!J55/Dados!$H55)) -> 100 | H71: =IF(OR(Dados!K55="",Dados!$H55=""),"",IF(Dados!$F55="Menor é melhor",100*Dados!$H55/Dados!K55,100*Dados!K55/Dados!$H55)) -> 111.52416 | I71: =IF(OR(Dados!M55="",Dados!$H55=""),"",IF(Dados!$F55="Menor é melhor",100*Dados!$H55/Dados!M55,100*Dados!M55/Dados!$H55)) -> 100 | J71: =IF(OR(Dados!N55="",Dados!$H55=""),"",IF(Dados!$F55="Menor é melhor",100*Dados!$H55/Dados!N55,100*Dados!N55/Dados!$H55)) -> 105.88235 | K71: =IF(OR(Dados!O55="",Dados!$H55=""),"",IF(Dados!$F55="Menor é melhor",100*Dados!$H55/Dados!O55,100*Dados!O55/Dados!$H55)) -> 112.5 | L71: =IF(OR(Dados!P55="",Dados!$H55=""),"",IF(Dados!$F55="Menor é melhor",100*Dados!$H55/Dados!P55,100*Dados!P55/Dados!$H55)) -> 120 | M71: =IF(OR(Dados!Q55="",Dados!$H55=""),"",IF(Dados!$F55="Menor é melhor",100*Dados!$H55/Dados!Q55,100*Dados!Q55/Dados!$H55)) -> 120 | N71: =IF(OR(Dados!R55="",Dados!$H55=""),"",IF(Dados!$F55="Menor é melhor",100*Dados!$H55/Dados!R55,100*Dados!R55/Dados!$H55)) -> 120 | O71: =IF(ISNUMBER(E71),LN(E71),"") -> 4.6051702 | P71: =IF(ISNUMBER(F71),LN(F71),"") -> 4.6051702 | Q71: =IF(ISNUMBER(G71),LN(G71),"") -> 4.6051702 | R71: =IF(ISNUMBER(H71),LN(H71),"") -> 4.7142413 | S71: =IF(ISNUMBER(I71),LN(I71),"") -> 4.6051702 | T71: =IF(ISNUMBER(J71),LN(J71),"") -> 4.6623286 | U71: =IF(ISNUMBER(K71),LN(K71),"") -> 4.7229532 | V71: =IF(ISNUMBER(L71),LN(L71),"") -> 4.7874917 | ... X71: =IF(ISNUMBER(N71),LN(N71),"") -> 4.7874917 | Y71: =Dados!U55 -> 1

Sheet ICE
A1: ICE — Índice Compósito de Execução do PDN (Executado / Previsto)
A2: Grau de atingimento da meta anual interpolada (distância-à-meta com tecto de 100%: excedentes não compensam défices; indicadores «menor é melhor» invertidos). Agregação: média aritmética dentro do domínio e entre os 7 domínios. 46 indicadores com meta.
A4: A. Resultados — domínios e índice global
A5: Domínio | B5: 2023 | C5: 2024 | D5: 2025 | E5: 2025 sem tecto | F5: Δ 2025−2024 | G5: Semáforo 2025
A6: Saúde | B6: =AVERAGEIFS($D$21:$D$71,$A$21:$A$71,$A6,$D$21:$D$71,">0") -> 0.97317948 | C6: =AVERAGEIFS($E$21:$E$71,$A$21:$A$71,$A6,$E$21:$E$71,">0") -> 0.94106861 | D6: =AVERAGEIFS($F$21:$F$71,$A$21:$A$71,$A6,$F$21:$F$71,">0") -> 0.92974221 | E6: =AVERAGEIFS($G$21:$G$71,$A$21:$A$71,$A6,$G$21:$G$71,">0") -> 0.99835123 | F6: =D6-C6 -> -0.0113264 | G6: =D6 -> 0.92974221
A7: Protecção Social | B7: =AVERAGEIFS($D$21:$D$71,$A$21:$A$71,$A7,$D$21:$D$71,">0") -> 0.76454173 | C7: =AVERAGEIFS($E$21:$E$71,$A$21:$A$71,$A7,$E$21:$E$71,">0") -> 0.75038059 | D7: =AVERAGEIFS($F$21:$F$71,$A$21:$A$71,$A7,$F$21:$F$71,">0") -> 0.71452441 | E7: =AVERAGEIFS($G$21:$G$71,$A$21:$A$71,$A7,$G$21:$G$71,">0") -> 0.80210272 | F7: =D7-C7 -> -0.035856176 | G7: =D7 -> 0.71452441
A8: Comunicação | B8: =AVERAGEIFS($D$21:$D$71,$A$21:$A$71,$A8,$D$21:$D$71,">0") -> 0.98529412 | C8: =AVERAGEIFS($E$21:$E$71,$A$21:$A$71,$A8,$E$21:$E$71,">0") -> 0.96281465 | D8: =AVERAGEIFS($F$21:$F$71,$A$21:$A$71,$A8,$F$21:$F$71,">0") -> 0.99367089 | E8: =AVERAGEIFS($G$21:$G$71,$A$21:$A$71,$A8,$G$21:$G$71,">0") -> 1.088909 | F8: =D8-C8 -> 0.030856241 | G8: =D8 -> 0.99367089
A9: Educação e FP | B9: =AVERAGEIFS($D$21:$D$71,$A$21:$A$71,$A9,$D$21:$D$71,">0") -> 0.95696565 | C9: =AVERAGEIFS($E$21:$E$71,$A$21:$A$71,$A9,$E$21:$E$71,">0") -> 0.91624162 | D9: =AVERAGEIFS($F$21:$F$71,$A$21:$A$71,$A9,$F$21:$F$71,">0") -> 0.89157843 | E9: =AVERAGEIFS($G$21:$G$71,$A$21:$A$71,$A9,$G$21:$G$71,">0") -> 1.2707739 | F9: =D9-C9 -> -0.024663192 | G9: =D9 -> 0.89157843
A10: Infraestruturas | B10: =AVERAGEIFS($D$21:$D$71,$A$21:$A$71,$A10,$D$21:$D$71,">0") -> 0.87727498 | C10: =AVERAGEIFS($E$21:$E$71,$A$21:$A$71,$A10,$E$21:$E$71,">0") -> 0.83383112 | D10: =AVERAGEIFS($F$21:$F$71,$A$21:$A$71,$A10,$F$21:$F$71,">0") -> 0.80944156 | E10: =AVERAGEIFS($G$21:$G$71,$A$21:$A$71,$A10,$G$21:$G$71,">0") -> 0.81297522 | F10: =D10-C10 -> -0.024389554 | G10: =D10 -> 0.80944156
A11: Fomento à Produção | B11: =AVERAGEIFS($D$21:$D$71,$A$21:$A$71,$A11,$D$21:$D$71,">0") -> 0.93441698 | C11: =AVERAGEIFS($E$21:$E$71,$A$21:$A$71,$A11,$E$21:$E$71,">0") -> 0.85567815 | D11: =AVERAGEIFS($F$21:$F$71,$A$21:$A$71,$A11,$F$21:$F$71,">0") -> 0.79184027 | E11: =AVERAGEIFS($G$21:$G$71,$A$21:$A$71,$A11,$G$21:$G$71,">0") -> 1.0335434 | F11: =D11-C11 -> -0.06383788 | G11: =D11 -> 0.79184027
A12: Económico | B12: =AVERAGEIFS($D$21:$D$71,$A$21:$A$71,$A12,$D$21:$D$71,">0") -> 0.60310245 | C12: =AVERAGEIFS($E$21:$E$71,$A$21:$A$71,$A12,$E$21:$E$71,">0") -> 0.85540675 | D12: =AVERAGEIFS($F$21:$F$71,$A$21:$A$71,$A12,$F$21:$F$71,">0") -> 0.94067534 | E12: =AVERAGEIFS($G$21:$G$71,$A$21:$A$71,$A12,$G$21:$G$71,">0") -> 0.97192534 | F12: =D12-C12 -> 0.085268595 | G12: =D12 -> 0.94067534
A13: ÍNDICE GLOBAL (ICE) | B13: =AVERAGE(B6:B12) -> 0.8706822 | C13: =AVERAGE(C6:C12) -> 0.87363164 | D13: =AVERAGE(D6:D12) -> 0.8673533 | E13: =AVERAGE(E6:E12) -> 0.99694011 | F13: =D13-C13 -> -0.006278338 | G13: =D13 -> 0.8673533
A14: Robustez: média simples dos 46 indicadores | B14: =AVERAGEIF($D$21:$D$71,">0") -> 0.89698872 | C14: =AVERAGEIF($E$21:$E$71,">0") -> 0.8747165 | D14: =AVERAGEIF($F$21:$F$71,">0") -> 0.85579978
A15: Leitura: 100% = meta anual cumprida. O semáforo assinala ≥90% (verde), 75–90% (amarelo) e <75% (vermelho).
A19: B. Detalhe por indicador — % de execução da meta anual (tecto 100%)
A20: Domínio | B20: Indicador | C20: Direcção | D20: 2023 | E20: 2024 | F20: 2025 | G20: 2025 sem tecto | H20: 2025 vs meta MINPLAN publicada (s/ tecto) | I20: Classe 2025 | J20: Chave téc.
A21: =Dados!C5 -> Saúde | B21: =Dados!D5 -> Novas Camas em Hospitais (Cumulativo) | C21: =Dados!F5 -> Maior é melhor | D21: =IF(OR(Dados!N5="",Dados!I5=""),"",IF(Dados!$F5="Menor é melhor",MIN(1,Dados!N5/Dados!I5),MIN(1,Dados!I5/Dados!N5))) | E21: =IF(OR(Dados!O5="",Dados!J5=""),"",IF(Dados!$F5="Menor é melhor",MIN(1,Dados!O5/Dados!J5),MIN(1,Dados!J5/Dados!O5))) | F21: =IF(OR(Dados!P5="",Dados!K5=""),"",IF(Dados!$F5="Menor é melhor",MIN(1,Dados!P5/Dados!K5),MIN(1,Dados!K5/Dados!P5))) | G21: =IF(OR(Dados!P5="",Dados!K5=""),"",IF(Dados!$F5="Menor é melhor",Dados!P5/Dados!K5,Dados!K5/Dados!P5)) | H21: =IF(OR(Dados!L5="",Dados!K5=""),"",IF(Dados!$F5="Menor é melhor",Dados!L5/Dados!K5,Dados!K5/Dados!L5)) | I21: =IF(G21="","Sem dados",IF(G21>=1,"≥100%",IF(G21>=0.75,"75–100%",IF(G21>=0.5,"50–75%","<50%")))) -> Sem dados | J21: =IF(G21="","",G21+ROW()/10^7)
A22: =Dados!C6 -> Saúde | B22: =Dados!D6 -> Taxa de cobertura da 4.ª consulta pré-natal | C22: =Dados!F6 -> Maior é melhor | D22: =IF(OR(Dados!N6="",Dados!I6=""),"",IF(Dados!$F6="Menor é melhor",MIN(1,Dados!N6/Dados!I6),MIN(1,Dados!I6/Dados!N6))) -> 1 | E22: =IF(OR(Dados!O6="",Dados!J6=""),"",IF(Dados!$F6="Menor é melhor",MIN(1,Dados!O6/Dados!J6),MIN(1,Dados!J6/Dados!O6))) -> 1 | F22: =IF(OR(Dados!P6="",Dados!K6=""),"",IF(Dados!$F6="Menor é melhor",MIN(1,Dados!P6/Dados!K6),MIN(1,Dados!K6/Dados!P6))) -> 1 | G22: =IF(OR(Dados!P6="",Dados!K6=""),"",IF(Dados!$F6="Menor é melhor",Dados!P6/Dados!K6,Dados!K6/Dados!P6)) -> 1.0714286 | H22: =IF(OR(Dados!L6="",Dados!K6=""),"",IF(Dados!$F6="Menor é melhor",Dados!L6/Dados!K6,Dados!K6/Dados!L6)) -> 1.0714286 | I22: =IF(G22="","Sem dados",IF(G22>=1,"≥100%",IF(G22>=0.75,"75–100%",IF(G22>=0.5,"50–75%","<50%")))) -> ≥100% | J22: =IF(G22="","",G22+ROW()/10^7) -> 1.0714308
A23: =Dados!C7 -> Saúde | B23: =Dados!D7 -> Taxa de imunização BCG | C23: =Dados!F7 -> Maior é melhor | D23: =IF(OR(Dados!N7="",Dados!I7=""),"",IF(Dados!$F7="Menor é melhor",MIN(1,Dados!N7/Dados!I7),MIN(1,Dados!I7/Dados!N7))) -> 1 | E23: =IF(OR(Dados!O7="",Dados!J7=""),"",IF(Dados!$F7="Menor é melhor",MIN(1,Dados!O7/Dados!J7),MIN(1,Dados!J7/Dados!O7))) -> 1 | F23: =IF(OR(Dados!P7="",Dados!K7=""),"",IF(Dados!$F7="Menor é melhor",MIN(1,Dados!P7/Dados!K7),MIN(1,Dados!K7/Dados!P7))) -> 0.90697674 | G23: =IF(OR(Dados!P7="",Dados!K7=""),"",IF(Dados!$F7="Menor é melhor",Dados!P7/Dados!K7,Dados!K7/Dados!P7)) -> 0.90697674 | H23: =IF(OR(Dados!L7="",Dados!K7=""),"",IF(Dados!$F7="Menor é melhor",Dados!L7/Dados!K7,Dados!K7/Dados!L7)) -> 0.90697674 | I23: =IF(G23="","Sem dados",IF(G23>=1,"≥100%",IF(G23>=0.75,"75–100%",IF(G23>=0.5,"50–75%","<50%")))) -> 75–100% | J23: =IF(G23="","",G23+ROW()/10^7) -> 0.90697904
A24: =Dados!C8 -> Saúde | B24: =Dados!D8 -> Taxa de vacinação contra o sarampo | C24: =Dados!F8 -> Maior é melhor | D24: =IF(OR(Dados!N8="",Dados!I8=""),"",IF(Dados!$F8="Menor é melhor",MIN(1,Dados!N8/Dados!I8),MIN(1,Dados!I8/Dados!N8))) -> 1 | E24: =IF(OR(Dados!O8="",Dados!J8=""),"",IF(Dados!$F8="Menor é melhor",MIN(1,Dados!O8/Dados!J8),MIN(1,Dados!J8/Dados!O8))) -> 0.90265487 | F24: =IF(OR(Dados!P8="",Dados!K8=""),"",IF(Dados!$F8="Menor é melhor",MIN(1,Dados!P8/Dados!K8),MIN(1,Dados!K8/Dados!P8))) -> 0.95 | G24: =IF(OR(Dados!P8="",Dados!K8=""),"",IF(Dados!$F8="Menor é melhor",Dados!P8/Dados!K8,Dados!K8/Dados!P8)) -> 0.95 | H24: =IF(OR(Dados!L8="",Dados!K8=""),"",IF(Dados!$F8="Menor é melhor",Dados!L8/Dados!K8,Dados!K8/Dados!L8)) -> 0.95 | I24: =IF(G24="","Sem dados",IF(G24>=1,"≥100%",IF(G24>=0.75,"75–100%",IF(G24>=0.5,"50–75%","<50%")))) -> 75–100% | J24: =IF(G24="","",G24+ROW()/10^7) -> 0.9500024
A25: =Dados!C9 -> Saúde | B25: =Dados!D9 -> Taxa de incidência da malária | C25: =Dados!F9 -> Menor é melhor | D25: =IF(OR(Dados!N9="",Dados!I9=""),"",IF(Dados!$F9="Menor é melhor",MIN(1,Dados!N9/Dados!I9),MIN(1,Dados!I9/Dados!N9))) -> 0.9085213 | E25: =IF(OR(Dados!O9="",Dados!J9=""),"",IF(Dados!$F9="Menor é melhor",MIN(1,Dados!O9/Dados!J9),MIN(1,Dados!J9/Dados!O9))) -> 0.74375679 | F25: =IF(OR(Dados!P9="",Dados!K9=""),"",IF(Dados!$F9="Menor é melhor",MIN(1,Dados!P9/Dados!K9),MIN(1,Dados!K9/Dados!P9))) -> 0.72147651 | G25: =IF(OR(Dados!P9="",Dados!K9=""),"",IF(Dados!$F9="Menor é melhor",Dados!P9/Dados!K9,Dados!K9/Dados!P9)) -> 0.72147651 | H25: =IF(OR(Dados!L9="",Dados!K9=""),"",IF(Dados!$F9="Menor é melhor",Dados!L9/Dados!K9,Dados!K9/Dados!L9)) -> 0.72147651 | I25: =IF(G25="","Sem dados",IF(G25>=1,"≥100%",IF(G25>=0.75,"75–100%",IF(G25>=0.5,"50–75%","<50%")))) -> 50–75% | J25: =IF(G25="","",G25+ROW()/10^7) -> 0.72147901
A26: =Dados!C10 -> Saúde | B26: =Dados!D10 -> Taxa de sucesso do tratamento para a tuberculose | C26: =Dados!F10 -> Maior é melhor | D26: =IF(OR(Dados!N10="",Dados!I10=""),"",IF(Dados!$F10="Menor é melhor",MIN(1,Dados!N10/Dados!I10),MIN(1,Dados!I10/Dados!N10))) -> 0.93055556 | E26: =IF(OR(Dados!O10="",Dados!J10=""),"",IF(Dados!$F10="Menor é melhor",MIN(1,Dados!O10/Dados!J10),MIN(1,Dados!J10/Dados!O10))) -> 1 | F26: =IF(OR(Dados!P10="",Dados!K10=""),"",IF(Dados!$F10="Menor é melhor",MIN(1,Dados!P10/Dados!K10),MIN(1,Dados!K10/Dados!P10))) -> 1 | G26: =IF(OR(Dados!P10="",Dados!K10=""),"",IF(Dados!$F10="Menor é melhor",Dados!P10/Dados!K10,Dados!K10/Dados!P10)) -> 1.1973684 | H26: =IF(OR(Dados!L10="",Dados!K10=""),"",IF(Dados!$F10="Menor é melhor",Dados!L10/Dados!K10,Dados!K10/Dados!L10)) -> 1.1973684 | I26: =IF(G26="","Sem dados",IF(G26>=1,"≥100%",IF(G26>=0.75,"75–100%",IF(G26>=0.5,"50–75%","<50%")))) -> ≥100% | J26: =IF(G26="","",G26+ROW()/10^7) -> 1.197371
A27: =Dados!C11 -> Saúde | B27: =Dados!D11 -> Partos institucionais realizados por profissionais qualificados | C27: =Dados!F11 -> Maior é melhor | D27: =IF(OR(Dados!N11="",Dados!I11=""),"",IF(Dados!$F11="Menor é melhor",MIN(1,Dados!N11/Dados!I11),MIN(1,Dados!I11/Dados!N11))) -> 1 | E27: =IF(OR(Dados!O11="",Dados!J11=""),"",IF(Dados!$F11="Menor é melhor",MIN(1,Dados!O11/Dados!J11),MIN(1,Dados!J11/Dados!O11))) -> 1 | F27: =IF(OR(Dados!P11="",Dados!K11=""),"",IF(Dados!$F11="Menor é melhor",MIN(1,Dados!P11/Dados!K11),MIN(1,Dados!K11/Dados!P11))) -> 1 | G27: =IF(OR(Dados!P11="",Dados!K11=""),"",IF(Dados!$F11="Menor é melhor",Dados!P11/Dados!K11,Dados!K11/Dados!P11)) -> 1.1428571 | H27: =IF(OR(Dados!L11="",Dados!K11=""),"",IF(Dados!$F11="Menor é melhor",Dados!L11/Dados!K11,Dados!K11/Dados!L11)) -> 1.1428571 | I27: =IF(G27="","Sem dados",IF(G27>=1,"≥100%",IF(G27>=0.75,"75–100%",IF(G27>=0.5,"50–75%","<50%")))) -> ≥100% | J27: =IF(G27="","",G27+ROW()/10^7) -> 1.1428598
A28: =Dados!C12 -> Protecção Social | B28: =Dados!D12 -> Pessoas integradas em actividades geradoras de renda (cumulativo) | C28: =Dados!F12 -> Maior é melhor | D28: =IF(OR(Dados!N12="",Dados!I12=""),"",IF(Dados!$F12="Menor é melhor",MIN(1,Dados!N12/Dados!I12),MIN(1,Dados!I12/Dados!N12))) -> 0.65106936 | E28: =IF(OR(Dados!O12="",Dados!J12=""),"",IF(Dados!$F12="Menor é melhor",MIN(1,Dados!O12/Dados!J12),MIN(1,Dados!J12/Dados!O12))) -> 0.48879574 | F28: =IF(OR(Dados!P12="",Dados!K12=""),"",IF(Dados!$F12="Menor é melhor",MIN(1,Dados!P12/Dados!K12),MIN(1,Dados!K12/Dados!P12))) -> 0.39310101 | G28: =IF(OR(Dados!P12="",Dados!K12=""),"",IF(Dados!$F12="Menor é melhor",Dados!P12/Dados!K12,Dados!K12/Dados!P12)) -> 0.39310101 | H28: =IF(OR(Dados!L12="",Dados!K12=""),"",IF(Dados!$F12="Menor é melhor",Dados!L12/Dados!K12,Dados!K12/Dados!L12)) -> 0.39310101 | I28: =IF(G28="","Sem dados",IF(G28>=1,"≥100%",IF(G28>=0.75,"75–100%",IF(G28>=0.5,"50–75%","<50%")))) -> <50% | J28: =IF(G28="","",G28+ROW()/10^7) -> 0.39310381
A29: =Dados!C13 -> Protecção Social | B29: =Dados!D13 -> Beneficiários de transferências sociais monetárias (cumulativo) | C29: =Dados!F13 -> Maior é melhor | D29: =IF(OR(Dados!N13="",Dados!I13=""),"",IF(Dados!$F13="Menor é melhor",MIN(1,Dados!N13/Dados!I13),MIN(1,Dados!I13/Dados!N13))) -> 0.94438329 | E29: =IF(OR(Dados!O13="",Dados!J13=""),"",IF(Dados!$F13="Menor é melhor",MIN(1,Dados!O13/Dados!J13),MIN(1,Dados!J13/Dados!O13))) -> 0.76234602 | F29: =IF(OR(Dados!P13="",Dados!K13=""),"",IF(Dados!$F13="Menor é melhor",MIN(1,Dados!P13/Dados!K13),MIN(1,Dados!K13/Dados!P13))) -> 0.75047222 | G29: =IF(OR(Dados!P13="",Dados!K13=""),"",IF(Dados!$F13="Menor é melhor",Dados!P13/Dados!K13,Dados!K13/Dados!P13)) -> 0.75047222 | H29: =IF(OR(Dados!L13="",Dados!K13=""),"",IF(Dados!$F13="Menor é melhor",Dados!L13/Dados!K13,Dados!K13/Dados!L13)) -> 0.75047222 | I29: =IF(G29="","Sem dados",IF(G29>=1,"≥100%",IF(G29>=0.75,"75–100%",IF(G29>=0.5,"50–75%","<50%")))) -> 75–100% | J29: =IF(G29="","",G29+ROW()/10^7) -> 0.75047512
