Workbook

Sheet Resumo_Compilacao
A1: Resumo da compilação de indicadores sugeridos
A2: Ficheiro gerado a partir do workbook original, com dados 2015-2025 para os indicadores sugeridos quando disponíveis em fontes estruturadas.
A4: Dimensão | B4: Indicadores atuais | C4: Indicadores sugeridos | D4: Sugeridos com algum dado | E4: Sugeridos sem dados automáticos
A5: 1. Governança e Estado de Direito | B5: 5 | C5: 8 | D5: 4 | E5: 4
A6: 2. Estabilidade Macroeconómica | B6: 7 | C6: 9 | D6: 8 | E6: 1
A7: 3. Capital Humano | B7: 6 | C7: 9 | D7: 7 | E7: 2
A8: 4. Inclusão Social e Protecção | B8: 5 | C8: 10 | D8: 8 | E8: 2
A9: 5. Infraestruturas e Serviços | B9: 6 | C9: 10 | D9: 8 | E9: 2
A10: 6. Mercado de Trabalho | B10: 6 | C10: 10 | D10: 9 | E10: 1
A11: 7. Segurança Alimentar e Saúde | B11: 6 | C11: 12 | D11: 12 | E11: 0
A14: Fontes automáticas usadas
A15: Banco Mundial API/CSV | B15: https://api.worldbank.org/v2/en/indicator/{codigo}?downloadformat=csv
A16: World Bank WGI 2025 Revision | B16: https://datacatalogfiles.worldbank.org/ddh-published/0038026/DR0095947/wgidataset_with_sourcedata-2025.xlsx
A17: Demais fontes | B17: Mantidas como metadados/URLs na folha Compilacao_Sugeridos; exigem recolha manual se não houver código/API.
A20: Notas metodológicas
A21: A folha Base_Alargada combina indicadores atuais e sugeridos; a folha Compilacao_Sugeridos isola apenas os sugeridos.
A22: Indicadores sem código/API ficam compilados com fonte, URL, parâmetros sugeridos e estado "recolha manual".
A23: A variação cambial foi calculada como variação absoluta anual da taxa oficial PA.NUS.FCRF.
A24: As fórmulas de normalização usam mínimos/máximos sugeridos. Estes parâmetros devem ser revistos antes de publicação final do índice.

Sheet Instruções
A1: ÍNDICE DE DESENVOLVIMENTO DE ANGOLA (IGDA-BDA)
A3: INSTRUÇÕES DE UTILIZAÇÃO
A5: 1. ESTRUTURA DO FICHEIRO
A6: Este ficheiro está organizado nas seguintes folhas:
A7: • Instruções - Esta folha com orientações de utilização
A8: • Input_Dados - Onde deve introduzir os valores dos indicadores (células azuis)
A9: • Parametros - Definição de pesos, mínimos e máximos para normalização
A10: • Normalizacao - Cálculo automático da normalização (0-100)
A11: • Subindices - Cálculo dos 7 subíndices temáticos
A12: • Indice_Global - Cálculo do IGDA-BDA e dashboard
A14: 2. COMO UTILIZAR
A15: a) Vá à folha 'Input_Dados' e introduza os valores dos indicadores (pode modificar os indicadores)
... A47: - Subíndices continuam a ser média aritmética ponderada dos indicadores (igual ao Output 1).

Sheet Input_Dados
A1: Subíndice | B1: Indicador | C1: Unidade | D1: Sentido | E1: Fonte | F1: 2015 | G1: 2016 | H1: 2017 | I1: 2018 | J1: 2019 | K1: 2020 | L1: 2021 | M1: 2022 | N1: 2023 | O1: 2024 | P1: 2025
A2: 1. Governança | B2: Índice de Percepção da Corrupção | C2: 0-100 | D2: + | E2: Transparency Int. | F2: 15 | G2: 18 | H2: 19 | I2: 19 | J2: 26 | K2: 27 | L2: 29 | M2: 33 | N2: 33 | O2: 32 | Q2: Angola - Corruption Perceptions Index 2023 | countryeconomy.com
A3: 1. Governança | B3: WGI - Estado de Direito | C3: -2.5 a 2.5 | D3: + | E3: Banco Mundial | F3: -1.3086297 | G3: -1.3287764 | H3: -1.3317055 | I3: -1.1105522 | J3: -1.0519682 | K3: -0.9475038 | L3: -1.0980135 | M3: -1.1625439 | N3: -1.1944432 | O3: -1.1697408 | Q3: Angola's Income Inequality (2018) – Trends & Historical Data
A4: 1. Governança | B4: WGI - Eficiência do Governo | C4: -2.5 a 2.5 | D4: + | E4: Banco Mundial | F4: -0.9378237 | G4: -0.9493847 | H4: -0.9681157 | I4: -0.9784602 | J4: -0.9116965 | K4: -1.0163604 | L4: -0.9347008 | M4: -0.8325718 | N4: -0.8287026 | O4: -0.7851909
A5: 1. Governança | B5: Estabilidade Política (WGI) | C5: -2.5 a 2.5 | D5: + | E5: Banco Mundial | F5: -0.5591026 | G5: -0.434628 | H5: -0.5372145 | I5: -0.4058117 | J5: -0.4207039 | K5: -0.6427634 | L5: -0.7936068 | M5: -0.5414068 | N5: -0.3131654 | O5: -0.5735964
A6: 1. Governança | B6: Doing Business / Ease of Business | C6: 0-100 | D6: + | E6: Banco Mundial | F6: 37.09 | G6: 38.46 | H6: 38.41 | I6: 41.49 | J6: 43.86 | K6: 41.9 | Q6: Internet Users in Angola | 2025 Trends & Rankings | World View Data
A7: 2. Macroeconomia | B7: Taxa de Crescimento do PIB | C7: % | D7: + | E7: INE/MEP | F7: 0.76317771 | G7: -1.7005304 | H7: -0.14939623 | I7: -0.59441123 | J7: -0.20468025 | K7: -4.0424472 | L7: 2.1027525 | M7: 4.2160026 | N7: 1.2633081 | O7: 4.4239066 | Q7: Repositório de Conhecimento Aberto
A8: 2. Macroeconomia | B8: PIB per Capita (USD) | C8: USD | D8: + | E8: INE/MEP | F8: 4400.1341 | G8: 4136.7763 | H8: 4955.1922 | I8: 3214.8018 | J8: 2397.7613 | K8: 1902.3184 | L8: 2990.8603 | M8: 3935.501 | N8: 2773.0062 | O8: 3181.6243
A9: 2. Macroeconomia | B9: Inflação (IPC) | C9: % | D9: - | E9: INE/BNA | F9: 12.094268 | G9: 41.121135 | H9: 23.66655 | I9: 18.601105 | J9: 16.897288 | K9: 25.09653 | L9: 27.029944 | M9: 13.860475 | N9: 20.00716 | O9: 26.480339 | P9: 15.69722
A10: 2. Macroeconomia | B10: Dívida Pública (% do PIB) | C10: % | D10: - | E10: MINFIN | F10: 50 | G10: 67 | H10: 60 | I10: 83 | J10: 101 | K10: 119 | L10: 74 | M10: 56 | N10: 72 | O10: 60 | P10: 63 | Q10: PUBLIC DEBT STATISTICAL BULLETIN AS OF []
A11: 2. Macroeconomia | B11: Saldo Orçamental (% do PIB) | C11: % | D11: + | E11: MINFIN | F11: -2 | G11: -3 | H11: 1.5 | I11: -0.5 | J11: 0.5 | K11: -5 | L11: 1.5 | M11: 0.7 | N11: -1.9 | O11: -1.5 | P11: -1.65
A12: 2. Macroeconomia | B12: IDE não-petrolífero (% PIB) | C12: % | D12: + | E12: AIPEX/BNA
A13: 2. Macroeconomia | B13: Reservas Internacionais (meses) | C13: Meses | D13: + | E13: BNA | F13: =+F47 | G13: =+G47 | H13: =+H47 | I13: =+I47 | J13: =+J47 | K13: =+K47 | L13: =+L47 | M13: =+M47 | ... P13: =+P47
A14: 3. Capital Humano | B14: Índice de Desenvolvimento Humano | C14: 0-1 | D14: + | E14: PNUD | F14: 0.591 | G14: 0.595 | H14: 0.597 | I14: 0.598 | J14: 0.597 | K14: 0.594 | L14: 0.59 | M14: 0.591 | N14: 0.616 | Q14: Relatório do Desenvolvimento Humano (RDH) 2023-2024 | United Nations Development Programme
A15: 3. Capital Humano | B15: Esperança Média de Vida | C15: Anos | D15: + | E15: INE/OMS | F15: 61.042 | G15: 61.619 | H15: 61.7 | I15: 61.7 | J15: 62.2 | K15: 62.48 | L15: 62.72 | M15: 62.95 | N15: 64.617 | O15: 64 | P15: 65 | Q15: Life Expectancy at Birth, Total for Angola (SPDYNLE00INAGO) | FRED | St. Louis Fed
A16: 3. Capital Humano | B16: Taxa de Alfabetização (+15 anos) | C16: % | D16: + | E16: INE/MED
A17: 3. Capital Humano | B17: Taxa de Matrícula (primário) | C17: % | D17: + | E17: MED
A18: 3. Capital Humano | B18: Anos Médios de Escolaridade | C18: Anos | D18: + | E18: UNESCO
A19: 3. Capital Humano | B19: Mortalidade Infantil (por 1000) | C19: ‰ | D19: - | E19: INE/MINSA | H19: 61.1 | I19: 60 | J19: 58.9 | K19: 57.8 | L19: 56.81 | M19: 55.84
A20: 4. Inclusão Social | B20: Taxa de Pobreza (< 2.15 USD/dia) | C20: % | D20: - | E20: INE/BM | I20: 31.1 | Q20: UNdata | record view | Poverty headcount ratio at $2.15 a day (2017 PPP) (% of population)
A21: 4. Inclusão Social | B21: Índice de Gini | C21: 0-100 | D21: - | E21: INE/BM | I21: 51.3 | Q21: Gini index - Angola | Data
A22: 4. Inclusão Social | B22: Cobertura Protecção Social | C22: % | D22: + | E22: INSS
A23: 4. Inclusão Social | B23: Global Gender Gap Index | C23: 0-1 | D23: + | E23: WEF | F23: 0.637 | G23: 0.643 | H23: 0.64 | I23: 0.633 | K23: 0.66 | L23: 0.657 | M23: 0.638 | N23: 0.656 | O23: 0.668 | P23: 0.668 | Q23: Angola - Global Gender Gap Index 2024 | countryeconomy.com
A24: 4. Inclusão Social | B24: RNB per Capita (USD) | C24: USD | D24: + | E24: INE | F24: 2350 | G24: 3100 | H24: 2850 | I24: 2450 | J24: 2300 | K24: 2250 | L24: 2300 | M24: 2400 | N24: 2500 | O24: 2840 | P24: 2900 | Q24: GNI per capita, Atlas method (current US$) - Angola | Data
A25: 5. Infraestruturas | B25: Taxa de Electrificação | C25: % | D25: + | E25: MINEA | F25: 42 | G25: 41.8 | H25: 42.9 | I25: 45.3 | J25: 45.6 | K25: 47 | L25: 48.2 | M25: 48.5 | N25: 51.1 | Q25: Angola - Access To Electricity (% Of Population) - 2026 Data 2027 Forecast 1990-2023 Historical
A26: 5. Infraestruturas | B26: Acesso a Água Potável | C26: % | D26: + | E26: MINEA/INE | F26: 54.3 | G26: 55.1 | H26: 55.8 | I26: 56.6 | J26: 56.9 | K26: 57.2 | L26: 57.4 | M26: 57.7 | Q26: Access to Basic Drinking Water in Angola | 2025 Trends & Rankings | World View Data
A27: 5. Infraestruturas | B27: Acesso a Saneamento Básico | C27: % | D27: + | E27: MINEA/INE | F27: 47 | G27: 48 | H27: 48 | I27: 49 | J27: 50 | K27: 50 | L27: 50 | M27: 50 | Q27: People using at least basic sanitation services (% of population) - Angola | Data
A28: 5. Infraestruturas | B28: Cobertura de Rede 4G | C28: % | D28: + | E28: INACOM | Q28: Não tem estatísticas anuais
A29: 5. Infraestruturas | B29: Utilizadores de Internet (%) | C29: % | D29: + | E29: INACOM | F29: 22 | G29: 23.2 | H29: 26 | I29: 29 | J29: 32.1 | K29: 36.6 | L29: 39.3 | M29: 42 | N29: 44 | Q29: Table Data - Internet users for Angola | FRED | St. Louis Fed
A30: 5. Infraestruturas | B30: Densidade Rodoviária (km/1000km²) | C30: km | D30: + | E30: MINTRANS | F30: 29 | G30: 29 | H30: 29 | I30: 29 | J30: 29 | K30: 30 | L30: 31 | M30: 31 | N30: 32 | O30: 33 | Q30: World Bank Document
A31: 6. Mercado Trabalho | B31: Taxa de Emprego | C31: % | D31: + | E31: INE | J31: 61.190162 | K31: 60.774759 | L31: 61.491468 | M31: 62.715613 | N31: 60.653315 | O31: 61.666148 | P31: 64.441287
A32: 6. Mercado Trabalho | B32: Taxa de Desemprego | C32: % | D32: - | E32: INE | J32: 30.208847 | K32: 32.181087 | L32: 32.320726 | M32: 30.155336 | N32: 31.852861 | O32: 31.466353 | P32: 26.860611
A33: 6. Mercado Trabalho | B33: Desemprego Juvenil (15-25) | C33: % | D33: - | E33: INE
A34: 6. Mercado Trabalho | B34: Emprego Informal (%) | C34: % | D34: - | E34: INE | J34: 74.541816 | K34: 80.353575 | L34: 80.447518 | M34: 79.860137 | N34: 80.488095 | O34: 79.759923 | P34: 77.120842
A35: 6. Mercado Trabalho | B35: Taxa de Formalização | C35: % | D35: + | E35: INSS | J35: 25.458184 | K35: 19.646425 | L35: 19.552482 | M35: 20.139863 | N35: 19.511905 | O35: 20.240077 | P35: 22.879158
A36: 6. Mercado Trabalho | B36: Crescimento da Produtividade | C36: % | D36: + | E36: INE/MEP
A37: 7. Seg. Alimentar/Saúde | B37: Índice Global Seg. Alimentar | C37: 0-100 | D37: + | E37: EIU | F37: 35.1 | O37: 26 | P37: 29.7 | Q37: Indicadores Segurança Alimentar
A38: 7. Seg. Alimentar/Saúde | B38: Prevalência de Desnutrição | C38: % | D38: - | E38: MINSA/FAO | G38: 15.2 | H38: 15.4 | I38: 15.9 | J38: 18.2 | K38: 20.8 | L38: 22.6 | M38: 23.1 | N38: 22.5 | Q38: Angola Prevalence of undernourishment - data, chart | TheGlobalEconomy.com
A39: 7. Seg. Alimentar/Saúde | B39: Mortalidade Materna (por 100k) | C39: por 100k | D39: - | E39: MINSA/OMS | F39: 477 | G39: 442 | H39: 400 | I39: 370 | J39: 330 | K39: 300 | L39: 290 | M39: 250 | N39: 183 | O39: 185 | P39: 170 | Q39: Lifetime risk of maternal death (%) - Angola | Data
A40: 7. Seg. Alimentar/Saúde | B40: Despesas Saúde (% PIB) | C40: % | D40: + | E40: MINFIN/OMS | F40: 2.61 | G40: 2.71 | H40: 2.79 | I40: 2.59 | J40: 2.48 | K40: 3.27 | L40: 3.09 | M40: 2.93 | Q40: Angola Health spending as percent of GDP - data, chart | TheGlobalEconomy.com
...

Sheet Parametros
A1: PARÂMETROS DE NORMALIZAÇÃO E PONDERAÇÃO
A3: Indicador | B3: Mínimo Teórico | C3: Máximo Teórico | D3: Meta 2027 | E3: Peso no Subíndice
A4: Índice de Percepção da Corrupção | B4: 0 | C4: 100 | D4: 35 | E4: 1
A5: WGI - Estado de Direito | B5: -2.5 | C5: 2.5 | D5: 0 | E5: 1
A6: WGI - Eficiência do Governo | B6: -2.5 | C6: 2.5 | D6: 0 | E6: 1
A7: Estabilidade Política (WGI) | B7: -2.5 | C7: 2.5 | D7: 0 | E7: 1
A8: Doing Business / Ease of Business | B8: 0 | C8: 100 | D8: 55 | E8: 1
A9: Taxa de Crescimento do PIB | B9: -10 | C9: 15 | D9: 5 | E9: 1
A10: PIB per Capita (USD) | B10: 500 | C10: 15000 | D10: 5000 | E10: 1
A11: Inflação (IPC) | B11: 0 | C11: 50 | D11: 10 | E11: 1
A12: Dívida Pública (% do PIB) | B12: 0 | C12: 150 | D12: 60 | E12: 1
A13: Saldo Orçamental (% do PIB) | B13: -15 | C13: 10 | D13: 0 | E13: 1
A14: IDE não-petrolífero (% PIB) | B14: 0 | C14: 10 | D14: 3 | E14: 1
A15: Reservas Internacionais (meses) | B15: 0 | C15: 12 | D15: 6 | E15: 1
... A44: Cobertura Vacinal (%) | B44: 0 | C44: 100 | D44: 80 | E44: 1
A46: Limiar de Cobertura Mínima por Subíndice (fração 0-1) | B46: 0.5
A47: Nº Mínimo de Subíndices para calcular o IGDA (de 7) | B47: 4
A50: PESOS DOS SUBÍNDICES
A51: Subíndice | B51: Peso
A52: 1. Governança e Estado de Direito | B52: 1
A53: 2. Estabilidade Macroeconómica | B53: 1
A54: 3. Capital Humano | B54: 1
A55: 4. Inclusão Social | B55: 1
A56: 5. Infraestruturas | B56: 1
A57: 6. Mercado de Trabalho | B57: 1
A58: 7. Segurança Alimentar e Saúde | B58: 1

Sheet Normalizacao
A1: Indicador | B1: Sentido | C1: 2015 | D1: 2016 | E1: 2017 | F1: 2018 | G1: 2019 | H1: 2020 | I1: 2021 | J1: 2022 | K1: 2023 | L1: 2024 | M1: 2025
A2: Índice de Percepção da Corrupção | B2: + | C2: =IF(Input_Dados!F$2="","",MIN(100,MAX(0,(Input_Dados!F$2-Parametros!$B$4)/(Parametros!$C$4-Parametros!$B$4)*100))) | D2: =IF(Input_Dados!G$2="","",MIN(100,MAX(0,(Input_Dados!G$2-Parametros!$B$4)/(Parametros!$C$4-Parametros!$B$4)*100))) | E2: =IF(Input_Dados!H$2="","",MIN(100,MAX(0,(Input_Dados!H$2-Parametros!$B$4)/(Parametros!$C$4-Parametros!$B$4)*100))) | F2: =IF(Input_Dados!I$2="","",MIN(100,MAX(0,(Input_Dados!I$2-Parametros!$B$4)/(Parametros!$C$4-Parametros!$B$4)*100))) | G2: =IF(Input_Dados!J$2="","",MIN(100,MAX(0,(Input_Dados!J$2-Parametros!$B$4)/(Parametros!$C$4-Parametros!$B$4)*100))) | H2: =IF(Input_Dados!K$2="","",MIN(100,MAX(0,(Input_Dados!K$2-Parametros!$B$4)/(Parametros!$C$4-Parametros!$B$4)*100))) | I2: =IF(Input_Dados!L$2="","",MIN(100,MAX(0,(Input_Dados!L$2-Parametros!$B$4)/(Parametros!$C$4-Parametros!$B$4)*100))) | J2: =IF(Input_Dados!M$2="","",MIN(100,MAX(0,(Input_Dados!M$2-Parametros!$B$4)/(Parametros!$C$4-Parametros!$B$4)*100))) | ... M2: =IF(Input_Dados!P$2="","",MIN(100,MAX(0,(Input_Dados!P$2-Parametros!$B$4)/(Parametros!$C$4-Parametros!$B$4)*100)))
A3: WGI - Estado de Direito | B3: + | C3: =IF(Input_Dados!F$3="","",MIN(100,MAX(0,(Input_Dados!F$3-Parametros!$B$5)/(Parametros!$C$5-Parametros!$B$5)*100))) | D3: =IF(Input_Dados!G$3="","",MIN(100,MAX(0,(Input_Dados!G$3-Parametros!$B$5)/(Parametros!$C$5-Parametros!$B$5)*100))) | E3: =IF(Input_Dados!H$3="","",MIN(100,MAX(0,(Input_Dados!H$3-Parametros!$B$5)/(Parametros!$C$5-Parametros!$B$5)*100))) | F3: =IF(Input_Dados!I$3="","",MIN(100,MAX(0,(Input_Dados!I$3-Parametros!$B$5)/(Parametros!$C$5-Parametros!$B$5)*100))) | G3: =IF(Input_Dados!J$3="","",MIN(100,MAX(0,(Input_Dados!J$3-Parametros!$B$5)/(Parametros!$C$5-Parametros!$B$5)*100))) | H3: =IF(Input_Dados!K$3="","",MIN(100,MAX(0,(Input_Dados!K$3-Parametros!$B$5)/(Parametros!$C$5-Parametros!$B$5)*100))) | I3: =IF(Input_Dados!L$3="","",MIN(100,MAX(0,(Input_Dados!L$3-Parametros!$B$5)/(Parametros!$C$5-Parametros!$B$5)*100))) | J3: =IF(Input_Dados!M$3="","",MIN(100,MAX(0,(Input_Dados!M$3-Parametros!$B$5)/(Parametros!$C$5-Parametros!$B$5)*100))) | ... M3: =IF(Input_Dados!P$3="","",MIN(100,MAX(0,(Input_Dados!P$3-Parametros!$B$5)/(Parametros!$C$5-Parametros!$B$5)*100)))
A4: WGI - Eficiência do Governo | B4: + | C4: =IF(Input_Dados!F$4="","",MIN(100,MAX(0,(Input_Dados!F$4-Parametros!$B$6)/(Parametros!$C$6-Parametros!$B$6)*100))) | D4: =IF(Input_Dados!G$4="","",MIN(100,MAX(0,(Input_Dados!G$4-Parametros!$B$6)/(Parametros!$C$6-Parametros!$B$6)*100))) | E4: =IF(Input_Dados!H$4="","",MIN(100,MAX(0,(Input_Dados!H$4-Parametros!$B$6)/(Parametros!$C$6-Parametros!$B$6)*100))) | F4: =IF(Input_Dados!I$4="","",MIN(100,MAX(0,(Input_Dados!I$4-Parametros!$B$6)/(Parametros!$C$6-Parametros!$B$6)*100))) | G4: =IF(Input_Dados!J$4="","",MIN(100,MAX(0,(Input_Dados!J$4-Parametros!$B$6)/(Parametros!$C$6-Parametros!$B$6)*100))) | H4: =IF(Input_Dados!K$4="","",MIN(100,MAX(0,(Input_Dados!K$4-Parametros!$B$6)/(Parametros!$C$6-Parametros!$B$6)*100))) | I4: =IF(Input_Dados!L$4="","",MIN(100,MAX(0,(Input_Dados!L$4-Parametros!$B$6)/(Parametros!$C$6-Parametros!$B$6)*100))) | J4: =IF(Input_Dados!M$4="","",MIN(100,MAX(0,(Input_Dados!M$4-Parametros!$B$6)/(Parametros!$C$6-Parametros!$B$6)*100))) | ... M4: =IF(Input_Dados!P$4="","",MIN(100,MAX(0,(Input_Dados!P$4-Parametros!$B$6)/(Parametros!$C$6-Parametros!$B$6)*100)))
A5: Estabilidade Política (WGI) | B5: + | C5: =IF(Input_Dados!F$5="","",MIN(100,MAX(0,(Input_Dados!F$5-Parametros!$B$7)/(Parametros!$C$7-Parametros!$B$7)*100))) | D5: =IF(Input_Dados!G$5="","",MIN(100,MAX(0,(Input_Dados!G$5-Parametros!$B$7)/(Parametros!$C$7-Parametros!$B$7)*100))) | E5: =IF(Input_Dados!H$5="","",MIN(100,MAX(0,(Input_Dados!H$5-Parametros!$B$7)/(Parametros!$C$7-Parametros!$B$7)*100))) | F5: =IF(Input_Dados!I$5="","",MIN(100,MAX(0,(Input_Dados!I$5-Parametros!$B$7)/(Parametros!$C$7-Parametros!$B$7)*100))) | G5: =IF(Input_Dados!J$5="","",MIN(100,MAX(0,(Input_Dados!J$5-Parametros!$B$7)/(Parametros!$C$7-Parametros!$B$7)*100))) | H5: =IF(Input_Dados!K$5="","",MIN(100,MAX(0,(Input_Dados!K$5-Parametros!$B$7)/(Parametros!$C$7-Parametros!$B$7)*100))) | I5: =IF(Input_Dados!L$5="","",MIN(100,MAX(0,(Input_Dados!L$5-Parametros!$B$7)/(Parametros!$C$7-Parametros!$B$7)*100))) | J5: =IF(Input_Dados!M$5="","",MIN(100,MAX(0,(Input_Dados!M$5-Parametros!$B$7)/(Parametros!$C$7-Parametros!$B$7)*100))) | ... M5: =IF(Input_Dados!P$5="","",MIN(100,MAX(0,(Input_Dados!P$5-Parametros!$B$7)/(Parametros!$C$7-Parametros!$B$7)*100)))
A6: Doing Business / Ease of Business | B6: + | C6: =IF(Input_Dados!F$6="","",MIN(100,MAX(0,(Input_Dados!F$6-Parametros!$B$8)/(Parametros!$C$8-Parametros!$B$8)*100))) | D6: =IF(Input_Dados!G$6="","",MIN(100,MAX(0,(Input_Dados!G$6-Parametros!$B$8)/(Parametros!$C$8-Parametros!$B$8)*100))) | E6: =IF(Input_Dados!H$6="","",MIN(100,MAX(0,(Input_Dados!H$6-Parametros!$B$8)/(Parametros!$C$8-Parametros!$B$8)*100))) | F6: =IF(Input_Dados!I$6="","",MIN(100,MAX(0,(Input_Dados!I$6-Parametros!$B$8)/(Parametros!$C$8-Parametros!$B$8)*100))) | G6: =IF(Input_Dados!J$6="","",MIN(100,MAX(0,(Input_Dados!J$6-Parametros!$B$8)/(Parametros!$C$8-Parametros!$B$8)*100))) | H6: =IF(Input_Dados!K$6="","",MIN(100,MAX(0,(Input_Dados!K$6-Parametros!$B$8)/(Parametros!$C$8-Parametros!$B$8)*100))) | I6: =IF(Input_Dados!L$6="","",MIN(100,MAX(0,(Input_Dados!L$6-Parametros!$B$8)/(Parametros!$C$8-Parametros!$B$8)*100))) | J6: =IF(Input_Dados!M$6="","",MIN(100,MAX(0,(Input_Dados!M$6-Parametros!$B$8)/(Parametros!$C$8-Parametros!$B$8)*100))) | ... M6: =IF(Input_Dados!P$6="","",MIN(100,MAX(0,(Input_Dados!P$6-Parametros!$B$8)/(Parametros!$C$8-Parametros!$B$8)*100)))
A7: Taxa de Crescimento do PIB | B7: + | C7: =IF(Input_Dados!F$7="","",MIN(100,MAX(0,(Input_Dados!F$7-Parametros!$B$9)/(Parametros!$C$9-Parametros!$B$9)*100))) | D7: =IF(Input_Dados!G$7="","",MIN(100,MAX(0,(Input_Dados!G$7-Parametros!$B$9)/(Parametros!$C$9-Parametros!$B$9)*100))) | E7: =IF(Input_Dados!H$7="","",MIN(100,MAX(0,(Input_Dados!H$7-Parametros!$B$9)/(Parametros!$C$9-Parametros!$B$9)*100))) | F7: =IF(Input_Dados!I$7="","",MIN(100,MAX(0,(Input_Dados!I$7-Parametros!$B$9)/(Parametros!$C$9-Parametros!$B$9)*100))) | G7: =IF(Input_Dados!J$7="","",MIN(100,MAX(0,(Input_Dados!J$7-Parametros!$B$9)/(Parametros!$C$9-Parametros!$B$9)*100))) | H7: =IF(Input_Dados!K$7="","",MIN(100,MAX(0,(Input_Dados!K$7-Parametros!$B$9)/(Parametros!$C$9-Parametros!$B$9)*100))) | I7: =IF(Input_Dados!L$7="","",MIN(100,MAX(0,(Input_Dados!L$7-Parametros!$B$9)/(Parametros!$C$9-Parametros!$B$9)*100))) | J7: =IF(Input_Dados!M$7="","",MIN(100,MAX(0,(Input_Dados!M$7-Parametros!$B$9)/(Parametros!$C$9-Parametros!$B$9)*100))) | ... M7: =IF(Input_Dados!P$7="","",MIN(100,MAX(0,(Input_Dados!P$7-Parametros!$B$9)/(Parametros!$C$9-Parametros!$B$9)*100)))
A8: PIB per Capita (USD) | B8: + | C8: =IF(Input_Dados!F$8="","",MIN(100,MAX(0,(Input_Dados!F$8-Parametros!$B$10)/(Parametros!$C$10-Parametros!$B$10)*100))) | D8: =IF(Input_Dados!G$8="","",MIN(100,MAX(0,(Input_Dados!G$8-Parametros!$B$10)/(Parametros!$C$10-Parametros!$B$10)*100))) | E8: =IF(Input_Dados!H$8="","",MIN(100,MAX(0,(Input_Dados!H$8-Parametros!$B$10)/(Parametros!$C$10-Parametros!$B$10)*100))) | F8: =IF(Input_Dados!I$8="","",MIN(100,MAX(0,(Input_Dados!I$8-Parametros!$B$10)/(Parametros!$C$10-Parametros!$B$10)*100))) | G8: =IF(Input_Dados!J$8="","",MIN(100,MAX(0,(Input_Dados!J$8-Parametros!$B$10)/(Parametros!$C$10-Parametros!$B$10)*100))) | H8: =IF(Input_Dados!K$8="","",MIN(100,MAX(0,(Input_Dados!K$8-Parametros!$B$10)/(Parametros!$C$10-Parametros!$B$10)*100))) | I8: =IF(Input_Dados!L$8="","",MIN(100,MAX(0,(Input_Dados!L$8-Parametros!$B$10)/(Parametros!$C$10-Parametros!$B$10)*100))) | J8: =IF(Input_Dados!M$8="","",MIN(100,MAX(0,(Input_Dados!M$8-Parametros!$B$10)/(Parametros!$C$10-Parametros!$B$10)*100))) | ... M8: =IF(Input_Dados!P$8="","",MIN(100,MAX(0,(Input_Dados!P$8-Parametros!$B$10)/(Parametros!$C$10-Parametros!$B$10)*100)))
A9: Inflação (IPC) | B9: - | C9: =IF(Input_Dados!F$9="","",MIN(100,MAX(0,(Parametros!$C$11-Input_Dados!F$9)/(Parametros!$C$11-Parametros!$B$11)*100))) | D9: =IF(Input_Dados!G$9="","",MIN(100,MAX(0,(Parametros!$C$11-Input_Dados!G$9)/(Parametros!$C$11-Parametros!$B$11)*100))) | E9: =IF(Input_Dados!H$9="","",MIN(100,MAX(0,(Parametros!$C$11-Input_Dados!H$9)/(Parametros!$C$11-Parametros!$B$11)*100))) | F9: =IF(Input_Dados!I$9="","",MIN(100,MAX(0,(Parametros!$C$11-Input_Dados!I$9)/(Parametros!$C$11-Parametros!$B$11)*100))) | G9: =IF(Input_Dados!J$9="","",MIN(100,MAX(0,(Parametros!$C$11-Input_Dados!J$9)/(Parametros!$C$11-Parametros!$B$11)*100))) | H9: =IF(Input_Dados!K$9="","",MIN(100,MAX(0,(Parametros!$C$11-Input_Dados!K$9)/(Parametros!$C$11-Parametros!$B$11)*100))) | I9: =IF(Input_Dados!L$9="","",MIN(100,MAX(0,(Parametros!$C$11-Input_Dados!L$9)/(Parametros!$C$11-Parametros!$B$11)*100))) | J9: =IF(Input_Dados!M$9="","",MIN(100,MAX(0,(Parametros!$C$11-Input_Dados!M$9)/(Parametros!$C$11-Parametros!$B$11)*100))) | ... M9: =IF(Input_Dados!P$9="","",MIN(100,MAX(0,(Parametros!$C$11-Input_Dados!P$9)/(Parametros!$C$11-Parametros!$B$11)*100)))
A10: Dívida Pública (% do PIB) | B10: - | C10: =IF(Input_Dados!F$10="","",MIN(100,MAX(0,(Parametros!$C$12-Input_Dados!F$10)/(Parametros!$C$12-Parametros!$B$12)*100))) | D10: =IF(Input_Dados!G$10="","",MIN(100,MAX(0,(Parametros!$C$12-Input_Dados!G$10)/(Parametros!$C$12-Parametros!$B$12)*100))) | E10: =IF(Input_Dados!H$10="","",MIN(100,MAX(0,(Parametros!$C$12-Input_Dados!H$10)/(Parametros!$C$12-Parametros!$B$12)*100))) | F10: =IF(Input_Dados!I$10="","",MIN(100,MAX(0,(Parametros!$C$12-Input_Dados!I$10)/(Parametros!$C$12-Parametros!$B$12)*100))) | G10: =IF(Input_Dados!J$10="","",MIN(100,MAX(0,(Parametros!$C$12-Input_Dados!J$10)/(Parametros!$C$12-Parametros!$B$12)*100))) | H10: =IF(Input_Dados!K$10="","",MIN(100,MAX(0,(Parametros!$C$12-Input_Dados!K$10)/(Parametros!$C$12-Parametros!$B$12)*100))) | I10: =IF(Input_Dados!L$10="","",MIN(100,MAX(0,(Parametros!$C$12-Input_Dados!L$10)/(Parametros!$C$12-Parametros!$B$12)*100))) | J10: =IF(Input_Dados!M$10="","",MIN(100,MAX(0,(Parametros!$C$12-Input_Dados!M$10)/(Parametros!$C$12-Parametros!$B$12)*100))) | ... M10: =IF(Input_Dados!P$10="","",MIN(100,MAX(0,(Parametros!$C$12-Input_Dados!P$10)/(Parametros!$C$12-Parametros!$B$12)*100)))
A11: Saldo Orçamental (% do PIB) | B11: + | C11: =IF(Input_Dados!F$11="","",MIN(100,MAX(0,(Input_Dados!F$11-Parametros!$B$13)/(Parametros!$C$13-Parametros!$B$13)*100))) | D11: =IF(Input_Dados!G$11="","",MIN(100,MAX(0,(Input_Dados!G$11-Parametros!$B$13)/(Parametros!$C$13-Parametros!$B$13)*100))) | E11: =IF(Input_Dados!H$11="","",MIN(100,MAX(0,(Input_Dados!H$11-Parametros!$B$13)/(Parametros!$C$13-Parametros!$B$13)*100))) | F11: =IF(Input_Dados!I$11="","",MIN(100,MAX(0,(Input_Dados!I$11-Parametros!$B$13)/(Parametros!$C$13-Parametros!$B$13)*100))) | G11: =IF(Input_Dados!J$11="","",MIN(100,MAX(0,(Input_Dados!J$11-Parametros!$B$13)/(Parametros!$C$13-Parametros!$B$13)*100))) | H11: =IF(Input_Dados!K$11="","",MIN(100,MAX(0,(Input_Dados!K$11-Parametros!$B$13)/(Parametros!$C$13-Parametros!$B$13)*100))) | I11: =IF(Input_Dados!L$11="","",MIN(100,MAX(0,(Input_Dados!L$11-Parametros!$B$13)/(Parametros!$C$13-Parametros!$B$13)*100))) | J11: =IF(Input_Dados!M$11="","",MIN(100,MAX(0,(Input_Dados!M$11-Parametros!$B$13)/(Parametros!$C$13-Parametros!$B$13)*100))) | ... M11: =IF(Input_Dados!P$11="","",MIN(100,MAX(0,(Input_Dados!P$11-Parametros!$B$13)/(Parametros!$C$13-Parametros!$B$13)*100)))
A12: IDE não-petrolífero (% PIB) | B12: + | C12: =IF(Input_Dados!F$12="","",MIN(100,MAX(0,(Input_Dados!F$12-Parametros!$B$14)/(Parametros!$C$14-Parametros!$B$14)*100))) | D12: =IF(Input_Dados!G$12="","",MIN(100,MAX(0,(Input_Dados!G$12-Parametros!$B$14)/(Parametros!$C$14-Parametros!$B$14)*100))) | E12: =IF(Input_Dados!H$12="","",MIN(100,MAX(0,(Input_Dados!H$12-Parametros!$B$14)/(Parametros!$C$14-Parametros!$B$14)*100))) | F12: =IF(Input_Dados!I$12="","",MIN(100,MAX(0,(Input_Dados!I$12-Parametros!$B$14)/(Parametros!$C$14-Parametros!$B$14)*100))) | G12: =IF(Input_Dados!J$12="","",MIN(100,MAX(0,(Input_Dados!J$12-Parametros!$B$14)/(Parametros!$C$14-Parametros!$B$14)*100))) | H12: =IF(Input_Dados!K$12="","",MIN(100,MAX(0,(Input_Dados!K$12-Parametros!$B$14)/(Parametros!$C$14-Parametros!$B$14)*100))) | I12: =IF(Input_Dados!L$12="","",MIN(100,MAX(0,(Input_Dados!L$12-Parametros!$B$14)/(Parametros!$C$14-Parametros!$B$14)*100))) | J12: =IF(Input_Dados!M$12="","",MIN(100,MAX(0,(Input_Dados!M$12-Parametros!$B$14)/(Parametros!$C$14-Parametros!$B$14)*100))) | ... M12: =IF(Input_Dados!P$12="","",MIN(100,MAX(0,(Input_Dados!P$12-Parametros!$B$14)/(Parametros!$C$14-Parametros!$B$14)*100)))
A13: Reservas Internacionais (meses) | B13: + | C13: =IF(Input_Dados!F$13="","",MIN(100,MAX(0,(Input_Dados!F$13-Parametros!$B$15)/(Parametros!$C$15-Parametros!$B$15)*100))) | D13: =IF(Input_Dados!G$13="","",MIN(100,MAX(0,(Input_Dados!G$13-Parametros!$B$15)/(Parametros!$C$15-Parametros!$B$15)*100))) | E13: =IF(Input_Dados!H$13="","",MIN(100,MAX(0,(Input_Dados!H$13-Parametros!$B$15)/(Parametros!$C$15-Parametros!$B$15)*100))) | F13: =IF(Input_Dados!I$13="","",MIN(100,MAX(0,(Input_Dados!I$13-Parametros!$B$15)/(Parametros!$C$15-Parametros!$B$15)*100))) | G13: =IF(Input_Dados!J$13="","",MIN(100,MAX(0,(Input_Dados!J$13-Parametros!$B$15)/(Parametros!$C$15-Parametros!$B$15)*100))) | H13: =IF(Input_Dados!K$13="","",MIN(100,MAX(0,(Input_Dados!K$13-Parametros!$B$15)/(Parametros!$C$15-Parametros!$B$15)*100))) | I13: =IF(Input_Dados!L$13="","",MIN(100,MAX(0,(Input_Dados!L$13-Parametros!$B$15)/(Parametros!$C$15-Parametros!$B$15)*100))) | J13: =IF(Input_Dados!M$13="","",MIN(100,MAX(0,(Input_Dados!M$13-Parametros!$B$15)/(Parametros!$C$15-Parametros!$B$15)*100))) | ... M13: =IF(Input_Dados!P$13="","",MIN(100,MAX(0,(Input_Dados!P$13-Parametros!$B$15)/(Parametros!$C$15-Parametros!$B$15)*100)))
A14: Índice de Desenvolvimento Humano | B14: + | C14: =IF(Input_Dados!F$14="","",MIN(100,MAX(0,(Input_Dados!F$14-Parametros!$B$16)/(Parametros!$C$16-Parametros!$B$16)*100))) | D14: =IF(Input_Dados!G$14="","",MIN(100,MAX(0,(Input_Dados!G$14-Parametros!$B$16)/(Parametros!$C$16-Parametros!$B$16)*100))) | E14: =IF(Input_Dados!H$14="","",MIN(100,MAX(0,(Input_Dados!H$14-Parametros!$B$16)/(Parametros!$C$16-Parametros!$B$16)*100))) | F14: =IF(Input_Dados!I$14="","",MIN(100,MAX(0,(Input_Dados!I$14-Parametros!$B$16)/(Parametros!$C$16-Parametros!$B$16)*100))) | G14: =IF(Input_Dados!J$14="","",MIN(100,MAX(0,(Input_Dados!J$14-Parametros!$B$16)/(Parametros!$C$16-Parametros!$B$16)*100))) | H14: =IF(Input_Dados!K$14="","",MIN(100,MAX(0,(Input_Dados!K$14-Parametros!$B$16)/(Parametros!$C$16-Parametros!$B$16)*100))) | I14: =IF(Input_Dados!L$14="","",MIN(100,MAX(0,(Input_Dados!L$14-Parametros!$B$16)/(Parametros!$C$16-Parametros!$B$16)*100))) | J14: =IF(Input_Dados!M$14="","",MIN(100,MAX(0,(Input_Dados!M$14-Parametros!$B$16)/(Parametros!$C$16-Parametros!$B$16)*100))) | ... M14: =IF(Input_Dados!P$14="","",MIN(100,MAX(0,(Input_Dados!P$14-Parametros!$B$16)/(Parametros!$C$16-Parametros!$B$16)*100)))
A15: Esperança Média de Vida | B15: + | C15: =IF(Input_Dados!F$15="","",MIN(100,MAX(0,(Input_Dados!F$15-Parametros!$B$17)/(Parametros!$C$17-Parametros!$B$17)*100))) | D15: =IF(Input_Dados!G$15="","",MIN(100,MAX(0,(Input_Dados!G$15-Parametros!$B$17)/(Parametros!$C$17-Parametros!$B$17)*100))) | E15: =IF(Input_Dados!H$15="","",MIN(100,MAX(0,(Input_Dados!H$15-Parametros!$B$17)/(Parametros!$C$17-Parametros!$B$17)*100))) | F15: =IF(Input_Dados!I$15="","",MIN(100,MAX(0,(Input_Dados!I$15-Parametros!$B$17)/(Parametros!$C$17-Parametros!$B$17)*100))) | G15: =IF(Input_Dados!J$15="","",MIN(100,MAX(0,(Input_Dados!J$15-Parametros!$B$17)/(Parametros!$C$17-Parametros!$B$17)*100))) | H15: =IF(Input_Dados!K$15="","",MIN(100,MAX(0,(Input_Dados!K$15-Parametros!$B$17)/(Parametros!$C$17-Parametros!$B$17)*100))) | I15: =IF(Input_Dados!L$15="","",MIN(100,MAX(0,(Input_Dados!L$15-Parametros!$B$17)/(Parametros!$C$17-Parametros!$B$17)*100))) | J15: =IF(Input_Dados!M$15="","",MIN(100,MAX(0,(Input_Dados!M$15-Parametros!$B$17)/(Parametros!$C$17-Parametros!$B$17)*100))) | ... M15: =IF(Input_Dados!P$15="","",MIN(100,MAX(0,(Input_Dados!P$15-Parametros!$B$17)/(Parametros!$C$17-Parametros!$B$17)*100)))
A16: Taxa de Alfabetização (+15 anos) | B16: + | C16: =IF(Input_Dados!F$16="","",MIN(100,MAX(0,(Input_Dados!F$16-Parametros!$B$18)/(Parametros!$C$18-Parametros!$B$18)*100))) | D16: =IF(Input_Dados!G$16="","",MIN(100,MAX(0,(Input_Dados!G$16-Parametros!$B$18)/(Parametros!$C$18-Parametros!$B$18)*100))) | E16: =IF(Input_Dados!H$16="","",MIN(100,MAX(0,(Input_Dados!H$16-Parametros!$B$18)/(Parametros!$C$18-Parametros!$B$18)*100))) | F16: =IF(Input_Dados!I$16="","",MIN(100,MAX(0,(Input_Dados!I$16-Parametros!$B$18)/(Parametros!$C$18-Parametros!$B$18)*100))) | G16: =IF(Input_Dados!J$16="","",MIN(100,MAX(0,(Input_Dados!J$16-Parametros!$B$18)/(Parametros!$C$18-Parametros!$B$18)*100))) | H16: =IF(Input_Dados!K$16="","",MIN(100,MAX(0,(Input_Dados!K$16-Parametros!$B$18)/(Parametros!$C$18-Parametros!$B$18)*100))) | I16: =IF(Input_Dados!L$16="","",MIN(100,MAX(0,(Input_Dados!L$16-Parametros!$B$18)/(Parametros!$C$18-Parametros!$B$18)*100))) | J16: =IF(Input_Dados!M$16="","",MIN(100,MAX(0,(Input_Dados!M$16-Parametros!$B$18)/(Parametros!$C$18-Parametros!$B$18)*100))) | ... M16: =IF(Input_Dados!P$16="","",MIN(100,MAX(0,(Input_Dados!P$16-Parametros!$B$18)/(Parametros!$C$18-Parametros!$B$18)*100)))
A17: Taxa de Matrícula (primário) | B17: + | C17: =IF(Input_Dados!F$17="","",MIN(100,MAX(0,(Input_Dados!F$17-Parametros!$B$19)/(Parametros!$C$19-Parametros!$B$19)*100))) | D17: =IF(Input_Dados!G$17="","",MIN(100,MAX(0,(Input_Dados!G$17-Parametros!$B$19)/(Parametros!$C$19-Parametros!$B$19)*100))) | E17: =IF(Input_Dados!H$17="","",MIN(100,MAX(0,(Input_Dados!H$17-Parametros!$B$19)/(Parametros!$C$19-Parametros!$B$19)*100))) | F17: =IF(Input_Dados!I$17="","",MIN(100,MAX(0,(Input_Dados!I$17-Parametros!$B$19)/(Parametros!$C$19-Parametros!$B$19)*100))) | G17: =IF(Input_Dados!J$17="","",MIN(100,MAX(0,(Input_Dados!J$17-Parametros!$B$19)/(Parametros!$C$19-Parametros!$B$19)*100))) | H17: =IF(Input_Dados!K$17="","",MIN(100,MAX(0,(Input_Dados!K$17-Parametros!$B$19)/(Parametros!$C$19-Parametros!$B$19)*100))) | I17: =IF(Input_Dados!L$17="","",MIN(100,MAX(0,(Input_Dados!L$17-Parametros!$B$19)/(Parametros!$C$19-Parametros!$B$19)*100))) | J17: =IF(Input_Dados!M$17="","",MIN(100,MAX(0,(Input_Dados!M$17-Parametros!$B$19)/(Parametros!$C$19-Parametros!$B$19)*100))) | ... M17: =IF(Input_Dados!P$17="","",MIN(100,MAX(0,(Input_Dados!P$17-Parametros!$B$19)/(Parametros!$C$19-Parametros!$B$19)*100)))
A18: Anos Médios de Escolaridade | B18: + | C18: =IF(Input_Dados!F$18="","",MIN(100,MAX(0,(Input_Dados!F$18-Parametros!$B$20)/(Parametros!$C$20-Parametros!$B$20)*100))) | D18: =IF(Input_Dados!G$18="","",MIN(100,MAX(0,(Input_Dados!G$18-Parametros!$B$20)/(Parametros!$C$20-Parametros!$B$20)*100))) | E18: =IF(Input_Dados!H$18="","",MIN(100,MAX(0,(Input_Dados!H$18-Parametros!$B$20)/(Parametros!$C$20-Parametros!$B$20)*100))) | F18: =IF(Input_Dados!I$18="","",MIN(100,MAX(0,(Input_Dados!I$18-Parametros!$B$20)/(Parametros!$C$20-Parametros!$B$20)*100))) | G18: =IF(Input_Dados!J$18="","",MIN(100,MAX(0,(Input_Dados!J$18-Parametros!$B$20)/(Parametros!$C$20-Parametros!$B$20)*100))) | H18: =IF(Input_Dados!K$18="","",MIN(100,MAX(0,(Input_Dados!K$18-Parametros!$B$20)/(Parametros!$C$20-Parametros!$B$20)*100))) | I18: =IF(Input_Dados!L$18="","",MIN(100,MAX(0,(Input_Dados!L$18-Parametros!$B$20)/(Parametros!$C$20-Parametros!$B$20)*100))) | J18: =IF(Input_Dados!M$18="","",MIN(100,MAX(0,(Input_Dados!M$18-Parametros!$B$20)/(Parametros!$C$20-Parametros!$B$20)*100))) | ... M18: =IF(Input_Dados!P$18="","",MIN(100,MAX(0,(Input_Dados!P$18-Parametros!$B$20)/(Parametros!$C$20-Parametros!$B$20)*100)))
A19: Mortalidade Infantil (por 1000) | B19: - | C19: =IF(Input_Dados!F$19="","",MIN(100,MAX(0,(Parametros!$C$21-Input_Dados!F$19)/(Parametros!$C$21-Parametros!$B$21)*100))) | D19: =IF(Input_Dados!G$19="","",MIN(100,MAX(0,(Parametros!$C$21-Input_Dados!G$19)/(Parametros!$C$21-Parametros!$B$21)*100))) | E19: =IF(Input_Dados!H$19="","",MIN(100,MAX(0,(Parametros!$C$21-Input_Dados!H$19)/(Parametros!$C$21-Parametros!$B$21)*100))) | F19: =IF(Input_Dados!I$19="","",MIN(100,MAX(0,(Parametros!$C$21-Input_Dados!I$19)/(Parametros!$C$21-Parametros!$B$21)*100))) | G19: =IF(Input_Dados!J$19="","",MIN(100,MAX(0,(Parametros!$C$21-Input_Dados!J$19)/(Parametros!$C$21-Parametros!$B$21)*100))) | H19: =IF(Input_Dados!K$19="","",MIN(100,MAX(0,(Parametros!$C$21-Input_Dados!K$19)/(Parametros!$C$21-Parametros!$B$21)*100))) | I19: =IF(Input_Dados!L$19="","",MIN(100,MAX(0,(Parametros!$C$21-Input_Dados!L$19)/(Parametros!$C$21-Parametros!$B$21)*100))) | J19: =IF(Input_Dados!M$19="","",MIN(100,MAX(0,(Parametros!$C$21-Input_Dados!M$19)/(Parametros!$C$21-Parametros!$B$21)*100))) | ... M19: =IF(Input_Dados!P$19="","",MIN(100,MAX(0,(Parametros!$C$21-Input_Dados!P$19)/(Parametros!$C$21-Parametros!$B$21)*100)))
A20: Taxa de Pobreza (< 2.15 USD/dia) | B20: - | C20: =IF(Input_Dados!F$20="","",MIN(100,MAX(0,(Parametros!$C$22-Input_Dados!F$20)/(Parametros!$C$22-Parametros!$B$22)*100))) | D20: =IF(Input_Dados!G$20="","",MIN(100,MAX(0,(Parametros!$C$22-Input_Dados!G$20)/(Parametros!$C$22-Parametros!$B$22)*100))) | E20: =IF(Input_Dados!H$20="","",MIN(100,MAX(0,(Parametros!$C$22-Input_Dados!H$20)/(Parametros!$C$22-Parametros!$B$22)*100))) | F20: =IF(Input_Dados!I$20="","",MIN(100,MAX(0,(Parametros!$C$22-Input_Dados!I$20)/(Parametros!$C$22-Parametros!$B$22)*100))) | G20: =IF(Input_Dados!J$20="","",MIN(100,MAX(0,(Parametros!$C$22-Input_Dados!J$20)/(Parametros!$C$22-Parametros!$B$22)*100))) | H20: =IF(Input_Dados!K$20="","",MIN(100,MAX(0,(Parametros!$C$22-Input_Dados!K$20)/(Parametros!$C$22-Parametros!$B$22)*100))) | I20: =IF(Input_Dados!L$20="","",MIN(100,MAX(0,(Parametros!$C$22-Input_Dados!L$20)/(Parametros!$C$22-Parametros!$B$22)*100))) | J20: =IF(Input_Dados!M$20="","",MIN(100,MAX(0,(Parametros!$C$22-Input_Dados!M$20)/(Parametros!$C$22-Parametros!$B$22)*100))) | ... M20: =IF(Input_Dados!P$20="","",MIN(100,MAX(0,(Parametros!$C$22-Input_Dados!P$20)/(Parametros!$C$22-Parametros!$B$22)*100)))
A21: Índice de Gini | B21: - | C21: =IF(Input_Dados!F$21="","",MIN(100,MAX(0,(Parametros!$C$23-Input_Dados!F$21)/(Parametros!$C$23-Parametros!$B$23)*100))) | D21: =IF(Input_Dados!G$21="","",MIN(100,MAX(0,(Parametros!$C$23-Input_Dados!G$21)/(Parametros!$C$23-Parametros!$B$23)*100))) | E21: =IF(Input_Dados!H$21="","",MIN(100,MAX(0,(Parametros!$C$23-Input_Dados!H$21)/(Parametros!$C$23-Parametros!$B$23)*100))) | F21: =IF(Input_Dados!I$21="","",MIN(100,MAX(0,(Parametros!$C$23-Input_Dados!I$21)/(Parametros!$C$23-Parametros!$B$23)*100))) | G21: =IF(Input_Dados!J$21="","",MIN(100,MAX(0,(Parametros!$C$23-Input_Dados!J$21)/(Parametros!$C$23-Parametros!$B$23)*100))) | H21: =IF(Input_Dados!K$21="","",MIN(100,MAX(0,(Parametros!$C$23-Input_Dados!K$21)/(Parametros!$C$23-Parametros!$B$23)*100))) | I21: =IF(Input_Dados!L$21="","",MIN(100,MAX(0,(Parametros!$C$23-Input_Dados!L$21)/(Parametros!$C$23-Parametros!$B$23)*100))) | J21: =IF(Input_Dados!M$21="","",MIN(100,MAX(0,(Parametros!$C$23-Input_Dados!M$21)/(Parametros!$C$23-Parametros!$B$23)*100))) | ... M21: =IF(Input_Dados!P$21="","",MIN(100,MAX(0,(Parametros!$C$23-Input_Dados!P$21)/(Parametros!$C$23-Parametros!$B$23)*100)))
A22: Cobertura Protecção Social | B22: + | C22: =IF(Input_Dados!F$22="","",MIN(100,MAX(0,(Input_Dados!F$22-Parametros!$B$24)/(Parametros!$C$24-Parametros!$B$24)*100))) | D22: =IF(Input_Dados!G$22="","",MIN(100,MAX(0,(Input_Dados!G$22-Parametros!$B$24)/(Parametros!$C$24-Parametros!$B$24)*100))) | E22: =IF(Input_Dados!H$22="","",MIN(100,MAX(0,(Input_Dados!H$22-Parametros!$B$24)/(Parametros!$C$24-Parametros!$B$24)*100))) | F22: =IF(Input_Dados!I$22="","",MIN(100,MAX(0,(Input_Dados!I$22-Parametros!$B$24)/(Parametros!$C$24-Parametros!$B$24)*100))) | G22: =IF(Input_Dados!J$22="","",MIN(100,MAX(0,(Input_Dados!J$22-Parametros!$B$24)/(Parametros!$C$24-Parametros!$B$24)*100))) | H22: =IF(Input_Dados!K$22="","",MIN(100,MAX(0,(Input_Dados!K$22-Parametros!$B$24)/(Parametros!$C$24-Parametros!$B$24)*100))) | I22: =IF(Input_Dados!L$22="","",MIN(100,MAX(0,(Input_Dados!L$22-Parametros!$B$24)/(Parametros!$C$24-Parametros!$B$24)*100))) | J22: =IF(Input_Dados!M$22="","",MIN(100,MAX(0,(Input_Dados!M$22-Parametros!$B$24)/(Parametros!$C$24-Parametros!$B$24)*100))) | ... M22: =IF(Input_Dados!P$22="","",MIN(100,MAX(0,(Input_Dados!P$22-Parametros!$B$24)/(Parametros!$C$24-Parametros!$B$24)*100)))
A23: Global Gender Gap Index | B23: + | C23: =IF(Input_Dados!F$23="","",MIN(100,MAX(0,(Input_Dados!F$23-Parametros!$B$25)/(Parametros!$C$25-Parametros!$B$25)*100))) | D23: =IF(Input_Dados!G$23="","",MIN(100,MAX(0,(Input_Dados!G$23-Parametros!$B$25)/(Parametros!$C$25-Parametros!$B$25)*100))) | E23: =IF(Input_Dados!H$23="","",MIN(100,MAX(0,(Input_Dados!H$23-Parametros!$B$25)/(Parametros!$C$25-Parametros!$B$25)*100))) | F23: =IF(Input_Dados!I$23="","",MIN(100,MAX(0,(Input_Dados!I$23-Parametros!$B$25)/(Parametros!$C$25-Parametros!$B$25)*100))) | G23: =IF(Input_Dados!J$23="","",MIN(100,MAX(0,(Input_Dados!J$23-Parametros!$B$25)/(Parametros!$C$25-Parametros!$B$25)*100))) | H23: =IF(Input_Dados!K$23="","",MIN(100,MAX(0,(Input_Dados!K$23-Parametros!$B$25)/(Parametros!$C$25-Parametros!$B$25)*100))) | I23: =IF(Input_Dados!L$23="","",MIN(100,MAX(0,(Input_Dados!L$23-Parametros!$B$25)/(Parametros!$C$25-Parametros!$B$25)*100))) | J23: =IF(Input_Dados!M$23="","",MIN(100,MAX(0,(Input_Dados!M$23-Parametros!$B$25)/(Parametros!$C$25-Parametros!$B$25)*100))) | ... M23: =IF(Input_Dados!P$23="","",MIN(100,MAX(0,(Input_Dados!P$23-Parametros!$B$25)/(Parametros!$C$25-Parametros!$B$25)*100)))
A24: RNB per Capita (USD) | B24: + | C24: =IF(Input_Dados!F$24="","",MIN(100,MAX(0,(Input_Dados!F$24-Parametros!$B$26)/(Parametros!$C$26-Parametros!$B$26)*100))) | D24: =IF(Input_Dados!G$24="","",MIN(100,MAX(0,(Input_Dados!G$24-Parametros!$B$26)/(Parametros!$C$26-Parametros!$B$26)*100))) | E24: =IF(Input_Dados!H$24="","",MIN(100,MAX(0,(Input_Dados!H$24-Parametros!$B$26)/(Parametros!$C$26-Parametros!$B$26)*100))) | F24: =IF(Input_Dados!I$24="","",MIN(100,MAX(0,(Input_Dados!I$24-Parametros!$B$26)/(Parametros!$C$26-Parametros!$B$26)*100))) | G24: =IF(Input_Dados!J$24="","",MIN(100,MAX(0,(Input_Dados!J$24-Parametros!$B$26)/(Parametros!$C$26-Parametros!$B$26)*100))) | H24: =IF(Input_Dados!K$24="","",MIN(100,MAX(0,(Input_Dados!K$24-Parametros!$B$26)/(Parametros!$C$26-Parametros!$B$26)*100))) | I24: =IF(Input_Dados!L$24="","",MIN(100,MAX(0,(Input_Dados!L$24-Parametros!$B$26)/(Parametros!$C$26-Parametros!$B$26)*100))) | J24: =IF(Input_Dados!M$24="","",MIN(100,MAX(0,(Input_Dados!M$24-Parametros!$B$26)/(Parametros!$C$26-Parametros!$B$26)*100))) | ... M24: =IF(Input_Dados!P$24="","",MIN(100,MAX(0,(Input_Dados!P$24-Parametros!$B$26)/(Parametros!$C$26-Parametros!$B$26)*100)))
A25: Taxa de Electrificação | B25: + | C25: =IF(Input_Dados!F$25="","",MIN(100,MAX(0,(Input_Dados!F$25-Parametros!$B$27)/(Parametros!$C$27-Parametros!$B$27)*100))) | D25: =IF(Input_Dados!G$25="","",MIN(100,MAX(0,(Input_Dados!G$25-Parametros!$B$27)/(Parametros!$C$27-Parametros!$B$27)*100))) | E25: =IF(Input_Dados!H$25="","",MIN(100,MAX(0,(Input_Dados!H$25-Parametros!$B$27)/(Parametros!$C$27-Parametros!$B$27)*100))) | F25: =IF(Input_Dados!I$25="","",MIN(100,MAX(0,(Input_Dados!I$25-Parametros!$B$27)/(Parametros!$C$27-Parametros!$B$27)*100))) | G25: =IF(Input_Dados!J$25="","",MIN(100,MAX(0,(Input_Dados!J$25-Parametros!$B$27)/(Parametros!$C$27-Parametros!$B$27)*100))) | H25: =IF(Input_Dados!K$25="","",MIN(100,MAX(0,(Input_Dados!K$25-Parametros!$B$27)/(Parametros!$C$27-Parametros!$B$27)*100))) | I25: =IF(Input_Dados!L$25="","",MIN(100,MAX(0,(Input_Dados!L$25-Parametros!$B$27)/(Parametros!$C$27-Parametros!$B$27)*100))) | J25: =IF(Input_Dados!M$25="","",MIN(100,MAX(0,(Input_Dados!M$25-Parametros!$B$27)/(Parametros!$C$27-Parametros!$B$27)*100))) | ... M25: =IF(Input_Dados!P$25="","",MIN(100,MAX(0,(Input_Dados!P$25-Parametros!$B$27)/(Parametros!$C$27-Parametros!$B$27)*100)))
A26: Acesso a Água Potável | B26: + | C26: =IF(Input_Dados!F$26="","",MIN(100,MAX(0,(Input_Dados!F$26-Parametros!$B$28)/(Parametros!$C$28-Parametros!$B$28)*100))) | D26: =IF(Input_Dados!G$26="","",MIN(100,MAX(0,(Input_Dados!G$26-Parametros!$B$28)/(Parametros!$C$28-Parametros!$B$28)*100))) | E26: =IF(Input_Dados!H$26="","",MIN(100,MAX(0,(Input_Dados!H$26-Parametros!$B$28)/(Parametros!$C$28-Parametros!$B$28)*100))) | F26: =IF(Input_Dados!I$26="","",MIN(100,MAX(0,(Input_Dados!I$26-Parametros!$B$28)/(Parametros!$C$28-Parametros!$B$28)*100))) | G26: =IF(Input_Dados!J$26="","",MIN(100,MAX(0,(Input_Dados!J$26-Parametros!$B$28)/(Parametros!$C$28-Parametros!$B$28)*100))) | H26: =IF(Input_Dados!K$26="","",MIN(100,MAX(0,(Input_Dados!K$26-Parametros!$B$28)/(Parametros!$C$28-Parametros!$B$28)*100))) | I26: =IF(Input_Dados!L$26="","",MIN(100,MAX(0,(Input_Dados!L$26-Parametros!$B$28)/(Parametros!$C$28-Parametros!$B$28)*100))) | J26: =IF(Input_Dados!M$26="","",MIN(100,MAX(0,(Input_Dados!M$26-Parametros!$B$28)/(Parametros!$C$28-Parametros!$B$28)*100))) | ... M26: =IF(Input_Dados!P$26="","",MIN(100,MAX(0,(Input_Dados!P$26-Parametros!$B$28)/(Parametros!$C$28-Parametros!$B$28)*100)))
A27: Acesso a Saneamento Básico | B27: + | C27: =IF(Input_Dados!F$27="","",MIN(100,MAX(0,(Input_Dados!F$27-Parametros!$B$29)/(Parametros!$C$29-Parametros!$B$29)*100))) | D27: =IF(Input_Dados!G$27="","",MIN(100,MAX(0,(Input_Dados!G$27-Parametros!$B$29)/(Parametros!$C$29-Parametros!$B$29)*100))) | E27: =IF(Input_Dados!H$27="","",MIN(100,MAX(0,(Input_Dados!H$27-Parametros!$B$29)/(Parametros!$C$29-Parametros!$B$29)*100))) | F27: =IF(Input_Dados!I$27="","",MIN(100,MAX(0,(Input_Dados!I$27-Parametros!$B$29)/(Parametros!$C$29-Parametros!$B$29)*100))) | G27: =IF(Input_Dados!J$27="","",MIN(100,MAX(0,(Input_Dados!J$27-Parametros!$B$29)/(Parametros!$C$29-Parametros!$B$29)*100))) | H27: =IF(Input_Dados!K$27="","",MIN(100,MAX(0,(Input_Dados!K$27-Parametros!$B$29)/(Parametros!$C$29-Parametros!$B$29)*100))) | I27: =IF(Input_Dados!L$27="","",MIN(100,MAX(0,(Input_Dados!L$27-Parametros!$B$29)/(Parametros!$C$29-Parametros!$B$29)*100))) | J27: =IF(Input_Dados!M$27="","",MIN(100,MAX(0,(Input_Dados!M$27-Parametros!$B$29)/(Parametros!$C$29-Parametros!$B$29)*100))) | ... M27: =IF(Input_Dados!P$27="","",MIN(100,MAX(0,(Input_Dados!P$27-Parametros!$B$29)/(Parametros!$C$29-Parametros!$B$29)*100)))
A28: Cobertura de Rede 4G | B28: + | C28: =IF(Input_Dados!F$28="","",MIN(100,MAX(0,(Input_Dados!F$28-Parametros!$B$30)/(Parametros!$C$30-Parametros!$B$30)*100))) | D28: =IF(Input_Dados!G$28="","",MIN(100,MAX(0,(Input_Dados!G$28-Parametros!$B$30)/(Parametros!$C$30-Parametros!$B$30)*100))) | E28: =IF(Input_Dados!H$28="","",MIN(100,MAX(0,(Input_Dados!H$28-Parametros!$B$30)/(Parametros!$C$30-Parametros!$B$30)*100))) | F28: =IF(Input_Dados!I$28="","",MIN(100,MAX(0,(Input_Dados!I$28-Parametros!$B$30)/(Parametros!$C$30-Parametros!$B$30)*100))) | G28: =IF(Input_Dados!J$28="","",MIN(100,MAX(0,(Input_Dados!J$28-Parametros!$B$30)/(Parametros!$C$30-Parametros!$B$30)*100))) | H28: =IF(Input_Dados!K$28="","",MIN(100,MAX(0,(Input_Dados!K$28-Parametros!$B$30)/(Parametros!$C$30-Parametros!$B$30)*100))) | I28: =IF(Input_Dados!L$28="","",MIN(100,MAX(0,(Input_Dados!L$28-Parametros!$B$30)/(Parametros!$C$30-Parametros!$B$30)*100))) | J28: =IF(Input_Dados!M$28="","",MIN(100,MAX(0,(Input_Dados!M$28-Parametros!$B$30)/(Parametros!$C$30-Parametros!$B$30)*100))) | ... M28: =IF(Input_Dados!P$28="","",MIN(100,MAX(0,(Input_Dados!P$28-Parametros!$B$30)/(Parametros!$C$30-Parametros!$B$30)*100)))
A29: Utilizadores de Internet (%) | B29: + | C29: =IF(Input_Dados!F$29="","",MIN(100,MAX(0,(Input_Dados!F$29-Parametros!$B$31)/(Parametros!$C$31-Parametros!$B$31)*100))) | D29: =IF(Input_Dados!G$29="","",MIN(100,MAX(0,(Input_Dados!G$29-Parametros!$B$31)/(Parametros!$C$31-Parametros!$B$31)*100))) | E29: =IF(Input_Dados!H$29="","",MIN(100,MAX(0,(Input_Dados!H$29-Parametros!$B$31)/(Parametros!$C$31-Parametros!$B$31)*100))) | F29: =IF(Input_Dados!I$29="","",MIN(100,MAX(0,(Input_Dados!I$29-Parametros!$B$31)/(Parametros!$C$31-Parametros!$B$31)*100))) | G29: =IF(Input_Dados!J$29="","",MIN(100,MAX(0,(Input_Dados!J$29-Parametros!$B$31)/(Parametros!$C$31-Parametros!$B$31)*100))) | H29: =IF(Input_Dados!K$29="","",MIN(100,MAX(0,(Input_Dados!K$29-Parametros!$B$31)/(Parametros!$C$31-Parametros!$B$31)*100))) | I29: =IF(Input_Dados!L$29="","",MIN(100,MAX(0,(Input_Dados!L$29-Parametros!$B$31)/(Parametros!$C$31-Parametros!$B$31)*100))) | J29: =IF(Input_Dados!M$29="","",MIN(100,MAX(0,(Input_Dados!M$29-Parametros!$B$31)/(Parametros!$C$31-Parametros!$B$31)*100))) | ... M29: =IF(Input_Dados!P$29="","",MIN(100,MAX(0,(Input_Dados!P$29-Parametros!$B$31)/(Parametros!$C$31-Parametros!$B$31)*100)))
A30: Densidade Rodoviária (km/1000km²) | B30: + | C30: =IF(Input_Dados!F$30="","",MIN(100,MAX(0,(Input_Dados!F$30-Parametros!$B$32)/(Parametros!$C$32-Parametros!$B$32)*100))) | D30: =IF(Input_Dados!G$30="","",MIN(100,MAX(0,(Input_Dados!G$30-Parametros!$B$32)/(Parametros!$C$32-Parametros!$B$32)*100))) | E30: =IF(Input_Dados!H$30="","",MIN(100,MAX(0,(Input_Dados!H$30-Parametros!$B$32)/(Parametros!$C$32-Parametros!$B$32)*100))) | F30: =IF(Input_Dados!I$30="","",MIN(100,MAX(0,(Input_Dados!I$30-Parametros!$B$32)/(Parametros!$C$32-Parametros!$B$32)*100))) | G30: =IF(Input_Dados!J$30="","",MIN(100,MAX(0,(Input_Dados!J$30-Parametros!$B$32)/(Parametros!$C$32-Parametros!$B$32)*100))) | H30: =IF(Input_Dados!K$30="","",MIN(100,MAX(0,(Input_Dados!K$30-Parametros!$B$32)/(Parametros!$C$32-Parametros!$B$32)*100))) | I30: =IF(Input_Dados!L$30="","",MIN(100,MAX(0,(Input_Dados!L$30-Parametros!$B$32)/(Parametros!$C$32-Parametros!$B$32)*100))) | J30: =IF(Input_Dados!M$30="","",MIN(100,MAX(0,(Input_Dados!M$30-Parametros!$B$32)/(Parametros!$C$32-Parametros!$B$32)*100))) | ... M30: =IF(Input_Dados!P$30="","",MIN(100,MAX(0,(Input_Dados!P$30-Parametros!$B$32)/(Parametros!$C$32-Parametros!$B$32)*100)))
A31: Taxa de Emprego | B31: + | C31: =IF(Input_Dados!F$31="","",MIN(100,MAX(0,(Input_Dados!F$31-Parametros!$B$33)/(Parametros!$C$33-Parametros!$B$33)*100))) | D31: =IF(Input_Dados!G$31="","",MIN(100,MAX(0,(Input_Dados!G$31-Parametros!$B$33)/(Parametros!$C$33-Parametros!$B$33)*100))) | E31: =IF(Input_Dados!H$31="","",MIN(100,MAX(0,(Input_Dados!H$31-Parametros!$B$33)/(Parametros!$C$33-Parametros!$B$33)*100))) | F31: =IF(Input_Dados!I$31="","",MIN(100,MAX(0,(Input_Dados!I$31-Parametros!$B$33)/(Parametros!$C$33-Parametros!$B$33)*100))) | G31: =IF(Input_Dados!J$31="","",MIN(100,MAX(0,(Input_Dados!J$31-Parametros!$B$33)/(Parametros!$C$33-Parametros!$B$33)*100))) | H31: =IF(Input_Dados!K$31="","",MIN(100,MAX(0,(Input_Dados!K$31-Parametros!$B$33)/(Parametros!$C$33-Parametros!$B$33)*100))) | I31: =IF(Input_Dados!L$31="","",MIN(100,MAX(0,(Input_Dados!L$31-Parametros!$B$33)/(Parametros!$C$33-Parametros!$B$33)*100))) | J31: =IF(Input_Dados!M$31="","",MIN(100,MAX(0,(Input_Dados!M$31-Parametros!$B$33)/(Parametros!$C$33-Parametros!$B$33)*100))) | ... M31: =IF(Input_Dados!P$31="","",MIN(100,MAX(0,(Input_Dados!P$31-Parametros!$B$33)/(Parametros!$C$33-Parametros!$B$33)*100)))
A32: Taxa de Desemprego | B32: - | C32: =IF(Input_Dados!F$32="","",MIN(100,MAX(0,(Parametros!$C$34-Input_Dados!F$32)/(Parametros!$C$34-Parametros!$B$34)*100))) | D32: =IF(Input_Dados!G$32="","",MIN(100,MAX(0,(Parametros!$C$34-Input_Dados!G$32)/(Parametros!$C$34-Parametros!$B$34)*100))) | E32: =IF(Input_Dados!H$32="","",MIN(100,MAX(0,(Parametros!$C$34-Input_Dados!H$32)/(Parametros!$C$34-Parametros!$B$34)*100))) | F32: =IF(Input_Dados!I$32="","",MIN(100,MAX(0,(Parametros!$C$34-Input_Dados!I$32)/(Parametros!$C$34-Parametros!$B$34)*100))) | G32: =IF(Input_Dados!J$32="","",MIN(100,MAX(0,(Parametros!$C$34-Input_Dados!J$32)/(Parametros!$C$34-Parametros!$B$34)*100))) | H32: =IF(Input_Dados!K$32="","",MIN(100,MAX(0,(Parametros!$C$34-Input_Dados!K$32)/(Parametros!$C$34-Parametros!$B$34)*100))) | I32: =IF(Input_Dados!L$32="","",MIN(100,MAX(0,(Parametros!$C$34-Input_Dados!L$32)/(Parametros!$C$34-Parametros!$B$34)*100))) | J32: =IF(Input_Dados!M$32="","",MIN(100,MAX(0,(Parametros!$C$34-Input_Dados!M$32)/(Parametros!$C$34-Parametros!$B$34)*100))) | ... M32: =IF(Input_Dados!P$32="","",MIN(100,MAX(0,(Parametros!$C$34-Input_Dados!P$32)/(Parametros!$C$34-Parametros!$B$34)*100)))
A33: Desemprego Juvenil | B33: - | C33: =IF(Input_Dados!F$33="","",MIN(100,MAX(0,(Parametros!$C$35-Input_Dados!F$33)/(Parametros!$C$35-Parametros!$B$35)*100))) | D33: =IF(Input_Dados!G$33="","",MIN(100,MAX(0,(Parametros!$C$35-Input_Dados!G$33)/(Parametros!$C$35-Parametros!$B$35)*100))) | E33: =IF(Input_Dados!H$33="","",MIN(100,MAX(0,(Parametros!$C$35-Input_Dados!H$33)/(Parametros!$C$35-Parametros!$B$35)*100))) | F33: =IF(Input_Dados!I$33="","",MIN(100,MAX(0,(Parametros!$C$35-Input_Dados!I$33)/(Parametros!$C$35-Parametros!$B$35)*100))) | G33: =IF(Input_Dados!J$33="","",MIN(100,MAX(0,(Parametros!$C$35-Input_Dados!J$33)/(Parametros!$C$35-Parametros!$B$35)*100))) | H33: =IF(Input_Dados!K$33="","",MIN(100,MAX(0,(Parametros!$C$35-Input_Dados!K$33)/(Parametros!$C$35-Parametros!$B$35)*100))) | I33: =IF(Input_Dados!L$33="","",MIN(100,MAX(0,(Parametros!$C$35-Input_Dados!L$33)/(Parametros!$C$35-Parametros!$B$35)*100))) | J33: =IF(Input_Dados!M$33="","",MIN(100,MAX(0,(Parametros!$C$35-Input_Dados!M$33)/(Parametros!$C$35-Parametros!$B$35)*100))) | ... M33: =IF(Input_Dados!P$33="","",MIN(100,MAX(0,(Parametros!$C$35-Input_Dados!P$33)/(Parametros!$C$35-Parametros!$B$35)*100)))
A34: Emprego Informal (%) | B34: - | C34: =IF(Input_Dados!F$34="","",MIN(100,MAX(0,(Parametros!$C$36-Input_Dados!F$34)/(Parametros!$C$36-Parametros!$B$36)*100))) | D34: =IF(Input_Dados!G$34="","",MIN(100,MAX(0,(Parametros!$C$36-Input_Dados!G$34)/(Parametros!$C$36-Parametros!$B$36)*100))) | E34: =IF(Input_Dados!H$34="","",MIN(100,MAX(0,(Parametros!$C$36-Input_Dados!H$34)/(Parametros!$C$36-Parametros!$B$36)*100))) | F34: =IF(Input_Dados!I$34="","",MIN(100,MAX(0,(Parametros!$C$36-Input_Dados!I$34)/(Parametros!$C$36-Parametros!$B$36)*100))) | G34: =IF(Input_Dados!J$34="","",MIN(100,MAX(0,(Parametros!$C$36-Input_Dados!J$34)/(Parametros!$C$36-Parametros!$B$36)*100))) | H34: =IF(Input_Dados!K$34="","",MIN(100,MAX(0,(Parametros!$C$36-Input_Dados!K$34)/(Parametros!$C$36-Parametros!$B$36)*100))) | I34: =IF(Input_Dados!L$34="","",MIN(100,MAX(0,(Parametros!$C$36-Input_Dados!L$34)/(Parametros!$C$36-Parametros!$B$36)*100))) | J34: =IF(Input_Dados!M$34="","",MIN(100,MAX(0,(Parametros!$C$36-Input_Dados!M$34)/(Parametros!$C$36-Parametros!$B$36)*100))) | ... M34: =IF(Input_Dados!P$34="","",MIN(100,MAX(0,(Parametros!$C$36-Input_Dados!P$34)/(Parametros!$C$36-Parametros!$B$36)*100)))
A35: Taxa de Formalização | B35: + | C35: =IF(Input_Dados!F$35="","",MIN(100,MAX(0,(Input_Dados!F$35-Parametros!$B$37)/(Parametros!$C$37-Parametros!$B$37)*100))) | D35: =IF(Input_Dados!G$35="","",MIN(100,MAX(0,(Input_Dados!G$35-Parametros!$B$37)/(Parametros!$C$37-Parametros!$B$37)*100))) | E35: =IF(Input_Dados!H$35="","",MIN(100,MAX(0,(Input_Dados!H$35-Parametros!$B$37)/(Parametros!$C$37-Parametros!$B$37)*100))) | F35: =IF(Input_Dados!I$35="","",MIN(100,MAX(0,(Input_Dados!I$35-Parametros!$B$37)/(Parametros!$C$37-Parametros!$B$37)*100))) | G35: =IF(Input_Dados!J$35="","",MIN(100,MAX(0,(Input_Dados!J$35-Parametros!$B$37)/(Parametros!$C$37-Parametros!$B$37)*100))) | H35: =IF(Input_Dados!K$35="","",MIN(100,MAX(0,(Input_Dados!K$35-Parametros!$B$37)/(Parametros!$C$37-Parametros!$B$37)*100))) | I35: =IF(Input_Dados!L$35="","",MIN(100,MAX(0,(Input_Dados!L$35-Parametros!$B$37)/(Parametros!$C$37-Parametros!$B$37)*100))) | J35: =IF(Input_Dados!M$35="","",MIN(100,MAX(0,(Input_Dados!M$35-Parametros!$B$37)/(Parametros!$C$37-Parametros!$B$37)*100))) | ... M35: =IF(Input_Dados!P$35="","",MIN(100,MAX(0,(Input_Dados!P$35-Parametros!$B$37)/(Parametros!$C$37-Parametros!$B$37)*100)))
A36: Crescimento da Produtividade | B36: + | C36: =IF(Input_Dados!F$36="","",MIN(100,MAX(0,(Input_Dados!F$36-Parametros!$B$38)/(Parametros!$C$38-Parametros!$B$38)*100))) | D36: =IF(Input_Dados!G$36="","",MIN(100,MAX(0,(Input_Dados!G$36-Parametros!$B$38)/(Parametros!$C$38-Parametros!$B$38)*100))) | E36: =IF(Input_Dados!H$36="","",MIN(100,MAX(0,(Input_Dados!H$36-Parametros!$B$38)/(Parametros!$C$38-Parametros!$B$38)*100))) | F36: =IF(Input_Dados!I$36="","",MIN(100,MAX(0,(Input_Dados!I$36-Parametros!$B$38)/(Parametros!$C$38-Parametros!$B$38)*100))) | G36: =IF(Input_Dados!J$36="","",MIN(100,MAX(0,(Input_Dados!J$36-Parametros!$B$38)/(Parametros!$C$38-Parametros!$B$38)*100))) | H36: =IF(Input_Dados!K$36="","",MIN(100,MAX(0,(Input_Dados!K$36-Parametros!$B$38)/(Parametros!$C$38-Parametros!$B$38)*100))) | I36: =IF(Input_Dados!L$36="","",MIN(100,MAX(0,(Input_Dados!L$36-Parametros!$B$38)/(Parametros!$C$38-Parametros!$B$38)*100))) | J36: =IF(Input_Dados!M$36="","",MIN(100,MAX(0,(Input_Dados!M$36-Parametros!$B$38)/(Parametros!$C$38-Parametros!$B$38)*100))) | ... M36: =IF(Input_Dados!P$36="","",MIN(100,MAX(0,(Input_Dados!P$36-Parametros!$B$38)/(Parametros!$C$38-Parametros!$B$38)*100)))
A37: Índice Global Seg. Alimentar | B37: + | C37: =IF(Input_Dados!F$37="","",MIN(100,MAX(0,(Input_Dados!F$37-Parametros!$B$39)/(Parametros!$C$39-Parametros!$B$39)*100))) | D37: =IF(Input_Dados!G$37="","",MIN(100,MAX(0,(Input_Dados!G$37-Parametros!$B$39)/(Parametros!$C$39-Parametros!$B$39)*100))) | E37: =IF(Input_Dados!H$37="","",MIN(100,MAX(0,(Input_Dados!H$37-Parametros!$B$39)/(Parametros!$C$39-Parametros!$B$39)*100))) | F37: =IF(Input_Dados!I$37="","",MIN(100,MAX(0,(Input_Dados!I$37-Parametros!$B$39)/(Parametros!$C$39-Parametros!$B$39)*100))) | G37: =IF(Input_Dados!J$37="","",MIN(100,MAX(0,(Input_Dados!J$37-Parametros!$B$39)/(Parametros!$C$39-Parametros!$B$39)*100))) | H37: =IF(Input_Dados!K$37="","",MIN(100,MAX(0,(Input_Dados!K$37-Parametros!$B$39)/(Parametros!$C$39-Parametros!$B$39)*100))) | I37: =IF(Input_Dados!L$37="","",MIN(100,MAX(0,(Input_Dados!L$37-Parametros!$B$39)/(Parametros!$C$39-Parametros!$B$39)*100))) | J37: =IF(Input_Dados!M$37="","",MIN(100,MAX(0,(Input_Dados!M$37-Parametros!$B$39)/(Parametros!$C$39-Parametros!$B$39)*100))) | ... M37: =IF(Input_Dados!P$37="","",MIN(100,MAX(0,(Input_Dados!P$37-Parametros!$B$39)/(Parametros!$C$39-Parametros!$B$39)*100)))
A38: Prevalência de Desnutrição | B38: - | C38: =IF(Input_Dados!F$38="","",MIN(100,MAX(0,(Parametros!$C$40-Input_Dados!F$38)/(Parametros!$C$40-Parametros!$B$40)*100))) | D38: =IF(Input_Dados!G$38="","",MIN(100,MAX(0,(Parametros!$C$40-Input_Dados!G$38)/(Parametros!$C$40-Parametros!$B$40)*100))) | E38: =IF(Input_Dados!H$38="","",MIN(100,MAX(0,(Parametros!$C$40-Input_Dados!H$38)/(Parametros!$C$40-Parametros!$B$40)*100))) | F38: =IF(Input_Dados!I$38="","",MIN(100,MAX(0,(Parametros!$C$40-Input_Dados!I$38)/(Parametros!$C$40-Parametros!$B$40)*100))) | G38: =IF(Input_Dados!J$38="","",MIN(100,MAX(0,(Parametros!$C$40-Input_Dados!J$38)/(Parametros!$C$40-Parametros!$B$40)*100))) | H38: =IF(Input_Dados!K$38="","",MIN(100,MAX(0,(Parametros!$C$40-Input_Dados!K$38)/(Parametros!$C$40-Parametros!$B$40)*100))) | I38: =IF(Input_Dados!L$38="","",MIN(100,MAX(0,(Parametros!$C$40-Input_Dados!L$38)/(Parametros!$C$40-Parametros!$B$40)*100))) | J38: =IF(Input_Dados!M$38="","",MIN(100,MAX(0,(Parametros!$C$40-Input_Dados!M$38)/(Parametros!$C$40-Parametros!$B$40)*100))) | ... M38: =IF(Input_Dados!P$38="","",MIN(100,MAX(0,(Parametros!$C$40-Input_Dados!P$38)/(Parametros!$C$40-Parametros!$B$40)*100)))
A39: Mortalidade Materna (por 100k) | B39: - | C39: =IF(Input_Dados!F$39="","",MIN(100,MAX(0,(Parametros!$C$41-Input_Dados!F$39)/(Parametros!$C$41-Parametros!$B$41)*100))) | D39: =IF(Input_Dados!G$39="","",MIN(100,MAX(0,(Parametros!$C$41-Input_Dados!G$39)/(Parametros!$C$41-Parametros!$B$41)*100))) | E39: =IF(Input_Dados!H$39="","",MIN(100,MAX(0,(Parametros!$C$41-Input_Dados!H$39)/(Parametros!$C$41-Parametros!$B$41)*100))) | F39: =IF(Input_Dados!I$39="","",MIN(100,MAX(0,(Parametros!$C$41-Input_Dados!I$39)/(Parametros!$C$41-Parametros!$B$41)*100))) | G39: =IF(Input_Dados!J$39="","",MIN(100,MAX(0,(Parametros!$C$41-Input_Dados!J$39)/(Parametros!$C$41-Parametros!$B$41)*100))) | H39: =IF(Input_Dados!K$39="","",MIN(100,MAX(0,(Parametros!$C$41-Input_Dados!K$39)/(Parametros!$C$41-Parametros!$B$41)*100))) | I39: =IF(Input_Dados!L$39="","",MIN(100,MAX(0,(Parametros!$C$41-Input_Dados!L$39)/(Parametros!$C$41-Parametros!$B$41)*100))) | J39: =IF(Input_Dados!M$39="","",MIN(100,MAX(0,(Parametros!$C$41-Input_Dados!M$39)/(Parametros!$C$41-Parametros!$B$41)*100))) | ... M39: =IF(Input_Dados!P$39="","",MIN(100,MAX(0,(Parametros!$C$41-Input_Dados!P$39)/(Parametros!$C$41-Parametros!$B$41)*100)))
A40: Despesas Saúde (% PIB) | B40: + | C40: =IF(Input_Dados!F$40="","",MIN(100,MAX(0,(Input_Dados!F$40-Parametros!$B$42)/(Parametros!$C$42-Parametros!$B$42)*100))) | D40: =IF(Input_Dados!G$40="","",MIN(100,MAX(0,(Input_Dados!G$40-Parametros!$B$42)/(Parametros!$C$42-Parametros!$B$42)*100))) | E40: =IF(Input_Dados!H$40="","",MIN(100,MAX(0,(Input_Dados!H$40-Parametros!$B$42)/(Parametros!$C$42-Parametros!$B$42)*100))) | F40: =IF(Input_Dados!I$40="","",MIN(100,MAX(0,(Input_Dados!I$40-Parametros!$B$42)/(Parametros!$C$42-Parametros!$B$42)*100))) | G40: =IF(Input_Dados!J$40="","",MIN(100,MAX(0,(Input_Dados!J$40-Parametros!$B$42)/(Parametros!$C$42-Parametros!$B$42)*100))) | H40: =IF(Input_Dados!K$40="","",MIN(100,MAX(0,(Input_Dados!K$40-Parametros!$B$42)/(Parametros!$C$42-Parametros!$B$42)*100))) | I40: =IF(Input_Dados!L$40="","",MIN(100,MAX(0,(Input_Dados!L$40-Parametros!$B$42)/(Parametros!$C$42-Parametros!$B$42)*100))) | J40: =IF(Input_Dados!M$40="","",MIN(100,MAX(0,(Input_Dados!M$40-Parametros!$B$42)/(Parametros!$C$42-Parametros!$B$42)*100))) | ... M40: =IF(Input_Dados!P$40="","",MIN(100,MAX(0,(Input_Dados!P$40-Parametros!$B$42)/(Parametros!$C$42-Parametros!$B$42)*100)))
...

Sheet Subindices
A1: Subíndice | B1: 2015 | C1: 2016 | D1: 2017 | E1: 2018 | F1: 2019 | G1: 2020 | H1: 2021 | I1: 2022 | J1: 2023 | K1: 2024 | L1: 2025
