Workbook

Sheet Metodologia_v4
A1: IGDA-BDA v4 - metodologia linkada
A2: Seleciona os melhores indicadores disponíveis por dimensão, separa dados observados de dados ajustados, e identifica todos os anos não observados usados no cálculo.
A4: Parâmetros editáveis
A5: Parâmetro | B5: Valor | C5: Uso nas fórmulas
A6: Ano inicial | B6: 2015 | C6: Referenciado pelas folhas de dados ajustados, flags, normalização, subíndices e IGDA.
A7: Ano final | B7: 2025 | C7: Referenciado pelas folhas de dados ajustados, flags, normalização, subíndices e IGDA.
A8: Escala normalizada mínima | B8: 0 | C8: Referenciado pelas folhas de dados ajustados, flags, normalização, subíndices e IGDA.
A9: Escala normalizada máxima | B9: 100 | C9: Referenciado pelas folhas de dados ajustados, flags, normalização, subíndices e IGDA.
A10: Limiar mínimo de cobertura por subíndice | B10: 0.5 | C10: Referenciado pelas folhas de dados ajustados, flags, normalização, subíndices e IGDA.
A11: Nº mínimo de subíndices para IGDA global | B11: 4 | C11: Referenciado pelas folhas de dados ajustados, flags, normalização, subíndices e IGDA.
A12: Lacuna máxima para interpolação linear (nº de anos sem observação entre dois dados) | B12: 3 | C12: Referenciado pelas folhas de dados ajustados, flags, normalização, subíndices e IGDA.
A13: Carry-forward máximo no fim da série (anos) | B13: 2 | C13: Referenciado pelas folhas de dados ajustados, flags, normalização, subíndices e IGDA.
A14: Carry-backward máximo no início da série (anos) | B14: 1 | C14: Referenciado pelas folhas de dados ajustados, flags, normalização, subíndices e IGDA.
A15: Agregação dos indicadores no subíndice | B15: Média aritmética ponderada | C15: Referenciado pelas folhas de dados ajustados, flags, normalização, subíndices e IGDA.
A16: Agregação dos subíndices no IGDA | B16: Média geométrica ponderada | C16: Referenciado pelas folhas de dados ajustados, flags, normalização, subíndices e IGDA.
A19: Regras para anos não observáveis
A20: Flag | B20: Descrição
A21: OBS | B21: Valor observado diretamente na fonte usada.
A22: EST_INTERP_LINEAR | B22: Ano sem observação estimado por interpolação linear entre dois anos observados, se a lacuna for menor ou igual a B12.
A23: EST_CARRY_FORWARD | B23: Ano final sem observação preenchido com o último valor observado, até ao limite de B13.
A24: EST_CARRY_BACKWARD | B24: Ano inicial sem observação preenchido com o primeiro valor observado posterior, até ao limite de B14.
A25: SEM_DADO | B25: Sem observação e sem ajustamento permitido; o indicador é ignorado nesse ano.
A29: Fórmulas metodológicas
A30: Item | B30: Regra
A31: Normalização sentido positivo | B31: Score = MIN(100, MAX(0, (valor - mínimo) / (máximo - mínimo) * 100))
A32: Normalização sentido negativo | B32: Score = MIN(100, MAX(0, (máximo - valor) / (máximo - mínimo) * 100))
A33: Subíndice | B33: Média aritmética ponderada dos indicadores ativos com score disponível, se cumprir o limiar mínimo de cobertura.
A34: IGDA global | B34: Média geométrica ponderada dos sete subíndices, se houver pelo menos o nº mínimo de subíndices.

Sheet Indicadores_v4
A1: Indicadores finais selecionados para o IGDA-BDA v4
A2: Edite pesos, ativos, mínimos, máximos e metas nesta folha. As demais folhas referenciam estes parâmetros.
A4: ID | B4: Dimensão | C4: Indicador | D4: Unidade | E4: Sentido | F4: Mínimo | G4: Máximo | H4: Meta 2027 | I4: Peso indicador | J4: Ativo | K4: Fonte | L4: Código/API | M4: Fonte_URL | N4: Prioridade | O4: Justificação | P4: Regra anos em falta
A5: GOV01 | B5: 1. Governança e Estado de Direito | C5: Índice de Percepção da Corrupção | D5: 0-100 | E5: + | F5: 0 | G5: 100 | H5: 35 | I5: 1 | J5: 1 | K5: Transparency International / ficheiro base | M5: https://www.transparency.org/en/cpi | N5: Alta | O5: Referência internacional já usada no modelo original. | P5: Usa regra global definida em Metodologia_v4!B12:B14
A6: GOV02 | B6: 1. Governança e Estado de Direito | C6: WGI - Estado de Direito | D6: -2.5 a 2.5 | E6: + | F6: -2.5 | G6: 2.5 | H6: 0 | I6: 1 | J6: 1 | K6: Worldwide Governance Indicators | L6: RL.EST | M6: https://datacatalogfiles.worldbank.org/ddh-published/0038026/DR0095947/wgidataset_with_sourcedata-2025.xlsx | N6: Alta | O6: Estado de Direito e execução de regras. | P6: Usa regra global definida em Metodologia_v4!B12:B14
A7: GOV03 | B7: 1. Governança e Estado de Direito | C7: WGI - Eficiência do Governo | D7: -2.5 a 2.5 | E7: + | F7: -2.5 | G7: 2.5 | H7: 0 | I7: 1 | J7: 1 | K7: Worldwide Governance Indicators | L7: GE.EST | M7: https://datacatalogfiles.worldbank.org/ddh-published/0038026/DR0095947/wgidataset_with_sourcedata-2025.xlsx | N7: Alta | O7: Capacidade do Estado para executar políticas públicas. | P7: Usa regra global definida em Metodologia_v4!B12:B14
A8: GOV04 | B8: 1. Governança e Estado de Direito | C8: WGI - Estabilidade Política | D8: -2.5 a 2.5 | E8: + | F8: -2.5 | G8: 2.5 | H8: 0 | I8: 1 | J8: 1 | K8: Worldwide Governance Indicators | L8: PV.EST | M8: https://datacatalogfiles.worldbank.org/ddh-published/0038026/DR0095947/wgidataset_with_sourcedata-2025.xlsx | N8: Alta | O8: Risco político, violência e continuidade institucional. | P8: Usa regra global definida em Metodologia_v4!B12:B14
A9: GOV05 | B9: 1. Governança e Estado de Direito | C9: WGI - Qualidade Regulatória | D9: -2.5 a 2.5 | E9: + | F9: -2.5 | G9: 2.5 | H9: 0 | I9: 1 | J9: 1 | K9: Worldwide Governance Indicators | L9: RQ.EST | M9: https://datacatalogfiles.worldbank.org/ddh-published/0038026/DR0095947/wgidataset_with_sourcedata-2025.xlsx | N9: Alta | O9: Substituto robusto para Doing Business, descontinuado. | P9: Usa regra global definida em Metodologia_v4!B12:B14
A10: GOV06 | B10: 1. Governança e Estado de Direito | C10: WGI - Controlo da Corrupção | D10: -2.5 a 2.5 | E10: + | F10: -2.5 | G10: 2.5 | H10: 0 | I10: 1 | J10: 1 | K10: Worldwide Governance Indicators | L10: CC.EST | M10: https://datacatalogfiles.worldbank.org/ddh-published/0038026/DR0095947/wgidataset_with_sourcedata-2025.xlsx | N10: Alta | O10: Complementa o CPI com uma métrica WGI coerente. | P10: Usa regra global definida em Metodologia_v4!B12:B14
A11: MAC01 | B11: 2. Estabilidade Macroeconómica | C11: Crescimento real do PIB | D11: % | E11: + | F11: -10 | G11: 15 | H11: 5 | I11: 1 | J11: 1 | K11: Banco Mundial/WDI | L11: NY.GDP.MKTP.KD.ZG | M11: https://data.worldbank.org/indicator/NY.GDP.MKTP.KD.ZG?locations=AO | N11: Alta | O11: Dinamismo económico real. | P11: Usa regra global definida em Metodologia_v4!B12:B14
A12: MAC02 | B12: 2. Estabilidade Macroeconómica | C12: PIB per capita | D12: USD correntes | E12: + | F12: 500 | G12: 15000 | H12: 5000 | I12: 1 | J12: 1 | K12: Banco Mundial/WDI | L12: NY.GDP.PCAP.CD | M12: https://data.worldbank.org/indicator/NY.GDP.PCAP.CD?locations=AO | N12: Alta | O12: Nível médio de rendimento. | P12: Usa regra global definida em Metodologia_v4!B12:B14
A13: MAC03 | B13: 2. Estabilidade Macroeconómica | C13: Inflação, preços ao consumidor | D13: % | E13: - | F13: 0 | G13: 50 | H13: 10 | I13: 1 | J13: 1 | K13: Banco Mundial/WDI | L13: FP.CPI.TOTL.ZG | M13: https://data.worldbank.org/indicator/FP.CPI.TOTL.ZG?locations=AO | N13: Alta | O13: Estabilidade de preços. | P13: Usa regra global definida em Metodologia_v4!B12:B14
A14: MAC04 | B14: 2. Estabilidade Macroeconómica | C14: Dívida pública do governo central | D14: % PIB | E14: - | F14: 0 | G14: 150 | H14: 60 | I14: 1 | J14: 1 | K14: Banco Mundial/WDI | L14: GC.DOD.TOTL.GD.ZS | M14: https://data.worldbank.org/indicator/GC.DOD.TOTL.GD.ZS?locations=AO | N14: Alta | O14: Sustentabilidade fiscal. | P14: Usa regra global definida em Metodologia_v4!B12:B14
A15: MAC05 | B15: 2. Estabilidade Macroeconómica | C15: Saldo orçamental de caixa | D15: % PIB | E15: + | F15: -15 | G15: 10 | H15: 0 | I15: 1 | J15: 1 | K15: Banco Mundial/WDI | L15: GC.BAL.CASH.GD.ZS | M15: https://data.worldbank.org/indicator/GC.BAL.CASH.GD.ZS?locations=AO | N15: Alta | O15: Equilíbrio fiscal corrente. | P15: Usa regra global definida em Metodologia_v4!B12:B14
A16: MAC06 | B16: 2. Estabilidade Macroeconómica | C16: Saldo da conta corrente | D16: % PIB | E16: + | F16: -30 | G16: 30 | H16: 0 | I16: 1 | J16: 1 | K16: Banco Mundial/WDI | L16: BN.CAB.XOKA.GD.ZS | M16: https://data.worldbank.org/indicator/BN.CAB.XOKA.GD.ZS?locations=AO | N16: Alta | O16: Sustentabilidade externa. | P16: Usa regra global definida em Metodologia_v4!B12:B14
A17: MAC07 | B17: 2. Estabilidade Macroeconómica | C17: Reservas internacionais | D17: meses de importações | E17: + | F17: 0 | G17: 12 | H17: 6 | I17: 1 | J17: 1 | K17: Banco Mundial/WDI | L17: FI.RES.TOTL.MO | M17: https://data.worldbank.org/indicator/FI.RES.TOTL.MO?locations=AO | N17: Alta | O17: Almofada externa contra choques. | P17: Usa regra global definida em Metodologia_v4!B12:B14
A18: MAC08 | B18: 2. Estabilidade Macroeconómica | C18: Receita fiscal | D18: % PIB | E18: + | F18: 0 | G18: 40 | H18: 18 | I18: 1 | J18: 1 | K18: Banco Mundial/WDI | L18: GC.TAX.TOTL.GD.ZS | M18: https://data.worldbank.org/indicator/GC.TAX.TOTL.GD.ZS?locations=AO | N18: Alta | O18: Capacidade doméstica de financiamento público. | P18: Usa regra global definida em Metodologia_v4!B12:B14
A19: HUM01 | B19: 3. Capital Humano | C19: Índice de Desenvolvimento Humano | D19: 0-1 | E19: + | F19: 0 | G19: 1 | H19: 0.6 | I19: 1 | J19: 1 | K19: PNUD/HDR / ficheiro base | M19: https://hdr.undp.org/data-center | N19: Alta | O19: Indicador sintético de saúde, educação e rendimento. | P19: Usa regra global definida em Metodologia_v4!B12:B14
A20: HUM02 | B20: 3. Capital Humano | C20: Esperança de vida à nascença | D20: anos | E20: + | F20: 40 | G20: 85 | H20: 65 | I20: 1 | J20: 1 | K20: Banco Mundial/WDI | L20: SP.DYN.LE00.IN | M20: https://data.worldbank.org/indicator/SP.DYN.LE00.IN?locations=AO | N20: Alta | O20: Resultado central de saúde e bem-estar. | P20: Usa regra global definida em Metodologia_v4!B12:B14
A21: HUM03 | B21: 3. Capital Humano | C21: Alfabetização adulta | D21: % | E21: + | F21: 0 | G21: 100 | H21: 75 | I21: 1 | J21: 1 | K21: Banco Mundial/UNESCO | L21: SE.ADT.LITR.ZS | M21: https://data.worldbank.org/indicator/SE.ADT.LITR.ZS?locations=AO | N21: Média | O21: Competência básica acumulada. | P21: Usa regra global definida em Metodologia_v4!B12:B14
A22: HUM04 | B22: 3. Capital Humano | C22: Conclusão do ensino primário | D22: % | E22: + | F22: 0 | G22: 100 | H22: 90 | I22: 1 | J22: 1 | K22: Banco Mundial/UNESCO | L22: SE.PRM.CMPT.ZS | M22: https://data.worldbank.org/indicator/SE.PRM.CMPT.ZS?locations=AO | N22: Alta | O22: Resultado educacional mais robusto que matrícula simples. | P22: Usa regra global definida em Metodologia_v4!B12:B14
A23: HUM05 | B23: 3. Capital Humano | C23: Matrícula no ensino secundário | D23: % bruto | E23: + | F23: 0 | G23: 150 | H23: 80 | I23: 1 | J23: 1 | K23: Banco Mundial/UNESCO | L23: SE.SEC.ENRR | M23: https://data.worldbank.org/indicator/SE.SEC.ENRR?locations=AO | N23: Alta | O23: Continuidade escolar pós-primária. | P23: Usa regra global definida em Metodologia_v4!B12:B14
A24: HUM06 | B24: 3. Capital Humano | C24: Despesa pública em educação | D24: % PIB | E24: + | F24: 0 | G24: 10 | H24: 5 | I24: 1 | J24: 1 | K24: Banco Mundial/UNESCO | L24: SE.XPD.TOTL.GD.ZS | M24: https://data.worldbank.org/indicator/SE.XPD.TOTL.GD.ZS?locations=AO | N24: Média | O24: Esforço público em educação. | P24: Usa regra global definida em Metodologia_v4!B12:B14
A25: HUM07 | B25: 3. Capital Humano | C25: Mortalidade infantil | D25: por 1000 nados-vivos | E25: - | F25: 0 | G25: 150 | H25: 40 | I25: 1 | J25: 1 | K25: Banco Mundial/WDI | L25: SP.DYN.IMRT.IN | M25: https://data.worldbank.org/indicator/SP.DYN.IMRT.IN?locations=AO | N25: Alta | O25: Resultado de saúde infantil. | P25: Usa regra global definida em Metodologia_v4!B12:B14
A26: INC01 | B26: 4. Inclusão Social e Protecção | C26: Pobreza internacional | D26: % pop. abaixo de 3,00 USD/dia PPP 2021 | E26: - | F26: 0 | G26: 90 | H26: 40 | I26: 1 | J26: 1 | K26: Banco Mundial/PIP | L26: SI.POV.DDAY | M26: https://data.worldbank.org/indicator/SI.POV.DDAY?locations=AO | N26: Alta | O26: Pobreza monetária internacional atualizada. | P26: Usa regra global definida em Metodologia_v4!B12:B14
A27: INC02 | B27: 4. Inclusão Social e Protecção | C27: Índice de Gini | D27: 0-100 | E27: - | F27: 0 | G27: 70 | H27: 40 | I27: 1 | J27: 1 | K27: Banco Mundial/PIP | L27: SI.POV.GINI | M27: https://data.worldbank.org/indicator/SI.POV.GINI?locations=AO | N27: Alta | O27: Desigualdade de rendimento. | P27: Usa regra global definida em Metodologia_v4!B12:B14
A28: INC03 | B28: 4. Inclusão Social e Protecção | C28: Rendimento dos 20% mais pobres | D28: % rendimento total | E28: + | F28: 0 | G28: 20 | H28: 7 | I28: 1 | J28: 1 | K28: Banco Mundial/PIP | L28: SI.DST.FRST.20 | M28: https://data.worldbank.org/indicator/SI.DST.FRST.20?locations=AO | N28: Média | O28: Inclusão distributiva na base da distribuição. | P28: Usa regra global definida em Metodologia_v4!B12:B14
A29: INC04 | B29: 4. Inclusão Social e Protecção | C29: Global Gender Gap Index | D29: 0-1 | E29: + | F29: 0 | G29: 1 | H29: 0.7 | I29: 1 | J29: 1 | K29: WEF / ficheiro base | M29: https://www.weforum.org/publications/global-gender-gap-report-2025/ | N29: Alta | O29: Medida internacional de igualdade de género. | P29: Usa regra global definida em Metodologia_v4!B12:B14
A30: INC05 | B30: 4. Inclusão Social e Protecção | C30: Participação feminina na força de trabalho | D30: % | E30: + | F30: 0 | G30: 100 | H30: 65 | I30: 1 | J30: 1 | K30: Banco Mundial/OIT | L30: SL.TLF.CACT.FE.ZS | M30: https://data.worldbank.org/indicator/SL.TLF.CACT.FE.ZS?locations=AO | N30: Alta | O30: Inclusão económica das mulheres. | P30: Usa regra global definida em Metodologia_v4!B12:B14
A31: INC06 | B31: 4. Inclusão Social e Protecção | C31: Mulheres no parlamento | D31: % lugares | E31: + | F31: 0 | G31: 60 | H31: 35 | I31: 1 | J31: 1 | K31: Banco Mundial/IPU | L31: SG.GEN.PARL.ZS | M31: https://data.worldbank.org/indicator/SG.GEN.PARL.ZS?locations=AO | N31: Média | O31: Inclusão política de género. | P31: Usa regra global definida em Metodologia_v4!B12:B14
A32: INC07 | B32: 4. Inclusão Social e Protecção | C32: Jovens NEET | D32: % jovens | E32: - | F32: 0 | G32: 70 | H32: 30 | I32: 1 | J32: 1 | K32: Banco Mundial/OIT | L32: SL.UEM.NEET.ZS | M32: https://data.worldbank.org/indicator/SL.UEM.NEET.ZS?locations=AO | N32: Alta | O32: Jovens fora de educação, emprego e formação. | P32: Usa regra global definida em Metodologia_v4!B12:B14
A33: INC08 | B33: 4. Inclusão Social e Protecção | C33: RNB per capita | D33: USD correntes | E33: + | F33: 500 | G33: 15000 | H33: 4500 | I33: 1 | J33: 1 | K33: Banco Mundial/WDI | L33: NY.GNP.PCAP.CD | M33: https://data.worldbank.org/indicator/NY.GNP.PCAP.CD?locations=AO | N33: Média | O33: Rendimento nacional médio, já presente na lógica original. | P33: Usa regra global definida em Metodologia_v4!B12:B14
A34: INF01 | B34: 5. Infraestruturas e Serviços | C34: Acesso à eletricidade | D34: % população | E34: + | F34: 0 | G34: 100 | H34: 60 | I34: 1 | J34: 1 | K34: Banco Mundial/IEA | L34: EG.ELC.ACCS.ZS | M34: https://data.worldbank.org/indicator/EG.ELC.ACCS.ZS?locations=AO | N34: Alta | O34: Acesso básico a energia. | P34: Usa regra global definida em Metodologia_v4!B12:B14
A35: INF02 | B35: 5. Infraestruturas e Serviços | C35: Perdas na rede elétrica | D35: % produção | E35: - | F35: 0 | G35: 60 | H35: 15 | I35: 1 | J35: 1 | K35: Banco Mundial/IEA | L35: EG.ELC.LOSS.ZS | M35: https://data.worldbank.org/indicator/EG.ELC.LOSS.ZS?locations=AO | N35: Média | O35: Qualidade e eficiência da rede elétrica. | P35: Usa regra global definida em Metodologia_v4!B12:B14
A36: INF03 | B36: 5. Infraestruturas e Serviços | C36: Acesso a água potável básica | D36: % população | E36: + | F36: 0 | G36: 100 | H36: 70 | I36: 1 | J36: 1 | K36: Banco Mundial/JMP | L36: SH.H2O.BASW.ZS | M36: https://data.worldbank.org/indicator/SH.H2O.BASW.ZS?locations=AO | N36: Alta | O36: Serviço básico essencial. | P36: Usa regra global definida em Metodologia_v4!B12:B14
A37: INF04 | B37: 5. Infraestruturas e Serviços | C37: Acesso a saneamento básico | D37: % população | E37: + | F37: 0 | G37: 100 | H37: 60 | I37: 1 | J37: 1 | K37: Banco Mundial/JMP | L37: SH.STA.BASS.ZS | M37: https://data.worldbank.org/indicator/SH.STA.BASS.ZS?locations=AO | N37: Alta | O37: Serviço básico com impacto em saúde. | P37: Usa regra global definida em Metodologia_v4!B12:B14
A38: INF05 | B38: 5. Infraestruturas e Serviços | C38: Acesso a energia limpa para cozinhar | D38: % população | E38: + | F38: 0 | G38: 100 | H38: 35 | I38: 1 | J38: 1 | K38: Banco Mundial/OMS | L38: EG.CFT.ACCS.ZS | M38: https://data.worldbank.org/indicator/EG.CFT.ACCS.ZS?locations=AO | N38: Alta | O38: Infraestrutura doméstica com impacto em saúde e ambiente. | P38: Usa regra global definida em Metodologia_v4!B12:B14
A39: INF06 | B39: 5. Infraestruturas e Serviços | C39: Utilizadores de internet | D39: % população | E39: + | F39: 0 | G39: 100 | H39: 40 | I39: 1 | J39: 1 | K39: Banco Mundial/ITU | L39: IT.NET.USER.ZS | M39: https://data.worldbank.org/indicator/IT.NET.USER.ZS?locations=AO | N39: Alta | O39: Acesso digital efetivo. | P39: Usa regra global definida em Metodologia_v4!B12:B14
A40: INF07 | B40: 5. Infraestruturas e Serviços | C40: Subscrições móveis | D40: por 100 habitantes | E40: + | F40: 0 | G40: 160 | H40: 100 | I40: 1 | J40: 1 | K40: Banco Mundial/ITU | L40: IT.CEL.SETS.P2 | M40: https://data.worldbank.org/indicator/IT.CEL.SETS.P2?locations=AO | N40: Alta | O40: Infraestrutura e penetração móvel. | P40: Usa regra global definida em Metodologia_v4!B12:B14
A41: INF08 | B41: 5. Infraestruturas e Serviços | C41: Banda larga fixa | D41: por 100 habitantes | E41: + | F41: 0 | G41: 50 | H41: 8 | I41: 1 | J41: 1 | K41: Banco Mundial/ITU | L41: IT.NET.BBND.P2 | M41: https://data.worldbank.org/indicator/IT.NET.BBND.P2?locations=AO | N41: Média | O41: Infraestrutura digital fixa. | P41: Usa regra global definida em Metodologia_v4!B12:B14
...

Sheet Dados_Observados_v4
A1: Dados observados por indicador
A2: Apenas valores diretamente observados nas fontes. Não contém estimativas.
A4: ID | B4: Dimensão | C4: Indicador | D4: Fonte | E4: Código/API | F4: Estado dados | G4: Cobertura observada | H4: Último ano obs. | I4: Nota | J4: 2015 | K4: 2016 | L4: 2017 | M4: 2018 | N4: 2019 | O4: 2020 | P4: 2021 | Q4: 2022 | R4: 2023 | S4: 2024 | T4: 2025
A5: GOV01 | B5: 1. Governança e Estado de Direito | C5: Índice de Percepção da Corrupção | D5: Transparency International / ficheiro base | F5: Série observada do ficheiro base | G5: 10/11 | H5: 2024 | J5: 15 | K5: 18 | L5: 19 | M5: 19 | N5: 26 | O5: 27 | P5: 29 | Q5: 33 | R5: 33 | S5: 32
A6: GOV02 | B6: 1. Governança e Estado de Direito | C6: WGI - Estado de Direito | D6: Worldwide Governance Indicators | E6: RL.EST | F6: Fonte oficial WGI 2025 | G6: 10/11 | H6: 2024 | I6: Rule of Law: Governance estimate | J6: -1.3086297 | K6: -1.3287764 | L6: -1.3317055 | M6: -1.1105522 | N6: -1.0519682 | O6: -0.9475038 | P6: -1.0980135 | Q6: -1.1625439 | R6: -1.1944432 | S6: -1.1697408
A7: GOV03 | B7: 1. Governança e Estado de Direito | C7: WGI - Eficiência do Governo | D7: Worldwide Governance Indicators | E7: GE.EST | F7: Fonte oficial WGI 2025 | G7: 10/11 | H7: 2024 | I7: Government Effectiveness: Governance estimate | J7: -0.9378237 | K7: -0.9493847 | L7: -0.9681157 | M7: -0.9784602 | N7: -0.9116965 | O7: -1.0163604 | P7: -0.9347008 | Q7: -0.8325718 | R7: -0.8287026 | S7: -0.7851909
A8: GOV04 | B8: 1. Governança e Estado de Direito | C8: WGI - Estabilidade Política | D8: Worldwide Governance Indicators | E8: PV.EST | F8: Fonte oficial WGI 2025 | G8: 10/11 | H8: 2024 | I8: Political Stability and Absence of Violence/Terrorism: Governance estimate | J8: -0.5591026 | K8: -0.434628 | L8: -0.5372145 | M8: -0.4058117 | N8: -0.4207039 | O8: -0.6427634 | P8: -0.7936068 | Q8: -0.5414068 | R8: -0.3131654 | S8: -0.5735964
A9: GOV05 | B9: 1. Governança e Estado de Direito | C9: WGI - Qualidade Regulatória | D9: Worldwide Governance Indicators | E9: RQ.EST | F9: Fonte oficial WGI 2025 | G9: 10/11 | H9: 2024 | I9: Regulatory Quality: Governance estimate | J9: -1.0904945 | K9: -1.1804235 | L9: -1.1799885 | M9: -1.0624393 | N9: -0.9960854 | O9: -1.0388818 | P9: -0.8486184 | Q9: -0.8618821 | R9: -0.904342 | S9: -0.77302
A10: GOV06 | B10: 1. Governança e Estado de Direito | C10: WGI - Controlo da Corrupção | D10: Worldwide Governance Indicators | E10: CC.EST | F10: Fonte oficial WGI 2025 | G10: 10/11 | H10: 2024 | I10: Control of Corruption: Governance estimate | J10: -1.4857649 | K10: -1.4881942 | L10: -1.4208093 | M10: -1.181782 | N10: -0.9647988 | O10: -0.8918323 | P10: -0.6416506 | Q10: -0.6031537 | R10: -0.6242518 | S10: -0.6225793
A11: MAC01 | B11: 2. Estabilidade Macroeconómica | C11: Crescimento real do PIB | D11: Banco Mundial/WDI | E11: NY.GDP.MKTP.KD.ZG | F11: Fonte Banco Mundial API/CSV | G11: 10/11 | H11: 2024 | I11: GDP growth (annual %) | J11: 0.76317771 | K11: -1.7005304 | L11: -0.14939623 | M11: -0.59441123 | N11: -0.20468025 | O11: -4.0424472 | P11: 2.1027525 | Q11: 4.2160026 | R11: 1.2633081 | S11: 4.4239066
A12: MAC02 | B12: 2. Estabilidade Macroeconómica | C12: PIB per capita | D12: Banco Mundial/WDI | E12: NY.GDP.PCAP.CD | F12: Fonte Banco Mundial API/CSV | G12: 10/11 | H12: 2024 | I12: GDP per capita (current US$) | J12: 3641.7289 | K12: 2051.8146 | L12: 2790.7189 | M12: 2860.0936 | N12: 2493.6788 | O12: 1759.3562 | P12: 2303.9081 | Q12: 3682.1132 | R12: 2916.1366 | S12: 2665.8744
A13: MAC03 | B13: 2. Estabilidade Macroeconómica | C13: Inflação, preços ao consumidor | D13: Banco Mundial/WDI | E13: FP.CPI.TOTL.ZG | F13: Fonte Banco Mundial API/CSV | G13: 10/11 | H13: 2024 | I13: Inflation, consumer prices (annual %) | J13: 9.3559722 | K13: 30.694415 | L13: 29.84448 | M13: 19.628938 | N13: 17.080954 | O13: 22.271539 | P13: 25.754295 | Q13: 21.35529 | R13: 13.644102 | S13: 28.240495
A14: MAC04 | B14: 2. Estabilidade Macroeconómica | C14: Dívida pública do governo central | D14: Banco Mundial/WDI | E14: GC.DOD.TOTL.GD.ZS | F14: Sem valores Angola no período; fallback para série do ficheiro base | G14: 11/11 | H14: 2025 | I14: Central government debt, total (% of GDP) | J14: 50 | K14: 67 | L14: 60 | M14: 83 | N14: 101 | O14: 119 | P14: 74 | Q14: 56 | R14: 72 | S14: 60 | T14: 63
A15: MAC05 | B15: 2. Estabilidade Macroeconómica | C15: Saldo orçamental de caixa | D15: Banco Mundial/WDI | E15: GC.BAL.CASH.GD.ZS | F15: Sem valores Angola no período; fallback para série do ficheiro base | G15: 11/11 | H15: 2025 | I15: Cash surplus/deficit (% of GDP) | J15: -2 | K15: -3 | L15: 1.5 | M15: -0.5 | N15: 0.5 | O15: -5 | P15: 1.5 | Q15: 0.7 | R15: -1.9 | S15: -1.5 | T15: -1.65
A16: MAC06 | B16: 2. Estabilidade Macroeconómica | C16: Saldo da conta corrente | D16: Banco Mundial/WDI | E16: BN.CAB.XOKA.GD.ZS | F16: Fonte Banco Mundial API/CSV | G16: 10/11 | H16: 2024 | I16: Current account balance (% of GDP) | J16: -10.018075 | K16: -5.1524476 | L16: -0.75004756 | M16: 8.2698865 | N16: 6.363326 | O16: 1.4815318 | P16: 10.557441 | Q16: 8.9647752 | R16: 3.905087 | S16: 6.2474404
A17: MAC07 | B17: 2. Estabilidade Macroeconómica | C17: Reservas internacionais | D17: Banco Mundial/WDI | E17: FI.RES.TOTL.MO | F17: Fonte Banco Mundial API/CSV | G17: 10/11 | H17: 2024 | I17: Total reserves in months of imports | J17: 6.4820457 | K17: 9.0838712 | L17: 5.8181869 | M17: 5.4126402 | N17: 6.4250943 | O17: 8.0261477 | P17: 6.9491541 | Q17: 4.3768329 | R17: 5.0892711 | S17: 5.5137491
A18: MAC08 | B18: 2. Estabilidade Macroeconómica | C18: Receita fiscal | D18: Banco Mundial/WDI | E18: GC.TAX.TOTL.GD.ZS | F18: Fonte Banco Mundial API/CSV | G18: 10/11 | H18: 2024 | I18: Tax revenue (% of GDP) | J18: 9.7095139 | K18: 8.5757867 | L18: 8.0555378 | M18: 9.9288802 | N18: 11.288852 | O18: 20.517608 | P18: 10.70333 | Q18: 12.731812 | R18: 8.8691289 | S18: 7.7443637
A19: HUM01 | B19: 3. Capital Humano | C19: Índice de Desenvolvimento Humano | D19: PNUD/HDR / ficheiro base | F19: Série observada do ficheiro base | G19: 9/11 | H19: 2023 | J19: 0.591 | K19: 0.595 | L19: 0.597 | M19: 0.598 | N19: 0.597 | O19: 0.594 | P19: 0.59 | Q19: 0.591 | R19: 0.616
A20: HUM02 | B20: 3. Capital Humano | C20: Esperança de vida à nascença | D20: Banco Mundial/WDI | E20: SP.DYN.LE00.IN | F20: Fonte Banco Mundial API/CSV | G20: 10/11 | H20: 2024 | I20: Life expectancy at birth, total (years) | J20: 61.042 | K20: 61.619 | L20: 62.122 | M20: 62.622 | N20: 63.051 | O20: 63.116 | P20: 62.958 | Q20: 64.246 | R20: 64.617 | S20: 64.805
A21: HUM03 | B21: 3. Capital Humano | C21: Alfabetização adulta | D21: Banco Mundial/UNESCO | E21: SE.ADT.LITR.ZS | F21: Fonte Banco Mundial API/CSV | G21: 2/11 | H21: 2023 | I21: Literacy rate, adult total (% of people ages 15 and above) | J21: 66.239998 | R21: 68.18
A22: HUM04 | B22: 3. Capital Humano | C22: Conclusão do ensino primário | D22: Banco Mundial/UNESCO | E22: SE.PRM.CMPT.ZS | F22: Fonte Banco Mundial API/CSV | G22: 2/11 | H22: 2023 | I22: Primary completion rate, total (% of relevant age group) | P22: 60.025939 | R22: 47.855679
A23: HUM05 | B23: 3. Capital Humano | C23: Matrícula no ensino secundário | D23: Banco Mundial/UNESCO | E23: SE.SEC.ENRR | F23: Fonte Banco Mundial API/CSV | G23: 3/11 | H23: 2023 | I23: School enrollment, secondary (% gross) | K23: 54.416799 | P23: 53.135154 | R23: 51.483905
A24: HUM06 | B24: 3. Capital Humano | C24: Despesa pública em educação | D24: Banco Mundial/UNESCO | E24: SE.XPD.TOTL.GD.ZS | F24: Fonte Banco Mundial API/CSV | G24: 9/11 | H24: 2023 | I24: Government expenditure on education, total (% of GDP) | J24: 3.4868958 | K24: 2.7549366 | L24: 2.4668788 | M24: 2.183513 | N24: 2.0730644 | O24: 2.6674473 | P24: 2.2971969 | Q24: 2.385359 | R24: 2.5127366
A25: HUM07 | B25: 3. Capital Humano | C25: Mortalidade infantil | D25: Banco Mundial/WDI | E25: SP.DYN.IMRT.IN | F25: Fonte Banco Mundial API/CSV | G25: 10/11 | H25: 2024 | I25: Mortality rate, infant (per 1,000 live births) | J25: 38.8 | K25: 37.6 | L25: 36.7 | M25: 36 | N25: 35.5 | O25: 34.9 | P25: 34.4 | Q25: 33.7 | R25: 33 | S25: 32.1
A26: INC01 | B26: 4. Inclusão Social e Protecção | C26: Pobreza internacional | D26: Banco Mundial/PIP | E26: SI.POV.DDAY | F26: Fonte Banco Mundial API/CSV | G26: 1/11 | H26: 2018 | I26: Poverty headcount ratio at $3.00 a day (2021 PPP) (% of population) | M26: 39.3
A27: INC02 | B27: 4. Inclusão Social e Protecção | C27: Índice de Gini | D27: Banco Mundial/PIP | E27: SI.POV.GINI | F27: Fonte Banco Mundial API/CSV | G27: 1/11 | H27: 2018 | I27: Gini index | M27: 51.3
A28: INC03 | B28: 4. Inclusão Social e Protecção | C28: Rendimento dos 20% mais pobres | D28: Banco Mundial/PIP | E28: SI.DST.FRST.20 | F28: Fonte Banco Mundial API/CSV | G28: 1/11 | H28: 2018 | I28: Income share held by lowest 20% | M28: 3.8
A29: INC04 | B29: 4. Inclusão Social e Protecção | C29: Global Gender Gap Index | D29: WEF / ficheiro base | F29: Série observada do ficheiro base | G29: 10/11 | H29: 2025 | J29: 0.637 | K29: 0.643 | L29: 0.64 | M29: 0.633 | O29: 0.66 | P29: 0.657 | Q29: 0.638 | R29: 0.656 | S29: 0.668 | T29: 0.668
A30: INC05 | B30: 4. Inclusão Social e Protecção | C30: Participação feminina na força de trabalho | D30: Banco Mundial/OIT | E30: SL.TLF.CACT.FE.ZS | F30: Fonte Banco Mundial API/CSV | G30: 11/11 | H30: 2025 | I30: Labor force participation rate, female (% of female population ages 15+) (modeled ILO estimate) | J30: 73.933 | K30: 73.697 | L30: 73.461 | M30: 73.224 | N30: 72.985 | O30: 71.342 | P30: 74.695 | Q30: 74.018 | R30: 72.318 | S30: 72.359 | T30: 72.224
A31: INC06 | B31: 4. Inclusão Social e Protecção | C31: Mulheres no parlamento | D31: Banco Mundial/IPU | E31: SG.GEN.PARL.ZS | F31: Fonte Banco Mundial API/CSV | G31: 11/11 | H31: 2025 | I31: Proportion of seats held by women in national parliaments (%) | J31: 36.818182 | K31: 36.818182 | L31: 30.454545 | M31: 30.454545 | N31: 30 | O31: 30 | P31: 29.545455 | Q31: 33.636364 | R31: 33.636364 | S31: 39.545455 | T31: 39.090909
A32: INC07 | B32: 4. Inclusão Social e Protecção | C32: Jovens NEET | D32: Banco Mundial/OIT | E32: SL.UEM.NEET.ZS | F32: Fonte Banco Mundial API/CSV | G32: 6/11 | H32: 2024 | I32: Share of youth not in education, employment or training, total (% of youth population) | N32: 22.922 | O32: 27.286 | P32: 28.126 | Q32: 24.766 | R32: 21.383 | S32: 24.564
A33: INC08 | B33: 4. Inclusão Social e Protecção | C33: RNB per capita | D33: Banco Mundial/WDI | E33: NY.GNP.PCAP.CD | F33: Fonte Banco Mundial API/CSV | G33: 10/11 | H33: 2024 | I33: GNI per capita, Atlas method (current US$) | J33: 4450 | K33: 2910 | L33: 2400 | M33: 2270 | N33: 2440 | O33: 2020 | P33: 1990 | Q33: 2340 | R33: 2700 | S33: 2840
A34: INF01 | B34: 5. Infraestruturas e Serviços | C34: Acesso à eletricidade | D34: Banco Mundial/IEA | E34: EG.ELC.ACCS.ZS | F34: Fonte Banco Mundial API/CSV | G34: 9/11 | H34: 2023 | I34: Access to electricity (% of population) | J34: 42 | K34: 41.8 | L34: 42.9 | M34: 45.3 | N34: 45.6 | O34: 47 | P34: 48.2 | Q34: 48.5 | R34: 51.1
A35: INF02 | B35: 5. Infraestruturas e Serviços | C35: Perdas na rede elétrica | D35: Banco Mundial/IEA | E35: EG.ELC.LOSS.ZS | F35: Fonte Banco Mundial API/CSV | G35: 9/11 | H35: 2023 | I35: Electric power transmission and distribution losses (% of output) | J35: 11.27007 | K35: 11.26696 | L35: 11.258031 | M35: 11.264913 | N35: 11.262912 | O35: 11.266159 | P35: 11.262288 | Q35: 11.261682 | R35: 11.266798
A36: INF03 | B36: 5. Infraestruturas e Serviços | C36: Acesso a água potável básica | D36: Banco Mundial/JMP | E36: SH.H2O.BASW.ZS | F36: Fonte Banco Mundial API/CSV | G36: 10/11 | H36: 2024 | I36: People using at least basic drinking water services (% of population) | J36: 58.619631 | K36: 60.192062 | L36: 61.773512 | M36: 63.362791 | N36: 64.159911 | O36: 64.944031 | P36: 65.716258 | Q36: 66.476327 | R36: 67.224425 | S36: 67.960742
A37: INF04 | B37: 5. Infraestruturas e Serviços | C37: Acesso a saneamento básico | D37: Banco Mundial/JMP | E37: SH.STA.BASS.ZS | F37: Fonte Banco Mundial API/CSV | G37: 8/11 | H37: 2022 | I37: People using at least basic sanitation services (% of population) | J37: 46.683765 | K37: 47.555909 | L37: 48.423766 | M37: 49.286523 | N37: 49.547024 | O37: 49.801638 | P37: 50.051135 | Q37: 50.295136
A38: INF05 | B38: 5. Infraestruturas e Serviços | C38: Acesso a energia limpa para cozinhar | D38: Banco Mundial/OMS | E38: EG.CFT.ACCS.ZS | F38: Fonte Banco Mundial API/CSV | G38: 9/11 | H38: 2023 | I38: Access to clean fuels and technologies for cooking (% of population) | J38: 47 | K38: 48 | L38: 48.2 | M38: 48.8 | N38: 49.2 | O38: 49.4 | P38: 49.8 | Q38: 50 | R38: 50.2
A39: INF06 | B39: 5. Infraestruturas e Serviços | C39: Utilizadores de internet | D39: Banco Mundial/ITU | E39: IT.NET.USER.ZS | F39: Fonte Banco Mundial API/CSV | G39: 10/11 | H39: 2024 | I39: Individuals using the Internet (% of population) | J39: 22 | K39: 23.200001 | L39: 26 | M39: 29 | N39: 32.129398 | O39: 33.3209 | P39: 34.556499 | Q39: 35.838001 | R39: 37.885899 | S39: 40.7048
A40: INF07 | B40: 5. Infraestruturas e Serviços | C40: Subscrições móveis | D40: Banco Mundial/ITU | E40: IT.CEL.SETS.P2 | F40: Fonte Banco Mundial API/CSV | G40: 10/11 | H40: 2024 | I40: Mobile cellular subscriptions (per 100 people) | J40: 49.309722 | K40: 44.550227 | L40: 44.068209 | M40: 42.458878 | N40: 45.806531 | O40: 43.780432 | P40: 44.386869 | Q40: 66.600807 | R40: 70.051959 | S40: 69.703947
A41: INF08 | B41: 5. Infraestruturas e Serviços | C41: Banda larga fixa | D41: Banco Mundial/ITU | E41: IT.NET.BBND.P2 | F41: Fonte Banco Mundial API/CSV | G41: 10/11 | H41: 2024 | I41: Fixed broadband subscriptions (per 100 people) | J41: 0.54539421 | K41: 0.29031901 | L41: 0.32055405 | M41: 0.35006696 | N41: 0.36777043 | O41: 0.36326424 | P41: 0.3909253 | Q41: 0.38669816 | R41: 0.37366898 | S41: 0.36284524
...

Sheet Dados_Ajustados_v4
A1: Dados ajustados usados no cálculo
A2: Valores observados + estimativas permitidas pela metodologia. As fórmulas estão ligadas a Metodologia_v4!B12:B14.
A4: ID | B4: Dimensão | C4: Indicador | D4: Fonte | E4: Código/API | F4: Estado dados | G4: Cobertura observada | H4: Último ano obs. | I4: Nota | J4: 2015 | K4: 2016 | L4: 2017 | M4: 2018 | N4: 2019 | O4: 2020 | P4: 2021 | Q4: 2022 | R4: 2023 | S4: 2024 | T4: 2025
A5: GOV01 | B5: 1. Governança e Estado de Direito | C5: Índice de Percepção da Corrupção | D5: Transparency International / ficheiro base | F5: Série observada do ficheiro base | G5: 10/11 | H5: 2024 | I5: Referenciado pelas regras de Metodologia_v4 | J5: =IF(Dados_Observados_v4!J5<>"",Dados_Observados_v4!J5,IF(AND(Dados_Observados_v4!K5<>"",(2016-2015)<=Metodologia_v4!$B$14),Dados_Observados_v4!K5,"")) | K5: =IF(Dados_Observados_v4!K5<>"",Dados_Observados_v4!K5,IF(AND(Dados_Observados_v4!J5<>"",Dados_Observados_v4!L5<>"",(2017-2015-1)<=Metodologia_v4!$B$12),Dados_Observados_v4!J5+(Dados_Observados_v4!L5-Dados_Observados_v4!J5)*(2016-2015)/(2017-2015),IF(AND(Dados_Observados_v4!J5<>"",(2016-2015)<=Metodologia_v4!$B$13),Dados_Observados_v4!J5,IF(AND(Dados_Observados_v4!L5<>"",(2017-2016)<=Metodologia_v4!$B$14),Dados_Observados_v4!L5,"")))) | L5: =IF(Dados_Observados_v4!L5<>"",Dados_Observados_v4!L5,IF(AND(Dados_Observados_v4!K5<>"",Dados_Observados_v4!M5<>"",(2018-2016-1)<=Metodologia_v4!$B$12),Dados_Observados_v4!K5+(Dados_Observados_v4!M5-Dados_Observados_v4!K5)*(2017-2016)/(2018-2016),IF(AND(Dados_Observados_v4!K5<>"",(2017-2016)<=Metodologia_v4!$B$13),Dados_Observados_v4!K5,IF(AND(Dados_Observados_v4!M5<>"",(2018-2017)<=Metodologia_v4!$B$14),Dados_Observados_v4!M5,"")))) | M5: =IF(Dados_Observados_v4!M5<>"",Dados_Observados_v4!M5,IF(AND(Dados_Observados_v4!L5<>"",Dados_Observados_v4!N5<>"",(2019-2017-1)<=Metodologia_v4!$B$12),Dados_Observados_v4!L5+(Dados_Observados_v4!N5-Dados_Observados_v4!L5)*(2018-2017)/(2019-2017),IF(AND(Dados_Observados_v4!L5<>"",(2018-2017)<=Metodologia_v4!$B$13),Dados_Observados_v4!L5,IF(AND(Dados_Observados_v4!N5<>"",(2019-2018)<=Metodologia_v4!$B$14),Dados_Observados_v4!N5,"")))) | N5: =IF(Dados_Observados_v4!N5<>"",Dados_Observados_v4!N5,IF(AND(Dados_Observados_v4!M5<>"",Dados_Observados_v4!O5<>"",(2020-2018-1)<=Metodologia_v4!$B$12),Dados_Observados_v4!M5+(Dados_Observados_v4!O5-Dados_Observados_v4!M5)*(2019-2018)/(2020-2018),IF(AND(Dados_Observados_v4!M5<>"",(2019-2018)<=Metodologia_v4!$B$13),Dados_Observados_v4!M5,IF(AND(Dados_Observados_v4!O5<>"",(2020-2019)<=Metodologia_v4!$B$14),Dados_Observados_v4!O5,"")))) | O5: =IF(Dados_Observados_v4!O5<>"",Dados_Observados_v4!O5,IF(AND(Dados_Observados_v4!N5<>"",Dados_Observados_v4!P5<>"",(2021-2019-1)<=Metodologia_v4!$B$12),Dados_Observados_v4!N5+(Dados_Observados_v4!P5-Dados_Observados_v4!N5)*(2020-2019)/(2021-2019),IF(AND(Dados_Observados_v4!N5<>"",(2020-2019)<=Metodologia_v4!$B$13),Dados_Observados_v4!N5,IF(AND(Dados_Observados_v4!P5<>"",(2021-2020)<=Metodologia_v4!$B$14),Dados_Observados_v4!P5,"")))) | P5: =IF(Dados_Observados_v4!P5<>"",Dados_Observados_v4!P5,IF(AND(Dados_Observados_v4!O5<>"",Dados_Observados_v4!Q5<>"",(2022-2020-1)<=Metodologia_v4!$B$12),Dados_Observados_v4!O5+(Dados_Observados_v4!Q5-Dados_Observados_v4!O5)*(2021-2020)/(2022-2020),IF(AND(Dados_Observados_v4!O5<>"",(2021-2020)<=Metodologia_v4!$B$13),Dados_Observados_v4!O5,IF(AND(Dados_Observados_v4!Q5<>"",(2022-2021)<=Metodologia_v4!$B$14),Dados_Observados_v4!Q5,"")))) | Q5: =IF(Dados_Observados_v4!Q5<>"",Dados_Observados_v4!Q5,IF(AND(Dados_Observados_v4!P5<>"",Dados_Observados_v4!R5<>"",(2023-2021-1)<=Metodologia_v4!$B$12),Dados_Observados_v4!P5+(Dados_Observados_v4!R5-Dados_Observados_v4!P5)*(2022-2021)/(2023-2021),IF(AND(Dados_Observados_v4!P5<>"",(2022-2021)<=Metodologia_v4!$B$13),Dados_Observados_v4!P5,IF(AND(Dados_Observados_v4!R5<>"",(2023-2022)<=Metodologia_v4!$B$14),Dados_Observados_v4!R5,"")))) | R5: =IF(Dados_Observados_v4!R5<>"",Dados_Observados_v4!R5,IF(AND(Dados_Observados_v4!Q5<>"",Dados_Observados_v4!S5<>"",(2024-2022-1)<=Metodologia_v4!$B$12),Dados_Observados_v4!Q5+(Dados_Observados_v4!S5-Dados_Observados_v4!Q5)*(2023-2022)/(2024-2022),IF(AND(Dados_Observados_v4!Q5<>"",(2023-2022)<=Metodologia_v4!$B$13),Dados_Observados_v4!Q5,IF(AND(Dados_Observados_v4!S5<>"",(2024-2023)<=Metodologia_v4!$B$14),Dados_Observados_v4!S5,"")))) | S5: =IF(Dados_Observados_v4!S5<>"",Dados_Observados_v4!S5,IF(AND(Dados_Observados_v4!R5<>"",(2024-2023)<=Metodologia_v4!$B$13),Dados_Observados_v4!R5,"")) | T5: =IF(Dados_Observados_v4!T5<>"",Dados_Observados_v4!T5,IF(AND(Dados_Observados_v4!S5<>"",(2025-2024)<=Metodologia_v4!$B$13),Dados_Observados_v4!S5,""))
A6: GOV02 | B6: 1. Governança e Estado de Direito | C6: WGI - Estado de Direito | D6: Worldwide Governance Indicators | E6: RL.EST | F6: Fonte oficial WGI 2025 | G6: 10/11 | H6: 2024 | I6: Referenciado pelas regras de Metodologia_v4 | J6: =IF(Dados_Observados_v4!J6<>"",Dados_Observados_v4!J6,IF(AND(Dados_Observados_v4!K6<>"",(2016-2015)<=Metodologia_v4!$B$14),Dados_Observados_v4!K6,"")) | K6: =IF(Dados_Observados_v4!K6<>"",Dados_Observados_v4!K6,IF(AND(Dados_Observados_v4!J6<>"",Dados_Observados_v4!L6<>"",(2017-2015-1)<=Metodologia_v4!$B$12),Dados_Observados_v4!J6+(Dados_Observados_v4!L6-Dados_Observados_v4!J6)*(2016-2015)/(2017-2015),IF(AND(Dados_Observados_v4!J6<>"",(2016-2015)<=Metodologia_v4!$B$13),Dados_Observados_v4!J6,IF(AND(Dados_Observados_v4!L6<>"",(2017-2016)<=Metodologia_v4!$B$14),Dados_Observados_v4!L6,"")))) | L6: =IF(Dados_Observados_v4!L6<>"",Dados_Observados_v4!L6,IF(AND(Dados_Observados_v4!K6<>"",Dados_Observados_v4!M6<>"",(2018-2016-1)<=Metodologia_v4!$B$12),Dados_Observados_v4!K6+(Dados_Observados_v4!M6-Dados_Observados_v4!K6)*(2017-2016)/(2018-2016),IF(AND(Dados_Observados_v4!K6<>"",(2017-2016)<=Metodologia_v4!$B$13),Dados_Observados_v4!K6,IF(AND(Dados_Observados_v4!M6<>"",(2018-2017)<=Metodologia_v4!$B$14),Dados_Observados_v4!M6,"")))) | M6: =IF(Dados_Observados_v4!M6<>"",Dados_Observados_v4!M6,IF(AND(Dados_Observados_v4!L6<>"",Dados_Observados_v4!N6<>"",(2019-2017-1)<=Metodologia_v4!$B$12),Dados_Observados_v4!L6+(Dados_Observados_v4!N6-Dados_Observados_v4!L6)*(2018-2017)/(2019-2017),IF(AND(Dados_Observados_v4!L6<>"",(2018-2017)<=Metodologia_v4!$B$13),Dados_Observados_v4!L6,IF(AND(Dados_Observados_v4!N6<>"",(2019-2018)<=Metodologia_v4!$B$14),Dados_Observados_v4!N6,"")))) | N6: =IF(Dados_Observados_v4!N6<>"",Dados_Observados_v4!N6,IF(AND(Dados_Observados_v4!M6<>"",Dados_Observados_v4!O6<>"",(2020-2018-1)<=Metodologia_v4!$B$12),Dados_Observados_v4!M6+(Dados_Observados_v4!O6-Dados_Observados_v4!M6)*(2019-2018)/(2020-2018),IF(AND(Dados_Observados_v4!M6<>"",(2019-2018)<=Metodologia_v4!$B$13),Dados_Observados_v4!M6,IF(AND(Dados_Observados_v4!O6<>"",(2020-2019)<=Metodologia_v4!$B$14),Dados_Observados_v4!O6,"")))) | O6: =IF(Dados_Observados_v4!O6<>"",Dados_Observados_v4!O6,IF(AND(Dados_Observados_v4!N6<>"",Dados_Observados_v4!P6<>"",(2021-2019-1)<=Metodologia_v4!$B$12),Dados_Observados_v4!N6+(Dados_Observados_v4!P6-Dados_Observados_v4!N6)*(2020-2019)/(2021-2019),IF(AND(Dados_Observados_v4!N6<>"",(2020-2019)<=Metodologia_v4!$B$13),Dados_Observados_v4!N6,IF(AND(Dados_Observados_v4!P6<>"",(2021-2020)<=Metodologia_v4!$B$14),Dados_Observados_v4!P6,"")))) | P6: =IF(Dados_Observados_v4!P6<>"",Dados_Observados_v4!P6,IF(AND(Dados_Observados_v4!O6<>"",Dados_Observados_v4!Q6<>"",(2022-2020-1)<=Metodologia_v4!$B$12),Dados_Observados_v4!O6+(Dados_Observados_v4!Q6-Dados_Observados_v4!O6)*(2021-2020)/(2022-2020),IF(AND(Dados_Observados_v4!O6<>"",(2021-2020)<=Metodologia_v4!$B$13),Dados_Observados_v4!O6,IF(AND(Dados_Observados_v4!Q6<>"",(2022-2021)<=Metodologia_v4!$B$14),Dados_Observados_v4!Q6,"")))) | Q6: =IF(Dados_Observados_v4!Q6<>"",Dados_Observados_v4!Q6,IF(AND(Dados_Observados_v4!P6<>"",Dados_Observados_v4!R6<>"",(2023-2021-1)<=Metodologia_v4!$B$12),Dados_Observados_v4!P6+(Dados_Observados_v4!R6-Dados_Observados_v4!P6)*(2022-2021)/(2023-2021),IF(AND(Dados_Observados_v4!P6<>"",(2022-2021)<=Metodologia_v4!$B$13),Dados_Observados_v4!P6,IF(AND(Dados_Observados_v4!R6<>"",(2023-2022)<=Metodologia_v4!$B$14),Dados_Observados_v4!R6,"")))) | R6: =IF(Dados_Observados_v4!R6<>"",Dados_Observados_v4!R6,IF(AND(Dados_Observados_v4!Q6<>"",Dados_Observados_v4!S6<>"",(2024-2022-1)<=Metodologia_v4!$B$12),Dados_Observados_v4!Q6+(Dados_Observados_v4!S6-Dados_Observados_v4!Q6)*(2023-2022)/(2024-2022),IF(AND(Dados_Observados_v4!Q6<>"",(2023-2022)<=Metodologia_v4!$B$13),Dados_Observados_v4!Q6,IF(AND(Dados_Observados_v4!S6<>"",(2024-2023)<=Metodologia_v4!$B$14),Dados_Observados_v4!S6,"")))) | S6: =IF(Dados_Observados_v4!S6<>"",Dados_Observados_v4!S6,IF(AND(Dados_Observados_v4!R6<>"",(2024-2023)<=Metodologia_v4!$B$13),Dados_Observados_v4!R6,"")) | T6: =IF(Dados_Observados_v4!T6<>"",Dados_Observados_v4!T6,IF(AND(Dados_Observados_v4!S6<>"",(2025-2024)<=Metodologia_v4!$B$13),Dados_Observados_v4!S6,""))
A7: GOV03 | B7: 1. Governança e Estado de Direito | C7: WGI - Eficiência do Governo | D7: Worldwide Governance Indicators | E7: GE.EST | F7: Fonte oficial WGI 2025 | G7: 10/11 | H7: 2024 | I7: Referenciado pelas regras de Metodologia_v4 | J7: =IF(Dados_Observados_v4!J7<>"",Dados_Observados_v4!J7,IF(AND(Dados_Observados_v4!K7<>"",(2016-2015)<=Metodologia_v4!$B$14),Dados_Observados_v4!K7,"")) | K7: =IF(Dados_Observados_v4!K7<>"",Dados_Observados_v4!K7,IF(AND(Dados_Observados_v4!J7<>"",Dados_Observados_v4!L7<>"",(2017-2015-1)<=Metodologia_v4!$B$12),Dados_Observados_v4!J7+(Dados_Observados_v4!L7-Dados_Observados_v4!J7)*(2016-2015)/(2017-2015),IF(AND(Dados_Observados_v4!J7<>"",(2016-2015)<=Metodologia_v4!$B$13),Dados_Observados_v4!J7,IF(AND(Dados_Observados_v4!L7<>"",(2017-2016)<=Metodologia_v4!$B$14),Dados_Observados_v4!L7,"")))) | L7: =IF(Dados_Observados_v4!L7<>"",Dados_Observados_v4!L7,IF(AND(Dados_Observados_v4!K7<>"",Dados_Observados_v4!M7<>"",(2018-2016-1)<=Metodologia_v4!$B$12),Dados_Observados_v4!K7+(Dados_Observados_v4!M7-Dados_Observados_v4!K7)*(2017-2016)/(2018-2016),IF(AND(Dados_Observados_v4!K7<>"",(2017-2016)<=Metodologia_v4!$B$13),Dados_Observados_v4!K7,IF(AND(Dados_Observados_v4!M7<>"",(2018-2017)<=Metodologia_v4!$B$14),Dados_Observados_v4!M7,"")))) | M7: =IF(Dados_Observados_v4!M7<>"",Dados_Observados_v4!M7,IF(AND(Dados_Observados_v4!L7<>"",Dados_Observados_v4!N7<>"",(2019-2017-1)<=Metodologia_v4!$B$12),Dados_Observados_v4!L7+(Dados_Observados_v4!N7-Dados_Observados_v4!L7)*(2018-2017)/(2019-2017),IF(AND(Dados_Observados_v4!L7<>"",(2018-2017)<=Metodologia_v4!$B$13),Dados_Observados_v4!L7,IF(AND(Dados_Observados_v4!N7<>"",(2019-2018)<=Metodologia_v4!$B$14),Dados_Observados_v4!N7,"")))) | N7: =IF(Dados_Observados_v4!N7<>"",Dados_Observados_v4!N7,IF(AND(Dados_Observados_v4!M7<>"",Dados_Observados_v4!O7<>"",(2020-2018-1)<=Metodologia_v4!$B$12),Dados_Observados_v4!M7+(Dados_Observados_v4!O7-Dados_Observados_v4!M7)*(2019-2018)/(2020-2018),IF(AND(Dados_Observados_v4!M7<>"",(2019-2018)<=Metodologia_v4!$B$13),Dados_Observados_v4!M7,IF(AND(Dados_Observados_v4!O7<>"",(2020-2019)<=Metodologia_v4!$B$14),Dados_Observados_v4!O7,"")))) | O7: =IF(Dados_Observados_v4!O7<>"",Dados_Observados_v4!O7,IF(AND(Dados_Observados_v4!N7<>"",Dados_Observados_v4!P7<>"",(2021-2019-1)<=Metodologia_v4!$B$12),Dados_Observados_v4!N7+(Dados_Observados_v4!P7-Dados_Observados_v4!N7)*(2020-2019)/(2021-2019),IF(AND(Dados_Observados_v4!N7<>"",(2020-2019)<=Metodologia_v4!$B$13),Dados_Observados_v4!N7,IF(AND(Dados_Observados_v4!P7<>"",(2021-2020)<=Metodologia_v4!$B$14),Dados_Observados_v4!P7,"")))) | P7: =IF(Dados_Observados_v4!P7<>"",Dados_Observados_v4!P7,IF(AND(Dados_Observados_v4!O7<>"",Dados_Observados_v4!Q7<>"",(2022-2020-1)<=Metodologia_v4!$B$12),Dados_Observados_v4!O7+(Dados_Observados_v4!Q7-Dados_Observados_v4!O7)*(2021-2020)/(2022-2020),IF(AND(Dados_Observados_v4!O7<>"",(2021-2020)<=Metodologia_v4!$B$13),Dados_Observados_v4!O7,IF(AND(Dados_Observados_v4!Q7<>"",(2022-2021)<=Metodologia_v4!$B$14),Dados_Observados_v4!Q7,"")))) | Q7: =IF(Dados_Observados_v4!Q7<>"",Dados_Observados_v4!Q7,IF(AND(Dados_Observados_v4!P7<>"",Dados_Observados_v4!R7<>"",(2023-2021-1)<=Metodologia_v4!$B$12),Dados_Observados_v4!P7+(Dados_Observados_v4!R7-Dados_Observados_v4!P7)*(2022-2021)/(2023-2021),IF(AND(Dados_Observados_v4!P7<>"",(2022-2021)<=Metodologia_v4!$B$13),Dados_Observados_v4!P7,IF(AND(Dados_Observados_v4!R7<>"",(2023-2022)<=Metodologia_v4!$B$14),Dados_Observados_v4!R7,"")))) | R7: =IF(Dados_Observados_v4!R7<>"",Dados_Observados_v4!R7,IF(AND(Dados_Observados_v4!Q7<>"",Dados_Observados_v4!S7<>"",(2024-2022-1)<=Metodologia_v4!$B$12),Dados_Observados_v4!Q7+(Dados_Observados_v4!S7-Dados_Observados_v4!Q7)*(2023-2022)/(2024-2022),IF(AND(Dados_Observados_v4!Q7<>"",(2023-2022)<=Metodologia_v4!$B$13),Dados_Observados_v4!Q7,IF(AND(Dados_Observados_v4!S7<>"",(2024-2023)<=Metodologia_v4!$B$14),Dados_Observados_v4!S7,"")))) | S7: =IF(Dados_Observados_v4!S7<>"",Dados_Observados_v4!S7,IF(AND(Dados_Observados_v4!R7<>"",(2024-2023)<=Metodologia_v4!$B$13),Dados_Observados_v4!R7,"")) | T7: =IF(Dados_Observados_v4!T7<>"",Dados_Observados_v4!T7,IF(AND(Dados_Observados_v4!S7<>"",(2025-2024)<=Metodologia_v4!$B$13),Dados_Observados_v4!S7,""))
A8: GOV04 | B8: 1. Governança e Estado de Direito | C8: WGI - Estabilidade Política | D8: Worldwide Governance Indicators | E8: PV.EST | F8: Fonte oficial WGI 2025 | G8: 10/11 | H8: 2024 | I8: Referenciado pelas regras de Metodologia_v4 | J8: =IF(Dados_Observados_v4!J8<>"",Dados_Observados_v4!J8,IF(AND(Dados_Observados_v4!K8<>"",(2016-2015)<=Metodologia_v4!$B$14),Dados_Observados_v4!K8,"")) | K8: =IF(Dados_Observados_v4!K8<>"",Dados_Observados_v4!K8,IF(AND(Dados_Observados_v4!J8<>"",Dados_Observados_v4!L8<>"",(2017-2015-1)<=Metodologia_v4!$B$12),Dados_Observados_v4!J8+(Dados_Observados_v4!L8-Dados_Observados_v4!J8)*(2016-2015)/(2017-2015),IF(AND(Dados_Observados_v4!J8<>"",(2016-2015)<=Metodologia_v4!$B$13),Dados_Observados_v4!J8,IF(AND(Dados_Observados_v4!L8<>"",(2017-2016)<=Metodologia_v4!$B$14),Dados_Observados_v4!L8,"")))) | L8: =IF(Dados_Observados_v4!L8<>"",Dados_Observados_v4!L8,IF(AND(Dados_Observados_v4!K8<>"",Dados_Observados_v4!M8<>"",(2018-2016-1)<=Metodologia_v4!$B$12),Dados_Observados_v4!K8+(Dados_Observados_v4!M8-Dados_Observados_v4!K8)*(2017-2016)/(2018-2016),IF(AND(Dados_Observados_v4!K8<>"",(2017-2016)<=Metodologia_v4!$B$13),Dados_Observados_v4!K8,IF(AND(Dados_Observados_v4!M8<>"",(2018-2017)<=Metodologia_v4!$B$14),Dados_Observados_v4!M8,"")))) | M8: =IF(Dados_Observados_v4!M8<>"",Dados_Observados_v4!M8,IF(AND(Dados_Observados_v4!L8<>"",Dados_Observados_v4!N8<>"",(2019-2017-1)<=Metodologia_v4!$B$12),Dados_Observados_v4!L8+(Dados_Observados_v4!N8-Dados_Observados_v4!L8)*(2018-2017)/(2019-2017),IF(AND(Dados_Observados_v4!L8<>"",(2018-2017)<=Metodologia_v4!$B$13),Dados_Observados_v4!L8,IF(AND(Dados_Observados_v4!N8<>"",(2019-2018)<=Metodologia_v4!$B$14),Dados_Observados_v4!N8,"")))) | N8: =IF(Dados_Observados_v4!N8<>"",Dados_Observados_v4!N8,IF(AND(Dados_Observados_v4!M8<>"",Dados_Observados_v4!O8<>"",(2020-2018-1)<=Metodologia_v4!$B$12),Dados_Observados_v4!M8+(Dados_Observados_v4!O8-Dados_Observados_v4!M8)*(2019-2018)/(2020-2018),IF(AND(Dados_Observados_v4!M8<>"",(2019-2018)<=Metodologia_v4!$B$13),Dados_Observados_v4!M8,IF(AND(Dados_Observados_v4!O8<>"",(2020-2019)<=Metodologia_v4!$B$14),Dados_Observados_v4!O8,"")))) | O8: =IF(Dados_Observados_v4!O8<>"",Dados_Observados_v4!O8,IF(AND(Dados_Observados_v4!N8<>"",Dados_Observados_v4!P8<>"",(2021-2019-1)<=Metodologia_v4!$B$12),Dados_Observados_v4!N8+(Dados_Observados_v4!P8-Dados_Observados_v4!N8)*(2020-2019)/(2021-2019),IF(AND(Dados_Observados_v4!N8<>"",(2020-2019)<=Metodologia_v4!$B$13),Dados_Observados_v4!N8,IF(AND(Dados_Observados_v4!P8<>"",(2021-2020)<=Metodologia_v4!$B$14),Dados_Observados_v4!P8,"")))) | P8: =IF(Dados_Observados_v4!P8<>"",Dados_Observados_v4!P8,IF(AND(Dados_Observados_v4!O8<>"",Dados_Observados_v4!Q8<>"",(2022-2020-1)<=Metodologia_v4!$B$12),Dados_Observados_v4!O8+(Dados_Observados_v4!Q8-Dados_Observados_v4!O8)*(2021-2020)/(2022-2020),IF(AND(Dados_Observados_v4!O8<>"",(2021-2020)<=Metodologia_v4!$B$13),Dados_Observados_v4!O8,IF(AND(Dados_Observados_v4!Q8<>"",(2022-2021)<=Metodologia_v4!$B$14),Dados_Observados_v4!Q8,"")))) | Q8: =IF(Dados_Observados_v4!Q8<>"",Dados_Observados_v4!Q8,IF(AND(Dados_Observados_v4!P8<>"",Dados_Observados_v4!R8<>"",(2023-2021-1)<=Metodologia_v4!$B$12),Dados_Observados_v4!P8+(Dados_Observados_v4!R8-Dados_Observados_v4!P8)*(2022-2021)/(2023-2021),IF(AND(Dados_Observados_v4!P8<>"",(2022-2021)<=Metodologia_v4!$B$13),Dados_Observados_v4!P8,IF(AND(Dados_Observados_v4!R8<>"",(2023-2022)<=Metodologia_v4!$B$14),Dados_Observados_v4!R8,"")))) | R8: =IF(Dados_Observados_v4!R8<>"",Dados_Observados_v4!R8,IF(AND(Dados_Observados_v4!Q8<>"",Dados_Observados_v4!S8<>"",(2024-2022-1)<=Metodologia_v4!$B$12),Dados_Observados_v4!Q8+(Dados_Observados_v4!S8-Dados_Observados_v4!Q8)*(2023-2022)/(2024-2022),IF(AND(Dados_Observados_v4!Q8<>"",(2023-2022)<=Metodologia_v4!$B$13),Dados_Observados_v4!Q8,IF(AND(Dados_Observados_v4!S8<>"",(2024-2023)<=Metodologia_v4!$B$14),Dados_Observados_v4!S8,"")))) | S8: =IF(Dados_Observados_v4!S8<>"",Dados_Observados_v4!S8,IF(AND(Dados_Observados_v4!R8<>"",(2024-2023)<=Metodologia_v4!$B$13),Dados_Observados_v4!R8,"")) | T8: =IF(Dados_Observados_v4!T8<>"",Dados_Observados_v4!T8,IF(AND(Dados_Observados_v4!S8<>"",(2025-2024)<=Metodologia_v4!$B$13),Dados_Observados_v4!S8,""))
A9: GOV05 | B9: 1. Governança e Estado de Direito | C9: WGI - Qualidade Regulatória | D9: Worldwide Governance Indicators | E9: RQ.EST | F9: Fonte oficial WGI 2025 | G9: 10/11 | H9: 2024 | I9: Referenciado pelas regras de Metodologia_v4 | J9: =IF(Dados_Observados_v4!J9<>"",Dados_Observados_v4!J9,IF(AND(Dados_Observados_v4!K9<>"",(2016-2015)<=Metodologia_v4!$B$14),Dados_Observados_v4!K9,"")) | K9: =IF(Dados_Observados_v4!K9<>"",Dados_Observados_v4!K9,IF(AND(Dados_Observados_v4!J9<>"",Dados_Observados_v4!L9<>"",(2017-2015-1)<=Metodologia_v4!$B$12),Dados_Observados_v4!J9+(Dados_Observados_v4!L9-Dados_Observados_v4!J9)*(2016-2015)/(2017-2015),IF(AND(Dados_Observados_v4!J9<>"",(2016-2015)<=Metodologia_v4!$B$13),Dados_Observados_v4!J9,IF(AND(Dados_Observados_v4!L9<>"",(2017-2016)<=Metodologia_v4!$B$14),Dados_Observados_v4!L9,"")))) | L9: =IF(Dados_Observados_v4!L9<>"",Dados_Observados_v4!L9,IF(AND(Dados_Observados_v4!K9<>"",Dados_Observados_v4!M9<>"",(2018-2016-1)<=Metodologia_v4!$B$12),Dados_Observados_v4!K9+(Dados_Observados_v4!M9-Dados_Observados_v4!K9)*(2017-2016)/(2018-2016),IF(AND(Dados_Observados_v4!K9<>"",(2017-2016)<=Metodologia_v4!$B$13),Dados_Observados_v4!K9,IF(AND(Dados_Observados_v4!M9<>"",(2018-2017)<=Metodologia_v4!$B$14),Dados_Observados_v4!M9,"")))) | M9: =IF(Dados_Observados_v4!M9<>"",Dados_Observados_v4!M9,IF(AND(Dados_Observados_v4!L9<>"",Dados_Observados_v4!N9<>"",(2019-2017-1)<=Metodologia_v4!$B$12),Dados_Observados_v4!L9+(Dados_Observados_v4!N9-Dados_Observados_v4!L9)*(2018-2017)/(2019-2017),IF(AND(Dados_Observados_v4!L9<>"",(2018-2017)<=Metodologia_v4!$B$13),Dados_Observados_v4!L9,IF(AND(Dados_Observados_v4!N9<>"",(2019-2018)<=Metodologia_v4!$B$14),Dados_Observados_v4!N9,"")))) | N9: =IF(Dados_Observados_v4!N9<>"",Dados_Observados_v4!N9,IF(AND(Dados_Observados_v4!M9<>"",Dados_Observados_v4!O9<>"",(2020-2018-1)<=Metodologia_v4!$B$12),Dados_Observados_v4!M9+(Dados_Observados_v4!O9-Dados_Observados_v4!M9)*(2019-2018)/(2020-2018),IF(AND(Dados_Observados_v4!M9<>"",(2019-2018)<=Metodologia_v4!$B$13),Dados_Observados_v4!M9,IF(AND(Dados_Observados_v4!O9<>"",(2020-2019)<=Metodologia_v4!$B$14),Dados_Observados_v4!O9,"")))) | O9: =IF(Dados_Observados_v4!O9<>"",Dados_Observados_v4!O9,IF(AND(Dados_Observados_v4!N9<>"",Dados_Observados_v4!P9<>"",(2021-2019-1)<=Metodologia_v4!$B$12),Dados_Observados_v4!N9+(Dados_Observados_v4!P9-Dados_Observados_v4!N9)*(2020-2019)/(2021-2019),IF(AND(Dados_Observados_v4!N9<>"",(2020-2019)<=Metodologia_v4!$B$13),Dados_Observados_v4!N9,IF(AND(Dados_Observados_v4!P9<>"",(2021-2020)<=Metodologia_v4!$B$14),Dados_Observados_v4!P9,"")))) | P9: =IF(Dados_Observados_v4!P9<>"",Dados_Observados_v4!P9,IF(AND(Dados_Observados_v4!O9<>"",Dados_Observados_v4!Q9<>"",(2022-2020-1)<=Metodologia_v4!$B$12),Dados_Observados_v4!O9+(Dados_Observados_v4!Q9-Dados_Observados_v4!O9)*(2021-2020)/(2022-2020),IF(AND(Dados_Observados_v4!O9<>"",(2021-2020)<=Metodologia_v4!$B$13),Dados_Observados_v4!O9,IF(AND(Dados_Observados_v4!Q9<>"",(2022-2021)<=Metodologia_v4!$B$14),Dados_Observados_v4!Q9,"")))) | Q9: =IF(Dados_Observados_v4!Q9<>"",Dados_Observados_v4!Q9,IF(AND(Dados_Observados_v4!P9<>"",Dados_Observados_v4!R9<>"",(2023-2021-1)<=Metodologia_v4!$B$12),Dados_Observados_v4!P9+(Dados_Observados_v4!R9-Dados_Observados_v4!P9)*(2022-2021)/(2023-2021),IF(AND(Dados_Observados_v4!P9<>"",(2022-2021)<=Metodologia_v4!$B$13),Dados_Observados_v4!P9,IF(AND(Dados_Observados_v4!R9<>"",(2023-2022)<=Metodologia_v4!$B$14),Dados_Observados_v4!R9,"")))) | R9: =IF(Dados_Observados_v4!R9<>"",Dados_Observados_v4!R9,IF(AND(Dados_Observados_v4!Q9<>"",Dados_Observados_v4!S9<>"",(2024-2022-1)<=Metodologia_v4!$B$12),Dados_Observados_v4!Q9+(Dados_Observados_v4!S9-Dados_Observados_v4!Q9)*(2023-2022)/(2024-2022),IF(AND(Dados_Observados_v4!Q9<>"",(2023-2022)<=Metodologia_v4!$B$13),Dados_Observados_v4!Q9,IF(AND(Dados_Observados_v4!S9<>"",(2024-2023)<=Metodologia_v4!$B$14),Dados_Observados_v4!S9,"")))) | S9: =IF(Dados_Observados_v4!S9<>"",Dados_Observados_v4!S9,IF(AND(Dados_Observados_v4!R9<>"",(2024-2023)<=Metodologia_v4!$B$13),Dados_Observados_v4!R9,"")) | T9: =IF(Dados_Observados_v4!T9<>"",Dados_Observados_v4!T9,IF(AND(Dados_Observados_v4!S9<>"",(2025-2024)<=Metodologia_v4!$B$13),Dados_Observados_v4!S9,""))
A10: GOV06 | B10: 1. Governança e Estado de Direito | C10: WGI - Controlo da Corrupção | D10: Worldwide Governance Indicators | E10: CC.EST | F10: Fonte oficial WGI 2025 | G10: 10/11 | H10: 2024 | I10: Referenciado pelas regras de Metodologia_v4 | J10: =IF(Dados_Observados_v4!J10<>"",Dados_Observados_v4!J10,IF(AND(Dados_Observados_v4!K10<>"",(2016-2015)<=Metodologia_v4!$B$14),Dados_Observados_v4!K10,"")) | K10: =IF(Dados_Observados_v4!K10<>"",Dados_Observados_v4!K10,IF(AND(Dados_Observados_v4!J10<>"",Dados_Observados_v4!L10<>"",(2017-2015-1)<=Metodologia_v4!$B$12),Dados_Observados_v4!J10+(Dados_Observados_v4!L10-Dados_Observados_v4!J10)*(2016-2015)/(2017-2015),IF(AND(Dados_Observados_v4!J10<>"",(2016-2015)<=Metodologia_v4!$B$13),Dados_Observados_v4!J10,IF(AND(Dados_Observados_v4!L10<>"",(2017-2016)<=Metodologia_v4!$B$14),Dados_Observados_v4!L10,"")))) | L10: =IF(Dados_Observados_v4!L10<>"",Dados_Observados_v4!L10,IF(AND(Dados_Observados_v4!K10<>"",Dados_Observados_v4!M10<>"",(2018-2016-1)<=Metodologia_v4!$B$12),Dados_Observados_v4!K10+(Dados_Observados_v4!M10-Dados_Observados_v4!K10)*(2017-2016)/(2018-2016),IF(AND(Dados_Observados_v4!K10<>"",(2017-2016)<=Metodologia_v4!$B$13),Dados_Observados_v4!K10,IF(AND(Dados_Observados_v4!M10<>"",(2018-2017)<=Metodologia_v4!$B$14),Dados_Observados_v4!M10,"")))) | M10: =IF(Dados_Observados_v4!M10<>"",Dados_Observados_v4!M10,IF(AND(Dados_Observados_v4!L10<>"",Dados_Observados_v4!N10<>"",(2019-2017-1)<=Metodologia_v4!$B$12),Dados_Observados_v4!L10+(Dados_Observados_v4!N10-Dados_Observados_v4!L10)*(2018-2017)/(2019-2017),IF(AND(Dados_Observados_v4!L10<>"",(2018-2017)<=Metodologia_v4!$B$13),Dados_Observados_v4!L10,IF(AND(Dados_Observados_v4!N10<>"",(2019-2018)<=Metodologia_v4!$B$14),Dados_Observados_v4!N10,"")))) | N10: =IF(Dados_Observados_v4!N10<>"",Dados_Observados_v4!N10,IF(AND(Dados_Observados_v4!M10<>"",Dados_Observados_v4!O10<>"",(2020-2018-1)<=Metodologia_v4!$B$12),Dados_Observados_v4!M10+(Dados_Observados_v4!O10-Dados_Observados_v4!M10)*(2019-2018)/(2020-2018),IF(AND(Dados_Observados_v4!M10<>"",(2019-2018)<=Metodologia_v4!$B$13),Dados_Observados_v4!M10,IF(AND(Dados_Observados_v4!O10<>"",(2020-2019)<=Metodologia_v4!$B$14),Dados_Observados_v4!O10,"")))) | O10: =IF(Dados_Observados_v4!O10<>"",Dados_Observados_v4!O10,IF(AND(Dados_Observados_v4!N10<>"",Dados_Observados_v4!P10<>"",(2021-2019-1)<=Metodologia_v4!$B$12),Dados_Observados_v4!N10+(Dados_Observados_v4!P10-Dados_Observados_v4!N10)*(2020-2019)/(2021-2019),IF(AND(Dados_Observados_v4!N10<>"",(2020-2019)<=Metodologia_v4!$B$13),Dados_Observados_v4!N10,IF(AND(Dados_Observados_v4!P10<>"",(2021-2020)<=Metodologia_v4!$B$14),Dados_Observados_v4!P10,"")))) | P10: =IF(Dados_Observados_v4!P10<>"",Dados_Observados_v4!P10,IF(AND(Dados_Observados_v4!O10<>"",Dados_Observados_v4!Q10<>"",(2022-2020-1)<=Metodologia_v4!$B$12),Dados_Observados_v4!O10+(Dados_Observados_v4!Q10-Dados_Observados_v4!O10)*(2021-2020)/(2022-2020),IF(AND(Dados_Observados_v4!O10<>"",(2021-2020)<=Metodologia_v4!$B$13),Dados_Observados_v4!O10,IF(AND(Dados_Observados_v4!Q10<>"",(2022-2021)<=Metodologia_v4!$B$14),Dados_Observados_v4!Q10,"")))) | Q10: =IF(Dados_Observados_v4!Q10<>"",Dados_Observados_v4!Q10,IF(AND(Dados_Observados_v4!P10<>"",Dados_Observados_v4!R10<>"",(2023-2021-1)<=Metodologia_v4!$B$12),Dados_Observados_v4!P10+(Dados_Observados_v4!R10-Dados_Observados_v4!P10)*(2022-2021)/(2023-2021),IF(AND(Dados_Observados_v4!P10<>"",(2022-2021)<=Metodologia_v4!$B$13),Dados_Observados_v4!P10,IF(AND(Dados_Observados_v4!R10<>"",(2023-2022)<=Metodologia_v4!$B$14),Dados_Observados_v4!R10,"")))) | R10: =IF(Dados_Observados_v4!R10<>"",Dados_Observados_v4!R10,IF(AND(Dados_Observados_v4!Q10<>"",Dados_Observados_v4!S10<>"",(2024-2022-1)<=Metodologia_v4!$B$12),Dados_Observados_v4!Q10+(Dados_Observados_v4!S10-Dados_Observados_v4!Q10)*(2023-2022)/(2024-2022),IF(AND(Dados_Observados_v4!Q10<>"",(2023-2022)<=Metodologia_v4!$B$13),Dados_Observados_v4!Q10,IF(AND(Dados_Observados_v4!S10<>"",(2024-2023)<=Metodologia_v4!$B$14),Dados_Observados_v4!S10,"")))) | S10: =IF(Dados_Observados_v4!S10<>"",Dados_Observados_v4!S10,IF(AND(Dados_Observados_v4!R10<>"",(2024-2023)<=Metodologia_v4!$B$13),Dados_Observados_v4!R10,"")) | T10: =IF(Dados_Observados_v4!T10<>"",Dados_Observados_v4!T10,IF(AND(Dados_Observados_v4!S10<>"",(2025-2024)<=Metodologia_v4!$B$13),Dados_Observados_v4!S10,""))
