Workbook

Sheet 00_Painel
B2: ÍNDICE GLOBAL DE DESENVOLVIMENTO DE ANGOLA (IGDA-BDA) — Selecção Final
B3: ="Período 2015–2025 · "&TEXT(SUMPRODUCT(('01_Criterios'!$C$26:$C$36=1)*1),"0")&" dimensões activas · "&TEXT(SUM('01_Criterios'!$H$26:$H$36),"0")&" indicadores seleccionados · selecção "&LOWER('01_Criterios'!$C$18) -> Período 2015–2025 · 8 dimensões activas · 41 indicadores seleccionados · selecção automática
B5: INDICADORES-CHAVE
B7: =IFERROR(LOOKUP(9.99E+307,'07_Subindices'!F18:P18),"–") -> 46.432549 | E7: =IFERROR(INDEX('07_Subindices'!F18:P18,MATCH(TRUE,INDEX(ISNUMBER('07_Subindices'!F18:P18),0),0)),"–") -> 43.248684 | H7: =IF('07_Subindices'!S18="","–",'07_Subindices'!S18) -> 3.1838649 | K7: =IFERROR(INDEX('07_Subindices'!$A$5:$A$15,MATCH(MAX('07_Subindices'!$T$5:$T$15),'07_Subindices'!$T$5:$T$15,0)),"–") -> Mercado Trabalho | N7: =IFERROR(INDEX('07_Subindices'!$A$5:$A$15,MATCH(MIN('07_Subindices'!$T$5:$T$15),'07_Subindices'!$T$5:$T$15,0)),"–") -> Diversificação
B9: ="IGDA "&IFERROR(LOOKUP(2,1/ISNUMBER('07_Subindices'!F18:P18),'07_Subindices'!$F$4:$P$4),"")&" (último ano)" -> IGDA 2025 (último ano) | E9: ="IGDA "&IFERROR(INDEX('07_Subindices'!$F$4:$P$4,MATCH(TRUE,INDEX(ISNUMBER('07_Subindices'!F18:P18),0),0)),"")&" (primeiro ano)" -> IGDA 2015 (primeiro ano) | H9: ="Variação no período (p.p.)" -> Variação no período (p.p.) | K9: ="Melhor dimensão (último ano)" -> Melhor dimensão (último ano) | N9: ="Pior dimensão (último ano)" -> Pior dimensão (último ano)
B11: =SUMPRODUCT(('01_Criterios'!$C$26:$C$36=1)*1)&" / 11" -> 8 / 11 | E11: =SUM('01_Criterios'!$H$26:$H$36) -> 41 | H11: =IFERROR(SUM('05_Flags_Qualidade'!$W$5:$W$114)/(SUM('05_Flags_Qualidade'!$V$5:$V$114)+SUM('05_Flags_Qualidade'!$W$5:$W$114)),0) -> 0.057649667 | K11: =IFERROR(LOOKUP(2,1/('07_Subindices'!F19:P19<>""),'07_Subindices'!F19:P19),"–") -> Médio
B12: ="Dimensões activas" -> Dimensões activas | E12: ="Indicadores no índice" -> Indicadores no índice | H12: ="Células estimadas (imputação)" -> Células estimadas (imputação) | K12: ="Classificação (último ano)" -> Classificação (último ano)
B14: NAVEGAÇÃO
B15: → 01 · Critérios de selecção | E15: Parâmetros, dimensões a incluir, nº de indicadores e modo automático/manual
B16: → 02 · Base potencial | E16: Catálogo completo de candidatos com dados de origem, scores e ranking
B17: → 03 · Base do índice | E17: Indicadores seleccionados (dados observados usados no índice)
B18: → 04 · Dados ajustados | E18: Séries completadas por interpolação/carry com limites controlados
B19: → 05 · Flags de qualidade | E19: Origem de cada célula: observada, estimada ou sem dado
B20: → 06 · Normalização | E20: Scores 0–100 com sentido direccional
B21: → 07 · Subíndices | E21: Subíndices por dimensão, IGDA global e diagnóstico de cobertura
B22: → 08 · Visualizações | E22: Mapa de calor, radar e variação entre anos
B23: → 09 · Metodologia | E23: Nota metodológica completa e instruções de utilização
B24: → 10 · Fontes | E24: Fontes e ligações de todos os indicadores
B26: EVOLUÇÃO DOS SUBÍNDICES
B27: Dimensão | C27: 2015 | D27: 2016 | E27: 2017 | F27: 2018 | G27: 2019 | H27: 2020 | I27: 2021 | J27: 2022 | K27: 2023 | L27: 2024 | M27: 2025
B28: ='07_Subindices'!A5 -> Governança | C28: =IF('07_Subindices'!F5="","",'07_Subindices'!F5) -> 27.415798 | D28: =IF('07_Subindices'!G5="","",'07_Subindices'!G5) -> 28.02715 | E28: =IF('07_Subindices'!H5="","",'07_Subindices'!H5) -> 27.731903 | F28: =IF('07_Subindices'!I5="","",'07_Subindices'!I5) -> 29.570946 | G28: =IF('07_Subindices'!J5="","",'07_Subindices'!J5) -> 31.678184 | H28: =IF('07_Subindices'!K5="","",'07_Subindices'!K5) -> 30.817962 | I28: =IF('07_Subindices'!L5="","",'07_Subindices'!L5) -> 31.100242 | J28: =IF('07_Subindices'!M5="","",'07_Subindices'!M5) -> 33.006382 | ... M28: =IF('07_Subindices'!P5="","",'07_Subindices'!P5) -> 33.193808
B29: ='07_Subindices'!A6 -> Macroeconomia | C29: =IF('07_Subindices'!F6="","",'07_Subindices'!F6) -> 49.133768 | D29: =IF('07_Subindices'!G6="","",'07_Subindices'!G6) -> 44.476292 | E29: =IF('07_Subindices'!H6="","",'07_Subindices'!H6) -> 46.557339 | F29: =IF('07_Subindices'!I6="","",'07_Subindices'!I6) -> 45.108331 | G29: =IF('07_Subindices'!J6="","",'07_Subindices'!J6) -> 44.095034 | H29: =IF('07_Subindices'!K6="","",'07_Subindices'!K6) -> 33.062574 | I29: =IF('07_Subindices'!L6="","",'07_Subindices'!L6) -> 48.695603 | J29: =IF('07_Subindices'!M6="","",'07_Subindices'!M6) -> 49.63024 | ... M29: =IF('07_Subindices'!P6="","",'07_Subindices'!P6) -> 49.659758
B30: ='07_Subindices'!A7 -> Capital Humano | C30: =IF('07_Subindices'!F7="","",'07_Subindices'!F7) -> 50.479034 | D30: =IF('07_Subindices'!G7="","",'07_Subindices'!G7) -> 56.862 | E30: =IF('07_Subindices'!H7="","",'07_Subindices'!H7) -> 56.5713 | F30: =IF('07_Subindices'!I7="","",'07_Subindices'!I7) -> 56.257329 | G30: =IF('07_Subindices'!J7="","",'07_Subindices'!J7) -> 56.302875 | H30: =IF('07_Subindices'!K7="","",'07_Subindices'!K7) -> 57.924943 | I30: =IF('07_Subindices'!L7="","",'07_Subindices'!L7) -> 56.994873 | J30: =IF('07_Subindices'!M7="","",'07_Subindices'!M7) -> 58.0475 | ... M30: =IF('07_Subindices'!P7="","",'07_Subindices'!P7) -> 59.0515
B31: ='07_Subindices'!A8 -> Inclusão Social | C31: =IF('07_Subindices'!F8="","",'07_Subindices'!F8) -> 50.768339 | D31: =IF('07_Subindices'!G8="","",'07_Subindices'!G8) -> 47.543051 | E31: =IF('07_Subindices'!H8="","",'07_Subindices'!H8) -> 42.712295 | F31: =IF('07_Subindices'!I8="","",'07_Subindices'!I8) -> 42.157123 | G31: =IF('07_Subindices'!J8="","",'07_Subindices'!J8) -> 42.722414 | H31: =IF('07_Subindices'!K8="","",'07_Subindices'!K8) -> 42.114943 | I31: =IF('07_Subindices'!L8="","",'07_Subindices'!L8) -> 41.670463 | J31: =IF('07_Subindices'!M8="","",'07_Subindices'!M8) -> 44.068478 | ... M31: =IF('07_Subindices'!P8="","",'07_Subindices'!P8) -> 49.409126
B32: ='07_Subindices'!A9 -> Infraestruturas | C32: =IF('07_Subindices'!F9="","",'07_Subindices'!F9) -> 45.989556 | D32: =IF('07_Subindices'!G9="","",'07_Subindices'!G9) -> 39.273909 | E32: =IF('07_Subindices'!H9="","",'07_Subindices'!H9) -> 44.683769 | F32: =IF('07_Subindices'!I9="","",'07_Subindices'!I9) -> 42.12924 | G32: =IF('07_Subindices'!J9="","",'07_Subindices'!J9) -> 44.854886 | H32: =IF('07_Subindices'!K9="","",'07_Subindices'!K9) -> 42.272599 | I32: =IF('07_Subindices'!L9="","",'07_Subindices'!L9) -> 44.079489 | J32: =IF('07_Subindices'!M9="","",'07_Subindices'!M9) -> 45.81254 | ... M32: =IF('07_Subindices'!P9="","",'07_Subindices'!P9) -> 47.984623
B33: ='07_Subindices'!A10 -> Mercado Trabalho | C33: =IF('07_Subindices'!F10="","",'07_Subindices'!F10) -> 65.104271 | D33: =IF('07_Subindices'!G10="","",'07_Subindices'!G10) -> 63.743466 | E33: =IF('07_Subindices'!H10="","",'07_Subindices'!H10) -> 63.451158 | F33: =IF('07_Subindices'!I10="","",'07_Subindices'!I10) -> 62.984662 | G33: =IF('07_Subindices'!J10="","",'07_Subindices'!J10) -> 62.98275 | H33: =IF('07_Subindices'!K10="","",'07_Subindices'!K10) -> 59.20706 | I33: =IF('07_Subindices'!L10="","",'07_Subindices'!L10) -> 62.696663 | J33: =IF('07_Subindices'!M10="","",'07_Subindices'!M10) -> 67.141387 | ... M33: =IF('07_Subindices'!P10="","",'07_Subindices'!P10) -> 66.04686
B34: ='07_Subindices'!A11 -> Saúde/Alimentar | C34: =IF('07_Subindices'!F11="","",'07_Subindices'!F11) -> 59.244851 | D34: =IF('07_Subindices'!G11="","",'07_Subindices'!G11) -> 58.281855 | E34: =IF('07_Subindices'!H11="","",'07_Subindices'!H11) -> 57.759991 | F34: =IF('07_Subindices'!I11="","",'07_Subindices'!I11) -> 58.248643 | G34: =IF('07_Subindices'!J11="","",'07_Subindices'!J11) -> 58.239981 | H34: =IF('07_Subindices'!K11="","",'07_Subindices'!K11) -> 58.150154 | I34: =IF('07_Subindices'!L11="","",'07_Subindices'!L11) -> 56.503793 | J34: =IF('07_Subindices'!M11="","",'07_Subindices'!M11) -> 56.375636 | ... M34: =IF('07_Subindices'!P11="","",'07_Subindices'!P11) -> 57.021835
B35: ='07_Subindices'!A12 -> Diversificação | C35: =IF('07_Subindices'!F12="","",'07_Subindices'!F12) -> 19.988441 | D35: =IF('07_Subindices'!G12="","",'07_Subindices'!G12) -> 23.478583 | E35: =IF('07_Subindices'!H12="","",'07_Subindices'!H12) -> 24.641194 | F35: =IF('07_Subindices'!I12="","",'07_Subindices'!I12) -> 23.183337 | G35: =IF('07_Subindices'!J12="","",'07_Subindices'!J12) -> 21.835223 | H35: =IF('07_Subindices'!K12="","",'07_Subindices'!K12) -> 17.201785 | I35: =IF('07_Subindices'!L12="","",'07_Subindices'!L12) -> 24.551909 | J35: =IF('07_Subindices'!M12="","",'07_Subindices'!M12) -> 22.852556 | ... M35: =IF('07_Subindices'!P12="","",'07_Subindices'!P12) -> 24.859076
B36: ='07_Subindices'!A13 -> Ambiente | C36: =IF('07_Subindices'!F13="","",'07_Subindices'!F13) | D36: =IF('07_Subindices'!G13="","",'07_Subindices'!G13) | E36: =IF('07_Subindices'!H13="","",'07_Subindices'!H13) | F36: =IF('07_Subindices'!I13="","",'07_Subindices'!I13) | G36: =IF('07_Subindices'!J13="","",'07_Subindices'!J13) | H36: =IF('07_Subindices'!K13="","",'07_Subindices'!K13) | I36: =IF('07_Subindices'!L13="","",'07_Subindices'!L13) | J36: =IF('07_Subindices'!M13="","",'07_Subindices'!M13) | ... M36: =IF('07_Subindices'!P13="","",'07_Subindices'!P13)
B37: ='07_Subindices'!A14 -> Demografia | C37: =IF('07_Subindices'!F14="","",'07_Subindices'!F14) | D37: =IF('07_Subindices'!G14="","",'07_Subindices'!G14) | E37: =IF('07_Subindices'!H14="","",'07_Subindices'!H14) | F37: =IF('07_Subindices'!I14="","",'07_Subindices'!I14) | G37: =IF('07_Subindices'!J14="","",'07_Subindices'!J14) | H37: =IF('07_Subindices'!K14="","",'07_Subindices'!K14) | I37: =IF('07_Subindices'!L14="","",'07_Subindices'!L14) | J37: =IF('07_Subindices'!M14="","",'07_Subindices'!M14) | ... M37: =IF('07_Subindices'!P14="","",'07_Subindices'!P14)
B38: ='07_Subindices'!A15 -> Digital/Inovação | C38: =IF('07_Subindices'!F15="","",'07_Subindices'!F15) | D38: =IF('07_Subindices'!G15="","",'07_Subindices'!G15) | E38: =IF('07_Subindices'!H15="","",'07_Subindices'!H15) | F38: =IF('07_Subindices'!I15="","",'07_Subindices'!I15) | G38: =IF('07_Subindices'!J15="","",'07_Subindices'!J15) | H38: =IF('07_Subindices'!K15="","",'07_Subindices'!K15) | I38: =IF('07_Subindices'!L15="","",'07_Subindices'!L15) | J38: =IF('07_Subindices'!M15="","",'07_Subindices'!M15) | ... M38: =IF('07_Subindices'!P15="","",'07_Subindices'!P15)
B39: IGDA GLOBAL | C39: =IF('07_Subindices'!F18="","",'07_Subindices'!F18) -> 43.248684 | D39: =IF('07_Subindices'!G18="","",'07_Subindices'!G18) -> 42.933393 | E39: =IF('07_Subindices'!H18="","",'07_Subindices'!H18) -> 43.400965 | F39: =IF('07_Subindices'!I18="","",'07_Subindices'!I18) -> 42.835765 | G39: =IF('07_Subindices'!J18="","",'07_Subindices'!J18) -> 43.173605 | H39: =IF('07_Subindices'!K18="","",'07_Subindices'!K18) -> 39.742017 | I39: =IF('07_Subindices'!L18="","",'07_Subindices'!L18) -> 43.898046 | J39: =IF('07_Subindices'!M18="","",'07_Subindices'!M18) -> 44.929553 | ... M39: =IF('07_Subindices'!P18="","",'07_Subindices'!P18) -> 46.432549
B42: DESTAQUES AUTOMÁTICOS
B43: ="• IGDA no último ano com dados: "&IFERROR(FIXED(LOOKUP(9.99E+307,'07_Subindices'!F18:P18),1),"–")&" ("&IFERROR(LOOKUP(2,1/ISNUMBER('07_Subindices'!F18:P18),'07_Subindices'!$F$4:$P$4),"–")&") — classificação "&IFERROR(LOOKUP(2,1/('07_Subindices'!F19:P19<>""),'07_Subindices'!F19:P19),"–") -> • IGDA no último ano com dados: 46,4 (2025) — classificação Médio
B44: ="• Variação no período: "&IF('07_Subindices'!S18="","–",FIXED('07_Subindices'!S18,1))&" p.p. desde "&IFERROR(INDEX('07_Subindices'!$F$4:$P$4,MATCH(TRUE,INDEX(ISNUMBER('07_Subindices'!F18:P18),0),0)),"–") -> • Variação no período: 3,2 p.p. desde 2015
B45: ="• Dimensão mais forte: "&IFERROR(INDEX('07_Subindices'!$A$5:$A$15,MATCH(MAX('07_Subindices'!$T$5:$T$15),'07_Subindices'!$T$5:$T$15,0))&" ("&FIXED(MAX('07_Subindices'!$T$5:$T$15),1)&")","–") -> • Dimensão mais forte: Mercado Trabalho (66,0)
B46: ="• Dimensão mais fraca: "&IFERROR(INDEX('07_Subindices'!$A$5:$A$15,MATCH(MIN('07_Subindices'!$T$5:$T$15),'07_Subindices'!$T$5:$T$15,0))&" ("&FIXED(MIN('07_Subindices'!$T$5:$T$15),1)&")","–") -> • Dimensão mais fraca: Diversificação (24,9)
B47: ="• Maior progresso no período: "&IFERROR(INDEX('07_Subindices'!$A$5:$A$15,MATCH(MAX('07_Subindices'!$U$5:$U$15),'07_Subindices'!$U$5:$U$15,0))&" ("&FIXED(MAX('07_Subindices'!$U$5:$U$15),1)&" p.p.)","–") -> • Maior progresso no período: Capital Humano (8,6 p.p.)
B48: ="• Maior retrocesso no período: "&IFERROR(INDEX('07_Subindices'!$A$5:$A$15,MATCH(MIN('07_Subindices'!$U$5:$U$15),'07_Subindices'!$U$5:$U$15,0))&" ("&FIXED(MIN('07_Subindices'!$U$5:$U$15),1)&" p.p.)","–") -> • Maior retrocesso no período: Saúde/Alimentar (-2,2 p.p.)

Sheet 01_Criterios
A1: ← Painel
B2: CRITÉRIOS DE SELECÇÃO E PARÂMETROS DO ÍNDICE
B3: Células amarelas são editáveis. Tudo o resto recalcula automaticamente (selecção de indicadores, imputação, normalização, subíndices e IGDA).
B5: A. Parâmetros gerais
B6: Parâmetro | C6: Valor | D6: Explicação
B7: Ano inicial do período | C7: 2015 | D7: Período fixo desta versão (colunas 2015–2025).
B8: Ano final do período | C8: 2025 | D8: Usado no cálculo da recência dos indicadores.
B9: Escala normalizada mínima | C9: 0 | D9: Limite inferior dos scores normalizados.
B10: Escala normalizada máxima | C10: 100 | D10: Limite superior dos scores normalizados.
B11: Cobertura mínima do indicador (% de anos observados) | C11: 0.8 | D11: Indicadores abaixo deste limiar ficam inelegíveis (demasiado incompletos).
B12: Último ano observado mínimo (recência) | C12: 2023 | D12: Indicadores sem observações desde este ano são ignorados (desactualizados).
B13: Lacuna máxima para interpolação linear (anos) | C13: 2 | D13: Lacunas internas até este nº de anos são interpoladas linearmente.
B14: Carry-forward máximo no fim da série (anos) | C14: 2 | D14: Propagação do último valor observado, no máximo este nº de anos.
B15: Carry-backward máximo no início da série (anos) | C15: 2 | D15: Propagação retroactiva do primeiro valor observado.
B16: Cobertura mínima por subíndice (fracção de indicadores com score) | C16: 0.75 | D16: Num dado ano, o subíndice só é calculado se houver scores suficientes.
B17: Nº mínimo de subíndices para calcular o IGDA | C17: 4 | D17: Abaixo deste número o IGDA global não é calculado.
B18: Modo de selecção (Automática / Manual) | C18: Automática | D18: Automática: top-N por score + ajustes manuais. Manual: só entram os "Incluir".
B19: Peso do critério Relevância | C19: 0.4 | D19: Prioridade do indicador no catálogo.
B20: Peso do critério Completude | C20: 0.35 | D20: % de anos do período com observação.
B21: Peso do critério Consistência | C21: 0.25 | D21: Continuidade da série e recência.
B22: Bónus fonte nacional (pontos) | C22: 12 | D22: Acresce ao score de indicadores com fonte nacional (BNA/INE/IIMS).
B24: B. Dimensões do índice
B25: Dimensão | C25: Incluir? (1/0) | D25: Peso | E25: Indicadores alvo | F25: Candidatos | G25: Elegíveis | H25: Seleccionados | I25: Cobertura média (sel.) | J25: Score médio (sel.)
B26: 1. Governança e Estado de Direito | C26: 1 | D26: 1 | E26: 5 | F26: =COUNTIF('02_Base_Potencial'!$B$5:$B$335,$B26) -> 28 | G26: =SUMPRODUCT(('02_Base_Potencial'!$B$5:$B$335=$B26)*('02_Base_Potencial'!$AL$5:$AL$335=1)) -> 8 | H26: =SUMPRODUCT(('02_Base_Potencial'!$B$5:$B$335=$B26)*('02_Base_Potencial'!$AQ$5:$AQ$335=1)) -> 5 | I26: =IFERROR(SUMPRODUCT(('02_Base_Potencial'!$B$5:$B$335=$B26)*('02_Base_Potencial'!$AQ$5:$AQ$335=1),'02_Base_Potencial'!$AC$5:$AC$335)/$H26,"") -> 0.92727273 | J26: =IFERROR(SUMPRODUCT(('02_Base_Potencial'!$B$5:$B$335=$B26)*('02_Base_Potencial'!$AQ$5:$AQ$335=1),'02_Base_Potencial'!$AK$5:$AK$335)/$H26,"") -> 94.24
B27: 2. Estabilidade Macroeconómica | C27: 1 | D27: 1 | E27: 7 | F27: =COUNTIF('02_Base_Potencial'!$B$5:$B$335,$B27) -> 57 | G27: =SUMPRODUCT(('02_Base_Potencial'!$B$5:$B$335=$B27)*('02_Base_Potencial'!$AL$5:$AL$335=1)) -> 48 | H27: =SUMPRODUCT(('02_Base_Potencial'!$B$5:$B$335=$B27)*('02_Base_Potencial'!$AQ$5:$AQ$335=1)) -> 7 | I27: =IFERROR(SUMPRODUCT(('02_Base_Potencial'!$B$5:$B$335=$B27)*('02_Base_Potencial'!$AQ$5:$AQ$335=1),'02_Base_Potencial'!$AC$5:$AC$335)/$H27,"") -> 1 | J27: =IFERROR(SUMPRODUCT(('02_Base_Potencial'!$B$5:$B$335=$B27)*('02_Base_Potencial'!$AQ$5:$AQ$335=1),'02_Base_Potencial'!$AK$5:$AK$335)/$H27,"") -> 111.14286
B28: 3. Capital Humano | C28: 1 | D28: 1 | E28: 5 | F28: =COUNTIF('02_Base_Potencial'!$B$5:$B$335,$B28) -> 30 | G28: =SUMPRODUCT(('02_Base_Potencial'!$B$5:$B$335=$B28)*('02_Base_Potencial'!$AL$5:$AL$335=1)) -> 6 | H28: =SUMPRODUCT(('02_Base_Potencial'!$B$5:$B$335=$B28)*('02_Base_Potencial'!$AQ$5:$AQ$335=1)) -> 4 | I28: =IFERROR(SUMPRODUCT(('02_Base_Potencial'!$B$5:$B$335=$B28)*('02_Base_Potencial'!$AQ$5:$AQ$335=1),'02_Base_Potencial'!$AC$5:$AC$335)/$H28,"") -> 0.93181818 | J28: =IFERROR(SUMPRODUCT(('02_Base_Potencial'!$B$5:$B$335=$B28)*('02_Base_Potencial'!$AQ$5:$AQ$335=1),'02_Base_Potencial'!$AK$5:$AK$335)/$H28,"") -> 90.225
B29: 4. Inclusão Social e Protecção | C29: 1 | D29: 1 | E29: 5 | F29: =COUNTIF('02_Base_Potencial'!$B$5:$B$335,$B29) -> 30 | G29: =SUMPRODUCT(('02_Base_Potencial'!$B$5:$B$335=$B29)*('02_Base_Potencial'!$AL$5:$AL$335=1)) -> 5 | H29: =SUMPRODUCT(('02_Base_Potencial'!$B$5:$B$335=$B29)*('02_Base_Potencial'!$AQ$5:$AQ$335=1)) -> 3 | I29: =IFERROR(SUMPRODUCT(('02_Base_Potencial'!$B$5:$B$335=$B29)*('02_Base_Potencial'!$AQ$5:$AQ$335=1),'02_Base_Potencial'!$AC$5:$AC$335)/$H29,"") -> 0.96969697 | J29: =IFERROR(SUMPRODUCT(('02_Base_Potencial'!$B$5:$B$335=$B29)*('02_Base_Potencial'!$AQ$5:$AQ$335=1),'02_Base_Potencial'!$AK$5:$AK$335)/$H29,"") -> 96.166667
B30: 5. Infraestruturas e Serviços | C30: 1 | D30: 1 | E30: 5 | F30: =COUNTIF('02_Base_Potencial'!$B$5:$B$335,$B30) -> 33 | G30: =SUMPRODUCT(('02_Base_Potencial'!$B$5:$B$335=$B30)*('02_Base_Potencial'!$AL$5:$AL$335=1)) -> 17 | H30: =SUMPRODUCT(('02_Base_Potencial'!$B$5:$B$335=$B30)*('02_Base_Potencial'!$AQ$5:$AQ$335=1)) -> 5 | I30: =IFERROR(SUMPRODUCT(('02_Base_Potencial'!$B$5:$B$335=$B30)*('02_Base_Potencial'!$AQ$5:$AQ$335=1),'02_Base_Potencial'!$AC$5:$AC$335)/$H30,"") -> 0.87272727 | J30: =IFERROR(SUMPRODUCT(('02_Base_Potencial'!$B$5:$B$335=$B30)*('02_Base_Potencial'!$AQ$5:$AQ$335=1),'02_Base_Potencial'!$AK$5:$AK$335)/$H30,"") -> 89.62
B31: 6. Mercado de Trabalho | C31: 1 | D31: 1 | E31: 5 | F31: =COUNTIF('02_Base_Potencial'!$B$5:$B$335,$B31) -> 27 | G31: =SUMPRODUCT(('02_Base_Potencial'!$B$5:$B$335=$B31)*('02_Base_Potencial'!$AL$5:$AL$335=1)) -> 19 | H31: =SUMPRODUCT(('02_Base_Potencial'!$B$5:$B$335=$B31)*('02_Base_Potencial'!$AQ$5:$AQ$335=1)) -> 5 | I31: =IFERROR(SUMPRODUCT(('02_Base_Potencial'!$B$5:$B$335=$B31)*('02_Base_Potencial'!$AQ$5:$AQ$335=1),'02_Base_Potencial'!$AC$5:$AC$335)/$H31,"") -> 1 | J31: =IFERROR(SUMPRODUCT(('02_Base_Potencial'!$B$5:$B$335=$B31)*('02_Base_Potencial'!$AQ$5:$AQ$335=1),'02_Base_Potencial'!$AK$5:$AK$335)/$H31,"") -> 104.8
B32: 7. Segurança Alimentar e Saúde | C32: 1 | D32: 1 | E32: 7 | F32: =COUNTIF('02_Base_Potencial'!$B$5:$B$335,$B32) -> 37 | G32: =SUMPRODUCT(('02_Base_Potencial'!$B$5:$B$335=$B32)*('02_Base_Potencial'!$AL$5:$AL$335=1)) -> 17 | H32: =SUMPRODUCT(('02_Base_Potencial'!$B$5:$B$335=$B32)*('02_Base_Potencial'!$AQ$5:$AQ$335=1)) -> 7 | I32: =IFERROR(SUMPRODUCT(('02_Base_Potencial'!$B$5:$B$335=$B32)*('02_Base_Potencial'!$AQ$5:$AQ$335=1),'02_Base_Potencial'!$AC$5:$AC$335)/$H32,"") -> 0.88311688 | J32: =IFERROR(SUMPRODUCT(('02_Base_Potencial'!$B$5:$B$335=$B32)*('02_Base_Potencial'!$AQ$5:$AQ$335=1),'02_Base_Potencial'!$AK$5:$AK$335)/$H32,"") -> 96.957143
B33: 8. Diversificação Produtiva e Setor Privado | C33: 1 | D33: 1 | E33: 5 | F33: =COUNTIF('02_Base_Potencial'!$B$5:$B$335,$B33) -> 20 | G33: =SUMPRODUCT(('02_Base_Potencial'!$B$5:$B$335=$B33)*('02_Base_Potencial'!$AL$5:$AL$335=1)) -> 15 | H33: =SUMPRODUCT(('02_Base_Potencial'!$B$5:$B$335=$B33)*('02_Base_Potencial'!$AQ$5:$AQ$335=1)) -> 5 | I33: =IFERROR(SUMPRODUCT(('02_Base_Potencial'!$B$5:$B$335=$B33)*('02_Base_Potencial'!$AQ$5:$AQ$335=1),'02_Base_Potencial'!$AC$5:$AC$335)/$H33,"") -> 0.96363636 | J33: =IFERROR(SUMPRODUCT(('02_Base_Potencial'!$B$5:$B$335=$B33)*('02_Base_Potencial'!$AQ$5:$AQ$335=1),'02_Base_Potencial'!$AK$5:$AK$335)/$H33,"") -> 94.12
B34: 9. Ambiente, Clima e Resiliência | C34: 0 | D34: 1 | E34: 7 | F34: =COUNTIF('02_Base_Potencial'!$B$5:$B$335,$B34) -> 23 | G34: =SUMPRODUCT(('02_Base_Potencial'!$B$5:$B$335=$B34)*('02_Base_Potencial'!$AL$5:$AL$335=1)) -> 10 | H34: =SUMPRODUCT(('02_Base_Potencial'!$B$5:$B$335=$B34)*('02_Base_Potencial'!$AQ$5:$AQ$335=1)) -> 0 | I34: =IFERROR(SUMPRODUCT(('02_Base_Potencial'!$B$5:$B$335=$B34)*('02_Base_Potencial'!$AQ$5:$AQ$335=1),'02_Base_Potencial'!$AC$5:$AC$335)/$H34,"") | J34: =IFERROR(SUMPRODUCT(('02_Base_Potencial'!$B$5:$B$335=$B34)*('02_Base_Potencial'!$AQ$5:$AQ$335=1),'02_Base_Potencial'!$AK$5:$AK$335)/$H34,"")
B35: 10. Demografia, Território e Urbanização | C35: 0 | D35: 1 | E35: 7 | F35: =COUNTIF('02_Base_Potencial'!$B$5:$B$335,$B35) -> 23 | G35: =SUMPRODUCT(('02_Base_Potencial'!$B$5:$B$335=$B35)*('02_Base_Potencial'!$AL$5:$AL$335=1)) -> 7 | H35: =SUMPRODUCT(('02_Base_Potencial'!$B$5:$B$335=$B35)*('02_Base_Potencial'!$AQ$5:$AQ$335=1)) -> 0 | I35: =IFERROR(SUMPRODUCT(('02_Base_Potencial'!$B$5:$B$335=$B35)*('02_Base_Potencial'!$AQ$5:$AQ$335=1),'02_Base_Potencial'!$AC$5:$AC$335)/$H35,"") | J35: =IFERROR(SUMPRODUCT(('02_Base_Potencial'!$B$5:$B$335=$B35)*('02_Base_Potencial'!$AQ$5:$AQ$335=1),'02_Base_Potencial'!$AK$5:$AK$335)/$H35,"")
B36: 11. Transformação Digital e Inovação | C36: 0 | D36: 1 | E36: 7 | F36: =COUNTIF('02_Base_Potencial'!$B$5:$B$335,$B36) -> 23 | G36: =SUMPRODUCT(('02_Base_Potencial'!$B$5:$B$335=$B36)*('02_Base_Potencial'!$AL$5:$AL$335=1)) -> 9 | H36: =SUMPRODUCT(('02_Base_Potencial'!$B$5:$B$335=$B36)*('02_Base_Potencial'!$AQ$5:$AQ$335=1)) -> 0 | I36: =IFERROR(SUMPRODUCT(('02_Base_Potencial'!$B$5:$B$335=$B36)*('02_Base_Potencial'!$AQ$5:$AQ$335=1),'02_Base_Potencial'!$AC$5:$AC$335)/$H36,"") | J36: =IFERROR(SUMPRODUCT(('02_Base_Potencial'!$B$5:$B$335=$B36)*('02_Base_Potencial'!$AQ$5:$AQ$335=1),'02_Base_Potencial'!$AK$5:$AK$335)/$H36,"")
B38: Como funciona: no modo "Automática", entram os melhores N indicadores por dimensão (N = "Indicadores alvo"), por ordem do Score Total da Base_Potencial; a coluna "Ajuste manual" dessa folha permite forçar ("Incluir") ou bloquear ("Excluir") qualquer candidato. No modo "Manual" só entram os marcados como "Incluir". Máximo de 10 indicadores por dimensão.

Sheet 02_Base_Potencial
A1: ← Painel
B2: BASE DE INDICADORES POTENCIAIS (CATÁLOGO POR DIMENSÃO)
B3: 331 indicadores candidatos, valores anuais como extraídos das fontes de origem (BNA, INE, IIMS, Banco Mundial/WDI, FMI/WEO, benchmarks internacionais). Colunas de avaliação e selecção calculadas por fórmulas. Editável: Peso (J) e Ajuste manual (AP).
A4: ID | B4: Dimensão | C4: Subtema | D4: Indicador | E4: Unidade | F4: Sentido | G4: Mínimo | H4: Máximo | I4: Meta 2027 | J4: Peso | K4: Fonte | L4: Código/API | M4: Origem | N4: Fonte nacional | O4: Grupo (anti-duplicação) | P4: Prioridade | Q4: 2015 | R4: 2016 | S4: 2017 | T4: 2018 | U4: 2019 | V4: 2020 | W4: 2021 | X4: 2022 | Y4: 2023 | Z4: 2024 | AA4: 2025 | AB4: Nº obs. | AC4: Cobertura | AD4: Primeiro ano | AE4: Último ano | AF4: Continuidade | AG4: Recência (anos) | AH4: Score Relevância | AI4: Score Completude | AJ4: Score Consistência | AK4: SCORE TOTAL | AL4: Elegível | AM4: Motivo de exclusão | AN4: Melhor do grupo | AO4: Rank na dimensão | AP4: Ajuste manual | AQ4: SELECCIONADO | AR4: Slot | AS4: Nota
A5: GOV004 | B5: 1. Governança e Estado de Direito | C5: 1. Governança | D5: Estabilidade Política (WGI) | E5: -2.5 a 2.5 | F5: + | G5: -2.5 | H5: 2.5 | I5: 0 | J5: 1 | K5: Banco Mundial | L5: PV.EST | M5: Compilação interna BDA | N5: 0 | O5: GOV004 | P5: Em uso | Q5: -0.5591026 | R5: -0.434628 | S5: -0.5372145 | T5: -0.4058117 | U5: -0.4207039 | V5: -0.6427634 | W5: -0.7936068 | X5: -0.5414068 | Y5: -0.3131654 | Z5: -0.5735964 | AB5: =COUNT(Q5:AA5) -> 10 | AC5: =AB5/11 -> 0.90909091 | AD5: =IFERROR(INDEX($Q$4:$AA$4,MATCH(TRUE,INDEX(ISNUMBER(Q5:AA5),0),0)),"") -> 2015 | AE5: =IFERROR(LOOKUP(2,1/ISNUMBER(Q5:AA5),$Q$4:$AA$4),"") -> 2024 | AF5: =IF(AB5=0,"",AB5/(AE5-AD5+1)) -> 1 | AG5: =IF(AB5=0,"",'01_Criterios'!$C$8-AE5) -> 1 | AH5: =IF(P5="Em uso",100,IF(P5="Alta",85,IF(P5="Média",55,30))) -> 100 | AI5: =ROUND(100*AC5,1) -> 90.9 | AJ5: =IF(AB5=0,0,ROUND(MAX(0,100*AF5-10*AG5),1)) -> 90 | AK5: =ROUND(('01_Criterios'!$C$19*AH5+'01_Criterios'!$C$20*AI5+'01_Criterios'!$C$21*AJ5)/('01_Criterios'!$C$19+'01_Criterios'!$C$20+'01_Criterios'!$C$21)+N5*'01_Criterios'!$C$22,1) -> 94.3 | AL5: =IF(AND(AB5>=3,AC5>='01_Criterios'!$C$11,N(AE5)>='01_Criterios'!$C$12,OR(F5="+",F5="-"),ISNUMBER(G5),ISNUMBER(H5)),1,0) -> 1 | AM5: =IF(AL5=1,"",TRIM(IF(AB5=0,"sem dados no período; ",IF(AB5<3,"série demasiado curta; ",""))&IF(AND(AB5>0,AC5<'01_Criterios'!$C$11),"cobertura insuficiente; ","")&IF(AND(AB5>0,N(AE5)<'01_Criterios'!$C$12),"desactualizado; ","")&IF(AND(F5<>"+",F5<>"-"),"sentido ambíguo; ","")&IF(OR(NOT(ISNUMBER(G5)),NOT(ISNUMBER(H5))),"sem limites min/max; ",""))) | AN5: =IF(OR(AL5=0,$AP5="Excluir"),0,IF(SUMPRODUCT(($O$5:$O$335=$O5)*($AL$5:$AL$335=1)*($AP$5:$AP$335<>"Excluir")*(($AK$5:$AK$335>$AK5)+(($AK$5:$AK$335=$AK5)*(ROW($O$5:$O$335)<ROW()))))=0,1,0)) -> 1 | AO5: =IF(AN5=0,"",1+SUMPRODUCT(($B$5:$B$335=$B5)*($AN$5:$AN$335=1)*(($AK$5:$AK$335>$AK5)+(($AK$5:$AK$335=$AK5)*(ROW($B$5:$B$335)<ROW()))))) -> 2 | AP5: Auto | AQ5: =IF(INDEX('01_Criterios'!$C$26:$C$36,MATCH($B5,'01_Criterios'!$B$26:$B$36,0))<>1,0,IF($AP5="Excluir",0,IF($AP5="Incluir",IF(AND(OR($F5="+",$F5="-"),ISNUMBER($G5),ISNUMBER($H5),COUNT($Q5:$AA5)>0),1,0),IF('01_Criterios'!$C$18="Automática",IF(AND($AN5=1,$AO5<>"",$AO5<=INDEX('01_Criterios'!$E$26:$E$36,MATCH($B5,'01_Criterios'!$B$26:$B$36,0))),1,0),0)))) -> 1 | AR5: =IF(AQ5=0,"",IF($AO5<>"",1+SUMPRODUCT(($B$5:$B$335=$B5)*($AQ$5:$AQ$335=1)*($AO$5:$AO$335<$AO5)),1+SUMPRODUCT(($B$5:$B$335=$B5)*($AQ$5:$AQ$335=1)*ISNUMBER($AO$5:$AO$335))+SUMPRODUCT(($B$5:$B$335=$B5)*($AQ$5:$AQ$335=1)*($AO$5:$AO$335="")*(ROW($AO$5:$AO$335)<ROW())))) -> 2 | AS5: Indicador já incluído no modelo original.
A6: GOV005 | B6: 1. Governança e Estado de Direito | C6: 1. Governança | D6: Doing Business / Ease of Business | E6: 0-100 | F6: + | G6: 0 | H6: 100 | I6: 55 | J6: 1 | K6: Banco Mundial | M6: Compilação interna BDA | N6: 0 | O6: GOV005 | P6: Em uso | Q6: 37.09 | R6: 38.46 | S6: 38.41 | T6: 41.49 | U6: 43.86 | V6: 41.9 | AB6: =COUNT(Q6:AA6) -> 6 | AC6: =AB6/11 -> 0.54545455 | AD6: =IFERROR(INDEX($Q$4:$AA$4,MATCH(TRUE,INDEX(ISNUMBER(Q6:AA6),0),0)),"") -> 2015 | AE6: =IFERROR(LOOKUP(2,1/ISNUMBER(Q6:AA6),$Q$4:$AA$4),"") -> 2020 | AF6: =IF(AB6=0,"",AB6/(AE6-AD6+1)) -> 1 | AG6: =IF(AB6=0,"",'01_Criterios'!$C$8-AE6) -> 5 | AH6: =IF(P6="Em uso",100,IF(P6="Alta",85,IF(P6="Média",55,30))) -> 100 | AI6: =ROUND(100*AC6,1) -> 54.5 | AJ6: =IF(AB6=0,0,ROUND(MAX(0,100*AF6-10*AG6),1)) -> 50 | AK6: =ROUND(('01_Criterios'!$C$19*AH6+'01_Criterios'!$C$20*AI6+'01_Criterios'!$C$21*AJ6)/('01_Criterios'!$C$19+'01_Criterios'!$C$20+'01_Criterios'!$C$21)+N6*'01_Criterios'!$C$22,1) -> 71.6 | AL6: =IF(AND(AB6>=3,AC6>='01_Criterios'!$C$11,N(AE6)>='01_Criterios'!$C$12,OR(F6="+",F6="-"),ISNUMBER(G6),ISNUMBER(H6)),1,0) -> 0 | AM6: =IF(AL6=1,"",TRIM(IF(AB6=0,"sem dados no período; ",IF(AB6<3,"série demasiado curta; ",""))&IF(AND(AB6>0,AC6<'01_Criterios'!$C$11),"cobertura insuficiente; ","")&IF(AND(AB6>0,N(AE6)<'01_Criterios'!$C$12),"desactualizado; ","")&IF(AND(F6<>"+",F6<>"-"),"sentido ambíguo; ","")&IF(OR(NOT(ISNUMBER(G6)),NOT(ISNUMBER(H6))),"sem limites min/max; ",""))) -> cobertura insuficiente; desactualizado; | AN6: =IF(OR(AL6=0,$AP6="Excluir"),0,IF(SUMPRODUCT(($O$5:$O$335=$O6)*($AL$5:$AL$335=1)*($AP$5:$AP$335<>"Excluir")*(($AK$5:$AK$335>$AK6)+(($AK$5:$AK$335=$AK6)*(ROW($O$5:$O$335)<ROW()))))=0,1,0)) -> 0 | AO6: =IF(AN6=0,"",1+SUMPRODUCT(($B$5:$B$335=$B6)*($AN$5:$AN$335=1)*(($AK$5:$AK$335>$AK6)+(($AK$5:$AK$335=$AK6)*(ROW($B$5:$B$335)<ROW()))))) | AP6: Auto | AQ6: =IF(INDEX('01_Criterios'!$C$26:$C$36,MATCH($B6,'01_Criterios'!$B$26:$B$36,0))<>1,0,IF($AP6="Excluir",0,IF($AP6="Incluir",IF(AND(OR($F6="+",$F6="-"),ISNUMBER($G6),ISNUMBER($H6),COUNT($Q6:$AA6)>0),1,0),IF('01_Criterios'!$C$18="Automática",IF(AND($AN6=1,$AO6<>"",$AO6<=INDEX('01_Criterios'!$E$26:$E$36,MATCH($B6,'01_Criterios'!$B$26:$B$36,0))),1,0),0)))) -> 0 | AR6: =IF(AQ6=0,"",IF($AO6<>"",1+SUMPRODUCT(($B$5:$B$335=$B6)*($AQ$5:$AQ$335=1)*($AO$5:$AO$335<$AO6)),1+SUMPRODUCT(($B$5:$B$335=$B6)*($AQ$5:$AQ$335=1)*ISNUMBER($AO$5:$AO$335))+SUMPRODUCT(($B$5:$B$335=$B6)*($AQ$5:$AQ$335=1)*($AO$5:$AO$335="")*(ROW($AO$5:$AO$335)<ROW())))) | AS6: Indicador já incluído no modelo original.
A7: GOV01 | B7: 1. Governança e Estado de Direito | C7: 1. Governança | D7: Índice de Percepção da Corrupção | E7: 0-100 | F7: + | G7: 0 | H7: 100 | I7: 35 | J7: 1 | K7: Transparency Int. | L7: TI_CPI_SCORE | M7: Transparency International — CPI | N7: 0 | O7: GOV01 | P7: Em uso | Q7: 15 | R7: 18 | S7: 19 | T7: 19 | U7: 26 | V7: 27 | W7: 29 | X7: 33 | Y7: 33 | Z7: 32 | AA7: 32 | AB7: =COUNT(Q7:AA7) -> 11 | AC7: =AB7/11 -> 1 | AD7: =IFERROR(INDEX($Q$4:$AA$4,MATCH(TRUE,INDEX(ISNUMBER(Q7:AA7),0),0)),"") -> 2015 | AE7: =IFERROR(LOOKUP(2,1/ISNUMBER(Q7:AA7),$Q$4:$AA$4),"") -> 2025 | AF7: =IF(AB7=0,"",AB7/(AE7-AD7+1)) -> 1 | AG7: =IF(AB7=0,"",'01_Criterios'!$C$8-AE7) -> 0 | AH7: =IF(P7="Em uso",100,IF(P7="Alta",85,IF(P7="Média",55,30))) -> 100 | AI7: =ROUND(100*AC7,1) -> 100 | AJ7: =IF(AB7=0,0,ROUND(MAX(0,100*AF7-10*AG7),1)) -> 100 | AK7: =ROUND(('01_Criterios'!$C$19*AH7+'01_Criterios'!$C$20*AI7+'01_Criterios'!$C$21*AJ7)/('01_Criterios'!$C$19+'01_Criterios'!$C$20+'01_Criterios'!$C$21)+N7*'01_Criterios'!$C$22,1) -> 100 | AL7: =IF(AND(AB7>=3,AC7>='01_Criterios'!$C$11,N(AE7)>='01_Criterios'!$C$12,OR(F7="+",F7="-"),ISNUMBER(G7),ISNUMBER(H7)),1,0) -> 1 | AM7: =IF(AL7=1,"",TRIM(IF(AB7=0,"sem dados no período; ",IF(AB7<3,"série demasiado curta; ",""))&IF(AND(AB7>0,AC7<'01_Criterios'!$C$11),"cobertura insuficiente; ","")&IF(AND(AB7>0,N(AE7)<'01_Criterios'!$C$12),"desactualizado; ","")&IF(AND(F7<>"+",F7<>"-"),"sentido ambíguo; ","")&IF(OR(NOT(ISNUMBER(G7)),NOT(ISNUMBER(H7))),"sem limites min/max; ",""))) | AN7: =IF(OR(AL7=0,$AP7="Excluir"),0,IF(SUMPRODUCT(($O$5:$O$335=$O7)*($AL$5:$AL$335=1)*($AP$5:$AP$335<>"Excluir")*(($AK$5:$AK$335>$AK7)+(($AK$5:$AK$335=$AK7)*(ROW($O$5:$O$335)<ROW()))))=0,1,0)) -> 1 | AO7: =IF(AN7=0,"",1+SUMPRODUCT(($B$5:$B$335=$B7)*($AN$5:$AN$335=1)*(($AK$5:$AK$335>$AK7)+(($AK$5:$AK$335=$AK7)*(ROW($B$5:$B$335)<ROW()))))) -> 1 | AP7: Auto | AQ7: =IF(INDEX('01_Criterios'!$C$26:$C$36,MATCH($B7,'01_Criterios'!$B$26:$B$36,0))<>1,0,IF($AP7="Excluir",0,IF($AP7="Incluir",IF(AND(OR($F7="+",$F7="-"),ISNUMBER($G7),ISNUMBER($H7),COUNT($Q7:$AA7)>0),1,0),IF('01_Criterios'!$C$18="Automática",IF(AND($AN7=1,$AO7<>"",$AO7<=INDEX('01_Criterios'!$E$26:$E$36,MATCH($B7,'01_Criterios'!$B$26:$B$36,0))),1,0),0)))) -> 1 | AR7: =IF(AQ7=0,"",IF($AO7<>"",1+SUMPRODUCT(($B$5:$B$335=$B7)*($AQ$5:$AQ$335=1)*($AO$5:$AO$335<$AO7)),1+SUMPRODUCT(($B$5:$B$335=$B7)*($AQ$5:$AQ$335=1)*ISNUMBER($AO$5:$AO$335))+SUMPRODUCT(($B$5:$B$335=$B7)*($AQ$5:$AQ$335=1)*($AO$5:$AO$335="")*(ROW($AO$5:$AO$335)<ROW())))) -> 1 | AS7: Nome local/API: Corruption Perceptions Index — score (0=highly corrupt, 100=clean) | 2025 preenchido a partir da página oficial Transparency International Angola/CPI 2025.
A8: GOV02 | B8: 1. Governança e Estado de Direito | C8: 1. Governança | D8: WGI - Estado de Direito | E8: -2.5 a 2.5 | F8: + | G8: -2.5 | H8: 2.5 | I8: 0 | J8: 1 | K8: Banco Mundial | L8: RL.EST | M8: Compilação interna BDA | N8: 0 | O8: GOV02 | P8: Em uso | Q8: -1.3086297 | R8: -1.3287764 | S8: -1.3317055 | T8: -1.1105522 | U8: -1.0519682 | V8: -0.9475038 | W8: -1.0980135 | X8: -1.1625439 | Y8: -1.1944432 | Z8: -1.1697408 | AB8: =COUNT(Q8:AA8) -> 10 | AC8: =AB8/11 -> 0.90909091 | AD8: =IFERROR(INDEX($Q$4:$AA$4,MATCH(TRUE,INDEX(ISNUMBER(Q8:AA8),0),0)),"") -> 2015 | AE8: =IFERROR(LOOKUP(2,1/ISNUMBER(Q8:AA8),$Q$4:$AA$4),"") -> 2024 | AF8: =IF(AB8=0,"",AB8/(AE8-AD8+1)) -> 1 | AG8: =IF(AB8=0,"",'01_Criterios'!$C$8-AE8) -> 1 | AH8: =IF(P8="Em uso",100,IF(P8="Alta",85,IF(P8="Média",55,30))) -> 100 | AI8: =ROUND(100*AC8,1) -> 90.9 | AJ8: =IF(AB8=0,0,ROUND(MAX(0,100*AF8-10*AG8),1)) -> 90 | AK8: =ROUND(('01_Criterios'!$C$19*AH8+'01_Criterios'!$C$20*AI8+'01_Criterios'!$C$21*AJ8)/('01_Criterios'!$C$19+'01_Criterios'!$C$20+'01_Criterios'!$C$21)+N8*'01_Criterios'!$C$22,1) -> 94.3 | AL8: =IF(AND(AB8>=3,AC8>='01_Criterios'!$C$11,N(AE8)>='01_Criterios'!$C$12,OR(F8="+",F8="-"),ISNUMBER(G8),ISNUMBER(H8)),1,0) -> 1 | AM8: =IF(AL8=1,"",TRIM(IF(AB8=0,"sem dados no período; ",IF(AB8<3,"série demasiado curta; ",""))&IF(AND(AB8>0,AC8<'01_Criterios'!$C$11),"cobertura insuficiente; ","")&IF(AND(AB8>0,N(AE8)<'01_Criterios'!$C$12),"desactualizado; ","")&IF(AND(F8<>"+",F8<>"-"),"sentido ambíguo; ","")&IF(OR(NOT(ISNUMBER(G8)),NOT(ISNUMBER(H8))),"sem limites min/max; ",""))) | AN8: =IF(OR(AL8=0,$AP8="Excluir"),0,IF(SUMPRODUCT(($O$5:$O$335=$O8)*($AL$5:$AL$335=1)*($AP$5:$AP$335<>"Excluir")*(($AK$5:$AK$335>$AK8)+(($AK$5:$AK$335=$AK8)*(ROW($O$5:$O$335)<ROW()))))=0,1,0)) -> 1 | AO8: =IF(AN8=0,"",1+SUMPRODUCT(($B$5:$B$335=$B8)*($AN$5:$AN$335=1)*(($AK$5:$AK$335>$AK8)+(($AK$5:$AK$335=$AK8)*(ROW($B$5:$B$335)<ROW()))))) -> 3 | AP8: Auto | AQ8: =IF(INDEX('01_Criterios'!$C$26:$C$36,MATCH($B8,'01_Criterios'!$B$26:$B$36,0))<>1,0,IF($AP8="Excluir",0,IF($AP8="Incluir",IF(AND(OR($F8="+",$F8="-"),ISNUMBER($G8),ISNUMBER($H8),COUNT($Q8:$AA8)>0),1,0),IF('01_Criterios'!$C$18="Automática",IF(AND($AN8=1,$AO8<>"",$AO8<=INDEX('01_Criterios'!$E$26:$E$36,MATCH($B8,'01_Criterios'!$B$26:$B$36,0))),1,0),0)))) -> 1 | AR8: =IF(AQ8=0,"",IF($AO8<>"",1+SUMPRODUCT(($B$5:$B$335=$B8)*($AQ$5:$AQ$335=1)*($AO$5:$AO$335<$AO8)),1+SUMPRODUCT(($B$5:$B$335=$B8)*($AQ$5:$AQ$335=1)*ISNUMBER($AO$5:$AO$335))+SUMPRODUCT(($B$5:$B$335=$B8)*($AQ$5:$AQ$335=1)*($AO$5:$AO$335="")*(ROW($AO$5:$AO$335)<ROW())))) -> 3 | AS8: Indicador já incluído no modelo original.
A9: GOV03 | B9: 1. Governança e Estado de Direito | C9: 1. Governança | D9: WGI - Eficiência do Governo | E9: -2.5 a 2.5 | F9: + | G9: -2.5 | H9: 2.5 | I9: 0 | J9: 1 | K9: Banco Mundial | L9: GE.EST | M9: Compilação interna BDA | N9: 0 | O9: GOV03 | P9: Em uso | Q9: -0.9378237 | R9: -0.9493847 | S9: -0.9681157 | T9: -0.9784602 | U9: -0.9116965 | V9: -1.0163604 | W9: -0.9347008 | X9: -0.8325718 | Y9: -0.8287026 | Z9: -0.7851909 | AB9: =COUNT(Q9:AA9) -> 10 | AC9: =AB9/11 -> 0.90909091 | AD9: =IFERROR(INDEX($Q$4:$AA$4,MATCH(TRUE,INDEX(ISNUMBER(Q9:AA9),0),0)),"") -> 2015 | AE9: =IFERROR(LOOKUP(2,1/ISNUMBER(Q9:AA9),$Q$4:$AA$4),"") -> 2024 | AF9: =IF(AB9=0,"",AB9/(AE9-AD9+1)) -> 1 | AG9: =IF(AB9=0,"",'01_Criterios'!$C$8-AE9) -> 1 | AH9: =IF(P9="Em uso",100,IF(P9="Alta",85,IF(P9="Média",55,30))) -> 100 | AI9: =ROUND(100*AC9,1) -> 90.9 | AJ9: =IF(AB9=0,0,ROUND(MAX(0,100*AF9-10*AG9),1)) -> 90 | AK9: =ROUND(('01_Criterios'!$C$19*AH9+'01_Criterios'!$C$20*AI9+'01_Criterios'!$C$21*AJ9)/('01_Criterios'!$C$19+'01_Criterios'!$C$20+'01_Criterios'!$C$21)+N9*'01_Criterios'!$C$22,1) -> 94.3 | AL9: =IF(AND(AB9>=3,AC9>='01_Criterios'!$C$11,N(AE9)>='01_Criterios'!$C$12,OR(F9="+",F9="-"),ISNUMBER(G9),ISNUMBER(H9)),1,0) -> 1 | AM9: =IF(AL9=1,"",TRIM(IF(AB9=0,"sem dados no período; ",IF(AB9<3,"série demasiado curta; ",""))&IF(AND(AB9>0,AC9<'01_Criterios'!$C$11),"cobertura insuficiente; ","")&IF(AND(AB9>0,N(AE9)<'01_Criterios'!$C$12),"desactualizado; ","")&IF(AND(F9<>"+",F9<>"-"),"sentido ambíguo; ","")&IF(OR(NOT(ISNUMBER(G9)),NOT(ISNUMBER(H9))),"sem limites min/max; ",""))) | AN9: =IF(OR(AL9=0,$AP9="Excluir"),0,IF(SUMPRODUCT(($O$5:$O$335=$O9)*($AL$5:$AL$335=1)*($AP$5:$AP$335<>"Excluir")*(($AK$5:$AK$335>$AK9)+(($AK$5:$AK$335=$AK9)*(ROW($O$5:$O$335)<ROW()))))=0,1,0)) -> 1 | AO9: =IF(AN9=0,"",1+SUMPRODUCT(($B$5:$B$335=$B9)*($AN$5:$AN$335=1)*(($AK$5:$AK$335>$AK9)+(($AK$5:$AK$335=$AK9)*(ROW($B$5:$B$335)<ROW()))))) -> 4 | AP9: Auto | AQ9: =IF(INDEX('01_Criterios'!$C$26:$C$36,MATCH($B9,'01_Criterios'!$B$26:$B$36,0))<>1,0,IF($AP9="Excluir",0,IF($AP9="Incluir",IF(AND(OR($F9="+",$F9="-"),ISNUMBER($G9),ISNUMBER($H9),COUNT($Q9:$AA9)>0),1,0),IF('01_Criterios'!$C$18="Automática",IF(AND($AN9=1,$AO9<>"",$AO9<=INDEX('01_Criterios'!$E$26:$E$36,MATCH($B9,'01_Criterios'!$B$26:$B$36,0))),1,0),0)))) -> 1 | AR9: =IF(AQ9=0,"",IF($AO9<>"",1+SUMPRODUCT(($B$5:$B$335=$B9)*($AQ$5:$AQ$335=1)*($AO$5:$AO$335<$AO9)),1+SUMPRODUCT(($B$5:$B$335=$B9)*($AQ$5:$AQ$335=1)*ISNUMBER($AO$5:$AO$335))+SUMPRODUCT(($B$5:$B$335=$B9)*($AQ$5:$AQ$335=1)*($AO$5:$AO$335="")*(ROW($AO$5:$AO$335)<ROW())))) -> 4 | AS9: Indicador já incluído no modelo original.
A10: GOV009 | B10: 1. Governança e Estado de Direito | C10: 1. Governança | D10: Índice Ibrahim - Governação Global | E10: 0-100 | F10: + | G10: 0 | H10: 100 | I10: 55 | J10: 1 | K10: Mo Ibrahim Foundation | L10: IIAG_OVERALL | M10: Mo Ibrahim Foundation | N10: 0 | O10: GOV009 | P10: Alta | Y10: 43.8 | AB10: =COUNT(Q10:AA10) -> 1 | AC10: =AB10/11 -> 0.090909091 | AD10: =IFERROR(INDEX($Q$4:$AA$4,MATCH(TRUE,INDEX(ISNUMBER(Q10:AA10),0),0)),"") -> 2023 | AE10: =IFERROR(LOOKUP(2,1/ISNUMBER(Q10:AA10),$Q$4:$AA$4),"") -> 2023 | AF10: =IF(AB10=0,"",AB10/(AE10-AD10+1)) -> 1 | AG10: =IF(AB10=0,"",'01_Criterios'!$C$8-AE10) -> 2 | AH10: =IF(P10="Em uso",100,IF(P10="Alta",85,IF(P10="Média",55,30))) -> 85 | AI10: =ROUND(100*AC10,1) -> 9.1 | AJ10: =IF(AB10=0,0,ROUND(MAX(0,100*AF10-10*AG10),1)) -> 80 | AK10: =ROUND(('01_Criterios'!$C$19*AH10+'01_Criterios'!$C$20*AI10+'01_Criterios'!$C$21*AJ10)/('01_Criterios'!$C$19+'01_Criterios'!$C$20+'01_Criterios'!$C$21)+N10*'01_Criterios'!$C$22,1) -> 57.2 | AL10: =IF(AND(AB10>=3,AC10>='01_Criterios'!$C$11,N(AE10)>='01_Criterios'!$C$12,OR(F10="+",F10="-"),ISNUMBER(G10),ISNUMBER(H10)),1,0) -> 0 | AM10: =IF(AL10=1,"",TRIM(IF(AB10=0,"sem dados no período; ",IF(AB10<3,"série demasiado curta; ",""))&IF(AND(AB10>0,AC10<'01_Criterios'!$C$11),"cobertura insuficiente; ","")&IF(AND(AB10>0,N(AE10)<'01_Criterios'!$C$12),"desactualizado; ","")&IF(AND(F10<>"+",F10<>"-"),"sentido ambíguo; ","")&IF(OR(NOT(ISNUMBER(G10)),NOT(ISNUMBER(H10))),"sem limites min/max; ",""))) -> série demasiado curta; cobertura insuficiente; | AN10: =IF(OR(AL10=0,$AP10="Excluir"),0,IF(SUMPRODUCT(($O$5:$O$335=$O10)*($AL$5:$AL$335=1)*($AP$5:$AP$335<>"Excluir")*(($AK$5:$AK$335>$AK10)+(($AK$5:$AK$335=$AK10)*(ROW($O$5:$O$335)<ROW()))))=0,1,0)) -> 0 | AO10: =IF(AN10=0,"",1+SUMPRODUCT(($B$5:$B$335=$B10)*($AN$5:$AN$335=1)*(($AK$5:$AK$335>$AK10)+(($AK$5:$AK$335=$AK10)*(ROW($B$5:$B$335)<ROW()))))) | AP10: Auto | AQ10: =IF(INDEX('01_Criterios'!$C$26:$C$36,MATCH($B10,'01_Criterios'!$B$26:$B$36,0))<>1,0,IF($AP10="Excluir",0,IF($AP10="Incluir",IF(AND(OR($F10="+",$F10="-"),ISNUMBER($G10),ISNUMBER($H10),COUNT($Q10:$AA10)>0),1,0),IF('01_Criterios'!$C$18="Automática",IF(AND($AN10=1,$AO10<>"",$AO10<=INDEX('01_Criterios'!$E$26:$E$36,MATCH($B10,'01_Criterios'!$B$26:$B$36,0))),1,0),0)))) -> 0 | AR10: =IF(AQ10=0,"",IF($AO10<>"",1+SUMPRODUCT(($B$5:$B$335=$B10)*($AQ$5:$AQ$335=1)*($AO$5:$AO$335<$AO10)),1+SUMPRODUCT(($B$5:$B$335=$B10)*($AQ$5:$AQ$335=1)*ISNUMBER($AO$5:$AO$335))+SUMPRODUCT(($B$5:$B$335=$B10)*($AQ$5:$AQ$335=1)*($AO$5:$AO$335="")*(ROW($AO$5:$AO$335)<ROW())))) | AS10: Benchmark africano com várias dimensões institucionais. | IIAG 2024: scorecard (2023) e perfil de país (2014). Dataset cobre 2014-2023; anos intermédios não rotulados numericamente.
A11: GOV020 | B11: 1. Governança e Estado de Direito | C11: Corrupção empresarial | D11: Incidência de subornos em empresas | E11: % | F11: - | G11: 0 | H11: 100 | I11: 10 | J11: 1 | K11: Banco Mundial/Enterprise Surveys | L11: IC.FRM.BRIB.ZS | M11: Banco Mundial — WDI | N11: 0 | O11: GOV020 | P11: Alta | Z11: 21.507504 | AB11: =COUNT(Q11:AA11) -> 1 | AC11: =AB11/11 -> 0.090909091 | AD11: =IFERROR(INDEX($Q$4:$AA$4,MATCH(TRUE,INDEX(ISNUMBER(Q11:AA11),0),0)),"") -> 2024 | AE11: =IFERROR(LOOKUP(2,1/ISNUMBER(Q11:AA11),$Q$4:$AA$4),"") -> 2024 | AF11: =IF(AB11=0,"",AB11/(AE11-AD11+1)) -> 1 | AG11: =IF(AB11=0,"",'01_Criterios'!$C$8-AE11) -> 1 | AH11: =IF(P11="Em uso",100,IF(P11="Alta",85,IF(P11="Média",55,30))) -> 85 | AI11: =ROUND(100*AC11,1) -> 9.1 | AJ11: =IF(AB11=0,0,ROUND(MAX(0,100*AF11-10*AG11),1)) -> 90 | AK11: =ROUND(('01_Criterios'!$C$19*AH11+'01_Criterios'!$C$20*AI11+'01_Criterios'!$C$21*AJ11)/('01_Criterios'!$C$19+'01_Criterios'!$C$20+'01_Criterios'!$C$21)+N11*'01_Criterios'!$C$22,1) -> 59.7 | AL11: =IF(AND(AB11>=3,AC11>='01_Criterios'!$C$11,N(AE11)>='01_Criterios'!$C$12,OR(F11="+",F11="-"),ISNUMBER(G11),ISNUMBER(H11)),1,0) -> 0 | AM11: =IF(AL11=1,"",TRIM(IF(AB11=0,"sem dados no período; ",IF(AB11<3,"série demasiado curta; ",""))&IF(AND(AB11>0,AC11<'01_Criterios'!$C$11),"cobertura insuficiente; ","")&IF(AND(AB11>0,N(AE11)<'01_Criterios'!$C$12),"desactualizado; ","")&IF(AND(F11<>"+",F11<>"-"),"sentido ambíguo; ","")&IF(OR(NOT(ISNUMBER(G11)),NOT(ISNUMBER(H11))),"sem limites min/max; ",""))) -> série demasiado curta; cobertura insuficiente; | AN11: =IF(OR(AL11=0,$AP11="Excluir"),0,IF(SUMPRODUCT(($O$5:$O$335=$O11)*($AL$5:$AL$335=1)*($AP$5:$AP$335<>"Excluir")*(($AK$5:$AK$335>$AK11)+(($AK$5:$AK$335=$AK11)*(ROW($O$5:$O$335)<ROW()))))=0,1,0)) -> 0 | AO11: =IF(AN11=0,"",1+SUMPRODUCT(($B$5:$B$335=$B11)*($AN$5:$AN$335=1)*(($AK$5:$AK$335>$AK11)+(($AK$5:$AK$335=$AK11)*(ROW($B$5:$B$335)<ROW()))))) | AP11: Auto | AQ11: =IF(INDEX('01_Criterios'!$C$26:$C$36,MATCH($B11,'01_Criterios'!$B$26:$B$36,0))<>1,0,IF($AP11="Excluir",0,IF($AP11="Incluir",IF(AND(OR($F11="+",$F11="-"),ISNUMBER($G11),ISNUMBER($H11),COUNT($Q11:$AA11)>0),1,0),IF('01_Criterios'!$C$18="Automática",IF(AND($AN11=1,$AO11<>"",$AO11<=INDEX('01_Criterios'!$E$26:$E$36,MATCH($B11,'01_Criterios'!$B$26:$B$36,0))),1,0),0)))) -> 0 | AR11: =IF(AQ11=0,"",IF($AO11<>"",1+SUMPRODUCT(($B$5:$B$335=$B11)*($AQ$5:$AQ$335=1)*($AO$5:$AO$335<$AO11)),1+SUMPRODUCT(($B$5:$B$335=$B11)*($AQ$5:$AQ$335=1)*ISNUMBER($AO$5:$AO$335))+SUMPRODUCT(($B$5:$B$335=$B11)*($AQ$5:$AQ$335=1)*($AO$5:$AO$335="")*(ROW($AO$5:$AO$335)<ROW())))) | AS11: Capta corrupção sentida pelas empresas, complementar ao CPI/WGI. | Nome local/API: Bribery incidence (% of firms experiencing at least one bribe payment request)
A12: GOV021 | B12: 1. Governança e Estado de Direito | C12: Corrupção empresarial | D12: Pagamentos informais a funcionários públicos | E12: % | F12: - | G12: 0 | H12: 100 | I12: 10 | J12: 1 | K12: Banco Mundial/Enterprise Surveys | L12: IC.FRM.CORR.ZS | M12: Banco Mundial — WDI | N12: 0 | O12: GOV021 | P12: Alta | Z12: 19.121405 | AB12: =COUNT(Q12:AA12) -> 1 | AC12: =AB12/11 -> 0.090909091 | AD12: =IFERROR(INDEX($Q$4:$AA$4,MATCH(TRUE,INDEX(ISNUMBER(Q12:AA12),0),0)),"") -> 2024 | AE12: =IFERROR(LOOKUP(2,1/ISNUMBER(Q12:AA12),$Q$4:$AA$4),"") -> 2024 | AF12: =IF(AB12=0,"",AB12/(AE12-AD12+1)) -> 1 | AG12: =IF(AB12=0,"",'01_Criterios'!$C$8-AE12) -> 1 | AH12: =IF(P12="Em uso",100,IF(P12="Alta",85,IF(P12="Média",55,30))) -> 85 | AI12: =ROUND(100*AC12,1) -> 9.1 | AJ12: =IF(AB12=0,0,ROUND(MAX(0,100*AF12-10*AG12),1)) -> 90 | AK12: =ROUND(('01_Criterios'!$C$19*AH12+'01_Criterios'!$C$20*AI12+'01_Criterios'!$C$21*AJ12)/('01_Criterios'!$C$19+'01_Criterios'!$C$20+'01_Criterios'!$C$21)+N12*'01_Criterios'!$C$22,1) -> 59.7 | AL12: =IF(AND(AB12>=3,AC12>='01_Criterios'!$C$11,N(AE12)>='01_Criterios'!$C$12,OR(F12="+",F12="-"),ISNUMBER(G12),ISNUMBER(H12)),1,0) -> 0 | AM12: =IF(AL12=1,"",TRIM(IF(AB12=0,"sem dados no período; ",IF(AB12<3,"série demasiado curta; ",""))&IF(AND(AB12>0,AC12<'01_Criterios'!$C$11),"cobertura insuficiente; ","")&IF(AND(AB12>0,N(AE12)<'01_Criterios'!$C$12),"desactualizado; ","")&IF(AND(F12<>"+",F12<>"-"),"sentido ambíguo; ","")&IF(OR(NOT(ISNUMBER(G12)),NOT(ISNUMBER(H12))),"sem limites min/max; ",""))) -> série demasiado curta; cobertura insuficiente; | AN12: =IF(OR(AL12=0,$AP12="Excluir"),0,IF(SUMPRODUCT(($O$5:$O$335=$O12)*($AL$5:$AL$335=1)*($AP$5:$AP$335<>"Excluir")*(($AK$5:$AK$335>$AK12)+(($AK$5:$AK$335=$AK12)*(ROW($O$5:$O$335)<ROW()))))=0,1,0)) -> 0 | AO12: =IF(AN12=0,"",1+SUMPRODUCT(($B$5:$B$335=$B12)*($AN$5:$AN$335=1)*(($AK$5:$AK$335>$AK12)+(($AK$5:$AK$335=$AK12)*(ROW($B$5:$B$335)<ROW()))))) | AP12: Auto | AQ12: =IF(INDEX('01_Criterios'!$C$26:$C$36,MATCH($B12,'01_Criterios'!$B$26:$B$36,0))<>1,0,IF($AP12="Excluir",0,IF($AP12="Incluir",IF(AND(OR($F12="+",$F12="-"),ISNUMBER($G12),ISNUMBER($H12),COUNT($Q12:$AA12)>0),1,0),IF('01_Criterios'!$C$18="Automática",IF(AND($AN12=1,$AO12<>"",$AO12<=INDEX('01_Criterios'!$E$26:$E$36,MATCH($B12,'01_Criterios'!$B$26:$B$36,0))),1,0),0)))) -> 0 | AR12: =IF(AQ12=0,"",IF($AO12<>"",1+SUMPRODUCT(($B$5:$B$335=$B12)*($AQ$5:$AQ$335=1)*($AO$5:$AO$335<$AO12)),1+SUMPRODUCT(($B$5:$B$335=$B12)*($AQ$5:$AQ$335=1)*ISNUMBER($AO$5:$AO$335))+SUMPRODUCT(($B$5:$B$335=$B12)*($AQ$5:$AQ$335=1)*($AO$5:$AO$335="")*(ROW($AO$5:$AO$335)<ROW())))) | AS12: Indicador empresarial direto de informalidade/corrupção administrativa. | Nome local/API: Informal payments to public officials (% of firms)
A13: GOV05 | B13: 1. Governança e Estado de Direito | C13: 1. Governança | D13: WGI - Qualidade Regulatória | E13: -2.5 a 2.5 | F13: + | G13: -2.5 | H13: 2.5 | I13: 0 | J13: 1 | K13: WGI/Banco Mundial | L13: RQ.EST | M13: Compilação interna BDA | N13: 0 | O13: GOV05 | P13: Alta | Q13: -1.0904945 | R13: -1.1804235 | S13: -1.1799885 | T13: -1.0624393 | U13: -0.9960854 | V13: -1.0388818 | W13: -0.8486184 | X13: -0.8618821 | Y13: -0.904342 | Z13: -0.77302 | AB13: =COUNT(Q13:AA13) -> 10 | AC13: =AB13/11 -> 0.90909091 | AD13: =IFERROR(INDEX($Q$4:$AA$4,MATCH(TRUE,INDEX(ISNUMBER(Q13:AA13),0),0)),"") -> 2015 | AE13: =IFERROR(LOOKUP(2,1/ISNUMBER(Q13:AA13),$Q$4:$AA$4),"") -> 2024 | AF13: =IF(AB13=0,"",AB13/(AE13-AD13+1)) -> 1 | AG13: =IF(AB13=0,"",'01_Criterios'!$C$8-AE13) -> 1 | AH13: =IF(P13="Em uso",100,IF(P13="Alta",85,IF(P13="Média",55,30))) -> 85 | AI13: =ROUND(100*AC13,1) -> 90.9 | AJ13: =IF(AB13=0,0,ROUND(MAX(0,100*AF13-10*AG13),1)) -> 90 | AK13: =ROUND(('01_Criterios'!$C$19*AH13+'01_Criterios'!$C$20*AI13+'01_Criterios'!$C$21*AJ13)/('01_Criterios'!$C$19+'01_Criterios'!$C$20+'01_Criterios'!$C$21)+N13*'01_Criterios'!$C$22,1) -> 88.3 | AL13: =IF(AND(AB13>=3,AC13>='01_Criterios'!$C$11,N(AE13)>='01_Criterios'!$C$12,OR(F13="+",F13="-"),ISNUMBER(G13),ISNUMBER(H13)),1,0) -> 1 | AM13: =IF(AL13=1,"",TRIM(IF(AB13=0,"sem dados no período; ",IF(AB13<3,"série demasiado curta; ",""))&IF(AND(AB13>0,AC13<'01_Criterios'!$C$11),"cobertura insuficiente; ","")&IF(AND(AB13>0,N(AE13)<'01_Criterios'!$C$12),"desactualizado; ","")&IF(AND(F13<>"+",F13<>"-"),"sentido ambíguo; ","")&IF(OR(NOT(ISNUMBER(G13)),NOT(ISNUMBER(H13))),"sem limites min/max; ",""))) | AN13: =IF(OR(AL13=0,$AP13="Excluir"),0,IF(SUMPRODUCT(($O$5:$O$335=$O13)*($AL$5:$AL$335=1)*($AP$5:$AP$335<>"Excluir")*(($AK$5:$AK$335>$AK13)+(($AK$5:$AK$335=$AK13)*(ROW($O$5:$O$335)<ROW()))))=0,1,0)) -> 1 | AO13: =IF(AN13=0,"",1+SUMPRODUCT(($B$5:$B$335=$B13)*($AN$5:$AN$335=1)*(($AK$5:$AK$335>$AK13)+(($AK$5:$AK$335=$AK13)*(ROW($B$5:$B$335)<ROW()))))) -> 5 | AP13: Auto | AQ13: =IF(INDEX('01_Criterios'!$C$26:$C$36,MATCH($B13,'01_Criterios'!$B$26:$B$36,0))<>1,0,IF($AP13="Excluir",0,IF($AP13="Incluir",IF(AND(OR($F13="+",$F13="-"),ISNUMBER($G13),ISNUMBER($H13),COUNT($Q13:$AA13)>0),1,0),IF('01_Criterios'!$C$18="Automática",IF(AND($AN13=1,$AO13<>"",$AO13<=INDEX('01_Criterios'!$E$26:$E$36,MATCH($B13,'01_Criterios'!$B$26:$B$36,0))),1,0),0)))) -> 1 | AR13: =IF(AQ13=0,"",IF($AO13<>"",1+SUMPRODUCT(($B$5:$B$335=$B13)*($AQ$5:$AQ$335=1)*($AO$5:$AO$335<$AO13)),1+SUMPRODUCT(($B$5:$B$335=$B13)*($AQ$5:$AQ$335=1)*ISNUMBER($AO$5:$AO$335))+SUMPRODUCT(($B$5:$B$335=$B13)*($AQ$5:$AQ$335=1)*($AO$5:$AO$335="")*(ROW($AO$5:$AO$335)<ROW())))) -> 5 | AS13: Bom substituto para Doing Business, que foi descontinuado. Cobertura estimada pela periodicidade WGI; o endpoint WDI simples não devolve esta série.
A14: GOV06 | B14: 1. Governança e Estado de Direito | C14: 1. Governança | D14: WGI - Controlo da Corrupção | E14: -2.5 a 2.5 | F14: + | G14: -2.5 | H14: 2.5 | I14: 0 | J14: 1 | K14: WGI/Banco Mundial | L14: CC.EST | M14: Compilação interna BDA | N14: 0 | O14: GOV06 | P14: Alta | Q14: -1.4857649 | R14: -1.4881942 | S14: -1.4208093 | T14: -1.181782 | U14: -0.9647988 | V14: -0.8918323 | W14: -0.6416506 | X14: -0.6031537 | Y14: -0.6242518 | Z14: -0.6225793 | AB14: =COUNT(Q14:AA14) -> 10 | AC14: =AB14/11 -> 0.90909091 | AD14: =IFERROR(INDEX($Q$4:$AA$4,MATCH(TRUE,INDEX(ISNUMBER(Q14:AA14),0),0)),"") -> 2015 | AE14: =IFERROR(LOOKUP(2,1/ISNUMBER(Q14:AA14),$Q$4:$AA$4),"") -> 2024 | AF14: =IF(AB14=0,"",AB14/(AE14-AD14+1)) -> 1 | AG14: =IF(AB14=0,"",'01_Criterios'!$C$8-AE14) -> 1 | AH14: =IF(P14="Em uso",100,IF(P14="Alta",85,IF(P14="Média",55,30))) -> 85 | AI14: =ROUND(100*AC14,1) -> 90.9 | AJ14: =IF(AB14=0,0,ROUND(MAX(0,100*AF14-10*AG14),1)) -> 90 | AK14: =ROUND(('01_Criterios'!$C$19*AH14+'01_Criterios'!$C$20*AI14+'01_Criterios'!$C$21*AJ14)/('01_Criterios'!$C$19+'01_Criterios'!$C$20+'01_Criterios'!$C$21)+N14*'01_Criterios'!$C$22,1) -> 88.3 | AL14: =IF(AND(AB14>=3,AC14>='01_Criterios'!$C$11,N(AE14)>='01_Criterios'!$C$12,OR(F14="+",F14="-"),ISNUMBER(G14),ISNUMBER(H14)),1,0) -> 1 | AM14: =IF(AL14=1,"",TRIM(IF(AB14=0,"sem dados no período; ",IF(AB14<3,"série demasiado curta; ",""))&IF(AND(AB14>0,AC14<'01_Criterios'!$C$11),"cobertura insuficiente; ","")&IF(AND(AB14>0,N(AE14)<'01_Criterios'!$C$12),"desactualizado; ","")&IF(AND(F14<>"+",F14<>"-"),"sentido ambíguo; ","")&IF(OR(NOT(ISNUMBER(G14)),NOT(ISNUMBER(H14))),"sem limites min/max; ",""))) | AN14: =IF(OR(AL14=0,$AP14="Excluir"),0,IF(SUMPRODUCT(($O$5:$O$335=$O14)*($AL$5:$AL$335=1)*($AP$5:$AP$335<>"Excluir")*(($AK$5:$AK$335>$AK14)+(($AK$5:$AK$335=$AK14)*(ROW($O$5:$O$335)<ROW()))))=0,1,0)) -> 0 | AO14: =IF(AN14=0,"",1+SUMPRODUCT(($B$5:$B$335=$B14)*($AN$5:$AN$335=1)*(($AK$5:$AK$335>$AK14)+(($AK$5:$AK$335=$AK14)*(ROW($B$5:$B$335)<ROW()))))) | AP14: Excluir | AQ14: =IF(INDEX('01_Criterios'!$C$26:$C$36,MATCH($B14,'01_Criterios'!$B$26:$B$36,0))<>1,0,IF($AP14="Excluir",0,IF($AP14="Incluir",IF(AND(OR($F14="+",$F14="-"),ISNUMBER($G14),ISNUMBER($H14),COUNT($Q14:$AA14)>0),1,0),IF('01_Criterios'!$C$18="Automática",IF(AND($AN14=1,$AO14<>"",$AO14<=INDEX('01_Criterios'!$E$26:$E$36,MATCH($B14,'01_Criterios'!$B$26:$B$36,0))),1,0),0)))) -> 0 | AR14: =IF(AQ14=0,"",IF($AO14<>"",1+SUMPRODUCT(($B$5:$B$335=$B14)*($AQ$5:$AQ$335=1)*($AO$5:$AO$335<$AO14)),1+SUMPRODUCT(($B$5:$B$335=$B14)*($AQ$5:$AQ$335=1)*ISNUMBER($AO$5:$AO$335))+SUMPRODUCT(($B$5:$B$335=$B14)*($AQ$5:$AQ$335=1)*($AO$5:$AO$335="")*(ROW($AO$5:$AO$335)<ROW())))) | AS14: Excluído por anti-duplicação (conceito já representado).
A15: GOV008 | B15: 1. Governança e Estado de Direito | C15: 1. Governança | D15: WGI - Voz e Responsabilização | E15: -2.5 a 2.5 | F15: + | G15: -2.5 | H15: 2.5 | I15: 0 | J15: 1 | K15: WGI/Banco Mundial | L15: VA.EST | M15: Compilação interna BDA | N15: 0 | O15: GOV008 | P15: Média | Q15: -1.1542998 | R15: -1.19498 | S15: -1.131561 | T15: -1.005668 | U15: -0.9382176 | V15: -0.9376898 | W15: -0.9985085 | X15: -1.0480912 | Y15: -1.020936 | Z15: -1.0588932 | AB15: =COUNT(Q15:AA15) -> 10 | AC15: =AB15/11 -> 0.90909091 | AD15: =IFERROR(INDEX($Q$4:$AA$4,MATCH(TRUE,INDEX(ISNUMBER(Q15:AA15),0),0)),"") -> 2015 | AE15: =IFERROR(LOOKUP(2,1/ISNUMBER(Q15:AA15),$Q$4:$AA$4),"") -> 2024 | AF15: =IF(AB15=0,"",AB15/(AE15-AD15+1)) -> 1 | AG15: =IF(AB15=0,"",'01_Criterios'!$C$8-AE15) -> 1 | AH15: =IF(P15="Em uso",100,IF(P15="Alta",85,IF(P15="Média",55,30))) -> 55 | AI15: =ROUND(100*AC15,1) -> 90.9 | AJ15: =IF(AB15=0,0,ROUND(MAX(0,100*AF15-10*AG15),1)) -> 90 | AK15: =ROUND(('01_Criterios'!$C$19*AH15+'01_Criterios'!$C$20*AI15+'01_Criterios'!$C$21*AJ15)/('01_Criterios'!$C$19+'01_Criterios'!$C$20+'01_Criterios'!$C$21)+N15*'01_Criterios'!$C$22,1) -> 76.3 | AL15: =IF(AND(AB15>=3,AC15>='01_Criterios'!$C$11,N(AE15)>='01_Criterios'!$C$12,OR(F15="+",F15="-"),ISNUMBER(G15),ISNUMBER(H15)),1,0) -> 1 | AM15: =IF(AL15=1,"",TRIM(IF(AB15=0,"sem dados no período; ",IF(AB15<3,"série demasiado curta; ",""))&IF(AND(AB15>0,AC15<'01_Criterios'!$C$11),"cobertura insuficiente; ","")&IF(AND(AB15>0,N(AE15)<'01_Criterios'!$C$12),"desactualizado; ","")&IF(AND(F15<>"+",F15<>"-"),"sentido ambíguo; ","")&IF(OR(NOT(ISNUMBER(G15)),NOT(ISNUMBER(H15))),"sem limites min/max; ",""))) | AN15: =IF(OR(AL15=0,$AP15="Excluir"),0,IF(SUMPRODUCT(($O$5:$O$335=$O15)*($AL$5:$AL$335=1)*($AP$5:$AP$335<>"Excluir")*(($AK$5:$AK$335>$AK15)+(($AK$5:$AK$335=$AK15)*(ROW($O$5:$O$335)<ROW()))))=0,1,0)) -> 1 | AO15: =IF(AN15=0,"",1+SUMPRODUCT(($B$5:$B$335=$B15)*($AN$5:$AN$335=1)*(($AK$5:$AK$335>$AK15)+(($AK$5:$AK$335=$AK15)*(ROW($B$5:$B$335)<ROW()))))) -> 6 | AP15: Auto | AQ15: =IF(INDEX('01_Criterios'!$C$26:$C$36,MATCH($B15,'01_Criterios'!$B$26:$B$36,0))<>1,0,IF($AP15="Excluir",0,IF($AP15="Incluir",IF(AND(OR($F15="+",$F15="-"),ISNUMBER($G15),ISNUMBER($H15),COUNT($Q15:$AA15)>0),1,0),IF('01_Criterios'!$C$18="Automática",IF(AND($AN15=1,$AO15<>"",$AO15<=INDEX('01_Criterios'!$E$26:$E$36,MATCH($B15,'01_Criterios'!$B$26:$B$36,0))),1,0),0)))) -> 0 | AR15: =IF(AQ15=0,"",IF($AO15<>"",1+SUMPRODUCT(($B$5:$B$335=$B15)*($AQ$5:$AQ$335=1)*($AO$5:$AO$335<$AO15)),1+SUMPRODUCT(($B$5:$B$335=$B15)*($AQ$5:$AQ$335=1)*ISNUMBER($AO$5:$AO$335))+SUMPRODUCT(($B$5:$B$335=$B15)*($AQ$5:$AQ$335=1)*($AO$5:$AO$335="")*(ROW($AO$5:$AO$335)<ROW())))) | AS15: Acrescenta dimensão de responsabilização pública e participação. Cobertura estimada pela periodicidade WGI; o endpoint WDI simples não devolve esta série.
A16: GOV010 | B16: 1. Governança e Estado de Direito | C16: 1. Governança | D16: Índice Ibrahim - Segurança e Estado de Direito | E16: 0-100 | F16: + | G16: 0 | H16: 100 | I16: 55 | J16: 1 | K16: Mo Ibrahim Foundation | L16: IIAG_SECRULE | M16: Mo Ibrahim Foundation | N16: 0 | O16: G_IIAG_SECRULE | P16: Média | Y16: 44.2 | AB16: =COUNT(Q16:AA16) -> 1 | AC16: =AB16/11 -> 0.090909091 | AD16: =IFERROR(INDEX($Q$4:$AA$4,MATCH(TRUE,INDEX(ISNUMBER(Q16:AA16),0),0)),"") -> 2023 | AE16: =IFERROR(LOOKUP(2,1/ISNUMBER(Q16:AA16),$Q$4:$AA$4),"") -> 2023 | AF16: =IF(AB16=0,"",AB16/(AE16-AD16+1)) -> 1 | AG16: =IF(AB16=0,"",'01_Criterios'!$C$8-AE16) -> 2 | AH16: =IF(P16="Em uso",100,IF(P16="Alta",85,IF(P16="Média",55,30))) -> 55 | AI16: =ROUND(100*AC16,1) -> 9.1 | AJ16: =IF(AB16=0,0,ROUND(MAX(0,100*AF16-10*AG16),1)) -> 80 | AK16: =ROUND(('01_Criterios'!$C$19*AH16+'01_Criterios'!$C$20*AI16+'01_Criterios'!$C$21*AJ16)/('01_Criterios'!$C$19+'01_Criterios'!$C$20+'01_Criterios'!$C$21)+N16*'01_Criterios'!$C$22,1) -> 45.2 | AL16: =IF(AND(AB16>=3,AC16>='01_Criterios'!$C$11,N(AE16)>='01_Criterios'!$C$12,OR(F16="+",F16="-"),ISNUMBER(G16),ISNUMBER(H16)),1,0) -> 0 | AM16: =IF(AL16=1,"",TRIM(IF(AB16=0,"sem dados no período; ",IF(AB16<3,"série demasiado curta; ",""))&IF(AND(AB16>0,AC16<'01_Criterios'!$C$11),"cobertura insuficiente; ","")&IF(AND(AB16>0,N(AE16)<'01_Criterios'!$C$12),"desactualizado; ","")&IF(AND(F16<>"+",F16<>"-"),"sentido ambíguo; ","")&IF(OR(NOT(ISNUMBER(G16)),NOT(ISNUMBER(H16))),"sem limites min/max; ",""))) -> série demasiado curta; cobertura insuficiente; | AN16: =IF(OR(AL16=0,$AP16="Excluir"),0,IF(SUMPRODUCT(($O$5:$O$335=$O16)*($AL$5:$AL$335=1)*($AP$5:$AP$335<>"Excluir")*(($AK$5:$AK$335>$AK16)+(($AK$5:$AK$335=$AK16)*(ROW($O$5:$O$335)<ROW()))))=0,1,0)) -> 0 | AO16: =IF(AN16=0,"",1+SUMPRODUCT(($B$5:$B$335=$B16)*($AN$5:$AN$335=1)*(($AK$5:$AK$335>$AK16)+(($AK$5:$AK$335=$AK16)*(ROW($B$5:$B$335)<ROW()))))) | AP16: Auto | AQ16: =IF(INDEX('01_Criterios'!$C$26:$C$36,MATCH($B16,'01_Criterios'!$B$26:$B$36,0))<>1,0,IF($AP16="Excluir",0,IF($AP16="Incluir",IF(AND(OR($F16="+",$F16="-"),ISNUMBER($G16),ISNUMBER($H16),COUNT($Q16:$AA16)>0),1,0),IF('01_Criterios'!$C$18="Automática",IF(AND($AN16=1,$AO16<>"",$AO16<=INDEX('01_Criterios'!$E$26:$E$36,MATCH($B16,'01_Criterios'!$B$26:$B$36,0))),1,0),0)))) -> 0 | AR16: =IF(AQ16=0,"",IF($AO16<>"",1+SUMPRODUCT(($B$5:$B$335=$B16)*($AQ$5:$AQ$335=1)*($AO$5:$AO$335<$AO16)),1+SUMPRODUCT(($B$5:$B$335=$B16)*($AQ$5:$AQ$335=1)*ISNUMBER($AO$5:$AO$335))+SUMPRODUCT(($B$5:$B$335=$B16)*($AQ$5:$AQ$335=1)*($AO$5:$AO$335="")*(ROW($AO$5:$AO$335)<ROW())))) | AS16: Aproxima governança de segurança, justiça e direitos no contexto africano. | IIAG 2024 scorecard/perfil; categoria Security & Rule of Law.
A17: GOV011 | B17: 1. Governança e Estado de Direito | C17: 1. Governança | D17: Open Budget Index | E17: 0-100 | F17: + | G17: 0 | H17: 100 | I17: 50 | J17: 1 | K17: International Budget Partnership | L17: OBI | M17: International Budget Partnership | N17: 0 | O17: GOV011 | P17: Média | Q17: 26 | S17: 25 | U17: 36 | W17: 30 | Y17: 26 | AB17: =COUNT(Q17:AA17) -> 5 | AC17: =AB17/11 -> 0.45454545 | AD17: =IFERROR(INDEX($Q$4:$AA$4,MATCH(TRUE,INDEX(ISNUMBER(Q17:AA17),0),0)),"") -> 2015 | AE17: =IFERROR(LOOKUP(2,1/ISNUMBER(Q17:AA17),$Q$4:$AA$4),"") -> 2023 | AF17: =IF(AB17=0,"",AB17/(AE17-AD17+1)) -> 0.55555556 | AG17: =IF(AB17=0,"",'01_Criterios'!$C$8-AE17) -> 2 | AH17: =IF(P17="Em uso",100,IF(P17="Alta",85,IF(P17="Média",55,30))) -> 55 | AI17: =ROUND(100*AC17,1) -> 45.5 | AJ17: =IF(AB17=0,0,ROUND(MAX(0,100*AF17-10*AG17),1)) -> 35.6 | AK17: =ROUND(('01_Criterios'!$C$19*AH17+'01_Criterios'!$C$20*AI17+'01_Criterios'!$C$21*AJ17)/('01_Criterios'!$C$19+'01_Criterios'!$C$20+'01_Criterios'!$C$21)+N17*'01_Criterios'!$C$22,1) -> 46.8 | AL17: =IF(AND(AB17>=3,AC17>='01_Criterios'!$C$11,N(AE17)>='01_Criterios'!$C$12,OR(F17="+",F17="-"),ISNUMBER(G17),ISNUMBER(H17)),1,0) -> 0 | AM17: =IF(AL17=1,"",TRIM(IF(AB17=0,"sem dados no período; ",IF(AB17<3,"série demasiado curta; ",""))&IF(AND(AB17>0,AC17<'01_Criterios'!$C$11),"cobertura insuficiente; ","")&IF(AND(AB17>0,N(AE17)<'01_Criterios'!$C$12),"desactualizado; ","")&IF(AND(F17<>"+",F17<>"-"),"sentido ambíguo; ","")&IF(OR(NOT(ISNUMBER(G17)),NOT(ISNUMBER(H17))),"sem limites min/max; ",""))) -> cobertura insuficiente; | AN17: =IF(OR(AL17=0,$AP17="Excluir"),0,IF(SUMPRODUCT(($O$5:$O$335=$O17)*($AL$5:$AL$335=1)*($AP$5:$AP$335<>"Excluir")*(($AK$5:$AK$335>$AK17)+(($AK$5:$AK$335=$AK17)*(ROW($O$5:$O$335)<ROW()))))=0,1,0)) -> 0 | AO17: =IF(AN17=0,"",1+SUMPRODUCT(($B$5:$B$335=$B17)*($AN$5:$AN$335=1)*(($AK$5:$AK$335>$AK17)+(($AK$5:$AK$335=$AK17)*(ROW($B$5:$B$335)<ROW()))))) | AP17: Auto | AQ17: =IF(INDEX('01_Criterios'!$C$26:$C$36,MATCH($B17,'01_Criterios'!$B$26:$B$36,0))<>1,0,IF($AP17="Excluir",0,IF($AP17="Incluir",IF(AND(OR($F17="+",$F17="-"),ISNUMBER($G17),ISNUMBER($H17),COUNT($Q17:$AA17)>0),1,0),IF('01_Criterios'!$C$18="Automática",IF(AND($AN17=1,$AO17<>"",$AO17<=INDEX('01_Criterios'!$E$26:$E$36,MATCH($B17,'01_Criterios'!$B$26:$B$36,0))),1,0),0)))) -> 0 | AR17: =IF(AQ17=0,"",IF($AO17<>"",1+SUMPRODUCT(($B$5:$B$335=$B17)*($AQ$5:$AQ$335=1)*($AO$5:$AO$335<$AO17)),1+SUMPRODUCT(($B$5:$B$335=$B17)*($AQ$5:$AQ$335=1)*ISNUMBER($AO$5:$AO$335))+SUMPRODUCT(($B$5:$B$335=$B17)*($AQ$5:$AQ$335=1)*($AO$5:$AO$335="")*(ROW($AO$5:$AO$335)<ROW())))) | AS17: Mede transparência orçamental, relevante para responsabilização fiscal. | IBP Open Budget Survey 2012-2023 (página de resultados de Angola 2023).
