Workbook

Sheet Índice
A1: IPP (Indice de Preços no Produtorl
A2: Designação | B2: Código CAE Rev-2 | C2: Ponderadores 2010 | D2: 2016_T4 | E2: 2017_T1 | F2: 2017_T2 | G2: 2017_T3 | H2: 2017_T4 | I2: 2018_T1 | J2: 2018_T2 | K2: 2018_T3 | L2: 2018_T4 | M2: 2019_T1 | N2: 2019_T2 | O2: 2019_T3 | P2: 2019_T4 | Q2: 2020_T1 | R2: 2020_T2 | S2: 2020_T3 | T2: 2020_T4 | U2: 2021T1 | V2: 2021T2 | W2: 2021T3 | X2: 2021T4 | Y2: 2022T1 | Z2: 2022T2 | AA2: 2022T3 | AB2: 2022_T4 | AC2: 2023_T1 | AD2: 2023_T2 | AE2: 2023_T3 | AF2: 2023_T4 | AG2: 2024_T1 | AH2: 2024_T2 | AI2: 2024_T3 | AJ2: 2024_T4 | AK2: Ponderadores 2019 | AL2: Jan-25 | AM2: Fev-25 | AN2: Mar-25 | AO2: Abr-25 | AP2: Mai-25 | AQ2: Jun-25 | AR2: Jul-25 | AS2: Ago-25 | AT2: Set-25 | AU2: Out-25 | AV2: Nov-25 | AW2: Dez-25 | AX2: Jan-26 | AY2: Fev-26 | AZ2: Mar-26
A3: INDÚSTRIA TOTAL | B3: BCDE | C3: 100 | D3: 122.60039 | E3: 143.63387 | F3: 137.41206 | G3: 130.87316 | H3: 157.66381 | I3: 172.21867 | J3: 176.27854 | K3: 187.36555 | L3: 148.16895 | M3: 186.6 | N3: 173.6 | O3: 167.47452 | P3: 173.30732 | Q3: 174.48815 | R3: 166.8246 | S3: 202.14573 | T3: 208.20436 | U3: 269.79739 | V3: 297.4 | W3: 316.9 | X3: 294.69913 | Y3: 358.50125 | Z3: 392.95324 | AA3: 353.03614 | AB3: 307.7 | AC3: 281.65209 | AD3: 274.82085 | AE3: 306.1 | AF3: 300.38896 | AG3: 296.89787 | AH3: 302.25029 | AI3: 286.41895 | AJ3: 270.16182 | AK3: 100 | AL3: 181.058 | AM3: 183.27706 | AN3: 191.33247 | AO3: 184.97247 | AP3: 177.48549 | AQ3: 188.14228 | AR3: 187.07853 | AS3: 182.73479 | AT3: 180.4136 | AU3: 174.82789 | AV3: 166.04684 | AW3: 164.2461 | AX3: 173.16006 | AY3: 178.52646 | AZ3: 254.60689
A4: Indústrias Extractivas | B4: B | C4: 87.2 | D4: 124.64472 | E4: 149.13962 | F4: 141.51563 | G4: 133.86461 | H4: 165.38497 | I4: 182.45602 | J4: 185.9037 | K4: 198.30495 | L4: 153.11642 | M4: 205.5 | N4: 183.5 | O4: 175.84987 | P4: 181.68163 | Q4: 183.69011 | R4: 173.33303 | S4: 211.39576 | T4: 220.64344 | U4: 287.95347 | V4: 319.3 | W4: 341.3 | X4: 316.18449 | Y4: 388.46311 | Z4: 427.64437 | AA4: 381.728 | AB4: 329 | AC4: 298.64328 | AD4: 290.35967 | AE4: 325.3 | AF4: 318.05702 | AG4: 313.35698 | AH4: 319.05441 | AI4: 300.51996 | AJ4: 281.78588 | AK4: 78.300091 | AL4: 199.28775 | AM4: 201.96864 | AN4: 212.13453 | AO4: 203.91103 | AP4: 194.28714 | AQ4: 207.26247 | AR4: 205.74557 | AS4: 200.09678 | AT4: 197.04872 | AU4: 189.78366 | AV4: 178.45331 | AW4: 176.01876 | AX4: 187.26582 | AY4: 193.97877 | AZ4: 291.00807
A5: Extracção de Petróleo | B5: 061_062 | C5: 85.3 | D5: 125.76818 | E5: 148.90143 | F5: 141.33143 | G5: 133.3579 | H5: 166.19 | I5: 182.65656 | J5: 185.21101 | K5: 199.05942 | L5: 150.14097 | M5: 183.6 | N5: 188.3 | O5: 179.24 | P5: 183.464 | Q5: 150.94776 | R5: 143.0168 | S5: 213.62034 | T5: 220.27135 | U5: 290.75818 | V5: 323.5 | W5: 344.8 | X5: 319.68606 | Y5: 390.35675 | Z5: 432.20778 | AA5: 386.38111 | AB5: 331.9 | AC5: 300.38284 | AD5: 291.72014 | AE5: 327.6 | AF5: 320.32861 | AG5: 313.55546 | AH5: 319.29354 | AI5: 302.54006 | AJ5: 282.76907 | AK5: 74.879159 | AL5: 192.74824 | AM5: 196.69872 | AN5: 207.22808 | AO5: 197.59514 | AP5: 194.50583 | AQ5: 208.14431 | AR5: 205.27819 | AS5: 199.55797 | AT5: 196.33429 | AU5: 188.32997 | AV5: 177.19021 | AW5: 174.71849 | AX5: 187.95515 | AY5: 196.25763 | AZ5: 294.82221
A6: Extracção de Diamantes | B6: 8991 | C6: 1.9 | D6: 75.084504 | E6: 131.74933 | F6: 123.88388 | G6: 125.94073 | H6: 117.9154 | I6: 148.06639 | J6: 174.4796 | K6: 200.65154 | L6: 225.21826 | M6: 150.65241 | N6: 104.9 | O6: 100.32934 | P6: 142.92114 | Q6: 140.81366 | R6: 103.63947 | S6: 114.5127 | T6: 117.42772 | U6: 164.35578 | V6: 133.1 | W6: 184.2 | X6: 160.55193 | Y6: 305.7947 | Z6: 227.11033 | AA6: 176.89727 | AB6: 199.2 | AC6: 222.27835 | AD6: 230.67241 | AE6: 224.4 | AF6: 218.18194 | AG6: 305.12061 | AH6: 309.03944 | AI6: 211.56512 | AJ6: 238.56907 | AK6: 3.0886928 | AL6: 366.77917 | AM6: 339.208 | AN6: 341.62971 | AO6: 366.70463 | AP6: 197.45778 | AQ6: 196.23687 | AR6: 226.27055 | AS6: 222.21303 | AT6: 223.09409 | AU6: 232.9401 | AV6: 215.60018 | AW6: 213.80582 | AX6: 178.03201 | AY6: 146.8853 | AZ6: 217.08237
A7: Resto das Indústrias Extractivas | B7: 081_091 | C7: 0 | D7: 103.54333 | E7: 101.35529 | F7: 101.35529 | G7: 101.35529 | H7: 101.35529 | I7: 148.26718 | J7: 166.6762 | K7: 166.6762 | L7: 163.22602 | M7: 178.9 | N7: 166.7 | O7: 172.53167 | P7: 177.76281 | Q7: 191.84133 | R7: 199.23704 | S7: 205.56603 | T7: 208.96256 | U7: 216.6075 | V7: 220.4 | W7: 222.3 | X7: 219.76917 | Y7: 226.71969 | Z7: 229.11064 | AA7: 230.99187 | AB7: 233.8 | AC7: 211.61441 | AD7: 217.06875 | AE7: 219.8 | AF7: 226.881 | AG7: 233.96545 | AH7: 236.85493 | AI7: 239.42609 | AJ7: 240.74293 | AK7: 0.33223913 | AL7: 117.53698 | AM7: 115.05257 | AN7: 115.22439 | AO7: 115.38997 | AP7: 115.54878 | AQ7: 115.7374 | AR7: 115.73128 | AS7: 115.92704 | AT7: 115.93129 | AU7: 116.20564 | AV7: 117.78865 | AW7: 117.78002 | AX7: 117.74865 | AY7: 118.18369 | AZ7: 118.64502
A8: Indústrias Transformadoras | B8: C | C8: 10.1 | D8: 106.07178 | E8: 108.06696 | F8: 108.79409 | G8: 109.01129 | H8: 106.85355 | I8: 113.82165 | J8: 115.46879 | K8: 115.5266 | L8: 107.54033 | M8: 125.5 | N8: 116.7 | O8: 111.5209 | P8: 126.90754 | Q8: 131.91422 | R8: 118.51439 | S8: 136.82762 | T8: 143.07198 | U8: 145.33988 | V8: 148.1 | W8: 150.9 | X8: 148.11329 | Y8: 155.50927 | Z8: 158.21934 | AA8: 159.54896 | AB8: 161.7 | AC8: 166.35208 | AD8: 170.23976 | AE8: 177.7 | AF8: 184.1213 | AG8: 190.12117 | AH8: 193.89314 | AI8: 197.2044 | AJ8: 198.03481 | AK8: 17.479131 | AL8: 118.96889 | AM8: 119.65499 | AN8: 120.2014 | AO8: 120.65345 | AP8: 120.93111 | AQ8: 121.60533 | AR8: 122.14446 | AS8: 122.76814 | AT8: 123.14255 | AU8: 123.73089 | AV8: 124.24937 | AW8: 124.853 | AX8: 125.4681 | AY8: 126.09826 | AZ8: 126.70697
A9: Indústrias alimentares, das bebidas e do Tabaco | B9: 10_12 | C9: 5.6 | D9: 105.38883 | E9: 102.14406 | F9: 103.30349 | G9: 103.43996 | H9: 101.36596 | I9: 101.41382 | J9: 104.52868 | K9: 103.25031 | L9: 97.534299 | M9: 93.2 | N9: 107.3 | O9: 96.774458 | P9: 113.68701 | Q9: 102.17972 | R9: 108.15193 | S9: 117.99624 | T9: 127.53628 | U9: 129.67048 | V9: 132.1 | W9: 135.4 | X9: 132.39016 | Y9: 139.18571 | Z9: 138.23 | AA9: 144.17292 | AB9: 145.3 | AC9: 149.23487 | AD9: 152.54897 | AE9: 155.7 | AF9: 161.66263 | AG9: 168.77863 | AH9: 172.72327 | AI9: 176.62305 | AJ9: 178.72138 | AK9: 10.82031 | AL9: 116.87027 | AM9: 117.38383 | AN9: 117.94671 | AO9: 118.18752 | AP9: 118.54994 | AQ9: 119.19754 | AR9: 119.37723 | AS9: 119.73139 | AT9: 120.00789 | AU9: 120.35367 | AV9: 120.66349 | AW9: 121.02162 | AX9: 121.44138 | AY9: 121.99846 | AZ9: 122.38612
A10: Indústrias Alimentares | B10: 101_108 | C10: 4.3 | D10: 103.185 | E10: 97.076839 | F10: 103.09763 | G10: 104.82419 | H10: 105.30873 | I10: 104.04939 | J10: 104.62642 | K10: 104.58377 | L10: 107.47387 | M10: 107.6 | N10: 107.4 | O10: 97.51458 | P10: 113.58407 | Q10: 110.32657 | R10: 114.25875 | S10: 119.25519 | T10: 129.27667 | U10: 131.50727 | V10: 133.9 | W10: 137.3 | X10: 134.23576 | Y10: 141.4474 | Z10: 143.95932 | AA10: 146.93475 | AB10: 148.2 | AC10: 152.0001 | AD10: 155.86831 | AE10: 159 | AF10: 164.79968 | AG10: 172.25253 | AH10: 176.48748 | AI10: 180.66181 | AJ10: 183.12824 | AK10: 8.3326045 | AL10: 115.35385 | AM10: 116.21804 | AN10: 116.73056 | AO10: 117.30922 | AP10: 117.5651 | AQ10: 118.06751 | AR10: 118.66411 | AS10: 119.00373 | AT10: 119.23105 | AU10: 119.58852 | AV10: 119.97504 | AW10: 120.34734 | AX10: 120.73752 | AY10: 121.1474 | AZ10: 121.60229
A11: Indústrias das bebidas e do Tabaco | B11: 11_12 | C11: 1.3 | D11: 112.86556 | E11: 120.2681 | F11: 103.37982 | G11: 97.614784 | H11: 86.060095 | I11: 90.958552 | J11: 103.47027 | K11: 97.614784 | L11: 65.65133 | M11: 90.3 | N11: 106.5 | O11: 94.26352 | P11: 112.25452 | Q11: 93.568595 | R11: 107.93232 | S11: 113.72513 | T11: 121.63181 | U11: 123.43901 | V11: 125.9 | W11: 129 | X11: 126.113 | Y11: 131.5127 | Z11: 132.74704 | AA11: 134.8031 | AB11: 135.7 | AC11: 139.85354 | AD11: 141.28777 | AE11: 144.7 | AF11: 151.01987 | AG11: 156.99311 | AH11: 159.95281 | AI11: 162.92112 | AJ11: 163.77066 | AK11: 2.4877055 | AL11: 119.27407 | AM11: 119.79208 | AN11: 120.30318 | AO11: 120.49395 | AP11: 120.9496 | AQ11: 121.77221 | AR11: 121.41788 | AS11: 122.16869 | AT11: 122.60992 | AU11: 122.91655 | AV11: 122.96946 | AW11: 123.28012 | AX11: 123.79895 | AY11: 124.84911 | AZ11: 125.01156
A12: Fabricação de téxteis, Vestuários e Calçados | B12: 13_15 | C12: 0.5 | D12: 112.43536 | E12: 119.8984 | F12: 119.8984 | G12: 129.92029 | H12: 130.61093 | I12: 129.04553 | J12: 132.15655 | K12: 129.92029 | L12: 151.71194 | M12: 156.3 | N12: 134.1 | O12: 131.2562 | P12: 151.71194 | Q12: 169.65694 | R12: 173.68618 | S12: 176.46323 | T12: 182.00861 | U12: 185.69584 | V12: 189.6 | W12: 194.8 | X12: 190.03195 | Y12: 200.21669 | Z12: 203.61808 | AA12: 205.85788 | AB12: 208 | AC12: 213.81627 | AD12: 218.06801 | AE12: 221.9 | AF12: 228.28171 | AG12: 235.05452 | AH12: 243.0758 | AI12: 248.28862 | AJ12: 248.55063 | AK12: 0.11581556 | AL12: 100.77729 | AM12: 100.46945 | AN12: 100.5195 | AO12: 100.8722 | AP12: 101.01483 | AQ12: 101.43343 | AR12: 102.19863 | AS12: 101.71829 | AT12: 101.97485 | AU12: 102.24097 | AV12: 103.06887 | AW12: 103.33819 | AX12: 104.21391 | AY12: 104.51094 | AZ12: 104.54803
A13: Indústrias de Madeira | B13: 16 | C13: 0.1 | D13: 113.00398 | E13: 113.00398 | F13: 110.18267 | G13: 110.00175 | H13: 100.42776 | I13: 98.022678 | J13: 103.24528 | K13: 110.00175 | L13: 89.226477 | M13: 90.7 | N13: 103.2 | O13: 105.85522 | P13: 117.39301 | Q13: 92.610914 | R13: 97.545182 | S13: 115.52862 | T13: 128.8509 | U13: 130.26641 | V13: 132.9 | W13: 134.4 | X13: 132.52214 | Y13: 139.34254 | Z13: 142.5977 | AA13: 149.44239 | AB13: 150.4 | AC13: 156.40461 | AD13: 159.19713 | AE13: 164.2 | AF13: 170.17265 | AG13: 178.88983 | AH13: 187.03352 | AI13: 190.29648 | AJ13: 190.4595 | AK13: 0.10460635 | AL13: 115.36631 | AM13: 115.86733 | AN13: 116.3789 | AO13: 117.22331 | AP13: 117.0006 | AQ13: 117.07909 | AR13: 118.85377 | AS13: 119.82122 | AT13: 120.35469 | AU13: 120.63023 | AV13: 122.46229 | AW13: 122.74274 | AX13: 123.91176 | AY13: 124.07152 | AZ13: 125.93697
A14: Fabricação de Pastas de Papel, Edição e Impressão | B14: 17_18 | C14: 0.2 | D14: 113.26667 | E14: 113.26667 | F14: 130.42507 | G14: 132.35596 | H14: 132.35596 | I14: 111.45621 | J14: 109.0895 | K14: 132.35596 | L14: 154.71391 | M14: 145.3 | N14: 111.5 | O14: 124.10057 | P14: 125.35468 | Q14: 144.22113 | R14: 144.24936 | S14: 148.41824 | T14: 154.13845 | U14: 156.23867 | V14: 159.5 | W14: 164 | X14: 159.91289 | Y14: 169.03613 | Z14: 170.67147 | AA14: 176.4743 | AB14: 179 | AC14: 182.60569 | AD14: 184.72107 | AE14: 186.4 | AF14: 190.06068 | AG14: 194.15728 | AH14: 199.05472 | AI14: 204.14452 | AJ14: 206.25242 | AK14: 0.76312583 | AL14: 107.57686 | AM14: 108.04403 | AN14: 108.59842 | AO14: 108.95955 | AP14: 109.13684 | AQ14: 109.63796 | AR14: 109.75952 | AS14: 109.99579 | AT14: 110.52952 | AU14: 110.67276 | AV14: 110.81389 | AW14: 110.95784 | AX14: 111.56944 | AY14: 112.03152 | AZ14: 112.6697
A15: Fabricação de Produtos Petrolíferos, Químicos e Outros | B15: 19_23 | C15: 3.4 | D15: 104.85417 | E15: 114.4885 | F15: 113.94576 | G15: 112.72092 | H15: 109.98818 | I15: 132.62807 | J15: 132.04131 | K15: 132.89934 | L15: 115.38597 | M15: 125.7 | N15: 130.5 | O15: 131.71437 | P15: 131.7555 | Q15: 135.23076 | R15: 133.06071 | S15: 162.49554 | T15: 162.99294 | U15: 165.19752 | V15: 168.1 | W15: 169.8 | X15: 167.69917 | Y15: 175.73772 | Z15: 179.13961 | AA15: 177.18976 | AB15: 180.8 | AC15: 186.67594 | AD15: 191.88152 | AE15: 207.9 | AF15: 215.51313 | AG15: 219.01639 | AH15: 221.32154 | AI15: 223.50947 | AJ15: 221.97055 | AK15: 3.3188208 | AL15: 106.847 | AM15: 107.31318 | AN15: 107.82398 | AO15: 108.07133 | AP15: 108.37755 | AQ15: 108.97115 | AR15: 109.94448 | AS15: 110.53654 | AT15: 110.91361 | AU15: 111.46798 | AV15: 112.47434 | AW15: 113.04112 | AX15: 113.24559 | AY15: 114.44863 | AZ15: 114.67632
A16: Indústrias Metalúrgicas | B16: 24_25 | C16: 0.3 | D16: 112.9423 | E16: 112.85154 | F16: 112.78838 | G16: 112.79705 | H16: 112.79659 | I16: 113.00695 | J16: 113.01263 | K16: 112.79705 | L16: 112.65448 | M16: 120.8 | N16: 113 | O16: 115.13587 | P16: 120.0915 | Q16: 123.3274 | R16: 123.3336 | S16: 128.45248 | T16: 136.76806 | U16: 140.15971 | V16: 144.1 | W16: 145.5 | X16: 143.25324 | Y16: 149.08085 | Z16: 152.41076 | AA16: 156.32749 | AB16: 160.4 | AC16: 163.42226 | AD16: 164.36106 | AE16: 167.8 | AF16: 171.5833 | AG16: 183.11801 | AH16: 189.5754 | AI16: 190.21405 | AJ16: 194.11808 | AK16: 1.927125 | AL16: 162.91848 | AM16: 163.62791 | AN16: 164.41884 | AO16: 165.07987 | AP16: 165.25909 | AQ16: 166.74478 | AR16: 167.58712 | AS16: 169.52354 | AT16: 170.49529 | AU16: 172.79212 | AV16: 173.7154 | AW16: 176.05905 | AX16: 178.40064 | AY16: 178.68098 | AZ16: 181.05909
A17: Fabricação de Máquinas, Equipamentos, Aparelhos e Automóveis | B17: 26_30 | C17: 0 | D17: 103.9906 | E17: 168.88638 | F17: 168.88638 | G17: 168.88638 | H17: 168.88638 | I17: 103.9906 | J17: 103.9906 | K17: 103.9906 | L17: 168.9 | M17: 114 | N17: 104 | O17: 119.20206 | P17: 120.63737 | Q17: 121.45986 | R17: 121.45986 | S17: 131.11051 | T17: 137.18765 | U17: 138.91983 | V17: 141.9 | W17: 147.1 | X17: 142.63994 | Y17: 149.46655 | Z17: 151.55692 | AA17: 156.18307 | AB17: 158.9 | AC17: 163.19787 | AD17: 165.9306 | AE17: 168.7 | AF17: 176.56074 | AG17: 186.49125 | AH17: 191.88555 | AI17: 194.86454 | AJ17: 198.03209 | AK17: 0.050170661 | AL17: 103.93625 | AM17: 104.38758 | AN17: 105.33896 | AO17: 105.3363 | AP17: 105.65177 | AQ17: 105.99572 | AR17: 107.1094 | AS17: 107.88212 | AT17: 108.5969 | AU17: 109.05437 | AV17: 110.20018 | AW17: 110.66441 | AX17: 110.76749 | AY17: 110.90692 | AZ17: 112.91721
A18: Fabricação de Mobiliário, Colchões e Outras | B18: 31_33 | C18: 0 | D18: 104.10075 | E18: 129.63214 | F18: 107.55241 | G18: 121.3675 | H18: 107.931 | I18: 111.39732 | J18: 78.686467 | K18: 121.36633 | L18: 111.83866 | M18: 113.3 | N18: 115.7 | O18: 127.62233 | P18: 133.62781 | Q18: 135.56163 | R18: 136.18842 | S18: 146.49917 | T18: 149.09535 | U18: 151.55921 | V18: 153.9 | W18: 159.9 | X18: 155.11974 | Y18: 163.71622 | Z18: 166.26657 | AA18: 169.35302 | AB18: 174.2 | AC18: 180.40987 | AD18: 186.03007 | AE18: 189.5 | AF18: 199.38244 | AG18: 206.59329 | AH18: 212.27159 | AI18: 212.96262 | AJ18: 216.037 | AK18: 0.39945448 | AL18: 104.98572 | AM18: 105.46761 | AN18: 106.11632 | AO18: 106.38067 | AP18: 106.58473 | AQ18: 107.24445 | AR18: 107.56819 | AS18: 107.74093 | AT18: 107.74093 | AU18: 107.95192 | AV18: 108.29794 | AW18: 108.51021 | AX18: 109.3179 | AY18: 109.42596 | AZ18: 110.22538
A19: Producão e Distribuição de Electricidade, Gás e Vapor | B19: D | C19: 1.7 | D19: 101.99275 | E19: 101.99275 | F19: 101.99275 | G19: 101.99275 | H19: 101.99275 | I19: 101.99275 | J19: 101.99275 | K19: 101.99275 | L19: 102 | M19: 102 | N19: 102 | O19: 119.21789 | P19: 119.21789 | Q19: 119.21789 | R19: 119.21789 | S19: 119.21789 | T19: 119.21789 | U19: 119.21789 | V19: 119.2 | W19: 119.2 | X19: 119.20596 | Y19: 119.21789 | Z19: 119.21789 | AA19: 119.21789 | AB19: 119.2 | AC19: 119.21734 | AD19: 119.2172 | AE19: 119.2 | AF19: 119.21702 | AG19: 119.21702 | AH19: 119.21702 | AI19: 119.21702 | AJ19: 119.21702 | AK19: 3.2863609 | AL19: 100 | AM19: 100 | AN19: 100 | AO19: 100 | AP19: 100 | AQ19: 111.54 | AR19: 111.54 | AS19: 111.54 | AT19: 111.54 | AU19: 111.54 | AV19: 111.54 | AW19: 111.54 | AX19: 111.54 | AY19: 111.54 | AZ19: 111.54
A20: Produçao e Distribuiçao de Electricidade | B20: 35 | C20: 1.7 | D20: 101.99275 | E20: 101.99275 | F20: 101.99275 | G20: 101.99275 | H20: 101.99275 | I20: 101.99275 | J20: 101.99275 | K20: 101.99275 | L20: 102 | M20: 102 | N20: 102 | O20: 119.21789 | P20: 119.21789 | Q20: 119.21789 | R20: 119.21789 | S20: 119.21789 | T20: 119.21789 | U20: 119.21789 | V20: 119.2 | W20: 119.2 | X20: 119.20596 | Y20: 119.21789 | Z20: 119.21789 | AA20: 119.21789 | AB20: 119.2 | AC20: 119.21734 | AD20: 119.2172 | AE20: 119.2 | AF20: 119.21702 | AG20: 119.21702 | AH20: 119.21702 | AI20: 119.21702 | AJ20: 119.21702 | AK20: 3.2863609 | AL20: 100 | AM20: 100 | AN20: 100 | AO20: 100 | AP20: 100 | AQ20: 111.54 | AR20: 111.54 | AS20: 111.54 | AT20: 111.54 | AU20: 111.54 | AV20: 111.54 | AW20: 111.54 | AX20: 111.54 | AY20: 111.54 | AZ20: 111.54
A21: Captação, Tratamento e Distribuição de Água e Saneamento | B21: E | C21: 0.9 | D21: 148.68834 | E21: 148.66458 | F21: 148.68834 | G21: 148.68834 | H21: 148.68834 | I21: 148.68834 | J21: 148.68834 | K21: 208.0173 | L21: 208.03361 | M21: 208 | N21: 148.7 | O21: 179.90974 | P21: 179.90974 | Q21: 199.12987 | R21: 199.12987 | S21: 199.12987 | T21: 200.04996 | U21: 200.04996 | V21: 200 | W21: 200 | X21: 200.01665 | Y21: 200 | Z21: 200 | AA21: 200 | AB21: 200 | AC21: 200 | AD21: 200 | AE21: 200 | AF21: 200 | AG21: 200 | AH21: 200 | AI21: 200 | AJ21: 200 | AK21: 0.93441661 | AL21: 100 | AM21: 100 | AN21: 100 | AO21: 100 | AP21: 100 | AQ21: 100 | AR21: 100 | AS21: 100 | AT21: 100 | AU21: 100 | AV21: 100 | AW21: 100 | AX21: 100 | AY21: 100 | AZ21: 100
A22: Captação, Tratamento e Distribuição de Água | B22: 36_37 | C22: 0.9 | D22: 148.68834 | E22: 148.66458 | F22: 148.68834 | G22: 148.68834 | H22: 148.68834 | I22: 148.68834 | J22: 148.68834 | K22: 208.0173 | L22: 208.03361 | M22: 208 | N22: 148.7 | O22: 179.90974 | P22: 179.90974 | Q22: 199.12987 | R22: 199.12987 | S22: 199.12987 | T22: 200.04996 | U22: 200.04996 | V22: 200 | W22: 200 | X22: 200.01665 | Y22: 200 | Z22: 200 | AA22: 200 | AB22: 200 | AC22: 200 | AD22: 200 | AE22: 200 | AF22: 200 | AG22: 200 | AH22: 200 | AI22: 200 | AJ22: 200 | AK22: 0.93441661 | AL22: 100 | AM22: 100 | AN22: 100 | AO22: 100 | AP22: 100 | AQ22: 100 | AR22: 100 | AS22: 100 | AT22: 100 | AU22: 100 | AV22: 100 | AW22: 100 | AX22: 100 | AY22: 100 | AZ22: 100
A23: TOTAL DE BENS | C23: ND | D23: ND | E23: ND | F23: ND | G23: ND | H23: ND | I23: ND | J23: ND | K23: ND | L23: ND | M23: ND | N23: ND | O23: ND | P23: ND | Q23: ND | R23: ND | S23: ND | T23: ND | U23: ND | V23: ND | W23: ND | X23: ND | Y23: ND | Z23: ND | AA23: ND | AB23: ND | AC23: ND | AD23: ND | AE23: ND | AF23: ND | AG23: ND | AH23: ND | AI23: ND | AJ23: ND | AK23: 100 | AL23: 179.85904 | AM23: 182.23253 | AN23: 190.34051 | AO23: 183.74962 | AP23: 177.24107 | AQ23: 187.59216 | AR23: 186.29065 | AS23: 182.34836 | AT23: 180.00552 | AU23: 174.31153 | AV23: 165.56648 | AW23: 163.75515 | AX23: 172.94484 | AY23: 178.5309 | AZ23: 254.55051
A24: Bens Intermédios (A1) | C24: 4.2 | D24: 103.81358 | E24: 104.8575 | F24: 104.70502 | G24: 104.75555 | H24: 104.44255 | I24: 144.90362 | J24: 160.89847 | K24: 161.42616 | L24: 160.87613 | M24: 163.1 | N24: 161.1 | O24: 164.74764 | P24: 171.75646 | Q24: 174.75772 | R24: 180.74445 | S24: 198.66146 | T24: 204.83929 | U24: 209.07821 | V24: 212.8 | W24: 214.8 | X24: 212.22607 | Y24: 219.24327 | Z24: 221.69198 | AA24: 223.52143 | AB24: 226.4 | AC24: 207.43111 | AD24: 212.71143 | AE24: 216.2 | AF24: 218.85951 | AG24: 230.34488 | AH24: 233.37798 | AI24: 235.92554 | AJ24: 237.17587 | AK24: 7.7242463 | AL24: 202.90831 | AM24: 194.23873 | AN24: 195.41687 | AO24: 203.80342 | AP24: 149.13678 | AQ24: 149.29572 | AR24: 159.56303 | AS24: 158.88243 | AT24: 159.54423 | AU24: 163.41504 | AV24: 158.42132 | AW24: 158.52532 | AX24: 147.5417 | AY24: 137.98118 | AZ24: 161.36873
A25: Bens de Investimentos (A2) | C25: ND | D25: ND | E25: ND | F25: ND | G25: ND | H25: ND | I25: ND | J25: ND | K25: ND | L25: ND | M25: ND | N25: ND | O25: ND | P25: ND | Q25: ND | R25: ND | S25: ND | T25: ND | U25: ND | V25: ND | W25: ND | X25: ND | Y25: ND | Z25: ND | AA25: ND | AB25: ND | AC25: ND | AD25: ND | AE25: ND | AF25: ND | AG25: ND | AH25: ND | AI25: ND | AJ25: ND | AK25: 0.83951658 | AL25: 103.93625 | AM25: 104.38758 | AN25: 105.33896 | AO25: 105.3363 | AP25: 105.65177 | AQ25: 105.99572 | AR25: 107.1094 | AS25: 107.88212 | AT25: 108.5969 | AU25: 109.05437 | AV25: 110.20018 | AW25: 110.66441 | AX25: 110.76749 | AY25: 110.90692 | AZ25: 112.91721
A26: Bens de Consumo (A3) | C26: 6.3 | D26: 106.0156 | E26: 105.30547 | F26: 106.41552 | G26: 107.38327 | H26: 105.56925 | I26: 103.82043 | J26: 106.7445 | K26: 105.69882 | L26: 103.64962 | M26: 94.8 | N26: 109.5 | O26: 114.8233 | P26: 117.21054 | Q26: 100.12107 | R26: 109.91756 | S26: 123.56544 | T26: 133.88332 | U26: 134.89877 | V26: 137.5 | W26: 141 | X26: 137.79959 | Y26: 144.89459 | Z26: 147.20885 | AA26: 149.99803 | AB26: 151.3 | AC26: 155.37197 | AD26: 158.74762 | AE26: 162 | AF26: 165.4516 | AG26: 175.09536 | AH26: 179.43065 | AI26: 183.42353 | AJ26: 185.39264 | AK26: 11.745873 | AL26: 116.25773 | AM26: 116.76166 | AN26: 117.32222 | AO26: 117.56265 | AP26: 117.91941 | AQ26: 118.32226 | AR26: 118.81785 | AS26: 119.13234 | AT26: 119.40417 | AU26: 119.75738 | AV26: 120.05262 | AW26: 120.4047 | AX26: 120.84523 | AY26: 121.35714 | AZ26: 121.78809
A27: Produtos de Energia (A4) | C27: 89.5 | D27: 124.68733 | E27: 146.52478 | F27: 139.37313 | G27: 131.84022 | H27: 162.858 | I27: 178.41462 | J27: 180.8279 | K27: 193.96701 | L27: 147.95111 | M27: 198.4 | N27: 202.7 | O27: 193.49804 | P27: 196.76462 | Q27: 197.75852 | R27: 187.70796 | S27: 209.24997 | T27: 221.47212 | U27: 282.75788 | V27: 313.9 | W27: 334.3 | X27: 310.31929 | Y27: 377.66819 | Z27: 417.54926 | AA27: 373.87969 | AB27: 322 | AC27: 291.92942 | AD27: 283.67447 | AE27: 317.9 | AF27: 312.97489 | AG27: 304.48198 | AH27: 309.94996 | AI27: 293.98508 | AJ27: 275.14473 | AK27: 79.690364 | AL27: 187.79919 | AM27: 191.53887 | AN27: 201.50638 | AO27: 192.38746 | AP27: 189.46299 | AQ27: 202.37373 | AR27: 199.66054 | AS27: 194.725 | AT27: 191.67334 | AU27: 184.09613 | AV27: 173.55079 | AW27: 171.21096 | AX27: 183.74131 | AY27: 191.60077 | AZ27: 284.90594
A28: Fonte: INE/Departamento de Estatísticas Económicas e Financeira
A29: ND (Não Disponível)

Sheet Variação periodo anterior
A1: Variação em relação ao período anterior
A2: Designação | B2: Código CAE Rev-2 | C2: 2016_T4 | D2: 2017_T1 | E2: 2017_T2 | F2: 2017_T3 | G2: 2017_T4 | H2: 2018_T1 | I2: 2018_T2 | J2: 2018_T3 | K2: 2018_T4 | L2: 2019_T1 | M2: 2019_T2 | N2: 2019_T3 | O2: 2019_T4 | P2: 2020_T1 | Q2: 2020_T2 | R2: 2020_T3 | S2: 2020_T4 | T2: 2021T1 | U2: 2021T2 | V2: 2021T3 | W2: 2021T4 | X2: 2022T1 | Y2: 2022T2 | Z2: 2022T3 | AA2: 2022_T4 | AB2: 2023_T1 | AC2: 2023_T2 | AD2: 2023_T3 | AE2: 2023_T4 | AF2: 2024_T1 | AG2: 2024_T2 | AH2: 2024_T3 | AI2: 2024_T4 | AJ2: Jan-25 | AK2: Fev-25 | AL2: Mar-25 | AM2: Abr-25 | AN2: Mai-25 | AO2: Jun-25 | AP2: Jul-25 | AQ2: Ago-25 | AR2: Set-25 | AS2: Out-25 | AT2: Nov-25 | AU2: Dez-25 | AV2: Jan-26 | AW2: Fev-26 | AX2: Mar-26
A3: INDÚSTRIA TOTAL | B3: BCDE | C3: =+Índice!D3/100*100-100 -> 22.600388 | D3: =+Índice!E3/Índice!D3*100-100 -> 17.156133 | E3: =+Índice!F3/Índice!E3*100-100 -> -4.3317163 | F3: =+Índice!G3/Índice!F3*100-100 -> -4.7586106 | G3: =+Índice!H3/Índice!G3*100-100 -> 20.470701 | H3: =+Índice!I3/Índice!H3*100-100 -> 9.2315832 | I3: =+Índice!J3/Índice!I3*100-100 -> 2.3573898 | J3: =+Índice!K3/Índice!J3*100-100 -> 6.2894829 | K3: =+Índice!L3/Índice!K3*100-100 -> -20.919856 | ... AI3: =+Índice!AJ3/Índice!AI3*100-100 -> -5.6759987 | AJ3: 1.6430308 | AK3: 1.2256093 | AL3: 4.3952075 | AM3: -3.3240565 | AN3: -4.0476178 | AO3: 6.0043143 | AP3: -0.56539828 | AQ3: -2.3218775 | AR3: -1.2702521 | AS3: -3.0960592 | AT3: -5.0226812 | AU3: -1.0844795 | AV3: 5.4272021 | AW3: 3.0990931 | AX3: 42.615775
A4: Indústrias Extractivas | B4: B | C4: =+Índice!D4/100*100-100 -> 24.644717 | D4: =+Índice!E4/Índice!D4*100-100 -> 19.651778 | E4: =+Índice!F4/Índice!E4*100-100 -> -5.1119845 | F4: =+Índice!G4/Índice!F4*100-100 -> -5.4064782 | G4: =+Índice!H4/Índice!G4*100-100 -> 23.546441 | H4: =+Índice!I4/Índice!H4*100-100 -> 10.322013 | I4: =+Índice!J4/Índice!I4*100-100 -> 1.8895932 | J4: =+Índice!K4/Índice!J4*100-100 -> 6.6707918 | K4: =+Índice!L4/Índice!K4*100-100 -> -22.787394 | ... AI4: =+Índice!AJ4/Índice!AI4*100-100 -> -6.2338878 | AJ4: 1.7947487 | AK4: 1.3452357 | AL4: 5.0333991 | AM4: -3.8765521 | AN4: -4.7196495 | AO4: 6.6784278 | AP4: -0.73187493 | AQ4: -2.7455179 | AR4: -1.523294 | AS4: -3.6869361 | AT4: -5.9701389 | AU4: -1.3642501 | AV4: 6.3896908 | AW4: 3.584717 | AX4: 50.02058
A5: Extracção de Petróleo | B5: 061_062 | C5: =+Índice!D5/100*100-100 -> 25.768185 | D5: =+Índice!E5/Índice!D5*100-100 -> 18.393559 | E5: =+Índice!F5/Índice!E5*100-100 -> -5.0838974 | F5: =+Índice!G5/Índice!F5*100-100 -> -5.6417281 | G5: =+Índice!H5/Índice!G5*100-100 -> 24.619537 | H5: =+Índice!I5/Índice!H5*100-100 -> 9.908279 | I5: =+Índice!J5/Índice!I5*100-100 -> 1.3984974 | J5: =+Índice!K5/Índice!J5*100-100 -> 7.4770979 | K5: =+Índice!L5/Índice!K5*100-100 -> -24.574797 | ... AI5: =+Índice!AJ5/Índice!AI5*100-100 -> -6.5349992 | AJ5: 2.9119752 | AK5: 2.0495536 | AL5: 5.3530409 | AM5: -4.6484707 | AN5: -1.5634563 | AO5: 7.0118647 | AP5: -1.3769893 | AQ5: -2.7865682 | AR5: -1.6154092 | AS5: -4.0768872 | AT5: -5.9150203 | AU5: -1.3949533 | AV5: 7.5759941 | AW5: 4.4172659 | AX5: 50.222038
A6: Extracção de Diamantes | B6: 8991 | C6: =+Índice!D6/100*100-100 -> -24.915496 | D6: =+Índice!E6/Índice!D6*100-100 -> 75.468075 | E6: =+Índice!F6/Índice!E6*100-100 -> -5.9700175 | F6: =+Índice!G6/Índice!F6*100-100 -> 1.6603048 | G6: =+Índice!H6/Índice!G6*100-100 -> -6.3723071 | H6: =+Índice!I6/Índice!H6*100-100 -> 25.570025 | I6: =+Índice!J6/Índice!I6*100-100 -> 17.838762 | J6: =+Índice!K6/Índice!J6*100-100 -> 15 | K6: =+Índice!L6/Índice!K6*100-100 -> 12.243473 | ... AI6: =+Índice!AJ6/Índice!AI6*100-100 -> 12.763892 | AJ6: -10.535406 | AK6: -7.5171036 | AL6: 0.71393258 | AM6: 7.3397948 | AN6: -46.153455 | AO6: -0.6183131 | AP6: 15.304813 | AQ6: -1.7932165 | AR6: 0.39649399 | AS6: 4.413386 | AT6: -7.4439402 | AU6: -0.83226097 | AV6: -16.731917 | AW6: -17.495006 | AX6: 47.790404
A7: Resto das Indústrias Extractivas | B7: 081_091 | C7: =+Índice!D7/100*100-100 -> 3.5433333 | D7: =+Índice!E7/Índice!D7*100-100 -> -2.113167 | E7: =+Índice!F7/Índice!E7*100-100 -> 0 | F7: =+Índice!G7/Índice!F7*100-100 -> 0 | G7: =+Índice!H7/Índice!G7*100-100 -> 0 | H7: =+Índice!I7/Índice!H7*100-100 -> 46.284598 | I7: =+Índice!J7/Índice!I7*100-100 -> 12.416113 | J7: =+Índice!K7/Índice!J7*100-100 -> 0 | K7: =+Índice!L7/Índice!K7*100-100 -> -2.0699868 | ... AI7: =+Índice!AJ7/Índice!AI7*100-100 -> 0.55 | AJ7: 0 | AK7: -2.1137254 | AL7: 0.14933394 | AM7: 0.14370716 | AN7: 0.13762903 | AO7: 0.16323844 | AP7: -0.0052886313 | AQ7: 0.16914734 | AR7: 0.0036669172 | AS7: 0.236652 | AT7: 1.36225 | AU7: -0.0073330277 | AV7: -0.026634054 | AW7: 0.36946918 | AX7: 0.39035033
A8: Indústrias Transformadoras | B8: C | C8: =+Índice!D8/100*100-100 -> 6.0717798 | D8: =+Índice!E8/Índice!D8*100-100 -> 1.880968 | E8: =+Índice!F8/Índice!E8*100-100 -> 0.67285256 | F8: =+Índice!G8/Índice!F8*100-100 -> 0.19964217 | G8: =+Índice!H8/Índice!G8*100-100 -> -1.9793709 | H8: =+Índice!I8/Índice!H8*100-100 -> 6.5211725 | I8: =+Índice!J8/Índice!I8*100-100 -> 1.4471246 | J8: =+Índice!K8/Índice!J8*100-100 -> 0.050065104 | K8: =+Índice!L8/Índice!K8*100-100 -> -6.9129262 | ... AI8: =+Índice!AJ8/Índice!AI8*100-100 -> 0.42109301 | AJ8: 0.85142971 | AK8: 0.57670529 | AL8: 0.45665514 | AM8: 0.37607076 | AN8: 0.23013039 | AO8: 0.55752668 | AP8: 0.44334751 | AQ8: 0.51060564 | AR8: 0.30497025 | AS8: 0.4777737 | AT8: 0.4190366 | AU8: 0.48582698 | AV8: 0.49265632 | AW8: 0.50224496 | AX8: 0.48273021
A9: Indústrias alimentares, das bebidas e do Tabaco | B9: 10_12 | C9: =+Índice!D9/100*100-100 -> 5.3888341 | D9: =+Índice!E9/Índice!D9*100-100 -> -3.0788555 | E9: =+Índice!F9/Índice!E9*100-100 -> 1.1350867 | F9: =+Índice!G9/Índice!F9*100-100 -> 0.13211183 | G9: =+Índice!H9/Índice!G9*100-100 -> -2.0050362 | H9: =+Índice!I9/Índice!H9*100-100 -> 0.047221215 | I9: =+Índice!J9/Índice!I9*100-100 -> 3.0714332 | J9: =+Índice!K9/Índice!J9*100-100 -> -1.2229867 | K9: =+Índice!L9/Índice!K9*100-100 -> -5.5360694 | ... AI9: =+Índice!AJ9/Índice!AI9*100-100 -> 1.1880312 | AJ9: 0.74762335 | AK9: 0.43942695 | AL9: 0.47952264 | AM9: 0.20416938 | AN9: 0.30664833 | AO9: 0.54626859 | AP9: 0.15075066 | AQ9: 0.29666901 | AR9: 0.23093647 | AS9: 0.28812862 | AT9: 0.2574267 | AU9: 0.2967981 | AV9: 0.34684933 | AW9: 0.45872409 | AX9: 0.31775694
A10: Indústrias Alimentares | B10: 101_108 | C10: =+Índice!D10/100*100-100 -> 3.185 | D10: =+Índice!E10/Índice!D10*100-100 -> -5.9196209 | E10: =+Índice!F10/Índice!E10*100-100 -> 6.2020908 | F10: =+Índice!G10/Índice!F10*100-100 -> 1.6746817 | G10: =+Índice!H10/Índice!G10*100-100 -> 0.46224183 | H10: =+Índice!I10/Índice!H10*100-100 -> -1.1958597 | I10: =+Índice!J10/Índice!I10*100-100 -> 0.55457162 | J10: =+Índice!K10/Índice!J10*100-100 -> -0.040763709 | K10: =+Índice!L10/Índice!K10*100-100 -> 2.7634376 | ... AI10: =+Índice!AJ10/Índice!AI10*100-100 -> 1.36522 | AJ10: 0.98828665 | AK10: 0.74917167 | AL10: 0.44099552 | AM10: 0.49571991 | AN10: 0.21813075 | AO10: 0.42734084 | AP10: 0.50530679 | AQ10: 0.28619976 | AR10: 0.19102254 | AS10: 0.29980974 | AT10: 0.3232114 | AU10: 0.31031141 | AV10: 0.32421677 | AW10: 0.3394739 | AX10: 0.37548971
A11: Indústrias das bebidas e do Tabaco | B11: 11_12 | C11: =+Índice!D11/100*100-100 -> 12.86556 | D11: =+Índice!E11/Índice!D11*100-100 -> 6.5587237 | E11: =+Índice!F11/Índice!E11*100-100 -> -14.042191 | F11: =+Índice!G11/Índice!F11*100-100 -> -5.5765619 | G11: =+Índice!H11/Índice!G11*100-100 -> -11.837028 | H11: =+Índice!I11/Índice!H11*100-100 -> 5.6919024 | I11: =+Índice!J11/Índice!I11*100-100 -> 13.755407 | J11: =+Índice!K11/Índice!J11*100-100 -> -5.6591002 | K11: =+Índice!L11/Índice!K11*100-100 -> -32.74448 | ... AI11: =+Índice!AJ11/Índice!AI11*100-100 -> 0.5214425 | AJ11: 0.74257046 | AK11: 0.43430761 | AL11: 0.4266562 | AM11: 0.15856941 | AN11: 0.37815056 | AO11: 0.68012608 | AP11: -0.29097094 | AQ11: 0.61836701 | AR11: 0.36116522 | AS11: 0.25008074 | AT11: 0.043045918 | AU11: 0.25263729 | AV11: 0.42085397 | AW11: 0.84827674 | AX11: 0.13011375
A12: Fabricação de téxteis, Vestuários e Calçados | B12: 13_15 | C12: =+Índice!D12/100*100-100 -> 12.435362 | D12: =+Índice!E12/Índice!D12*100-100 -> 6.6376252 | E12: =+Índice!F12/Índice!E12*100-100 -> 0 | F12: =+Índice!G12/Índice!F12*100-100 -> 8.3586506 | G12: =+Índice!H12/Índice!G12*100-100 -> 0.53158863 | H12: =+Índice!I12/Índice!H12*100-100 -> -1.1985236 | I12: =+Índice!J12/Índice!I12*100-100 -> 2.4107924 | J12: =+Índice!K12/Índice!J12*100-100 -> -1.6921284 | K12: =+Índice!L12/Índice!K12*100-100 -> 16.773097 | ... AI12: =+Índice!AJ12/Índice!AI12*100-100 -> 0.10552458 | AJ12: -0.23679671 | AK12: -0.30547246 | AL12: 0.049822605 | AM12: 0.35087617 | AN12: 0.1413996 | AO12: 0.41439476 | AP12: 0.75437877 | AQ12: -0.46999982 | AR12: 0.25222315 | AS12: 0.26096931 | AT12: 0.80974505 | AU12: 0.26130576 | AV12: 0.84742755 | AW12: 0.28502436 | AX12: 0.03548638
A13: Indústrias de Madeira | B13: 16 | C13: =+Índice!D13/100*100-100 -> 13.00398 | D13: =+Índice!E13/Índice!D13*100-100 -> 0 | E13: =+Índice!F13/Índice!E13*100-100 -> -2.4966456 | F13: =+Índice!G13/Índice!F13*100-100 -> -0.164199 | G13: =+Índice!H13/Índice!G13*100-100 -> -8.703491 | H13: =+Índice!I13/Índice!H13*100-100 -> -2.3948376 | I13: =+Índice!J13/Índice!I13*100-100 -> 5.3279553 | J13: =+Índice!K13/Índice!J13*100-100 -> 6.5440955 | K13: =+Índice!L13/Índice!K13*100-100 -> -18.886313 | ... AI13: =+Índice!AJ13/Índice!AI13*100-100 -> 0.0856652 | AJ13: 0.74254724 | AK13: 0.43428411 | AL13: 0.44151554 | AM13: 0.72556692 | AN13: -0.18999011 | AO13: 0.067087289 | AP13: 1.5157974 | AQ13: 0.81398324 | AR13: 0.44522415 | AS13: 0.22893475 | AT13: 1.51874 | AU13: 0.22901031 | AV13: 0.95241557 | AW13: 0.12893403 | AX13: 1.5035265
A14: Fabricação de Pastas de Papel, Edição e Impressão | B14: 17_18 | C14: =+Índice!D14/100*100-100 -> 13.266667 | D14: =+Índice!E14/Índice!D14*100-100 -> 0 | E14: =+Índice!F14/Índice!E14*100-100 -> 15.148683 | F14: =+Índice!G14/Índice!F14*100-100 -> 1.4804564 | G14: =+Índice!H14/Índice!G14*100-100 -> 0 | H14: =+Índice!I14/Índice!H14*100-100 -> -15.790563 | I14: =+Índice!J14/Índice!I14*100-100 -> -2.1234409 | J14: =+Índice!K14/Índice!J14*100-100 -> 21.327862 | K14: =+Índice!L14/Índice!K14*100-100 -> 16.89229 | ... AI14: =+Índice!AJ14/Índice!AI14*100-100 -> 1.032553 | AJ14: 0.74252722 | AK14: 0.43426385 | AL14: 0.51311815 | AM14: 0.33254182 | AN14: 0.16271142 | AO14: 0.45916209 | AP14: 0.110877 | AQ14: 0.21526291 | AR14: 0.48522155 | AS14: 0.12959598 | AT14: 0.12751848 | AU14: 0.12990951 | AV14: 0.55119416 | AW14: 0.41416185 | AX14: 0.56964289
A15: Fabricação de Produtos Petrolíferos, Químicos e Outros | B15: 19_23 | C15: =+Índice!D15/100*100-100 -> 4.8541724 | D15: =+Índice!E15/Índice!D15*100-100 -> 9.1883071 | E15: =+Índice!F15/Índice!E15*100-100 -> -0.47405222 | F15: =+Índice!G15/Índice!F15*100-100 -> -1.0749301 | G15: =+Índice!H15/Índice!G15*100-100 -> -2.4243402 | H15: =+Índice!I15/Índice!H15*100-100 -> 20.583929 | I15: =+Índice!J15/Índice!I15*100-100 -> -0.44240977 | J15: =+Índice!K15/Índice!J15*100-100 -> 0.64981545 | K15: =+Índice!L15/Índice!K15*100-100 -> -13.177921 | ... AI15: =+Índice!AJ15/Índice!AI15*100-100 -> -0.6885254 | AJ15: 0.74454755 | AK15: 0.43630892 | AL15: 0.47598796 | AM15: 0.22940081 | AN15: 0.28335424 | AO15: 0.5477141 | AP15: 0.89319902 | AQ15: 0.53850626 | AR15: 0.34112541 | AS15: 0.49982135 | AT15: 0.90283177 | AU15: 0.50391593 | AV15: 0.18087951 | AW15: 1.0623306 | AX15: 0.19894502
A16: Indústrias Metalúrgicas | B16: 24_25 | C16: =+Índice!D16/100*100-100 -> 12.942297 | D16: =+Índice!E16/Índice!D16*100-100 -> -0.080360337 | E16: =+Índice!F16/Índice!E16*100-100 -> -0.055963326 | F16: =+Índice!G16/Índice!F16*100-100 -> 0.0076892606 | G16: =+Índice!H16/Índice!G16*100-100 -> -0.00041103453 | H16: =+Índice!I16/Índice!H16*100-100 -> 0.1864982 | I16: =+Índice!J16/Índice!I16*100-100 -> 0.0050262941 | J16: =+Índice!K16/Índice!J16*100-100 -> -0.19075746 | K16: =+Índice!L16/Índice!K16*100-100 -> -0.12640104 | ... AI16: =+Índice!AJ16/Índice!AI16*100-100 -> 2.0524415 | AJ16: 0.74369914 | AK16: 0.43544982 | AL16: 0.4833742 | AM16: 0.40204002 | AN16: 0.10856295 | AO16: 0.89900523 | AP16: 0.50517194 | AQ16: 1.1554689 | AR16: 0.57322514 | AS16: 1.3471473 | AT16: 0.5343303 | AU16: 1.3491322 | AV16: 1.3300068 | AW16: 0.15713616 | AX16: 1.3309259
A17: Fabricação de Máquinas, Equipamentos, Aparelhos e Automóveis | B17: 26_30 | C17: =+Índice!D17/100*100-100 -> 3.9905964 | D17: =+Índice!E17/Índice!D17*100-100 -> 62.405431 | E17: =+Índice!F17/Índice!E17*100-100 -> 0 | F17: =+Índice!G17/Índice!F17*100-100 -> 0 | G17: =+Índice!H17/Índice!G17*100-100 -> 0 | H17: =+Índice!I17/Índice!H17*100-100 -> -38.425705 | I17: =+Índice!J17/Índice!I17*100-100 -> 0 | J17: =+Índice!K17/Índice!J17*100-100 -> 0 | K17: =+Índice!L17/Índice!K17*100-100 -> 62.418532 | ... AI17: =+Índice!AJ17/Índice!AI17*100-100 -> 1.625514 | AJ17: 0.74250181 | AK17: 0.43423814 | AL17: 0.91139451 | AM17: -0.002529333 | AN17: 0.29949082 | AO17: 0.3255472 | AP17: 1.050685 | AQ17: 0.72143026 | AR17: 0.66255325 | AS17: 0.42125524 | AT17: 1.050685 | AU17: 0.42125524 | AV17: 0.093148026 | AW17: 0.12587746 | AX17: 1.8125877
A18: Fabricação de Mobiliário, Colchões e Outras | B18: 31_33 | C18: =+Índice!D18/100*100-100 -> 4.100752 | D18: =+Índice!E18/Índice!D18*100-100 -> 24.525653 | E18: =+Índice!F18/Índice!E18*100-100 -> -17.032602 | F18: =+Índice!G18/Índice!F18*100-100 -> 12.844978 | G18: =+Índice!H18/Índice!G18*100-100 -> -11.070919 | H18: =+Índice!I18/Índice!H18*100-100 -> 3.2116092 | I18: =+Índice!J18/Índice!I18*100-100 -> -29.364131 | J18: =+Índice!K18/Índice!J18*100-100 -> 54.240408 | K18: =+Índice!L18/Índice!K18*100-100 -> -7.8503375 | ... AI18: =+Índice!AJ18/Índice!AI18*100-100 -> 1.4436257 | AJ18: 0.76665975 | AK18: 0.45900613 | AL18: 0.61507715 | AM18: 0.249113 | AN18: 0.19181904 | AO18: 0.61896433 | AP18: 0.3018728 | AQ18: 0.16058802 | AR18: 0 | AS18: 0.1958256 | AT18: 0.32053061 | AU18: 0.19600494 | AV18: 0.74435145 | AW18: 0.098845329 | AX18: 0.73055654
A19: Producão e Distribuição de Electricidade, Gás e Vapor | B19: D | C19: =+Índice!D19/100*100-100 -> 1.9927536 | D19: =+Índice!E19/Índice!D19*100-100 -> 0 | E19: =+Índice!F19/Índice!E19*100-100 -> 0 | F19: =+Índice!G19/Índice!F19*100-100 -> 0 | G19: =+Índice!H19/Índice!G19*100-100 -> 0 | H19: =+Índice!I19/Índice!H19*100-100 -> 0 | I19: =+Índice!J19/Índice!I19*100-100 -> 0 | J19: =+Índice!K19/Índice!J19*100-100 -> 0 | K19: =+Índice!L19/Índice!K19*100-100 -> 0.0071047957 | ... AI19: =+Índice!AJ19/Índice!AI19*100-100 -> 0 | AJ19: 0 | AK19: 0 | AL19: 0 | AM19: 0 | AN19: 0 | AO19: 11.54 | AP19: 0 | AQ19: 0 | AR19: 0 | AS19: 0 | AT19: 0 | AU19: 0 | AV19: 0 | AW19: 0 | AX19: 0
A20: Produçao e Distribuiçao de Electricidade | B20: 35 | C20: =+Índice!D20/100*100-100 -> 1.9927536 | D20: =+Índice!E20/Índice!D20*100-100 -> 0 | E20: =+Índice!F20/Índice!E20*100-100 -> 0 | F20: =+Índice!G20/Índice!F20*100-100 -> 0 | G20: =+Índice!H20/Índice!G20*100-100 -> 0 | H20: =+Índice!I20/Índice!H20*100-100 -> 0 | I20: =+Índice!J20/Índice!I20*100-100 -> 0 | J20: =+Índice!K20/Índice!J20*100-100 -> 0 | K20: =+Índice!L20/Índice!K20*100-100 -> 0.0071047957 | ... AI20: =+Índice!AJ20/Índice!AI20*100-100 -> 0 | AJ20: 0 | AK20: 0 | AL20: 0 | AM20: 0 | AN20: 0 | AO20: 11.54 | AP20: 0 | AQ20: 0 | AR20: 0 | AS20: 0 | AT20: 0 | AU20: 0 | AV20: 0 | AW20: 0 | AX20: 0
A21: Captação, Tratamento e Distribuição de Água e Saneamento | B21: E | C21: =+Índice!D21/100*100-100 -> 48.688338 | D21: =+Índice!E21/Índice!D21*100-100 -> -0.01598045 | E21: =+Índice!F21/Índice!E21*100-100 -> 0.015983004 | F21: =+Índice!G21/Índice!F21*100-100 -> 0 | G21: =+Índice!H21/Índice!G21*100-100 -> 0 | H21: =+Índice!I21/Índice!H21*100-100 -> 0 | I21: =+Índice!J21/Índice!I21*100-100 -> 0 | J21: =+Índice!K21/Índice!J21*100-100 -> 39.901557 | K21: =+Índice!L21/Índice!K21*100-100 -> 0.0078435133 | ... AI21: =+Índice!AJ21/Índice!AI21*100-100 -> 0 | AJ21: 0 | AK21: 0 | AL21: 0 | AM21: 0 | AN21: 0 | AO21: 0 | AP21: 0 | AQ21: 0 | AR21: 0 | AS21: 0 | AT21: 0 | AU21: 0 | AV21: 0 | AW21: 0 | AX21: 0
A22: Captação, Tratamento e Distribuição de Água | B22: 36_37 | C22: =+Índice!D22/100*100-100 -> 48.688338 | D22: =+Índice!E22/Índice!D22*100-100 -> -0.01598045 | E22: =+Índice!F22/Índice!E22*100-100 -> 0.015983004 | F22: =+Índice!G22/Índice!F22*100-100 -> 0 | G22: =+Índice!H22/Índice!G22*100-100 -> 0 | H22: =+Índice!I22/Índice!H22*100-100 -> 0 | I22: =+Índice!J22/Índice!I22*100-100 -> 0 | J22: =+Índice!K22/Índice!J22*100-100 -> 39.901557 | K22: =+Índice!L22/Índice!K22*100-100 -> 0.0078435133 | ... AI22: =+Índice!AJ22/Índice!AI22*100-100 -> 0 | AJ22: 0 | AK22: 0 | AL22: 0 | AM22: 0 | AN22: 0 | AO22: 0 | AP22: 0 | AQ22: 0 | AR22: 0 | AS22: 0 | AT22: 0 | AU22: 0 | AV22: 0 | AW22: 0 | AX22: 0
A23: TOTAL DE BENS | C23: ND | D23: ND | E23: ND | F23: ND | G23: ND | H23: ND | I23: ND | J23: ND | K23: ND | L23: ND | M23: ND | N23: ND | O23: ND | P23: ND | Q23: ND | R23: ND | S23: ND | T23: ND | U23: ND | V23: ND | W23: ND | X23: ND | Y23: ND | Z23: ND | AA23: ND | AB23: ND | AC23: ND | AD23: ND | AE23: ND | AF23: ND | AG23: ND | AH23: ND | AI23: ND | AJ23: 1.8032674 | AK23: 1.3196365 | AL23: 4.4492506 | AM23: -3.4626819 | AN23: -3.5420767 | AO23: 5.8401224 | AP23: -0.69380112 | AQ23: -2.1162035 | AR23: -1.2848115 | AS23: -3.1632321 | AT23: -5.0169072 | AU23: -1.0940209 | AV23: 5.6118483 | AW23: 3.2299615 | AX23: 42.580647
A24: Bens Intermédios (A1) | C24: =+Índice!D24/100*100-100 -> 3.8135766 | D24: =+Índice!E24/Índice!D24*100-100 -> 1.0055791 | E24: =+Índice!F24/Índice!E24*100-100 -> -0.14542343 | F24: =+Índice!G24/Índice!F24*100-100 -> 0.048264446 | G24: =+Índice!H24/Índice!G24*100-100 -> -0.29879274 | H24: =+Índice!I24/Índice!H24*100-100 -> 38.74002 | I24: =+Índice!J24/Índice!I24*100-100 -> 11.03827 | J24: =+Índice!K24/Índice!J24*100-100 -> 0.32796635 | K24: =+Índice!L24/Índice!K24*100-100 -> -0.34073028 | ... AI24: =+Índice!AJ24/Índice!AI24*100-100 -> 0.52996962 | AJ24: -6.1953634 | AK24: -4.2726577 | AL24: 0.60654109 | AM24: 4.2916187 | AN24: -26.823222 | AO24: 0.10657391 | AP24: 6.8771649 | AQ24: -0.42653885 | AR24: 0.41653088 | AS24: 2.4261688 | AT24: -3.0558512 | AU24: 0.065650812 | AV24: -6.9286255 | AW24: -6.4798766 | AX24: 16.949815
A25: Bens de Investimentos (A2) | C25: ND | D25: ND | E25: ND | F25: ND | G25: ND | H25: ND | I25: ND | J25: ND | K25: ND | L25: ND | M25: ND | N25: ND | O25: ND | P25: ND | Q25: ND | R25: ND | S25: ND | T25: ND | U25: ND | V25: ND | W25: ND | X25: ND | Y25: ND | Z25: ND | AA25: ND | AB25: ND | AC25: ND | AD25: ND | AE25: ND | AF25: ND | AG25: ND | AH25: ND | AI25: ND | AJ25: 0.74250181 | AK25: 0.43423814 | AL25: 0.91139451 | AM25: -0.002529333 | AN25: 0.29949082 | AO25: 0.3255472 | AP25: 1.050685 | AQ25: 0.72143026 | AR25: 0.66255325 | AS25: 0.42125524 | AT25: 1.050685 | AU25: 0.42125524 | AV25: 0.093148026 | AW25: 0.12587746 | AX25: 1.8125877
A26: Bens de Consumo (A3) | C26: =+Índice!D26/100*100-100 -> 6.0156003 | D26: =+Índice!E26/Índice!D26*100-100 -> -0.66983998 | E26: =+Índice!F26/Índice!E26*100-100 -> 1.0541279 | F26: =+Índice!G26/Índice!F26*100-100 -> 0.90940541 | G26: =+Índice!H26/Índice!G26*100-100 -> -1.6892966 | H26: =+Índice!I26/Índice!H26*100-100 -> -1.6565556 | I26: =+Índice!J26/Índice!I26*100-100 -> 2.8164657 | J26: =+Índice!K26/Índice!J26*100-100 -> -0.97960765 | K26: =+Índice!L26/Índice!K26*100-100 -> -1.9387151 | ... AI26: =+Índice!AJ26/Índice!AI26*100-100 -> 1.073528 | AJ26: 0.73943076 | AK26: 0.43345854 | AL26: 0.48009223 | AM26: 0.20493378 | AN26: 0.30346077 | AO26: 0.34163653 | AP26: 0.4188451 | AQ26: 0.26468316 | AR26: 0.22817429 | AS26: 0.29580794 | AT26: 0.24652912 | AU26: 0.29327836 | AV26: 0.36587011 | AW26: 0.42360963 | AX26: 0.35510464
A27: Produtos de Energia (A4) | C27: =+Índice!D27/100*100-100 -> 24.687335 | D27: =+Índice!E27/Índice!D27*100-100 -> 17.513768 | E27: =+Índice!F27/Índice!E27*100-100 -> -4.880848 | F27: =+Índice!G27/Índice!F27*100-100 -> -5.4048537 | G27: =+Índice!H27/Índice!G27*100-100 -> 23.526796 | H27: =+Índice!I27/Índice!H27*100-100 -> 9.5522592 | I27: =+Índice!J27/Índice!I27*100-100 -> 1.3526287 | J27: =+Índice!K27/Índice!J27*100-100 -> 7.2660853 | K27: =+Índice!L27/Índice!K27*100-100 -> -23.723574 | ... AI27: =+Índice!AJ27/Índice!AI27*100-100 -> -6.4086074 | AJ27: 2.8268973 | AK27: 1.9913189 | AL27: 5.2039127 | AM27: -4.5253765 | AN27: -1.5200927 | AO27: 6.8143837 | AP27: -1.3406821 | AQ27: -2.4719626 | AR27: -1.5671651 | AS27: -3.9531926 | AT27: -5.7281692 | AU27: -1.3482102 | AV27: 7.3186632 | AW27: 4.2774584 | AX27: 48.697701
A28: Fonte: INE/Departamento de Estatísticas Económicas e Financeira
A29: ND (Não Disponível)

Sheet Variação Homóloga 
A1: Variação Homóloga
A2: Designação | B2: Código CAE Rev-2 | C2: 2018_T1 | D2: 2018_T2 | E2: 2018_T3 | F2: 2018_T4 | G2: 2019_T1 | H2: 2019_T2 | I2: 2019_T3 | J2: 2019_T4 | K2: 2020_T1 | L2: 2020_T2 | M2: 2020_T3 | N2: 2020_T4 | O2: 2021T1 | P2: 2021T2 | Q2: 2021T3 | R2: 2021T4 | S2: 2022T1 | T2: 2022T2 | U2: 2022T3 | V2: 2022_T4 | W2: 2023_T1 | X2: 2023_T2 | Y2: 2023_T3 | Z2: 2023_T4 | AA2: 2024_T1 | AB2: 2024_T2 | AC2: 2024_T3 | AD2: 2024_T4 | AE2: Jan-25 | AF2: Fev-25 | AG2: Mar-25 | AH2: Abr-25 | AI2: Mai-25 | AJ2: Jun-25 | AK2: Jul-25 | AL2: Ago-25 | AM2: Set-25 | AN2: Out-25 | AO2: Nov-25 | AP2: Dez-25 | AQ2: Jan-26 | AR2: Fev-26 | AS2: Mar-26
A3: INDÚSTRIA TOTAL | B3: BCDE | C3: =+Índice!I3/Índice!E3*100-100 -> 19.901156 | D3: =+Índice!J3/Índice!F3*100-100 -> 28.284619 | E3: =+Índice!K3/Índice!G3*100-100 -> 43.16576 | F3: =+Índice!L3/Índice!H3*100-100 -> -6.0222208 | G3: =+Índice!M3/Índice!I3*100-100 -> 8.3506188 | H3: =+Índice!N3/Índice!J3*100-100 -> -1.5194932 | I3: =+Índice!O3/Índice!K3*100-100 -> -10.61616 | J3: =+Índice!P3/Índice!L3*100-100 -> 16.966018 | ... AD3: =+Índice!AJ3/Índice!AF3*100-100 -> -10.062667 | AE3: 23.652933 | AF3: 5.0078534 | AG3: 5.157208 | AH3: -0.88752222 | AI3: -5.8988892 | AJ3: 3.448251 | AK3: 54.940479 | AL3: -3.4409618 | AM3: -2.28 | AN3: -0.35361537 | AO3: -6.317377 | AP3: -7.7948996 | AQ3: -4.3621026 | AR3: -2.5920362 | AS3: 33.070402
A4: Indústrias Extractivas | B4: B | C4: =+Índice!I4/Índice!E4*100-100 -> 22.33907 | D4: =+Índice!J4/Índice!F4*100-100 -> 31.366201 | E4: =+Índice!K4/Índice!G4*100-100 -> 48.138439 | F4: =+Índice!L4/Índice!H4*100-100 -> -7.4181757 | G4: =+Índice!M4/Índice!I4*100-100 -> 12.62988 | H4: =+Índice!N4/Índice!J4*100-100 -> -1.2929813 | I4: =+Índice!O4/Índice!K4*100-100 -> -11.323507 | J4: =+Índice!P4/Índice!L4*100-100 -> 18.655879 | ... AD4: =+Índice!AJ4/Índice!AF4*100-100 -> -11.403974 | AE4: 27.491412 | AF4: 5.0895119 | AG4: 5.2224603 | AH4: -1.7489413 | AI4: -7.49454 | AJ4: 2.9233513 | AK4: 67.970153 | AL4: -4.9648355 | AM4: -3.66 | AN4: -1.5002811 | AO4: -8.410332 | AP4: -10.090884 | AQ4: -6.0324508 | AR4: -3.9559984 | AS4: 37.180906
A5: Extracção de Petróleo | B5: 061_062 | C5: =+Índice!I5/Índice!E5*100-100 -> 22.669449 | D5: =+Índice!J5/Índice!F5*100-100 -> 31.047288 | E5: =+Índice!K5/Índice!G5*100-100 -> 49.267064 | F5: =+Índice!L5/Índice!H5*100-100 -> -9.6570333 | G5: =+Índice!M5/Índice!I5*100-100 -> 0.51650784 | H5: =+Índice!N5/Índice!J5*100-100 -> 1.667821 | I5: =+Índice!O5/Índice!K5*100-100 -> -9.9565348 | J5: =+Índice!P5/Índice!L5*100-100 -> 22.194493 | ... AD5: =+Índice!AJ5/Índice!AF5*100-100 -> -11.725318 | AE5: 26.858828 | AF5: 5.1683257 | AG5: 6.0324746 | AH5: -2.7349708 | AI5: -6.1814454 | AJ5: 6.1350292 | AK5: 72.333928 | AL5: -3.6370513 | AM5: -1.58 | AN5: -0.32232254 | AO5: -6.1336332 | AP5: -6.7144519 | AQ5: -2.4867072 | AR5: -0.22424343 | AS5: 42.269434
A6: Extracção de Diamantes | B6: 8991 | C6: =+Índice!I6/Índice!E6*100-100 -> 12.384926 | D6: =+Índice!J6/Índice!F6*100-100 -> 40.841253 | E6: =+Índice!K6/Índice!G6*100-100 -> 59.322207 | F6: =+Índice!L6/Índice!H6*100-100 -> 90.999877 | G6: =+Índice!M6/Índice!I6*100-100 -> 1.7465265 | H6: =+Índice!N6/Índice!J6*100-100 -> -39.878359 | I6: =+Índice!O6/Índice!K6*100-100 -> -49.998224 | J6: =+Índice!P6/Índice!L6*100-100 -> -36.541052 | ... AD6: =+Índice!AJ6/Índice!AF6*100-100 -> 9.3440964 | AE6: 37.191817 | AF6: 4.1080483 | AG6: -5.3127098 | AH6: 13.109949 | AI6: -30.986649 | AJ6: -42.03601 | AK6: 27.435324 | AL6: -27.136649 | AM6: -33.68 | AN6: -20.063714 | AO6: -38.486702 | AP6: -47.84859 | AQ6: -51.460709 | AR6: -56.697573 | AS6: -36.456823
A7: Resto das Indústrias Extractivas | B7: 081_091 | C7: =+Índice!I7/Índice!E7*100-100 -> 46.284598 | D7: =+Índice!J7/Índice!F7*100-100 -> 64.447459 | E7: =+Índice!K7/Índice!G7*100-100 -> 64.447459 | F7: =+Índice!L7/Índice!H7*100-100 -> 61.043418 | G7: =+Índice!M7/Índice!I7*100-100 -> 20.660555 | H7: =+Índice!N7/Índice!J7*100-100 -> 0.014280254 | I7: =+Índice!O7/Índice!K7*100-100 -> 3.5130824 | J7: =+Índice!P7/Índice!L7*100-100 -> 8.9059252 | ... AD7: =+Índice!AJ7/Índice!AF7*100-100 -> 6.10978 | AE7: 5.6893176 | AF7: 1.9680646 | AG7: 1.8979268 | AH7: 1.8222774 | AI7: 1.9624144 | AJ7: 2.0054299 | AK7: 1.8968717 | AL7: 2.1725638 | AM7: -1.37 | AN7: -1.1326985 | AO7: 0.21412135 | AP7: 0.20677178 | AQ7: 0.18008266 | AR7: 2.7214669 | AS7: 2.9686733
A8: Indústrias Transformadoras | B8: C | C8: =+Índice!I8/Índice!E8*100-100 -> 5.3251215 | D8: =+Índice!J8/Índice!F8*100-100 -> 6.135174 | E8: =+Índice!K8/Índice!G8*100-100 -> 5.9767364 | F8: =+Índice!L8/Índice!H8*100-100 -> 0.64273587 | G8: =+Índice!M8/Índice!I8*100-100 -> 10.260216 | H8: =+Índice!N8/Índice!J8*100-100 -> 1.0662674 | I8: =+Índice!O8/Índice!K8*100-100 -> -3.4673463 | J8: =+Índice!P8/Índice!L8*100-100 -> 18.009246 | ... AD8: =+Índice!AJ8/Índice!AF8*100-100 -> 7.5567096 | AE8: 4.9758666 | AF8: 5.4540218 | AG8: 5.734282 | AH8: 5.9574547 | AI8: 6.0130748 | AJ8: 6.4220028 | AK8: 1.2649045 | AL8: 6.4167356 | AM8: 6.23 | AN8: 6.2058941 | AO8: 6.1298698 | AP8: 5.8394645 | AQ8: 5.4629465 | AR8: 5.3848687 | AS8: 5.4122229
A9: Indústrias alimentares, das bebidas e do Tabaco | B9: 10_12 | C9: =+Índice!I9/Índice!E9*100-100 -> -0.71491444 | D9: =+Índice!J9/Índice!F9*100-100 -> 1.1860117 | E9: =+Índice!K9/Índice!G9*100-100 -> -0.18334944 | F9: =+Índice!L9/Índice!H9*100-100 -> -3.7800231 | G9: =+Índice!M9/Índice!I9*100-100 -> -8.0993117 | H9: =+Índice!N9/Índice!J9*100-100 -> 2.6512539 | I9: =+Índice!O9/Índice!K9*100-100 -> -6.2719905 | J9: =+Índice!P9/Índice!L9*100-100 -> 16.561056 | ... AD9: =+Índice!AJ9/Índice!AF9*100-100 -> 10.552068 | AE9: 5.3981325 | AF9: 5.5837238 | AG9: 5.9507582 | AH9: 5.9581776 | AI9: 6.1087276 | AJ9: 6.4958796 | AK9: 1.6034741 | AL9: 5.8306093 | AM9: 5.51 | AN9: 5.3070004 | AO9: 5.0439412 | AP9: 4.3262807 | AQ9: 3.9112708 | AR9: 3.931235 | AS9: 3.7639122
A10: Indústrias Alimentares | B10: 101_108 | C10: =+Índice!I10/Índice!E10*100-100 -> 7.1825036 | D10: =+Índice!J10/Índice!F10*100-100 -> 1.482849 | E10: =+Índice!K10/Índice!G10*100-100 -> -0.22935986 | F10: =+Índice!L10/Índice!H10*100-100 -> 2.055994 | G10: =+Índice!M10/Índice!I10*100-100 -> 3.4124308 | H10: =+Índice!N10/Índice!J10*100-100 -> 2.6509414 | I10: =+Índice!O10/Índice!K10*100-100 -> -6.7593526 | J10: =+Índice!P10/Índice!L10*100-100 -> 5.6852907 | ... AD10: =+Índice!AJ10/Índice!AF10*100-100 -> 11.121721 | AE10: 4.6336877 | AF10: 5.4178279 | AG10: 5.6027545 | AH10: 5.9857565 | AI10: 6.0061791 | AJ10: 6.2830401 | AK10: 0.94751153 | AL10: 6.2308483 | AM10: 5.99 | AN10: 5.7349291 | AO10: 5.5697057 | AP10: 5.3599157 | AQ10: 4.6670993 | AR10: 4.2414692 | AS10: 4.1734848
A11: Indústrias das bebidas e do Tabaco | B11: 11_12 | C11: =+Índice!I11/Índice!E11*100-100 -> -24.370177 | D11: =+Índice!J11/Índice!F11*100-100 -> 0.08748933 | E11: =+Índice!K11/Índice!G11*100-100 -> 0 | F11: =+Índice!L11/Índice!H11*100-100 -> -23.714551 | G11: =+Índice!M11/Índice!I11*100-100 -> -0.72401281 | H11: =+Índice!N11/Índice!J11*100-100 -> 2.9281163 | I11: =+Índice!O11/Índice!K11*100-100 -> -3.433152 | J11: =+Índice!P11/Índice!L11*100-100 -> 70.985905 | ... AD11: =+Índice!AJ11/Índice!AF11*100-100 -> 8.4431206 | AE11: 5.3339039 | AF11: 5.5216569 | AG11: 5.836609 | AH11: 5.8016067 | AI11: 6.0323052 | AJ11: 6.5661905 | AK11: 1.5720727 | AL11: 5.7821595 | AM11: 5.6 | AN11: 5.3661133 | AO11: 4.8834343 | AP11: 4.1262105 | AQ11: 3.7936886 | AR11: 4.2215044 | AS11: 3.9137564
A12: Fabricação de téxteis, Vestuários e Calçados | B12: 13_15 | C12: =+Índice!I12/Índice!E12*100-100 -> 7.6290651 | D12: =+Índice!J12/Índice!F12*100-100 -> 10.223778 | E12: =+Índice!K12/Índice!G12*100-100 -> 0 | F12: =+Índice!L12/Índice!H12*100-100 -> 16.155627 | G12: =+Índice!M12/Índice!I12*100-100 -> 21.120045 | H12: =+Índice!N12/Índice!J12*100-100 -> 1.4705691 | I12: =+Índice!O12/Índice!K12*100-100 -> 1.0282549 | J12: =+Índice!P12/Índice!L12*100-100 -> 0 | ... AD12: =+Índice!AJ12/Índice!AF12*100-100 -> 8.8789072 | AE12: -2.2287569 | AF12: 0.16311935 | AG12: 0.36602909 | AH12: 0.64135964 | AI12: 0.82212073 | AJ12: 1.2206116 | AK12: -2.3163823 | AL12: 1.2639422 | AM12: 1.4 | AN12: 1.723925 | AO12: 2.5172308 | AP12: 2.2983307 | AQ12: 3.4101066 | AR12: 4.022611 | AS12: 4.0077056
A13: Indústrias de Madeira | B13: 16 | C13: =+Índice!I13/Índice!E13*100-100 -> -13.257322 | D13: =+Índice!J13/Índice!F13*100-100 -> -6.2962611 | E13: =+Índice!K13/Índice!G13*100-100 -> 0 | F13: =+Índice!L13/Índice!H13*100-100 -> -11.153572 | G13: =+Índice!M13/Índice!I13*100-100 -> -7.4703918 | H13: =+Índice!N13/Índice!J13*100-100 -> -0.043859212 | I13: =+Índice!O13/Índice!K13*100-100 -> -3.7695139 | J13: =+Índice!P13/Índice!L13*100-100 -> 31.567458 | ... AD13: =+Índice!AJ13/Índice!AF13*100-100 -> 11.921331 | AE13: 5.3336083 | AF13: 5.5213714 | AG13: 5.8520002 | AH13: 6.4160494 | AI13: 6.0444813 | AJ13: 5.9294988 | AK13: 1.5719637 | AL13: 7.2636962 | AM13: 7.17 | AN13: 6.9088039 | AO13: 7.988827 | AP13: 7.1839415 | AQ13: 7.4072286 | AR13: 7.0806787 | AS13: 8.2128884
A14: Fabricação de Pastas de Papel, Edição e Impressão | B14: 17_18 | C14: =+Índice!I14/Índice!E14*100-100 -> -1.5984026 | D14: =+Índice!J14/Índice!F14*100-100 -> -16.35849 | E14: =+Índice!K14/Índice!G14*100-100 -> 0 | F14: =+Índice!L14/Índice!H14*100-100 -> 16.89229 | G14: =+Índice!M14/Índice!I14*100-100 -> 30.365101 | H14: =+Índice!N14/Índice!J14*100-100 -> 2.2096511 | I14: =+Índice!O14/Índice!K14*100-100 -> -6.2372634 | J14: =+Índice!P14/Índice!L14*100-100 -> -18.976465 | ... AD14: =+Índice!AJ14/Índice!AF14*100-100 -> 8.5192477 | AE14: 5.3333533 | AF14: 5.5211251 | AG14: 5.9272279 | AH14: 6.0761768 | AI14: 6.0793503 | AJ14: 6.3795321 | AK14: 1.5718981 | AL14: 5.5977879 | AM14: 5.55 | AN14: 5.186004 | AO14: 4.7926034 | AP14: 3.9087206 | AQ14: 3.7113742 | AR14: 3.6906163 | AS14: 3.748928
A15: Fabricação de Produtos Petrolíferos, Químicos e Outros | B15: 19_23 | C15: =+Índice!I15/Índice!E15*100-100 -> 15.844018 | D15: =+Índice!J15/Índice!F15*100-100 -> 15.880849 | E15: =+Índice!K15/Índice!G15*100-100 -> 17.901216 | F15: =+Índice!L15/Índice!H15*100-100 -> 4.907604 | G15: =+Índice!M15/Índice!I15*100-100 -> -5.2236859 | H15: =+Índice!N15/Índice!J15*100-100 -> -1.1672971 | I15: =+Índice!O15/Índice!K15*100-100 -> -0.89162783 | J15: =+Índice!P15/Índice!L15*100-100 -> 14.186758 | ... AD15: =+Índice!AJ15/Índice!AF15*100-100 -> 2.9962969 | AE15: 5.3590489 | AF15: 5.5459486 | AG15: 5.911466 | AH15: 5.9490515 | AI15: 6.0779072 | AJ15: 6.469723 | AK15: 1.584427 | AL15: 6.8524932 | AM15: 6.65 | AN15: 6.6718908 | AO15: 7.0936851 | AP15: 6.5849004 | AQ15: 5.9885554 | AR15: 6.6491843 | AS15: 6.35512
A16: Indústrias Metalúrgicas | B16: 24_25 | C16: =+Índice!I16/Índice!E16*100-100 -> 0.13771819 | D16: =+Índice!J16/Índice!F16*100-100 -> 0.198826 | E16: =+Índice!K16/Índice!G16*100-100 -> 0 | F16: =+Índice!L16/Índice!H16*100-100 -> -0.12599053 | G16: =+Índice!M16/Índice!I16*100-100 -> 6.8960776 | H16: =+Índice!N16/Índice!J16*100-100 -> -0.01117834 | I16: =+Índice!O16/Índice!K16*100-100 -> 2.0734727 | J16: =+Índice!P16/Índice!L16*100-100 -> 6.6016202 | ... AD16: =+Índice!AJ16/Índice!AF16*100-100 -> 13.133435 | AE16: 5.3482791 | AF16: 5.5355397 | AG16: 5.9094512 | AH16: 6.130493 | AI16: 6.0751698 | AJ16: 6.8398431 | AK16: 1.5788909 | AL16: 7.4688311 | AM16: 7.51 | AN16: 8.4438195 | AO16: 8.4759252 | AP16: 8.869415 | AQ16: 9.5030127 | AR16: 9.1995722 | AS16: 10.120643
A17: Fabricação de Máquinas, Equipamentos, Aparelhos e Automóveis | B17: 26_30 | C17: =+Índice!I17/Índice!E17*100-100 -> -38.425705 | D17: =+Índice!J17/Índice!F17*100-100 -> -38.425705 | E17: =+Índice!K17/Índice!G17*100-100 -> -38.425705 | F17: =+Índice!L17/Índice!H17*100-100 -> 0.0080666173 | G17: =+Índice!M17/Índice!I17*100-100 -> 9.6252969 | H17: =+Índice!N17/Índice!J17*100-100 -> 0.0090427886 | I17: =+Índice!O17/Índice!K17*100-100 -> 14.627732 | J17: =+Índice!P17/Índice!L17*100-100 -> -28.574679 | ... AD17: =+Índice!AJ17/Índice!AF17*100-100 -> 12.160887 | AE17: 5.3330297 | AF17: 5.5208127 | AG17: 6.3466619 | AH17: 6.1405745 | AI17: 6.2887212 | AJ17: 6.4477538 | AK17: 1.5717336 | AL17: 7.196221 | AM17: 7.33 | AN17: 7.2782697 | AO17: 7.8624676 | AP17: 7.2639166 | AQ17: 6.5725279 | AR17: 6.245321 | AS17: 7.1941491
A18: Fabricação de Mobiliário, Colchões e Outras | B18: 31_33 | C18: =+Índice!I18/Índice!E18*100-100 -> -14.066587 | D18: =+Índice!J18/Índice!F18*100-100 -> -26.838958 | E18: =+Índice!K18/Índice!G18*100-100 -> -0.00096483218 | F18: =+Índice!L18/Índice!H18*100-100 -> 3.6205168 | G18: =+Índice!M18/Índice!I18*100-100 -> 1.7080097 | H18: =+Índice!N18/Índice!J18*100-100 -> 47.039262 | I18: =+Índice!O18/Índice!K18*100-100 -> 5.1546423 | J18: =+Índice!P18/Índice!L18*100-100 -> 19.48266 | ... AD18: =+Índice!AJ18/Índice!AF18*100-100 -> 8.3530705 | AE18: 5.6257225 | AF18: 5.802779 | AG18: 6.303876 | AH18: 6.3387096 | AI18: 6.3523697 | AJ18: 6.799173 | AK18: 1.7110023 | AL18: 6.110527 | AM18: 5.52 | AN18: 5.207185 | AO18: 4.9910639 | AP18: 4.1495048 | AQ18: 4.1264476 | AR18: 3.7531384 | AS18: 3.8722195
A19: Producão e Distribuição de Electricidade, Gás e Vapor | B19: D | C19: =+Índice!I19/Índice!E19*100-100 -> 0 | D19: =+Índice!J19/Índice!F19*100-100 -> 0 | E19: =+Índice!K19/Índice!G19*100-100 -> 0 | F19: =+Índice!L19/Índice!H19*100-100 -> 0.0071047957 | G19: =+Índice!M19/Índice!I19*100-100 -> 0.0071047957 | H19: =+Índice!N19/Índice!J19*100-100 -> 0.0071047957 | I19: =+Índice!O19/Índice!K19*100-100 -> 16.888593 | J19: =+Índice!P19/Índice!L19*100-100 -> 16.880289 | ... AD19: =+Índice!AJ19/Índice!AF19*100-100 -> 0 | AE19: 0 | AF19: 0 | AG19: 0 | AH19: 0 | AI19: 0 | AJ19: 11.54 | AK19: 11.54 | AL19: 11.54 | AM19: 11.54 | AN19: 11.54 | AO19: 11.54 | AP19: 11.54 | AQ19: 11.54 | AR19: 11.54 | AS19: 11.54
A20: Produçao e Distribuiçao de Electricidade | B20: 35 | C20: =+Índice!I20/Índice!E20*100-100 -> 0 | D20: =+Índice!J20/Índice!F20*100-100 -> 0 | E20: =+Índice!K20/Índice!G20*100-100 -> 0 | F20: =+Índice!L20/Índice!H20*100-100 -> 0.0071047957 | G20: =+Índice!M20/Índice!I20*100-100 -> 0.0071047957 | H20: =+Índice!N20/Índice!J20*100-100 -> 0.0071047957 | I20: =+Índice!O20/Índice!K20*100-100 -> 16.888593 | J20: =+Índice!P20/Índice!L20*100-100 -> 16.880289 | ... AD20: =+Índice!AJ20/Índice!AF20*100-100 -> 0 | AE20: 0 | AF20: 0 | AG20: 0 | AH20: 0 | AI20: 0 | AJ20: 11.54 | AK20: 11.54 | AL20: 11.54 | AM20: 11.54 | AN20: 11.54 | AO20: 11.54 | AP20: 11.54 | AQ20: 11.54 | AR20: 11.54 | AS20: 11.54
A21: Captação, Tratamento e Distribuição de Água e Saneamento | B21: E | C21: =+Índice!I21/Índice!E21*100-100 -> 0.015983004 | D21: =+Índice!J21/Índice!F21*100-100 -> 0 | E21: =+Índice!K21/Índice!G21*100-100 -> 39.901557 | F21: =+Índice!L21/Índice!H21*100-100 -> 39.91253 | G21: =+Índice!M21/Índice!I21*100-100 -> 39.889922 | H21: =+Índice!N21/Índice!J21*100-100 -> 0.0078435133 | I21: =+Índice!O21/Índice!K21*100-100 -> -13.512126 | J21: =+Índice!P21/Índice!L21*100-100 -> -13.518909 | ... AD21: =+Índice!AJ21/Índice!AF21*100-100 -> 0 | AE21: 0 | AF21: 0 | AG21: 0 | AH21: 0 | AI21: 0 | AJ21: 0 | AK21: 0 | AL21: 0 | AM21: 0 | AN21: 0 | AO21: 0 | AP21: 0 | AQ21: 0 | AR21: 0 | AS21: 0
A22: Captação, Tratamento e Distribuição de Água | B22: 36_37 | C22: =+Índice!I22/Índice!E22*100-100 -> 0.015983004 | D22: =+Índice!J22/Índice!F22*100-100 -> 0 | E22: =+Índice!K22/Índice!G22*100-100 -> 39.901557 | F22: =+Índice!L22/Índice!H22*100-100 -> 39.91253 | G22: =+Índice!M22/Índice!I22*100-100 -> 39.889922 | H22: =+Índice!N22/Índice!J22*100-100 -> 0.0078435133 | I22: =+Índice!O22/Índice!K22*100-100 -> -13.512126 | J22: =+Índice!P22/Índice!L22*100-100 -> -13.518909 | ... AD22: =+Índice!AJ22/Índice!AF22*100-100 -> 0 | AE22: 0 | AF22: 0 | AG22: 0 | AH22: 0 | AI22: 0 | AJ22: 0 | AK22: 0 | AL22: 0 | AM22: 0 | AN22: 0 | AO22: 0 | AP22: 0 | AQ22: 0 | AR22: 0 | AS22: 0
A23: TOTAL DE BENS | C23: ND | D23: ND | E23: ND | F23: ND | G23: ND | H23: ND | I23: ND | J23: ND | K23: ND | L23: ND | M23: ND | N23: ND | O23: ND | P23: ND | Q23: ND | R23: ND | S23: ND | T23: ND | U23: ND | V23: ND | W23: ND | X23: ND | Y23: ND | Z23: ND | AA23: ND | AB23: ND | AC23: ND | AD23: ND | AE23: 20.423488 | AF23: 5.0488526 | AG23: 5.9585511 | AH23: -1.1308103 | AI23: -6.19828 | AJ23: 3.8457222 | AK23: -1.4099752 | AL23: -3.5728501 | AM23: -1.9431814 | AN23: -0.82341644 | AO23: -5.8496748 | AP23: -6.1949823 | AQ23: -3.8442306 | AR23: -2.0312674 | AS23: 33.73428
A24: Bens Intermédios (A1) | C24: =+Índice!I24/Índice!E24*100-100 -> 38.190983 | D24: =+Índice!J24/Índice!F24*100-100 -> 53.668346 | E24: =+Índice!K24/Índice!G24*100-100 -> 54.097952 | F24: =+Índice!L24/Índice!H24*100-100 -> 54.033134 | G24: =+Índice!M24/Índice!I24*100-100 -> 12.557578 | H24: =+Índice!N24/Índice!J24*100-100 -> 0.12525421 | I24: =+Índice!O24/Índice!K24*100-100 -> 2.0575852 | J24: =+Índice!P24/Índice!L24*100-100 -> 6.7631718 | ... AD24: =+Índice!AJ24/Índice!AF24*100-100 -> 8.3690034 | AE24: -6.1068895 | AF24: 4.9008657 | AG24: 7.0238475 | AH24: 6.2637973 | AI24: 7.2551468 | AJ24: 6.1544336 | AK24: -4.121892 | AL24: -11.830721 | AM24: -16.44 | AN24: -7.5357439 | AO24: -19.283547 | AP24: -26.713647 | AQ24: -27.286519 | AR24: -28.9631 | AS24: -17.423338
