Workbook

Sheet Índice
A1: Indices de Preços dos Materiais de Construção (IPMC)
A2: Materiais de Construção | B2: Ponderadores 2016 | C2: 43831 | D2: 43862 | E2: 43891 | F2: 43922 | G2: 43952 | H2: 43983 | I2: 44013 | J2: 44044 | K2: 44075 | L2: 44105 | M2: 44136 | N2: 44166 | O2: 44197 | P2: 44228 | Q2: 44256 | R2: 44287 | S2: 44317 | T2: 44348 | U2: 44348 | V2: 44378 | W2: 44409 | X2: 44440 | Y2: 44470 | Z2: 44501 | AA2: 44531 | AB2: 44197 | AC2: 44228 | AD2: 44256 | AE2: 44287 | AF2: 44317 | AG2: 44713 | AH2: 44743 | AI2: 44774 | AJ2: 44805 | AK2: 44835 | AL2: 44866 | AM2: 44896 | AN2: Jan-23 | AO2: Fev-23 | AP2: Mar-23 | AQ2: Abr-23 | AR2: Mai-23 | AS2: Jun-23 | AT2: Jul-23 | AU2: Ago-23 | AV2: Set-23 | AW2: Out-23 | AX2: Nov-23 | AY2: Dez-23 | AZ2: Jan-23 | BA2: Fev-23 | BB2: Mar-23 | BC2: Abr-23 | BD2: Mai-23 | BE2: 45444 | BF2: 45474 | BG2: 45505 | BH2: 45536 | BI2: 45566 | BJ2: 45597 | BK2: 45627 | BL2: 45658 | BM2: 45689 | BN2: 45717 | BO2: 45748 | BP2: 45778 | BQ2: 45809 | BR2: 45839 | BS2: 45870 | BT2: 45901 | BU2: 45931 | BV2: 45962 | BW2: 45992
A3: Total Material de Construção | B3: 100 | C3: 120.09575 | D3: 121.43774 | E3: 122.51321 | F3: 123.11512 | G3: 124.81962 | H3: 125.31787 | I3: 125.98505 | J3: 127.77924 | K3: 129.02674 | L3: 130.34392 | M3: 132.76961 | N3: 136.47166 | O3: 138.39476 | P3: 140.10562 | Q3: 141.10726 | R3: 141.59528 | S3: 143.70023 | T3: 146.2121 | U3: 146.2121 | V3: 149.0537 | W3: 151.93765 | X3: 154.94649 | Y3: 157.36978 | Z3: 160.44412 | AA3: 163.57171 | AB3: 166.93527 | AC3: 170.50063 | AD3: 173.66333 | AE3: 175.19127 | AF3: 175.96668 | AG3: 176.57248 | AH3: 177.66297 | AI3: 178.87021 | AJ3: 179.72518 | AK3: 180.74465 | AL3: 182.01122 | AM3: 183.38566 | AN3: 184.76361 | AO3: 186.10666 | AP3: 187.74339 | AQ3: 189.6808 | AR3: 191.78461 | AS3: 194.0593 | AT3: 196.51049 | AU3: 199.14502 | AV3: 203.29898 | AW3: 207.57113 | AX3: 211.58104 | AY3: 217.08172 | AZ3: 221.99023 | BA3: 226.8386 | BB3: 231.65489 | BC3: 232.68464 | BD3: 237.03375 | BE3: 241.27486 | BF3: 244.71147 | BG3: 247.66503 | BH3: 251.10823 | BI3: 254.42086 | BJ3: 258.10193 | BK3: 262.05529 | BL3: 265.49022 | BM3: 268.78555 | BN3: 271.8532 | BO3: 274.92221 | BP3: 276.98125 | BQ3: 280.00194 | BR3: 281.49142 | BS3: 283.47927 | BT3: 285.33276 | BU3: 287.0001 | BV3: 289.15197 | BW3: 289.13113
A4: Aço | B4: 28.374786 | C4: 118.45084 | D4: 120.03387 | E4: 121.58254 | F4: 122.23043 | G4: 123.38803 | H4: 124.90852 | I4: 126.66279 | J4: 128.50492 | K4: 129.67834 | L4: 130.436 | M4: 133.35638 | N4: 135.70391 | O4: 138.76566 | P4: 140.28587 | Q4: 141.16228 | R4: 142.85323 | S4: 145.70518 | T4: 147.70483 | U4: 147.70483 | V4: 150.35448 | W4: 154.95898 | X4: 158.39626 | Y4: 161.97869 | Z4: 166.54311 | AA4: 170.10791 | AB4: 173.79596 | AC4: 177.67412 | AD4: 181.62071 | AE4: 184.14771 | AF4: 185.06776 | AG4: 185.75679 | AH4: 187.45039 | AI4: 188.37322 | AJ4: 189.41311 | AK4: 189.71894 | AL4: 190.68298 | AM4: 191.26181 | AN4: 193.68468 | AO4: 195.52799 | AP4: 197.85664 | AQ4: 200.67398 | AR4: 203.83505 | AS4: 207.34729 | AT4: 211.22058 | AU4: 215.46715 | AV4: 219.16894 | AW4: 221.22607 | AX4: 224.36474 | AY4: 228.63896 | AZ4: 230.81244 | BA4: 231.37549 | BB4: 232.33532 | BC4: 233.76891 | BD4: 238.82799 | BE4: 240.65099 | BF4: 242.87071 | BG4: 244.02274 | BH4: 245.6142 | BI4: 247.65034 | BJ4: 250.13998 | BK4: 252.14291 | BL4: 257.60829 | BM4: 263.48653 | BN4: 269.80208 | BO4: 276.38033 | BP4: 278.63465 | BQ4: 282.12983 | BR4: 285.73772 | BS4: 288.56303 | BT4: 289.92903 | BU4: 291.06791 | BV4: 293.193 | BW4: 294.12803
A5: Varões de aço | B5: 15.834286 | C5: 118.27578 | D5: 118.95528 | E5: 120.88866 | F5: 120.78162 | G5: 122.17722 | H5: 123.58519 | I5: 125.09911 | J5: 126.51129 | K5: 127.21596 | L5: 128.30518 | M5: 133.02043 | N5: 134.46327 | O5: 138.4129 | P5: 139.12775 | Q5: 140.15322 | R5: 141.8927 | S5: 144.66258 | T5: 147.01124 | U5: 147.01124 | V5: 149.92979 | W5: 155.63936 | X5: 159.375 | Y5: 163.0163 | Z5: 167.49933 | AA5: 171.0722 | AB5: 174.79288 | AC5: 178.69224 | AD5: 182.67908 | AE5: 186.04751 | AF5: 187.29646 | AG5: 196.15112 | AH5: 199.04066 | AI5: 199.24758 | AJ5: 200.75178 | AK5: 200.91009 | AL5: 202.13257 | AM5: 203.05034 | AN5: 209.32247 | AO5: 210.86386 | AP5: 212.92572 | AQ5: 215.49955 | AR5: 218.38453 | AS5: 221.57698 | AT5: 225.07577 | AU5: 228.88207 | AV5: 232.28643 | AW5: 234.73808 | AX5: 237.89384 | AY5: 241.77637 | AZ5: 242.37936 | BA5: 236.31061 | BB5: 236.45903 | BC5: 237.1842 | BD5: 242.40582 | BE5: 244.32008 | BF5: 246.51193 | BG5: 248.41384 | BH5: 250.52889 | BI5: 252.86712 | BJ5: 255.43943 | BK5: 257.6739 | BL5: 259.96072 | BM5: 262.31134 | BN5: 263.95424 | BO5: 264.97931 | BP5: 263.2849 | BQ5: 262.3047 | BR5: 261.781 | BS5: 264.0913 | BT5: 265.85255 | BU5: 260.78771 | BV5: 261.86523 | BW5: 269.57431
A6: Tubos de Aço | B6: 12.4305 | C6: 118.67084 | D6: 121.41333 | E6: 122.46519 | F6: 124.04254 | G6: 124.88337 | H6: 126.55081 | I6: 128.62017 | J6: 131.0132 | K6: 132.76681 | L6: 133.10061 | M6: 133.75628 | N6: 137.26985 | O6: 139.22674 | P6: 141.78385 | Q6: 142.46941 | R6: 144.09725 | S6: 147.05433 | T6: 148.60235 | U6: 148.60235 | V6: 150.9025 | W6: 154.10825 | X6: 157.16622 | Y6: 160.69057 | Z6: 165.36394 | AA6: 168.91803 | AB6: 172.567 | AC6: 176.42116 | AD6: 180.31944 | AE6: 181.77742 | AF6: 182.27751 | AG6: 172.56297 | AH6: 172.74709 | AI6: 174.58571 | AJ6: 175.04068 | AK6: 175.5333 | AL6: 176.16835 | AM6: 176.31132 | AN6: 173.82146 | AO6: 176.03065 | AP6: 178.67885 | AQ6: 181.78419 | AR6: 185.27189 | AS6: 189.16324 | AT6: 193.48171 | AU6: 198.25325 | AV6: 202.28533 | AW6: 203.8459 | AX6: 206.9707 | AY6: 211.75418 | AZ6: 215.94617 | BA6: 224.95942 | BB6: 226.95753 | BC6: 229.3011 | BD6: 234.19153 | BE6: 235.90672 | BF6: 238.17271 | BG6: 238.36951 | BH6: 239.29783 | BI6: 240.95687 | BJ6: 243.35283 | BK6: 245.0668 | BL6: 254.60784 | BM6: 265.0097 | BN6: 277.30745 | BO6: 290.99428 | BP6: 298.29479 | BQ6: 307.51757 | BR6: 316.41976 | BS6: 319.90908 | BT6: 320.75598 | BU6: 329.77919 | BV6: 333.25126 | BW6: 325.51485
A7: Malhasol | B7: 0.11 | C7: 118.78718 | D7: 119.40974 | E7: 121.72056 | F7: 126.00512 | G7: 128.70314 | H7: 129.81321 | I7: 130.55898 | J7: 132.03629 | K7: 135.12329 | L7: 136.04989 | M7: 136.52555 | N7: 137.33392 | O7: 137.44197 | P7: 137.71666 | Q7: 138.70222 | R7: 140.54033 | S7: 143.32423 | T7: 146.12213 | U7: 146.12213 | V7: 149.55913 | W7: 153.15571 | X7: 156.50761 | Y7: 158.18072 | Z7: 162.1494 | AA7: 165.7629 | AB7: 169.17037 | AC7: 172.70863 | AD7: 176.32099 | AE7: 178.52819 | AF7: 179.56099 | AG7: 180.47328 | AH7: 180.59115 | AI7: 181.08091 | AJ7: 181.3822 | AK7: 181.81611 | AL7: 182.75631 | AM7: 183.7979 | AN7: 187.28981 | AO7: 191.2462 | AP7: 195.86827 | AQ7: 201.19532 | AR7: 207.18722 | AS7: 213.89261 | AT7: 221.36519 | AU7: 229.66422 | AV7: 238.85504 | AW7: 240.23642 | AX7: 242.48378 | AY7: 245.59009 | AZ7: 245.73333 | BA7: 246.02007 | BB7: 246.45085 | BC7: 247.02647 | BD7: 247.748 | BE7: 248.61679 | BF7: 249.61908 | BG7: 250.77194 | BH7: 251.93176 | BI7: 253.09859 | BJ7: 254.27248 | BK7: 255.60139 | BL7: 258.04435 | BM7: 260.52833 | BN7: 263.44452 | BO7: 266.09318 | BP7: 266.5162 | BQ7: 266.98803 | BR7: 267.05181 | BS7: 268.97552 | BT7: 272.10485 | BU7: 275.29215 | BV7: 281.65084 | BW7: 281.7342
A8: Aluminio | B8: 7.2425 | C8: 118.31845 | D8: 120.00484 | E8: 121.60714 | F8: 122.29787 | G8: 124.56552 | H8: 125.87632 | I8: 127.58195 | J8: 130.58267 | K8: 135.08778 | L8: 136.48807 | M8: 140.92752 | N8: 146.13213 | O8: 150.5068 | P8: 153.65175 | Q8: 155.27728 | R8: 156.92885 | S8: 161.14266 | T8: 164.13061 | U8: 164.13061 | V8: 166.19008 | W8: 167.93144 | X8: 171.72005 | Y8: 174.91097 | Z8: 179.64929 | AA8: 184.16386 | AB8: 188.18505 | AC8: 192.48088 | AD8: 196.87474 | AE8: 200.69403 | AF8: 201.35943 | AG8: 202.17248 | AH8: 202.33378 | AI8: 203.74174 | AJ8: 205.01319 | AK8: 206.76265 | AL8: 208.94141 | AM8: 209.63124 | AN8: 209.99488 | AO8: 210.47689 | AP8: 211.07503 | AQ8: 211.79083 | AR8: 212.54572 | AS8: 213.34014 | AT8: 214.17457 | AU8: 215.04951 | AV8: 215.96549 | AW8: 216.92306 | AX8: 217.04187 | AY8: 218.35621 | AZ8: 225.05057 | BA8: 227.34333 | BB8: 229.26513 | BC8: 231.87191 | BD8: 236.44243 | BE8: 238.41294 | BF8: 240.14854 | BG8: 241.95069 | BH8: 245.42388 | BI8: 250.11488 | BJ8: 255.77499 | BK8: 261.23386 | BL8: 263.29518 | BM8: 267.47467 | BN8: 271.41669 | BO8: 275.78211 | BP8: 278.27643 | BQ8: 279.83292 | BR8: 282.60081 | BS8: 285.63231 | BT8: 289.1499 | BU8: 289.18543 | BV8: 293.01288 | BW8: 296.93689
A9: Chapas perfiladas | B9: 7.2425 | C9: 118.31845 | D9: 120.00484 | E9: 121.60714 | F9: 122.29787 | G9: 124.56552 | H9: 125.87632 | I9: 127.58195 | J9: 130.58267 | K9: 135.08778 | L9: 136.48807 | M9: 140.92752 | N9: 146.13213 | O9: 150.5068 | P9: 153.65175 | Q9: 155.27728 | R9: 156.92885 | S9: 161.14266 | T9: 164.13061 | U9: 164.13061 | V9: 166.19008 | W9: 167.93144 | X9: 171.72005 | Y9: 174.91097 | Z9: 179.64929 | AA9: 184.16386 | AB9: 188.18505 | AC9: 192.48088 | AD9: 196.87474 | AE9: 200.69403 | AF9: 201.35943 | AG9: 202.17248 | AH9: 202.33378 | AI9: 203.74174 | AJ9: 205.01319 | AK9: 206.76265 | AL9: 208.94141 | AM9: 209.63124 | AN9: 209.99488 | AO9: 210.47689 | AP9: 211.07503 | AQ9: 211.79083 | AR9: 212.54572 | AS9: 213.34014 | AT9: 214.17457 | AU9: 215.04951 | AV9: 215.96549 | AW9: 216.92306 | AX9: 217.04187 | AY9: 218.35621 | AZ9: 225.05057 | BA9: 227.34333 | BB9: 229.26513 | BC9: 231.87191 | BD9: 236.44243 | BE9: 238.41294 | BF9: 240.14854 | BG9: 241.95069 | BH9: 245.42388 | BI9: 250.11488 | BJ9: 255.77499 | BK9: 261.23386 | BL9: 263.29518 | BM9: 267.47467 | BN9: 271.41669 | BO9: 275.78211 | BP9: 278.27643 | BQ9: 279.83292 | BR9: 282.60081 | BS9: 285.63231 | BT9: 289.1499 | BU9: 289.18543 | BV9: 293.01288 | BW9: 296.93689
A10: Areia | B10: 13.874167 | C10: 120.41065 | D10: 121.20958 | E10: 121.34557 | F10: 121.53274 | G10: 121.96102 | H10: 122.60009 | I10: 123.40342 | J10: 124.04956 | K10: 126.66701 | L10: 129.24151 | M10: 132.62977 | N10: 135.07351 | O10: 136.34609 | P10: 138.33093 | Q10: 138.69752 | R10: 139.8823 | S10: 141.3579 | T10: 144.16474 | U10: 144.16474 | V10: 148.26991 | W10: 149.62379 | X10: 152.89401 | Y10: 154.37812 | Z10: 157.79593 | AA10: 161.14909 | AB10: 164.64034 | AC10: 168.23728 | AD10: 171.91277 | AE10: 171.84294 | AF10: 172.94277 | AG10: 174.06609 | AH10: 176.6524 | AI10: 179.89528 | AJ10: 180.82001 | AK10: 182.36256 | AL10: 183.70627 | AM10: 186.34961 | AN10: 187.87736 | AO10: 189.79271 | AP10: 191.91081 | AQ10: 194.23814 | AR10: 196.65032 | AS10: 199.15025 | AT10: 201.74093 | AU10: 204.42551 | AV10: 207.20725 | AW10: 210.02323 | AX10: 212.94165 | AY10: 215.96612 | AZ10: 216.38383 | BA10: 217.22175 | BB10: 218.48495 | BC10: 220.18104 | BD10: 222.32033 | BE10: 223.64426 | BF10: 225.10206 | BG10: 225.75833 | BH10: 226.4528 | BI10: 227.18464 | BJ10: 227.95303 | BK10: 227.99718 | BL10: 228.34866 | BM10: 229.06111 | BN10: 229.2948 | BO10: 229.54118 | BP10: 231.56992 | BQ10: 233.68623 | BR10: 236.31984 | BS10: 238.14759 | BT10: 241.26491 | BU10: 244.44847 | BV10: 247.9863 | BW10: 247.742
A11: Betão pronto | B11: 1.7346154 | C11: 120.57313 | D11: 124.82225 | E11: 124.16818 | F11: 125.84694 | G11: 127.92693 | H11: 130.50277 | I11: 129.38737 | J11: 132.04576 | K11: 132.29076 | L11: 131.80684 | M11: 139.04422 | N11: 142.97024 | O11: 144.66797 | P11: 147.3512 | Q11: 148.87754 | R11: 149.988 | S11: 152.94058 | T11: 156.63544 | U11: 156.63544 | V11: 159.23362 | W11: 162.41745 | X11: 166.11187 | Y11: 168.50076 | Z11: 172.24931 | AA11: 175.71372 | AB11: 179.48922 | AC11: 183.60229 | AD11: 187.8334 | AE11: 188.49723 | AF11: 189.74331 | AG11: 190.69445 | AH11: 193.52329 | AI11: 195.62866 | AJ11: 196.40871 | AK11: 198.13696 | AL11: 199.59624 | AM11: 201.66646 | AN11: 202.58971 | AO11: 203.71531 | AP11: 206.3047 | AQ11: 210.41373 | AR11: 214.61018 | AS11: 218.89611 | AT11: 223.27364 | AU11: 227.74494 | AV11: 232.30533 | AW11: 232.49468 | AX11: 232.71056 | AY11: 232.95146 | AZ11: 235.98732 | BA11: 242.18189 | BB11: 245.29864 | BC11: 248.44284 | BD11: 251.62786 | BE11: 254.88839 | BF11: 258.37285 | BG11: 262.00704 | BH11: 265.77425 | BI11: 269.67241 | BJ11: 273.69972 | BK11: 277.99858 | BL11: 278.33784 | BM11: 278.67752 | BN11: 279.59764 | BO11: 280.28733 | BP11: 283.04734 | BQ11: 288.20875 | BR11: 292.78353 | BS11: 294.89618 | BT11: 300.8636 | BU11: 301.67528 | BV11: 303.00243 | BW11: 303.83324
A12: Abobadilha | B12: 1.7346154 | C12: 120.57313 | D12: 124.82225 | E12: 124.16818 | F12: 125.84694 | G12: 127.92693 | H12: 130.50277 | I12: 129.38737 | J12: 132.04576 | K12: 132.29076 | L12: 131.80684 | M12: 139.04422 | N12: 142.97024 | O12: 144.66797 | P12: 147.3512 | Q12: 148.87754 | R12: 149.988 | S12: 152.94058 | T12: 156.63544 | U12: 156.63544 | V12: 159.23362 | W12: 162.41745 | X12: 166.11187 | Y12: 168.50076 | Z12: 172.24931 | AA12: 175.71372 | AB12: 179.48922 | AC12: 183.60229 | AD12: 187.8334 | AE12: 188.49723 | AF12: 189.74331 | AG12: 190.69445 | AH12: 193.52329 | AI12: 195.62866 | AJ12: 196.40871 | AK12: 198.13696 | AL12: 199.59624 | AM12: 201.66646 | AN12: 202.58971 | AO12: 203.71531 | AP12: 206.3047 | AQ12: 210.41373 | AR12: 214.61018 | AS12: 218.89611 | AT12: 223.27364 | AU12: 227.74494 | AV12: 232.30533 | AW12: 232.49468 | AX12: 232.71056 | AY12: 232.95146 | AZ12: 235.98732 | BA12: 242.18189 | BB12: 245.29864 | BC12: 248.44284 | BD12: 251.62786 | BE12: 254.88839 | BF12: 258.37285 | BG12: 262.00704 | BH12: 265.77425 | BI12: 269.67241 | BJ12: 273.69972 | BK12: 277.99858 | BL12: 278.33784 | BM12: 278.67752 | BN12: 279.59764 | BO12: 280.28733 | BP12: 283.04734 | BQ12: 288.20875 | BR12: 292.78353 | BS12: 294.89618 | BT12: 300.8636 | BU12: 301.67528 | BV12: 303.00243 | BW12: 303.83324
A13: Pedra britada e Mármore | B13: 0.865 | C13: 116.5722 | D13: 117.37119 | E13: 119.55077 | F13: 121.01228 | G13: 122.629 | H13: 124.6953 | I13: 126.22045 | J13: 128.89632 | K13: 131.06822 | L13: 132.6784 | M13: 132.98982 | N13: 134.88682 | O13: 136.62846 | P13: 137.38351 | Q13: 137.47307 | R13: 139.56892 | S13: 141.81949 | T13: 143.28381 | U13: 143.28381 | V13: 145.97739 | W13: 147.86829 | X13: 148.94379 | Y13: 151.66228 | Z13: 153.537 | AA13: 155.12475 | AB13: 156.90282 | AC13: 159.58895 | AD13: 162.33008 | AE13: 164.82584 | AF13: 165.57671 | AG13: 166.86137 | AH13: 169.35188 | AI13: 170.83351 | AJ13: 171.24897 | AK13: 174.32347 | AL13: 175.97182 | AM13: 177.48062 | AN13: 179.01164 | AO13: 180.70996 | AP13: 182.63731 | AQ13: 184.81248 | AR13: 187.12419 | AS13: 189.5799 | AT13: 192.18752 | AU13: 194.95551 | AV13: 197.89287 | AW13: 201.00917 | AX13: 204.31462 | AY13: 207.82008 | AZ13: 209.22504 | BA13: 212.08145 | BB13: 213.52957 | BC13: 215.22754 | BD13: 217.18192 | BE13: 219.40051 | BF13: 221.73939 | BG13: 224.3572 | BH13: 227.0161 | BI13: 229.71678 | BJ13: 232.45994 | BK13: 235.5058 | BL13: 236.33315 | BM13: 237.68714 | BN13: 239.09354 | BO13: 238.62966 | BP13: 239.23552 | BQ13: 239.48197 | BR13: 239.66637 | BS13: 241.92026 | BT13: 243.58524 | BU13: 245.26707 | BV13: 246.33857 | BW13: 245.62562
A14: Burgau | B14: 0.965 | C14: 116.5722 | D14: 117.37119 | E14: 119.55077 | F14: 121.01228 | G14: 122.629 | H14: 124.6953 | I14: 126.22045 | J14: 128.89632 | K14: 131.06822 | L14: 132.6784 | M14: 132.98982 | N14: 134.88682 | O14: 136.62846 | P14: 137.38351 | Q14: 137.47307 | R14: 139.56892 | S14: 141.81949 | T14: 143.28381 | U14: 143.28381 | V14: 145.97739 | W14: 147.86829 | X14: 148.94379 | Y14: 151.66228 | Z14: 153.537 | AA14: 155.12475 | AB14: 156.90282 | AC14: 159.58895 | AD14: 162.33008 | AE14: 164.82584 | AF14: 165.57671 | AG14: 166.86137 | AH14: 169.35188 | AI14: 170.83351 | AJ14: 171.24897 | AK14: 174.32347 | AL14: 175.97182 | AM14: 177.48062 | AN14: 179.01164 | AO14: 180.70996 | AP14: 182.63731 | AQ14: 184.81248 | AR14: 187.12419 | AS14: 189.5799 | AT14: 192.18752 | AU14: 194.95551 | AV14: 197.89287 | AW14: 201.00917 | AX14: 204.31462 | AY14: 207.82008 | AZ14: 209.22504 | BA14: 212.08145 | BB14: 213.52957 | BC14: 215.22754 | BD14: 217.18192 | BE14: 219.40051 | BF14: 221.73939 | BG14: 224.3572 | BH14: 227.0161 | BI14: 229.71678 | BJ14: 232.45994 | BK14: 235.5058 | BL14: 236.33315 | BM14: 237.68714 | BN14: 239.09354 | BO14: 238.62966 | BP14: 239.23552 | BQ14: 239.48197 | BR14: 239.66637 | BS14: 241.92026 | BT14: 243.58524 | BU14: 245.26707 | BV14: 246.33857 | BW14: 245.62562
... A28: Madeira e Contaplacado | B28: 0.9925 | C28: 120.15203 | D28: 120.2186 | E28: 118.74592 | F28: 118.90409 | G28: 120.37018 | H28: 121.40175 | I28: 123.12565 | J28: 126.66552 | K28: 130.91135 | L28: 132.661 | M28: 132.90313 | N28: 134.39096 | O28: 137.2925 | P28: 139.41425 | Q28: 140.1901 | R28: 142.87245 | S28: 146.98125 | T28: 149.2225 | U28: 149.2225 | V28: 153.87149 | W28: 158.79041 | X28: 162.21057 | Y28: 165.27226 | Z28: 170.17093 | AA28: 172.66184 | AB28: 176.09266 | AC28: 179.62195 | AD28: 183.22243 | AE28: 186.33709 | AF28: 189.36547 | AG28: 190.71025 | AH28: 191.60167 | AI28: 191.99535 | AJ28: 192.99043 | AK28: 195.17454 | AL28: 198.77722 | AM28: 202.97391 | AN28: 205.08691 | AO28: 207.46083 | AP28: 210.01993 | AQ28: 212.77473 | AR28: 215.71831 | AS28: 218.86235 | AT28: 222.21953 | AU28: 225.80361 | AV28: 229.62952 | AW28: 231.71679 | AX28: 233.91666 | AY28: 236.23323 | AZ28: 240.74844 | BA28: 250.39581 | BB28: 257.75727 | BC28: 262.37308 | BD28: 264.53791 | BE28: 265.2956 | BF28: 267.8138 | BG28: 270.10768 | BH28: 273.69623 | BI28: 278.53952 | BJ28: 284.60958 | BK28: 289.57838 | BL28: 292.31909 | BM28: 297.94429 | BN28: 306.65458 | BO28: 314.1787 | BP28: 318.90282 | BQ28: 320.31784 | BR28: 317.80843 | BS28: 320.78655 | BT28: 326.86785 | BU28: 333.35215 | BV28: 337.78354 | BW28: 331.53358
A29: Vigas, Vigotas e Ripas | B29: 0.083333333 | C29: 117.79096 | D29: 118.84707 | E29: 121.05406 | F29: 121.0233 | G29: 122.50584 | H29: 123.64946 | I29: 128.00192 | J29: 131.09109 | K29: 132.86344 | L29: 144.87243 | M29: 142.18132 | N29: 143.1214 | O29: 146.16421 | P29: 148.50137 | Q29: 149.25626 | R29: 150.03855 | S29: 153.28516 | T29: 156.13237 | AG29: 196.42905 | AH29: 197.67864 | AI29: 198.71263 | AJ29: 199.9972 | AK29: 201.63804 | AL29: 204.7013 | AM29: 208.15056 | AN29: 208.81843 | AO29: 209.86189 | AP29: 211.04167 | AQ29: 212.36011 | AR29: 213.76662 | AS29: 215.26267 | AT29: 216.84983 | AU29: 218.52983 | AV29: 220.30449 | AW29: 222.17577 | AX29: 224.14578 | AY29: 226.21674 | AZ29: 229.72782 | BA29: 233.77409 | BB29: 238.70735 | BC29: 243.99339 | BD29: 249.93946 | BE29: 254.64582 | BF29: 256.77833 | BG29: 258.56042 | BH29: 262.24845 | BI29: 267.80081 | BJ29: 275.20179 | BK29: 282.45037 | BL29: 290.04003 | BM29: 298.23073 | BN29: 307.22367 | BO29: 318.47635 | BP29: 320.24267 | BQ29: 320.69704 | BR29: 321.1525 | BS29: 323.89617 | BT29: 325.44166 | BU29: 327.34198 | BV29: 328.99035 | BW29: 328.46318
A30: Fonte: INE/Departamento de Estatísticas Económica e Financeira

Sheet Variação_Mensal
A1: Variação Mensal do IPMC
A2: Materiais de Construção | B2: 43831 | C2: 43862 | D2: 43891 | E2: 43922 | F2: 43952 | G2: 43983 | H2: 44013 | I2: 44044 | J2: 44075 | K2: 44105 | L2: 44136 | M2: 44166 | N2: 44197 | O2: 44228 | P2: 44256 | Q2: 44287 | R2: 44317 | S2: 44348 | T2: 44378 | U2: 44409 | V2: 44440 | W2: 44470 | X2: 44501 | Y2: 44531 | Z2: 44562 | AA2: 44593 | AB2: 44621 | AC2: 44652 | AD2: 44682 | AE2: 44713 | AF2: 44743 | AG2: 44774 | AH2: 44805 | AI2: 44835 | AJ2: 44866 | AK2: 44896 | AL2: Jan-23 | AM2: Fev-23 | AN2: Mar-23 | AO2: Abr-23 | AP2: Mai-23 | AQ2: Jun-23 | AR2: Jul-23 | AS2: Ago-23 | AT2: Set-23 | AU2: Out-23 | AV2: Nov-23 | AW2: Dez-23 | AX2: Jan-24 | AY2: Fev-24 | AZ2: Mar-23 | BA2: Abr-23 | BB2: Mai-23 | BC2: 45444 | BD2: 45474 | BE2: 45505 | BF2: 45536 | BG2: 45566 | BH2: 45597 | BI2: 45627 | BJ2: 45658 | BK2: 45689 | BL2: 45717 | BM2: 45748 | BN2: 45778 | BO2: 45809 | BP2: 45839 | BQ2: 45870 | BR2: 45901 | BS2: 45931 | BT2: 45962 | BU2: 45992
A3: Total Material de Construção | B3: 0.98892154 | C3: 1.1174292 | D3: 0.88561806 | E3: 0.49130359 | F3: 1.3844747 | G3: 1.3856311 | H3: 0.66650274 | I3: 1.3640145 | J3: 0.92195251 | K3: 0.90915254 | L3: 1.8456655 | M3: 2.7249733 | N3: 1.8526147 | O3: 2.7249733 | P3: 1.8526147 | Q3: 1.5066017 | R3: -0.79808704 | S3: 0.34584909 | T3: 1.4865971 | U3: 1.7479917 | V3: 1.9434798 | W3: 1.5639496 | X3: 1.9535782 | Y3: 1.9493311 | Z3: 2.0563245 | AA3: 2.135776 | AB3: 2.135776 | AC3: 1.8549454 | AD3: 0.87982958 | AE3: 0.44260612 | AF3: 0.34426923 | AG3: 0.61758818 | AH3: 0.67951099 | AI3: 0.4779861 | AJ3: 0.56723571 | AK3: 0.70075418 | AL3: 0.75514091 | AM3: 0.72689796 | AN3: 0.87945969 | AO3: 1.0319448 | AP3: 1.1091347 | AQ3: 1.186065 | AR3: 1.2631141 | AS3: 1.340656 | AT3: 2.0858963 | AU3: 2.1014141 | AV3: 1.9318234 | AW3: 2.5997968 | AX3: 2.2611347 | AY3: 2.1840479 | AZ3: 2.1232237 | BA3: 0.44451783 | BB3: 1.8690989 | BC3: 1.7892442 | BD3: 1.4243551 | BE3: 1.2069546 | BF3: 1.3902646 | BG3: 1.3192069 | BH3: 1.4468432 | BI3: 1.5317044 | BJ3: 1.3107653 | BK3: 1.2412228 | BL3: 1.1413017 | BM3: 1.1313066 | BN3: 0.4619476 | BO3: =+Índice!BQ3/Índice!BP3*100-100 -> 1.0905785 | BP3: =+Índice!BR3/Índice!BQ3*100-100 -> 0.5319521 | BQ3: =+Índice!BS3/Índice!BR3*100-100 -> 0.70618343 | BR3: 0.65383624 | BS3: 0.584352 | BT3: 0.74977883 | BU3: 0.57710436
A4: Aço | B4: 1.0291541 | C4: 1.3364475 | D4: 1.2901914 | E4: 0.53288116 | F4: 0.94707033 | G4: 1.2322797 | H4: 1.4044434 | I4: 1.4543548 | J4: 0.9131382 | K4: 0.58425785 | L4: 2.2389386 | M4: 1.760344 | N4: 2.2562008 | O4: 1.760344 | P4: 2.2562008 | Q4: 1.0955206 | R4: 0.62472913 | S4: 1.1978776 | T4: 1.9964196 | U4: 1.3723961 | V4: 1.793881 | W4: 2.2616896 | X4: 2.8179158 | Y4: 2.1404681 | Z4: 2.1680648 | AA4: 2.2314437 | AB4: 2.2314437 | AC4: 2.2212516 | AD4: 1.3913584 | AE4: 0.49962657 | AF4: 0.37231111 | AG4: 0.91172925 | AH4: 0.49230737 | AI4: 0.55203626 | AJ4: 0.1614624 | AK4: 0.50814377 | AL4: 0.30355468 | AM4: 0.95170609 | AN4: 1.1909539 | AO4: 1.4239331 | AP4: 1.5752258 | AQ4: 1.7230801 | AR4: 1.8680188 | AS4: 2.0104903 | AT4: 1.7180295 | AU4: 0.93860552 | AV4: 1.418764 | AW4: 1.9050301 | AX4: 0.9506168 | AY4: 0.24394264 | AZ4: 0.41483867 | BA4: 0.61703175 | BB4: 2.1641398 | BC4: 0.76331007 | BD4: 0.92238052 | BE4: 0.47433881 | BF4: 0.65217617 | BG4: 0.82900197 | BH4: 1.0053013 | BI4: 0.80072695 | BJ4: 2.1675687 | BK4: 2.2818555 | BL4: 2.3969132 | BM4: 2.4381784 | BN4: 0.81565831 | BO4: =+Índice!BQ4/Índice!BP4*100-100 -> 1.254394 | BP4: =+Índice!BR4/Índice!BQ4*100-100 -> 1.2788061 | BQ4: =+Índice!BS4/Índice!BR4*100-100 -> 0.98877728 | BR4: 0.47337823 | BS4: 0.39281372 | BT4: 0.73010102 | BU4: 0.71297861
A5: Varões de aço | B5: 1.425 | C5: 0.5745 | D5: 1.6253 | E5: -0.08854 | F5: 1.15547 | G5: 1.1524 | H5: 1.225 | I5: 1.12885 | J5: 0.557 | K5: 0.8562 | L5: 3.675024 | M5: 1.0846766 | N5: 2.9373294 | O5: 1.0846766 | P5: 2.9373294 | Q5: 0.51646565 | R5: 0.7370679 | S5: 1.2411256 | T5: 1.9521 | U5: 1.62354 | V5: 1.9852566 | W5: 2.284734 | X5: 2.7500514 | Y5: 2.1330641 | Z5: 2.1749194 | AA5: 2.2308471 | AB5: 2.2308471 | AC5: 2.2311174 | AD5: 1.8439064 | AE5: 0.67131078 | AF5: 4.7276153 | AG5: 1.4731206 | AH5: 0.10395624 | AI5: 0.75494074 | AJ5: 0.078857649 | AK5: 0.60847336 | AL5: 0.45404462 | AM5: 0.73637408 | AN5: 0.97781502 | AO5: 1.2087912 | AP5: 1.3387397 | AQ5: 1.4618486 | AR5: 1.5790417 | AS5: 1.6911169 | AT5: 1.4873897 | AU5: 1.0554414 | AV5: 1.3443732 | AW5: 1.6320463 | AX5: 0.24939821 | AY5: -2.5038239 | AZ5: 0.062809645 | BA5: 0.30667832 | BB5: 2.2015051 | BC5: 0.78969136 | BD5: 0.89712233 | BE5: 0.77152897 | BF5: 0.85142064 | BG5: 0.93331901 | BH5: 1.0172571 | BI5: 0.87475454 | BJ5: 0.887485 | BK5: 0.90422207 | BL5: 0.6263185 | BM5: 0.38834923 | BN5: -0.63944876 | BO5: =+Índice!BQ5/Índice!BP5*100-100 -> -0.37229706 | BP5: =+Índice!BR5/Índice!BQ5*100-100 -> -0.19965411 | BQ5: =+Índice!BS5/Índice!BR5*100-100 -> 0.88253044 | BR5: 0.66691142 | BS5: -1.905131 | BT5: 0.4131785 | BU5: 0.98269456
A6: Tubos de Aço | B6: 0.52214 | C6: 2.311 | D6: 0.86635 | E6: 1.288 | F6: 0.67785 | G6: 1.3352 | H6: 1.6352 | I6: 1.86054 | J6: 1.3385 | K6: 0.25142 | L6: 0.49261396 | M6: 2.6268432 | N6: 1.4255799 | O6: 2.6268432 | P6: 1.4255799 | Q6: 1.8366481 | R6: 0.48352845 | S6: 1.1425857 | T6: 2.0521456 | U6: 1.0526856 | V6: 1.5478545 | W6: 2.2424324 | X6: 2.9083057 | Y6: 2.1492575 | Z6: 2.1601982 | AA6: 2.2334272 | AB6: 2.2334272 | AC6: 2.2096457 | AD6: 0.80855533 | AE6: 0.27510801 | AF6: -5.3295288 | AG6: 0.10669708 | AH6: 1.0643406 | AI6: 0.2606005 | AJ6: 0.2814293 | AK6: 0.36178283 | AL6: 0.081158388 | AM6: 1.2709556 | AN6: 1.5043951 | AO6: 1.7379436 | AP6: 1.9185985 | AQ6: 2.1003407 | AR6: 2.2829355 | AS6: 2.466146 | AT6: 2.0338015 | AU6: 0.77146865 | AV6: 1.5329258 | AW6: 2.3111873 | AX6: 1.9796454 | AY6: 4.1738425 | AZ6: 0.88820919 | BA6: 1.0326033 | BB6: 2.1327533 | BC6: 0.73238907 | BD6: 0.96054487 | BE6: 0.082631352 | BF6: 0.38944468 | BG6: 0.69329209 | BH6: 0.99435213 | BI6: 0.70431657 | BJ6: 3.8932402 | BK6: 4.0854458 | BL6: 4.6404908 | BM6: 4.9356142 | BN6: 2.5088163 | BO6: =+Índice!BQ6/Índice!BP6*100-100 -> 3.0918342 | BP6: =+Índice!BR6/Índice!BQ6*100-100 -> 2.8948548 | BQ6: =+Índice!BS6/Índice!BR6*100-100 -> 1.1027517 | BR6: 0.26473074 | BS6: 2.8131073 | BT6: 1.0528447 | BU6: 0.42630742
A7: Malhasol | B7: 2.0524 | C7: 0.5241 | D7: 1.9352 | E7: 3.52 | F7: 2.1412 | G7: 0.8625 | H7: 0.5745 | I7: 1.13152 | J7: 2.338 | K7: 0.68574 | L7: 0.34962035 | M7: 0.59210201 | N7: 0.078679847 | O7: 0.59210201 | P7: 0.078679847 | Q7: 0.19985745 | R7: 0.71564563 | S7: 1.3252214 | T7: 1.9808533 | U7: 1.9521453 | V7: 2.3521459 | W7: 1.0690299 | X7: 2.5089496 | Y7: 2.2285015 | Z7: 2.0556265 | AA7: 2.0915374 | AB7: 2.0915374 | AC7: 2.0915942 | AD7: 1.2518092 | AE7: 0.57850552 | AF7: 0.50806689 | AG7: 0.06531222 | AH7: 0.27119712 | AI7: 0.16638237 | AJ7: 0.23922888 | AK7: 0.51711461 | AL7: 0.56993394 | AM7: 2.1124458 | AN7: 2.4168163 | AO7: 2.7197083 | AP7: 2.9781517 | AQ7: 3.236393 | AR7: 3.4936136 | AS7: 3.7490197 | AT7: 4.0018539 | AU7: 0.57833509 | AV7: 0.93547512 | AW7: 1.2810399 | AX7: 0.058324267 | AY7: 0.11668877 | AZ7: 0.17509974 | BA7: 0.23356344 | BB7: 0.29208611 | BC7: 0.35067399 | BD7: 0.40314589 | BE7: 0.46184822 | BF7: 0.46250092 | BG7: 0.46315355 | BH7: 0.46380611 | BI7: 0.52263031 | BJ7: 0.95577155 | BK7: 0.96261696 | BL7: 1.1193356 | BM7: 1.0053974 | BN7: 0.15897512 | BO7: =+Índice!BQ7/Índice!BP7*100-100 -> 0.17703694 | BP7: =+Índice!BR7/Índice!BQ7*100-100 -> 0.023886773 | BQ7: =+Índice!BS7/Índice!BR7*100-100 -> 0.72035114 | BR7: 1.1634255 | BS7: 1.1713509 | BT7: 2.3097949 | BU7: 1.2012952
A8: Aluminio | B8: 0.1552 | C8: 1.4253 | D8: 1.3352 | E8: 0.568 | F8: 1.8542 | G8: 1.0523 | H8: 1.355 | I8: 2.352 | J8: 3.45 | K8: 1.03658 | L8: 3.2526252 | M8: 3.6931172 | N8: 2.9936401 | O8: 3.6931172 | P8: 2.9936401 | Q8: 2.0895707 | R8: 1.057933 | S8: 1.0636225 | T8: 2.6851746 | U8: 1.8542254 | V8: 1.2547746 | W8: 1.8582097 | X8: 2.708986 | Y8: 2.5129949 | Z8: 2.1834805 | AA8: 2.2827718 | AB8: 2.2827718 | AC8: 2.2827497 | AD8: 1.939959 | AE8: 0.3315494 | AF8: 0.40378465 | AG8: 0.079783414 | AH8: 0.69585611 | AI8: 0.6240535 | AJ8: 0.85333761 | AK8: 1.0537491 | AL8: 0.3301535 | AM8: 0.22953307 | AN8: 0.28418616 | AO8: 0.33912037 | AP8: 0.35643091 | AQ8: 0.37376577 | AR8: 0.39112709 | AS8: 0.40851702 | AT8: 0.4259377 | AU8: 0.44339131 | AV8: 0.054767834 | AW8: 0.6055708 | AX8: 3.065797 | AY8: 1.0187752 | AZ8: 0.84533133 | BA8: 1.1370153 | BB8: 1.9711384 | BC8: 0.83340047 | BD8: 0.72798048 | BE8: 0.75043168 | BF8: 1.4354955 | BG8: 1.9113879 | BH8: 2.2630038 | BI8: 2.1342449 | BJ8: 0.78907354 | BK8: 1.5873747 | BL8: 1.4737932 | BM8: 1.6083817 | BN8: 0.90464996 | BO8: =+Índice!BQ8/Índice!BP8*100-100 -> 0.5593298 | BP8: =+Índice!BR8/Índice!BQ8*100-100 -> 0.98912543 | BQ8: =+Índice!BS8/Índice!BR8*100-100 -> 1.0727146 | BR8: 1.2315092 | BS8: 0.012287583 | BT8: 1.3235282 | BU8: 1.3516439
A9: Chapas perfiladas | B9: 0.1552 | C9: 1.4253 | D9: 1.3352 | E9: 0.568 | F9: 1.8542 | G9: 1.0523 | H9: 1.355 | I9: 2.352 | J9: 3.45 | K9: 1.03658 | L9: 3.2526252 | M9: 3.6931172 | N9: 2.9936401 | O9: 3.6931172 | P9: 2.9936401 | Q9: 2.0895707 | R9: 1.057933 | S9: 1.0636225 | T9: 2.6851746 | U9: 1.8542254 | V9: 1.2547746 | W9: 1.8582097 | X9: 2.708986 | Y9: 2.5129949 | Z9: 2.1834805 | AA9: 2.2827718 | AB9: 2.2827718 | AC9: 2.2827497 | AD9: 1.939959 | AE9: 0.3315494 | AF9: 0.40378465 | AG9: 0.079783414 | AH9: 0.69585611 | AI9: 0.6240535 | AJ9: 0.85333761 | AK9: 1.0537491 | AL9: 0.3301535 | AM9: 0.22953307 | AN9: 0.28418616 | AO9: 0.33912037 | AP9: 0.35643091 | AQ9: 0.37376577 | AR9: 0.39112709 | AS9: 0.40851702 | AT9: 0.4259377 | AU9: 0.44339131 | AV9: 0.054767834 | AW9: 0.6055708 | AX9: 3.065797 | AY9: 1.0187752 | AZ9: 0.84533133 | BA9: 1.1370153 | BB9: 1.9711384 | BC9: 0.83340047 | BD9: 0.72798048 | BE9: 0.75043168 | BF9: 1.4354955 | BG9: 1.9113879 | BH9: 2.2630038 | BI9: 2.1342449 | BJ9: 0.78907354 | BK9: 1.5873747 | BL9: 1.4737932 | BM9: 1.6083817 | BN9: 0.90464996 | BO9: =+Índice!BQ9/Índice!BP9*100-100 -> 0.5593298 | BP9: =+Índice!BR9/Índice!BQ9*100-100 -> 0.98912543 | BQ9: =+Índice!BS9/Índice!BR9*100-100 -> 1.0727146 | BR9: 1.2315092 | BS9: 0.012287583 | BT9: 1.3235282 | BU9: 1.3516439
A10: Areia | B10: 0.652 | C10: 0.6635 | D10: 0.1122 | E10: 0.15424 | F10: 0.3524 | G10: 0.524 | H10: 0.65524 | I10: 0.5236 | J10: 2.11 | K10: 2.0325 | L10: 2.6216474 | M10: 1.8425256 | N10: 0.94214049 | O10: 1.8425256 | P10: 0.94214049 | Q10: 1.45574 | R10: 0.26500595 | S10: 0.85422145 | T10: 1.054885 | U10: 1.9856255 | V10: 2.8475582 | W10: 0.97068455 | X10: 2.2139172 | Y10: 2.1250017 | Z10: 2.1664702 | AA10: 2.1847282 | AB10: 2.1847282 | AC10: 2.1847021 | AD10: -0.040621177 | AE10: 0.64002059 | AF10: 0.64953581 | AG10: 1.4858207 | AH10: 1.8357385 | AI10: 0.51404128 | AJ10: 0.85308584 | AK10: 0.73683058 | AL10: 1.4388989 | AM10: 1.0194694 | AN10: 1.1160063 | AO10: 1.2127145 | AP10: 1.2418675 | AQ10: 1.2712542 | AR10: 1.3008693 | AS10: 1.3307069 | AT10: 1.3607607 | AU10: 1.3590139 | AV10: 1.3895701 | AW10: 1.4203299 | AX10: 0.19341333 | AY10: 0.38724028 | AZ10: 0.58152132 | BA10: 0.77629704 | BB10: 0.97160804 | BC10: 0.59550512 | BD10: 0.65183599 | BE10: 0.2915442 | BF10: 0.30761852 | BG10: 0.32317353 | BH10: 0.33822509 | BI10: 0.019367622 | BJ10: 0.15415992 | BK10: 0.31200101 | BL10: 0.10202082 | BM10: 0.10745049 | BN10: 0.88382191 | BO10: =+Índice!BQ10/Índice!BP10*100-100 -> 0.91389689 | BP10: =+Índice!BR10/Índice!BQ10*100-100 -> 1.1269877 | BQ10: =+Índice!BS10/Índice!BR10*100-100 -> 0.7734219 | BR10: 1.3089876 | BS10: 1.3195277 | BT10: 1.4472679 | BU10: 1.2197166
A11: Betão pronto | B11: 2.142 | C11: 3.5241 | D11: -0.524 | E11: 1.352 | F11: 1.6528 | G11: 2.013525 | H11: -0.8547 | I11: 2.0546 | J11: 0.18554 | K11: -0.3658 | L11: 5.4908975 | M11: 2.8235785 | N11: 1.1874694 | O11: 2.8235785 | P11: 1.1874694 | Q11: 1.8547552 | R11: 1.0358507 | S11: 0.74588541 | T11: 1.9685452 | U11: 2.4158814 | V11: 1.6587446 | W11: 1.4381209 | X11: 2.224645 | Y11: 2.0112769 | Z11: 2.1486646 | AA11: 2.2915409 | AB11: 2.2915409 | AC11: 2.3044997 | AD11: 0.35341321 | AE11: 0.66105951 | AF11: 0.50127827 | AG11: 1.4834429 | AH11: 1.0879135 | AI11: 0.39874219 | AJ11: 0.87992223 | AK11: 0.73650438 | AL11: 1.0372014 | AM11: 0.55560564 | AN11: 1.2710854 | AO11: 1.9917261 | AP11: 1.9943799 | AQ11: 1.9970772 | AR11: 1.9998208 | AS11: 2.0026135 | AT11: 2.0024105 | AU11: 0.081507369 | AV11: 0.092856128 | AW11: 0.10351865 | AX11: 1.3032149 | AY11: 2.6249568 | AZ11: 1.2869486 | BA11: 1.2817822 | BB11: 1.2819938 | BC11: 1.2957762 | BD11: 1.3670503 | BE11: 1.406569 | BF11: 1.4378294 | BG11: 1.4667184 | BH11: 1.4934071 | BI11: 1.5706499 | BJ11: 0.12203469 | BK11: 0.1220384 | BL11: 0.33017475 | BM11: 0.24667417 | BN11: 0.9847047 | BO11: =+Índice!BQ11/Índice!BP11*100-100 -> 1.8235144 | BP11: =+Índice!BR11/Índice!BQ11*100-100 -> 1.5873153 | BQ11: =+Índice!BS11/Índice!BR11*100-100 -> 0.72157432 | BR11: 2.0235659 | BS11: 0.26978389 | BT11: 0.43992697 | BU11: 0.54471768
A12: Abobadilha | B12: 2.142 | C12: 3.5241 | D12: -0.524 | E12: 1.352 | F12: 1.6528 | G12: 2.013525 | H12: -0.8547 | I12: 2.0546 | J12: 0.18554 | K12: -0.3658 | L12: 5.4908975 | M12: 2.8235785 | N12: 1.1874694 | O12: 2.8235785 | P12: 1.1874694 | Q12: 1.8547552 | R12: 1.0358507 | S12: 0.74588541 | T12: 1.9685452 | U12: 2.4158814 | V12: 1.6587446 | W12: 1.4381209 | X12: 2.224645 | Y12: 2.0112769 | Z12: 2.1486646 | AA12: 2.2915409 | AB12: 2.2915409 | AC12: 2.3044997 | AD12: 0.35341321 | AE12: 0.66105951 | AF12: 0.50127827 | AG12: 1.4834429 | AH12: 1.0879135 | AI12: 0.39874219 | AJ12: 0.87992223 | AK12: 0.73650438 | AL12: 1.0372014 | AM12: 0.55560564 | AN12: 1.2710854 | AO12: 1.9917261 | AP12: 1.9943799 | AQ12: 1.9970772 | AR12: 1.9998208 | AS12: 2.0026135 | AT12: 2.0024105 | AU12: 0.081507369 | AV12: 0.092856128 | AW12: 0.10351865 | AX12: 1.3032149 | AY12: 2.6249568 | AZ12: 1.2869486 | BA12: 1.2817822 | BB12: 1.2819938 | BC12: 1.2957762 | BD12: 1.3670503 | BE12: 1.406569 | BF12: 1.4378294 | BG12: 1.4667184 | BH12: 1.4934071 | BI12: 1.5706499 | BJ12: 0.12203469 | BK12: 0.1220384 | BL12: 0.33017475 | BM12: 0.24667417 | BN12: 0.9847047 | BO12: =+Índice!BQ12/Índice!BP12*100-100 -> 1.8235144 | BP12: =+Índice!BR12/Índice!BQ12*100-100 -> 1.5873153 | BQ12: =+Índice!BS12/Índice!BR12*100-100 -> 0.72157432 | BR12: 2.0235659 | BS12: 0.26978389 | BT12: 0.43992697 | BU12: 0.54471768
A13: Pedra britada e Mármore | B13: 1.333 | C13: 0.6854 | D13: 1.857 | E13: 1.2225 | F13: 1.336 | G13: 1.685 | H13: 1.2231 | I13: 2.12 | J13: 1.685 | K13: 1.2285 | L13: 0.23472149 | M13: 1.4264236 | N13: 1.2911891 | O13: 1.4264236 | P13: 1.2911891 | Q13: 0.55262923 | R13: 0.065188507 | S13: 1.5245562 | T13: 1.6125146 | U13: 1.0325234 | V13: 1.8798857 | W13: 1.8251789 | X13: 1.2361151 | Y13: 1.0341203 | Z13: 1.1462175 | AA13: 1.7119727 | AB13: 1.7119727 | AC13: 1.7176136 | AD13: 1.5374615 | AE13: 0.45555707 | AF13: 0.77587044 | AG13: 1.4925567 | AH13: 0.8748881 | AI13: 0.24319273 | AJ13: 1.7953424 | AK13: 0.94556804 | AL13: 0.85740982 | AM13: 0.94872193 | AN13: 1.0665443 | AO13: 1.1909775 | AP13: 1.2508414 | AQ13: 1.312338 | AR13: 1.3754752 | AS13: 1.4402566 | AT13: 1.5066806 | AU13: 1.574741 | AV13: 1.6444255 | AW13: 1.7157168 | AX13: 0.67604938 | AY13: 1.3652308 | AZ13: 0.68281331 | BA13: 0.79519466 | BB13: 0.90805171 | BC13: 1.0215353 | BD13: 1.0660319 | BE13: 1.1805796 | BF13: 1.1851196 | BG13: 1.1896428 | BH13: 1.1941491 | BI13: 1.3102731 | BJ13: 0.35130596 | BK13: 0.57291537 | BL13: 0.59170093 | BM13: -0.19401645 | BN13: 0.25389335 | BO13: =+Índice!BQ13/Índice!BP13*100-100 -> 0.10301428 | BP13: =+Índice!BR13/Índice!BQ13*100-100 -> 0.077001698 | BQ13: =+Índice!BS13/Índice!BR13*100-100 -> 0.94042796 | BR13: 0.68823233 | BS13: 0.69045019 | BT13: 0.43687071 | BU13: 0.39903217
A14: Burgau | B14: 1.333 | C14: 0.6854 | D14: 1.857 | E14: 1.2225 | F14: 1.336 | G14: 1.685 | H14: 1.2231 | I14: 2.12 | J14: 1.685 | K14: 1.2285 | L14: 0.23472149 | M14: 1.4264236 | N14: 1.2911891 | O14: 1.4264236 | P14: 1.2911891 | Q14: 0.55262923 | R14: 0.065188507 | S14: 1.5245562 | T14: 1.6125146 | U14: 1.0325234 | V14: 1.8798857 | W14: 1.8251789 | X14: 1.2361151 | Y14: 1.0341203 | Z14: 1.1462175 | AA14: 1.7119727 | AB14: 1.7119727 | AC14: 1.7176136 | AD14: 1.5374615 | AE14: 0.45555707 | AF14: 0.77587044 | AG14: 1.4925567 | AH14: 0.8748881 | AI14: 0.24319273 | AJ14: 1.7953424 | AK14: 0.94556804 | AL14: 0.85740982 | AM14: 0.94872193 | AN14: 1.0665443 | AO14: 1.1909775 | AP14: 1.2508414 | AQ14: 1.312338 | AR14: 1.3754752 | AS14: 1.4402566 | AT14: 1.5066806 | AU14: 1.574741 | AV14: 1.6444255 | AW14: 1.7157168 | AX14: 0.67604938 | AY14: 1.3652308 | AZ14: 0.68281331 | BA14: 0.79519466 | BB14: 0.90805171 | BC14: 1.0215353 | BD14: 1.0660319 | BE14: 1.1805796 | BF14: 1.1851196 | BG14: 1.1896428 | BH14: 1.1941491 | BI14: 1.3102731 | BJ14: 0.35130596 | BK14: 0.57291537 | BL14: 0.59170093 | BM14: -0.19401645 | BN14: 0.25389335 | BO14: =+Índice!BQ14/Índice!BP14*100-100 -> 0.10301428 | BP14: =+Índice!BR14/Índice!BQ14*100-100 -> 0.077001698 | BQ14: =+Índice!BS14/Índice!BR14*100-100 -> 0.94042796 | BR14: 0.68823233 | BS14: 0.69045019 | BT14: 0.43687071 | BU14: 0.39903217
... A29: Vigas, Vigotas e Ripas | B29: 0.1158 | C29: 0.8966 | D29: 1.857 | E29: -0.02541 | F29: 1.225 | G29: 0.93352 | H29: 3.52 | I29: 2.41338 | J29: 1.352 | K29: 2.05644 | L29: 4.8568106 | M29: 0.66118491 | N29: 2.1260275 | O29: 0.66118491 | P29: 2.1260275 | Q29: 1.599 | R29: 0.50833552 | S29: 0.524125 | T29: 2.1638556 | U29: 1.8574589 | V29: 4.6859889 | W29: 1.6710271 | X29: 2.3893641 | Y29: 2.4767548 | Z29: 2.151277 | AA29: 2.1620894 | AB29: 2.1620894 | AC29: 2.1625885 | AD29: 0.93926931 | AE29: 0.27641116 | AF29: 0.38964847 | AG29: 0.63615196 | AH29: 0.52306796 | AI29: 0.64644652 | AJ29: 0.82043017 | AK29: 1.5191857 | AL29: 1.6850204 | AM29: 0.49969789 | AN29: 0.56216823 | AO29: 0.62473247 | AP29: 0.66232311 | AQ29: 0.69984936 | AR29: 0.73731603 | AS29: 0.7747281 | AT29: 0.81209064 | AU29: 0.84940888 | AV29: 0.88668817 | AW29: 0.92393399 | AX29: 1.5520875 | AY29: 1.7613312 | AZ29: 2.1102685 | BA29: 2.2144442 | BB29: 2.4369809 | BC29: 1.8829967 | BD29: 0.83744487 | BE29: 0.69401845 | BF29: 1.4263681 | BG29: 2.1172144 | BH29: 2.7636132 | BI29: 2.6339171 | BJ29: 2.6870755 | BK29: 2.8239914 | BL29: 3.0154289 | BM29: 3.6626994 | BN29: 0.55582848 | BO29: =+Índice!BQ29/Índice!BP29*100-100 -> 0.14188123 | BP29: =+Índice!BR29/Índice!BQ29*100-100 -> 0.14202146 | BQ29: =+Índice!BS29/Índice!BR29*100-100 -> 0.85432278 | BR29: 0.47715584 | BS29: 0.58391895 | BT29: 0.50356099 | BU29: 0.42274556
A30: Fonte: INE/Departamento de Estatísticas Económica e Financeira

Sheet Variação_Homóloga
A1: Variação Homóloga do IPMC
A2: Materiais de Construção | B2: 43831 | C2: 43862 | D2: 43891 | E2: 43922 | F2: 43952 | G2: 43983 | H2: 44013 | I2: 44044 | J2: 44075 | K2: 44105 | L2: 44136 | M2: 44166 | N2: 44197 | O2: 44228 | P2: 44256 | Q2: 44287 | R2: 44317 | S2: 44348 | T2: 44378 | U2: 44409 | V2: 44440 | W2: 44470 | X2: 44501 | Y2: 44531 | Z2: 44562 | AA2: 44228 | AB2: 44621 | AC2: 44652 | AD2: 44682 | AE2: 44713 | AF2: 44743 | AG2: 44774 | AH2: 44805 | AI2: 44835 | AJ2: 44866 | AK2: 44896 | AL2: Jan-23 | AM2: Fev-23 | AN2: Mar-23 | AO2: Abr-23 | AP2: Mai-23 | AQ2: Jun-23 | AR2: Jul-23 | AS2: Ago-23 | AT2: Set-23 | AU2: Out-23 | AV2: Nov-23 | AW2: Dez-23 | AX2: Jan-24 | AY2: Fev-24 | AZ2: Mar-24 | BA2: Abr-24 | BB2: Mai-24 | BC2: 45444 | BD2: 45474 | BE2: 45505 | BF2: 45536 | BG2: 45566 | BH2: 45597 | BI2: 45627 | BJ2: 45658 | BK2: 45689 | BL2: 45717 | BM2: 45748 | BN2: 45778 | BO2: 45809 | BP2: 45839 | BQ2: 45870 | BR2: 45901 | BS2: 45931 | BT2: 45962 | BU2: 45992
A3: Total Material de Construção | B3: 17.777376 | C3: 17.844705 | D3: 18.349843 | E3: 16.926323 | F3: 16.215627 | G3: 16.307558 | H3: 14.029048 | I3: 14.695806 | J3: 13.611929 | K3: 13.672497 | L3: 14.677509 | M3: 15.693492 | N3: 16.682944 | O3: 15.693492 | P3: 16.682944 | Q3: 17.132024 | R3: 15.177179 | S3: 16.810221 | T3: 16.634186 | U3: 16.672985 | V3: 18.31062 | W3: 20.734268 | X3: 20.844008 | Y3: 19.857637 | Z3: 20.622539 | AA3: 21.694355 | AB3: 21.694355 | AC3: 23.07186 | AD3: 23.726775 | AE3: 22.454 | AF3: 20.764616 | AG3: 19.193934 | AH3: 17.726058 | AI3: 15.991771 | AJ3: 14.853468 | AK3: 13.442127 | AL3: 12.113316 | AM3: 9.1530574 | AN3: 8.1076762 | AO3: 8.2706901 | AP3: 8.9891652 | AQ3: 9.9034837 | AR3: 10.608585 | AS3: 11.334932 | AT3: 13.116582 | AU3: 14.842204 | AV3: 16.246152 | AW3: 18.374422 | AX3: 20.14824 | AY3: 21.886346 | AZ3: 23.389109 | BA3: 22.671691 | BB3: 23.593725 | BC3: 24.330479 | BD3: 24.52845 | BE3: 24.364156 | BF3: 23.516716 | BG3: 22.570445 | BH3: 21.987268 | BI3: 20.717347 | BJ3: 19.595454 | BK3: 18.491978 | BL3: 17.352669 | BM3: 18.155068 | BN3: 16.522953 | BO3: =+Índice!BQ3/Índice!BE3*100-100 -> 16.051024 | BP3: =+Índice!BR3/Índice!BF3*100-100 -> 15.029925 | BQ3: =+Índice!BS3/Índice!BG3*100-100 -> 14.460758 | BR3: 13.628591 | BS3: 12.805638 | BT3: 12.030984 | BU3: 12.022911
A4: Aço | B4: 16.617502 | C4: 16.934979 | D4: 17.403533 | E4: 16.728385 | F4: 15.457062 | G4: 15.49989 | H4: 14.103121 | I4: 16.014986 | J4: 15.365332 | K4: 14.066571 | L4: 15.325721 | M4: 15.744658 | N4: 17.150431 | O4: 15.744658 | P4: 17.150431 | Q4: 16.871907 | R4: 16.104075 | S4: 16.87207 | T4: 18.08696 | U4: 18.250405 | V4: 18.704539 | W4: 24.182504 | X4: 24.885747 | Y4: 25.352256 | Z4: 25.244213 | AA4: 26.651474 | AB4: 26.651474 | AC4: 28.660939 | AD4: 28.906927 | AE4: 27.015223 | AF4: 25.76216 | AG4: 24.672298 | AH4: 21.56328 | AI4: 19.581806 | AJ4: 17.125863 | AK4: 14.494667 | AL4: 12.435573 | AM4: 10.048658 | AN4: 8.9394668 | AO4: 8.9744665 | AP4: 10.140768 | AQ4: 11.622997 | AR4: 12.680791 | AS4: 14.383111 | AT4: 15.709489 | AU4: 16.607267 | AV4: 17.663748 | AW4: 19.542402 | AX4: 19.169178 | AY4: 18.333694 | AZ4: 17.426097 | BA4: 16.491887 | BB4: 17.167285 | BC4: 16.061797 | BD4: 14.984398 | BE4: 13.252875 | BF4: 12.066154 | BG4: 11.944468 | BH4: 11.488094 | BI4: 10.279943 | BJ4: 11.609359 | BK4: 13.878326 | BL4: 16.126154 | BM4: 18.228013 | BN4: 16.667502 | BO4: =+Índice!BQ4/Índice!BE4*100-100 -> 17.236097 | BP4: =+Índice!BR4/Índice!BF4*100-100 -> 17.650137 | BQ4: =+Índice!BS4/Índice!BG4*100-100 -> 18.252517 | BR4: 18.044472 | BS4: 17.531964 | BT4: 17.211561 | BU4: 17.585363
A5: Varões de aço | B5: 16.959522 | C5: 16.317244 | D5: 17.343862 | E5: 15.659388 | F5: 13.530396 | G5: 13.471166 | H5: 12.880574 | I5: 14.033724 | J5: 13.82 | K5: 13.195973 | L5: 15.809661 | M5: 15.306248 | N5: 17.025558 | O5: 15.306248 | P5: 17.025558 | Q5: 16.958031 | R5: 15.935787 | S5: 17.478712 | T5: 18.403892 | U5: 18.955385 | V5: 19.848806 | W5: 27.053559 | X5: 25.920007 | Y5: 27.225971 | Z5: 26.283666 | AA5: 28.437526 | AB5: 28.437526 | AC5: 30.342406 | AD5: 31.118453 | AE5: 29.471257 | AF5: 33.425937 | AG5: 32.755916 | AH5: 28.018763 | AI5: 25.961898 | AJ5: 23.245399 | AK5: 20.676645 | AL5: 18.692778 | AM5: 18.003927 | AN5: 16.557258 | AO5: 15.830388 | AP5: 16.598318 | AQ5: 12.962382 | AR5: 13.080296 | AS5: 14.873198 | AT5: 15.708281 | AU5: 16.837379 | AV5: 17.691985 | AW5: 19.072132 | AX5: 15.792329 | AY5: 12.067855 | AZ5: 11.052357 | BA5: 10.062505 | BB5: 10.999542 | BC5: 10.2642 | BD5: 9.5239755 | BE5: 8.5335554 | BF5: 7.8534317 | BG5: 7.7230942 | BH5: 7.3753891 | BI5: 6.5753019 | BJ5: 7.253653 | BK5: 11.002778 | BL5: 11.627896 | BM5: 11.718785 | BN5: 8.6132738 | BO5: =+Índice!BQ5/Índice!BE5*100-100 -> 7.3610886 | BP5: =+Índice!BR5/Índice!BF5*100-100 -> 6.1940472 | BQ5: =+Índice!BS5/Índice!BG5*100-100 -> 6.3110217 | BR5: 6.116054 | BS5: 3.1311388 | BT5: 2.5153576 | BU5: 5.5333184
A6: Tubos de Aço | B6: 16.182756 | C6: 17.707998 | D6: 17.491585 | E6: 18.067935 | F6: 17.925375 | G6: 18.085253 | H6: 15.609778 | I6: 18.519705 | J6: 17.273926 | K6: 15.102137 | L6: 14.6889 | M6: 16.276742 | N6: 17.321776 | O6: 16.276742 | P6: 17.321776 | Q6: 16.777829 | R6: 16.334618 | S6: 16.167602 | T6: 17.753339 | U6: 17.425052 | V6: 17.324137 | W6: 20.728646 | X6: 23.630781 | Y6: 23.055451 | Z6: 23.946733 | AA6: 24.429659 | AB6: 24.429659 | AC6: 26.567125 | AD6: 26.149128 | AE6: 23.952489 | AF6: 16.123985 | AG6: 14.475965 | AH6: 13.28771 | AI6: 11.372968 | AJ6: 9.2368419 | AK6: 6.5337159 | AL6: 4.3768497 | AM6: -0.22134881 | AN6: -0.90982541 | AO6: 0.0037204995 | AP6: 1.642763 | AQ6: 9.6198276 | AR6: 12.002874 | AS6: 13.556401 | AT6: 15.564751 | AU6: 16.129474 | AV6: 17.484614 | AW6: 20.10243 | AX6: 24.234469 | AY6: 27.795595 | AZ6: 27.019808 | BA6: 26.13919 | BB6: 26.404238 | BC6: 24.71066 | BD6: 23.098307 | BE6: 20.234858 | BF6: 18.297176 | BG6: 18.205404 | BH6: 17.578392 | BI6: 15.731739 | BJ6: 17.903385 | BK6: 17.803338 | BL6: 22.184735 | BM6: 26.904878 | BN6: 27.372154 | BO6: =+Índice!BQ6/Índice!BE6*100-100 -> 30.35558 | BP6: =+Índice!BR6/Índice!BF6*100-100 -> 32.853072 | BQ6: =+Índice!BS6/Índice!BG6*100-100 -> 34.207214 | BR6: 34.039274 | BS6: 36.860555 | BT6: 36.943191 | BU6: 33.764063
A7: Malhasol | B7: 17.004773 | C7: 17.757473 | D7: 15.953097 | E7: 18.286373 | F7: 18.282529 | G7: 20.086158 | H7: 19.923062 | I7: 19.196511 | J7: 19.299095 | K7: 19.99893 | L7: 18.728607 | M7: 17.986269 | N7: 15.704384 | O7: 17.986269 | P7: 15.704384 | Q7: 15.331177 | R7: 13.951353 | S7: 11.535414 | T7: 11.36032 | U7: 12.563376 | V7: 14.552924 | W7: 16.266706 | X7: 18.76854 | Y7: 20.700628 | Z7: 23.084939 | AA7: 25.408668 | AB7: 25.408668 | AC7: 27.121966 | AD7: 27.029863 | AE7: 25.283064 | AF7: 23.50852 | AG7: 20.748994 | AH7: 18.233207 | AI7: 15.89353 | AJ7: 14.942017 | AK7: 12.708597 | AL7: 10.879999 | AM7: 10.733437 | AN7: 11.086189 | AO7: 12.696662 | AP7: 15.385428 | AQ7: 18.517606 | AR7: 22.578094 | AS7: 26.829613 | AT7: 31.686046 | AU7: 32.131536 | AV7: 32.681479 | AW7: 33.619638 | AX7: 31.204862 | AY7: 28.640502 | AZ7: 25.824797 | BA7: 22.779435 | BB7: 19.576876 | BC7: 16.234399 | BD7: 12.763473 | BE7: 9.190689 | BF7: 5.4747515 | BG7: 5.3539626 | BH7: 4.8616461 | BI7: 4.0764243 | BJ7: 5.0099109 | BK7: 5.897184 | BL7: 6.8953554 | BM7: 7.7184875 | BN7: 7.57552 | BO7: =+Índice!BQ7/Índice!BE7*100-100 -> 7.3893817 | BP7: =+Índice!BR7/Índice!BF7*100-100 -> 6.9837331 | BQ7: =+Índice!BS7/Índice!BG7*100-100 -> 7.2590177 | BR7: 8.008117 | BS7: 8.7681358 | BT7: 10.76841 | BU7: 10.801195
A8: Aluminio | B8: 15.846832 | C8: 16.478345 | D8: 16.984448 | E8: 18.313178 | F8: 18.697598 | G8: 19.030711 | H8: 16.772793 | I8: 19.286964 | J8: 21.996357 | K8: 22.214424 | L8: 23.292234 | M8: 23.699165 | N8: 27.204851 | O8: 23.699165 | P8: 27.204851 | Q8: 28.037961 | R8: 27.687631 | S8: 28.316906 | T8: 29.363776 | U8: 30.390374 | V8: 30.261436 | W8: 28.151107 | X8: 27.476374 | Y8: 26.025576 | Z8: 25.034245 | AA8: 25.270868 | AB8: 25.270868 | AC8: 26.789144 | AD8: 27.88855 | AE8: 24.957244 | AF8: 23.177808 | AG8: 21.748415 | AH8: 21.324354 | AI8: 19.388033 | AJ8: 18.210222 | AK8: 16.305171 | AL8: 13.828648 | AM8: 9.3495037 | AN8: 7.2128586 | AO8: 5.5292157 | AP8: 5.5553862 | AQ8: 5.5238271 | AR8: 5.8521069 | AS8: 5.5500543 | AT8: 5.3422398 | AU8: 4.9140472 | AV8: 3.8769044 | AW8: 4.1620579 | AX8: 7.1695499 | AY8: 8.0134401 | AZ8: 8.6178347 | BA8: 9.4815618 | BB8: 11.24309 | BC8: 11.752498 | BD8: 12.127473 | BE8: 12.509294 | BF8: 13.640323 | BG8: 15.301195 | BH8: 17.845924 | BI8: 19.63656 | BJ8: 16.993788 | BK8: 17.652306 | BL8: 18.385508 | BM8: 18.937264 | BN8: 17.693331 | BO8: =+Índice!BQ8/Índice!BE8*100-100 -> 17.373208 | BP8: =+Índice!BR8/Índice!BF8*100-100 -> 17.677507 | BQ8: =+Índice!BS8/Índice!BG8*100-100 -> 18.053937 | BR8: 17.818394 | BS8: 15.623299 | BT8: 14.561084 | BU8: 16.095276
A9: Chapas perfiladas | B9: 15.846832 | C9: 16.478345 | D9: 16.984448 | E9: 18.313178 | F9: 18.697598 | G9: 19.030711 | H9: 16.772793 | I9: 19.286964 | J9: 21.996357 | K9: 22.214424 | L9: 23.292234 | M9: 23.699165 | N9: 27.204851 | O9: 23.699165 | P9: 27.204851 | Q9: 28.037961 | R9: 27.687631 | S9: 28.316906 | T9: 29.363776 | U9: 30.390374 | V9: 30.261436 | W9: 28.151107 | X9: 27.476374 | Y9: 26.025576 | Z9: 25.034245 | AA9: 25.270868 | AB9: 25.270868 | AC9: 26.789144 | AD9: 27.88855 | AE9: 24.957244 | AF9: 23.177808 | AG9: 21.748415 | AH9: 21.324354 | AI9: 19.388033 | AJ9: 18.210222 | AK9: 16.305171 | AL9: 13.828648 | AM9: 9.3495037 | AN9: 7.2128586 | AO9: 5.5292157 | AP9: 5.5553862 | AQ9: 5.5238271 | AR9: 5.8521069 | AS9: 5.5500543 | AT9: 5.3422398 | AU9: 4.9140472 | AV9: 3.8769044 | AW9: 4.1620579 | AX9: 7.1695499 | AY9: 8.0134401 | AZ9: 8.6178347 | BA9: 9.4815618 | BB9: 11.24309 | BC9: 11.752498 | BD9: 12.127473 | BE9: 12.509294 | BF9: 13.640323 | BG9: 15.301195 | BH9: 17.845924 | BI9: 19.63656 | BJ9: 16.993788 | BK9: 17.652306 | BL9: 18.385508 | BM9: 18.937264 | BN9: 17.693331 | BO9: =+Índice!BQ9/Índice!BE9*100-100 -> 17.373208 | BP9: =+Índice!BR9/Índice!BF9*100-100 -> 17.677507 | BQ9: =+Índice!BS9/Índice!BG9*100-100 -> 18.053937 | BR9: 17.818394 | BS9: 15.623299 | BT9: 14.561084 | BU9: 16.095276
A10: Areia | B10: 18.066374 | C10: 18.063049 | D10: 18.685092 | E10: 16.407301 | F10: 13.818284 | G10: 13.46875 | H10: 12.957617 | I10: 12.577402 | J10: 9.2561687 | K10: 9.9897391 | L10: 11.367592 | M10: 12.90877 | N10: 13.234242 | O10: 12.90877 | P10: 13.234242 | Q10: 14.125416 | R10: 14.29961 | S10: 15.098454 | T10: 15.904164 | U10: 17.589419 | V10: 20.150571 | W10: 19.449332 | X10: 18.974743 | Y10: 19.304738 | Z10: 20.751788 | AA10: 21.619424 | AB10: 21.619424 | AC10: 23.947977 | AD10: 22.848232 | AE10: 22.343898 | AF10: 20.741099 | AG10: 19.142445 | AH10: 20.231737 | AI10: 18.264946 | AJ10: 18.127205 | AK10: 16.420157 | AL10: 15.638015 | AM10: 12.812515 | AN10: 11.632668 | AO10: 13.032369 | AP10: 13.708324 | AQ10: 14.410708 | AR10: 14.202201 | AS10: 13.635841 | AT10: 14.593097 | AU10: 15.167952 | AV10: 15.9142 | AW10: 15.892981 | AX10: 15.172914 | AY10: 14.452106 | AZ10: 13.847128 | BA10: 13.356232 | BB10: 13.053634 | BC10: 12.299265 | BD10: 11.579765 | BE10: 10.435497 | BF10: 9.288068 | BG10: 8.1711965 | BH10: 7.0495304 | BI10: 5.5708096 | BJ10: 5.5294495 | BK10: 5.4503562 | BL10: 4.9476446 | BM10: 4.251113 | BN10: 4.1604756 | BO10: =+Índice!BQ10/Índice!BE10*100-100 -> 4.4901508 | BP10: =+Índice!BR10/Índice!BF10*100-100 -> 4.9834222 | BQ10: =+Índice!BS10/Índice!BG10*100-100 -> 5.4878433 | BR10: 6.5422454 | BS10: 7.601229 | BT10: 8.7897768 | BU10: 8.6826067
A11: Betão pronto | B11: 17.572334 | C11: 19.169174 | D11: 14.524627 | E11: 16.279262 | F11: 13.43542 | G11: 13.294959 | H11: 13.468634 | I11: 12.19298 | J11: 10.824662 | K11: 12.801982 | L11: 17.77625 | M11: 21.115425 | N11: 19.983585 | O11: 21.115425 | P11: 19.983585 | Q11: 18.048828 | R11: 19.899913 | S11: 19.182877 | T11: 19.553072 | U11: 20.024607 | V11: 23.067366 | W11: 27.839167 | X11: 23.880958 | Y11: 22.902304 | Z11: 24.069772 | AA11: 24.601823 | AB11: 24.601823 | AC11: 26.166376 | AD11: 25.674874 | AE11: 24.063415 | AF11: 21.744125 | AG11: 21.534187 | AH11: 20.448053 | AI11: 18.238815 | AJ11: 17.588165 | AK11: 15.876369 | AL11: 14.7699 | AM11: 10.954668 | AN11: 9.833875 | AO11: 11.626961 | AP11: 13.105531 | AQ11: 14.788924 | AR11: 15.373004 | AS11: 16.416964 | AT11: 18.276491 | AU11: 17.340391 | AV11: 16.590653 | AW11: 15.513242 | AX11: 16.485346 | AY11: 18.882518 | AZ11: 18.90114 | BA11: 18.073493 | BB11: 17.248802 | BC11: 16.442635 | BD11: 15.720266 | BE11: 15.044063 | BF11: 14.407297 | BG11: 15.990789 | BH11: 17.613792 | BI11: 19.337556 | BJ11: 17.946098 | BK11: 15.069513 | BL11: 13.982547 | BM11: 12.817636 | BN11: 12.486487 | BO11: =+Índice!BQ11/Índice!BE11*100-100 -> 13.072527 | BP11: =+Índice!BR11/Índice!BF11*100-100 -> 13.318227 | BQ11: =+Índice!BS11/Índice!BG11*100-100 -> 12.55277 | BR11: 13.204499 | BS11: 11.868313 | BT11: 10.706039 | BU11: 11.009589
A12: Abobadilha | B12: 17.572334 | C12: 19.169174 | D12: 14.524627 | E12: 16.279262 | F12: 13.43542 | G12: 13.294959 | H12: 13.468634 | I12: 12.19298 | J12: 10.824662 | K12: 12.801982 | L12: 17.77625 | M12: 21.115425 | N12: 19.983585 | O12: 21.115425 | P12: 19.983585 | Q12: 18.048828 | R12: 19.899913 | S12: 19.182877 | T12: 19.553072 | U12: 20.024607 | V12: 23.067366 | W12: 27.839167 | X12: 23.880958 | Y12: 22.902304 | Z12: 24.069772 | AA12: 24.601823 | AB12: 24.601823 | AC12: 26.166376 | AD12: 25.674874 | AE12: 24.063415 | AF12: 21.744125 | AG12: 21.534187 | AH12: 20.448053 | AI12: 18.238815 | AJ12: 17.588165 | AK12: 15.876369 | AL12: 14.7699 | AM12: 10.954668 | AN12: 9.833875 | AO12: 11.626961 | AP12: 13.105531 | AQ12: 14.788924 | AR12: 15.373004 | AS12: 16.416964 | AT12: 18.276491 | AU12: 17.340391 | AV12: 16.590653 | AW12: 15.513242 | AX12: 16.485346 | AY12: 18.882518 | AZ12: 18.90114 | BA12: 18.073493 | BB12: 17.248802 | BC12: 16.442635 | BD12: 15.720266 | BE12: 15.044063 | BF12: 14.407297 | BG12: 15.990789 | BH12: 17.613792 | BI12: 19.337556 | BJ12: 17.946098 | BK12: 15.069513 | BL12: 13.982547 | BM12: 12.817636 | BN12: 12.486487 | BO12: =+Índice!BQ12/Índice!BE12*100-100 -> 13.072527 | BP12: =+Índice!BR12/Índice!BF12*100-100 -> 13.318227 | BQ12: =+Índice!BS12/Índice!BG12*100-100 -> 12.55277 | BR12: 13.204499 | BS12: 11.868313 | BT12: 10.706039 | BU12: 11.009589
A13: Pedra britada e Mármore | B13: 12.896941 | C13: 12.859839 | D13: 16.133991 | E13: 13.994214 | F13: 14.539443 | G13: 12.803324 | H13: 12.803324 | I13: 12.965096 | J13: 13.115271 | K13: 13.110143 | L13: 11.847244 | M13: 17.253395 | N13: 17.205015 | O13: 17.253395 | P13: 17.205015 | Q13: 17.05046 | R13: 14.991374 | S13: 15.334517 | T13: 15.64923 | U13: 14.907149 | V13: 15.652724 | W13: 14.308192 | X13: 15.450186 | Y13: 15.003641 | Z13: 14.839044 | AA13: 16.163106 | AB13: 16.163106 | AC13: 18.081363 | AD13: 18.096373 | AE13: 16.751731 | AF13: 16.455147 | AG13: 16.012405 | AH13: 15.530867 | AI13: 14.975572 | AJ13: 14.941882 | AK13: 14.612 | AL13: 14.411541 | AM13: 13.23463 | AN13: 12.509843 | AO13: 12.125917 | AP13: 13.013593 | AQ13: 13.615207 | AR13: 13.484141 | AS13: 14.12018 | AT13: 15.558576 | AU13: 15.308149 | AV13: 16.10644 | AW13: 17.094518 | AX13: 16.877899 | AY13: 17.360131 | AZ13: 16.914537 | BA13: 16.457255 | BB13: 16.062983 | BC13: 15.729841 | BD13: 15.376582 | BE13: 15.081229 | BF13: 14.716665 | BG13: 14.281743 | BH13: 13.775484 | BI13: 13.321969 | BJ13: 12.956435 | BK13: 12.073517 | BL13: 11.972097 | BM13: 10.873195 | BN13: 10.154436 | BO13: =+Índice!BQ13/Índice!BE13*100-100 -> 9.1528752 | BP13: =+Índice!BR13/Índice!BF13*100-100 -> 8.0847073 | BQ13: =+Índice!BS13/Índice!BG13*100-100 -> 7.8281688 | BR13: 7.2968176 | BS13: 6.7678348 | BT13: 5.9703046 | BU13: 5.6636056
A14: Burgau | B14: 12.896941 | C14: 12.896829 | D14: 16.133991 | E14: 13.994214 | F14: 14.539443 | G14: 12.803324 | H14: 12.803324 | I14: 12.965096 | J14: 13.115271 | K14: 13.110143 | L14: 11.847244 | M14: 17.253395 | N14: 17.205015 | O14: 17.253395 | P14: 17.205015 | Q14: 17.05046 | R14: 14.991374 | S14: 15.334517 | T14: 15.64923 | U14: 14.907149 | V14: 15.652724 | W14: 14.308192 | X14: 15.450186 | Y14: 15.003641 | Z14: 14.839044 | AA14: 16.163106 | AB14: 16.163106 | AC14: 18.081363 | AD14: 18.096373 | AE14: 16.751731 | AF14: 16.455147 | AG14: 16.012405 | AH14: 15.530867 | AI14: 14.975572 | AJ14: 14.941882 | AK14: 14.612 | AL14: 14.411541 | AM14: 13.23463 | AN14: 12.509843 | AO14: 12.125917 | AP14: 13.013593 | AQ14: 13.615207 | AR14: 13.484141 | AS14: 14.12018 | AT14: 15.558576 | AU14: 15.308149 | AV14: 16.10644 | AW14: 17.094518 | AX14: 16.877899 | AY14: 17.360131 | AZ14: 16.914537 | BA14: 16.457255 | BB14: 16.062983 | BC14: 15.729841 | BD14: 15.376582 | BE14: 15.081229 | BF14: 14.716665 | BG14: 14.281743 | BH14: 13.775484 | BI14: 13.321969 | BJ14: 12.956435 | BK14: 12.073517 | BL14: 11.972097 | BM14: 10.873195 | BN14: 10.154436 | BO14: =+Índice!BQ14/Índice!BE14*100-100 -> 9.1528752 | BP14: =+Índice!BR14/Índice!BF14*100-100 -> 8.0847073 | BQ14: =+Índice!BS14/Índice!BG14*100-100 -> 7.8281688 | BR14: 7.2968176 | BS14: 6.7678348 | BT14: 5.9703046 | BU14: 5.6636056
... A29: Vigas, Vigotas e Ripas | B29: 13.784603 | C29: 14.031089 | D29: 16.831569 | E29: 14.341258 | F29: 12.248757 | G29: 13.077704 | H29: 9.0936051 | I29: 13.923032 | J29: 13.81074 | K29: 14.409533 | L29: 19.332057 | M29: 21.645278 | N29: 24.087796 | O29: 21.645278 | P29: 24.087796 | Q29: 24.951643 | R29: 23.297188 | S29: 23.974922 | T29: 25.124781 | U29: 26.270166 | V29: 27.692399 | W29: 19.279672 | X29: 24.441282 | Y29: 26.68576 | Z29: 26.717082 | AA29: 27.419382 | AB29: 27.419382 | AC29: 29.516561 | AD29: 30.051438 | AE29: 27.648779 | AF29: 25.809305 | AG29: 20.9423 | AH29: 19.2891 | AI29: 17.670866 | AJ29: 16.686412 | AK29: 15.694727 | AL29: 14.800871 | AM29: 10.909212 | AN29: 9.1717717 | AO29: 8.8315816 | AP29: 9.2504179 | AQ29: 9.5879983 | AR29: 9.6981612 | AS29: 9.9727912 | AT29: 10.153785 | AU29: 10.185446 | AV29: 9.498955 | AW29: 8.6793833 | AX29: 10.013194 | AY29: 11.394256 | AZ29: 13.10911 | BA29: 14.896056 | BB29: 16.921651 | BC29: 18.295393 | BD29: 18.412974 | BE29: 18.318138 | BF29: 19.039084 | BG29: 20.535557 | BH29: 22.778036 | BI29: 24.858299 | BJ29: 26.253767 | BK29: 27.572194 | BL29: 28.703062 | BM29: 30.526629 | BN29: 28.129638 | BO29: =+Índice!BQ29/Índice!BE29*100-100 -> 25.938467 | BP29: =+Índice!BR29/Índice!BF29*100-100 -> 25.069935 | BQ29: =+Índice!BS29/Índice!BG29*100-100 -> 25.269046 | BR29: 24.095963 | BS29: 22.233749 | BT29: 22.84927 | BU29: 19.354353
A30: Fonte: INE/Departamento de Estatísticas Económica e Financeira

Sheet Contribuição_Mensal
A1: Contribuição Mensal do IPMC
A2: Materiais de Construção | B2: 43831 | C2: 43862 | D2: 43891 | E2: 43922 | F2: 43952 | G2: 43983 | H2: 44013 | I2: 44044 | J2: 44075 | K2: 44105 | L2: 44136 | M2: 44166 | N2: 44197 | O2: 44228 | P2: 44256 | Q2: 44287 | R2: 44317 | S2: 44348 | T2: 44378 | U2: 44409 | V2: 44440 | W2: 44470 | X2: 44501 | Y2: 44531 | Z2: 44562 | AA2: 44593 | AB2: 44621 | AC2: 44652 | AD2: 44682 | AE2: 44713 | AF2: 44743 | AG2: 44774 | AH2: 44805 | AI2: 44835 | AJ2: 44866 | AK2: 44896 | AL2: Jan-23 | AM2: Fev-23 | AN2: Mar-23 | AO2: Abr-23 | AP2: Mai-23 | AQ2: Jun-23 | AR2: Jul-23 | AS2: Ago-23 | AT2: Set-23 | AU2: Out-23 | AV2: Nov-23 | AW2: Dez-23 | AX2: Jan-23 | AY2: Fev-23 | AZ2: Mar-23 | BA2: Abr-23 | BB2: Mai-23 | BC2: 45444 | BD2: 45474 | BE2: 45505 | BF2: 45536 | BG2: 45566 | BH2: 45597 | BI2: 45627 | BJ2: 45658 | BK2: 45689 | BL2: 45717 | BM2: 45748 | BN2: 45778 | BO2: 45809 | BP2: 45839 | BQ2: 45870 | BR2: 45901 | BS2: 45931 | BT2: 45962 | BU2: 45992
A3: Total Material de Construção | B3: 0.98892154 | C3: 1.1174292 | D3: 0.88561806 | E3: 0.49130359 | F3: 1.3844747 | G3: 1.3856311 | H3: 0.66650274 | I3: 1.3640145 | J3: 0.92195251 | K3: 0.90915254 | L3: 1.8456655 | M3: 2.7249733 | N3: 1.8526147 | O3: 2.7249733 | P3: 1.8526147 | Q3: 1.5066017 | R3: -0.79808704 | S3: 0.34584909 | T3: 1.4865971 | U3: 1.7479917 | V3: 1.9434798 | W3: 1.5639496 | X3: 1.9535782 | Y3: 1.9493311 | Z3: 2.0563245 | AA3: 2.135776 | AB3: 2.135776 | AC3: 1.8549454 | AD3: 0.87982958 | AE3: 0.44260612 | AF3: 0.34426923 | AG3: 0.61758818 | AH3: 0.67951099 | AI3: 0.4779861 | AJ3: 0.56723571 | AK3: 0.70075418 | AL3: 0.75514091 | AM3: 0.72689796 | AN3: 0.87945969 | AO3: 1.0319448 | AP3: 1.0214044 | AQ3: 1.1091347 | AR3: 1.186065 | AS3: 1.2631141 | AT3: 1.340656 | AU3: 2.0858963 | AV3: 2.1014141 | AW3: 1.9318234 | AX3: 2.5997968 | AY3: 2.2611347 | AZ3: 2.1232237 | BA3: 0.44451783 | BB3: 0.44451783 | BC3: 1.8690989 | BD3: 1.7892442 | BE3: 1.4243551 | BF3: 1.2069546 | BG3: 1.3902646 | BH3: 1.3192069 | BI3: 1.4468432 | BJ3: 1.5317044 | BK3: 1.3107653 | BL3: 1.2412228 | BM3: 1.1413017 | BN3: 0.4619476 | BO3: 0.83 | BP3: 1.08 | BQ3: 0.70669129 | BR3: 0.65383624 | BS3: 0.584352 | BT3: 0.74977883 | BU3: 0.57710436
A4: Aço | B4: 0.28790586 | C4: 0.37402013 | D4: 0.36185691 | E4: 0.15005526 | F4: 0.26679811 | G4: 0.34564644 | H4: 0.39334137 | I4: 0.4103059 | J4: 0.25784624 | K4: 0.16496466 | L4: 0.63012685 | M4: 0.49734428 | N4: 0.63145132 | O4: 0.49734428 | P4: 0.63145132 | Q4: 0.30782235 | R4: 0.17482719 | S4: 0.34002774 | T4: 0.57151246 | U4: 0.39484768 | V4: 0.51420658 | W4: 0.65603764 | X4: 0.82299491 | Y4: 0.63044068 | Z4: 0.63976604 | AA4: 0.65918925 | AB4: 2.2314437 | AC4: 2.2212516 | AD4: 1.3913584 | AE4: 0.49962657 | AF4: 0.37231111 | AG4: 0.91172925 | AH4: 0.49230737 | AI4: 0.55203626 | AJ4: 0.1614624 | AK4: 0.15134373 | AL4: 0.09023672 | AM4: 0.28308331 | AN4: 0.35503777 | AO4: 0.28308331 | AP4: 0.42580243 | AQ4: 0.42145326 | AR4: 0.47287147 | AS4: 0.5196407 | AT4: 0.56634065 | AU4: 0.61317587 | AV4: 0.52744211 | AW4: 0.28711739 | AX4: 0.42905414 | AY4: 0.28409596 | AZ4: 0.12006383 | BA4: 0.1755957 | BB4: 0.1755957 | BC4: 0.61693148 | BD4: 0.21822707 | BE4: 0.26104675 | BF4: 0.13358019 | BG4: 0.1823321 | BH4: 0.23008096 | BI4: 0.2776611 | BJ4: 0.22019572 | BK4: 0.59177867 | BL4: 0.62824931 | BM4: 0.66671067 | BN4: 0.23266332 | BO4: 0.36 | BP4: 0.37 | BQ4: 0.28456762 | BR4: 0.13672888 | BS4: 0.1132555 | BT4: 0.21010085 | BU4: 0.20552484
